Workbook
Name DEfensive: Lists!$CQ:$CQ
Name EventType: Lists!$A$2:$A$16
Name Faceoff: Lists!$U$2:$U$1048576
Name Goal: Lists!$X$2:$X$1048576
Name Goal_PenaltyShot: Lists!$BO$2:$BO$1048576
Name Goal_Scored: Lists!$BM$2:$BM$1048576
Name Goal_Shootout: Lists!$BN$2:$BN$1048576
Name LoosePuck: Lists!$AD$2:$AD$1048576
Name Offensive: Lists!$CO:$CO
Name Pass: Lists!$W$2:$W$1048576
Name Pass_Completed: Lists!$AF$2:$AF$1048576
Name Pass_Deflected: Lists!$AH$2:$AH$1048576
Name Pass_Intercepted: Lists!$AI$2:$AI$1048576
Name Pass_Missed: Lists!$AG$2:$AG$1048576
Name Penalty: Lists!$AA$2:$AA$1048576
Name Penalty_Major: Lists!$AO$2:$AO$1048576
Name Penalty_Minor: Lists!$AP$2:$AP$1048576
Name Penalty_Offsetting: Lists!$AQ$2:$AQ$1048576
Name PenaltyShot_Missed: Lists!$AY$2:$AY$1048576
Name PenaltyShot_OnNet: Lists!$AX$2:$AX$1048576
Name PenaltyShot_Saved: Lists!$AZ$2:$AZ$1048576
Name PenaltyShot_Shootout: Lists!$AB$2:$AB$1048576
Name Play: Lists!$T:$T
Name Play_Defensive: Lists!$BS:$BS
Name Play_Offensive: Lists!$BR:$BR
Name Possession: Lists!$BT:$BT
Name Rebound: Lists!$BQ$2:$BQ$1048576
Name Save: Lists!$AE$2:$AE$1048576
Name Save_Freeze: Lists!$BB$2:$BB$1048576
Name Save_Played: Lists!$BP:$BP
Name Save_Rebound: Lists!$BA$2:$BA$1048576
Name Shootout_Missed: Lists!$AV$2:$AV$1048576
Name Shootout_OnNet: Lists!$AU$2:$AU$1048576
Name Shootout_Saved: Lists!$AW$2:$AW$1048576
Name Shot: Lists!$V$2:$V$1048576
Name Shot_Blocked: Lists!$BE$2:$BE$1048576
Name Shot_BlockedSameTeam: Lists!$BF$2:$BF$1048576
Name Shot_Deflected: Lists!$BG$2:$BG$1048576
Name Shot_DeflectedGoal: Lists!$BL$2:$BL$1048576
Name Shot_DeflectedOnNetSaved: Lists!$BH$2:$BH$1048576
Name Shot_Missed: Lists!$BD$2:$BD$1048576
Name Shot_MissedPost: Lists!$BW:$BW
Name Shot_OnNetGoal: Lists!$BJ$2:$BJ$1048576
Name Shot_OnNetSaved: Lists!$BC$2:$BC$1048576
Name Shot_TippedGoal: Lists!$BK$2:$BK$1048576
Name Shot_TippedOnNetSaved: Lists!$BI$2:$BI$1048576
Name Stoppage: Lists!$AC$2:$AC$1048576
Name Stoppage_Other: Lists!$AT$2:$AT$1048576
Name Stoppage_Period: Lists!$AS$2:$AS$1048576
Name Stoppage_Play: Lists!$AR$2:$AR$1048576
Name Turnover: Lists!$Y$2:$Y$1048576
Name Turnover_Giveaway: Lists!$AJ$2:$AJ$1048576
Name Turnover_Takeaway: Lists!$AK$2:$AK$1048576
Name Zone_Entry: Lists!$AL$2:$AL$1048576
Name Zone_Entry_Exit: Lists!$Z$2:$Z$1048576
Name Zone_EntryFailed: Lists!$DG:$DG
Name Zone_Exit: Lists!$AM$2:$AM$1048576
Name Zone_ExitFailed: Lists!$DH:$DH
Name Zone_Keepin: Lists!$AN$2:$AN$1048576

Sheet Rules
A1: EventType | B1: Definition | C1: Next Event | D1: Uses | E1: Linked Events | F1: Successful/Unsuccessful | G1: Successful Def | J1: EventTypeDetail | K1: Definition | L1: Next Event | M1: Uses | N1: Linked Events | O1: Successful/Unsuccessful | P1: Successful Def | S1: EventTypeDetail2 | T1: Definition | U1: Next Event | V1: Uses | W1: Linked Events | X1: Successful/Unsuccessful | Y1: Successful Def | AC1: Definition | AD1: Next Event | AE1: Uses | AF1: Linked Events | AG1: Successful/Unsuccessful | AH1: Successful Def | AL1: Definition | AM1: Next Event | AN1: Uses | AO1: Linked Events | AP1: Linked Events | AQ1: Successful/Unsuccessful | AR1: Successful Def | AT1: play_tag1 | AU1: Definition | AV1: Next Event | AW1: Uses | AX1: Linked Events | AZ1: play_tag2 | BA1: Definition | BB1: Next Event | BC1: Uses | BD1: Linked Events | BF1: Context | BG1: Definition | BH1: Next Event | BI1: Uses | BJ1: Linked Events | BM1: shift_start | BN1: Definition | BO1: Next Event | BP1: Linked Events | BR1: shift_end | BS1: Definition | BT1: Next Event | BU1: Linked Events
A2: Faceoff | J2: Faceoff | S2: PenaltyShot/Shootout | AB2: Offensive | AH2: sucessful if next play positive | AK2: Defensive | AR2: sucessful if next play positive | AT2: LowToHigh | AZ2: Rush | BF2: LeadToBreakout | BM2: PeriodStart | BR2: -
A3: Shot | E3: Save | J3: Faceoff-AfterPenalty | S3: PenaltyShot_OnNet | X3: s | AB3: OffensivePlay_Possession-DriveMiddle | AK3: Defensive_PlayPossession-PokeCheck | AT3: HighToLow | AZ3: Cycle | BF3: LeadToZoneEntry | BM3: FaceoffAfterGoal | BR3: Period Start
A4: Pass | J4: Faceoff-AfterGoal | S4: PenaltyShot_Missed | X4: u | AB4: OffensivePlay_Possession-DriveWide | AK4: Defensive_PlayPossession-SeperateFromPuck | AT4: CrossIce | AZ4: Forecheck | BF4: LeadToTurnover | BM4: GameStart | BR4: Period End
A5: Goal | E5: Shot | J5: Faceoff-PeriodStart | S5: PenaltyShot_Saved | X5: s | AB5: OffensivePlay_Possession-DriveCorner | AK5: Defensive_PlayPossession-Backcheck | AT5: Slot | AZ5: Dumpin | BF5: LeadToShot | BM5: FaceoffAfterPenalty | BR5: Puck Out of Play
A6: Turnover | E6: Pass, Shot, Play | J6: Shot-OnNet | S6: ShootoutShot_OnNet | X6: s | AB6: OffensivePlay_Possession-DriveNetMiddle | AK6: Defensive_PlayPossession-FroceWide | AZ6: Regroup | BF6: LeadToGoal | BM6: OtherFaceoff | BR6: Injury
A7: Zone_Entry_Exit | E7: Pass, Turnover, Attempted Failed, Keepins | J7: Shot-Missed | S7: ShootoutShot_Missed | X7: u | AB7: OffensivePlay_Possession-DriveNetWide | AK7: Defensive_PlayPossession-Contain | AZ7: Counter | BF7: LeadToPenalty | BM7: DeadIce/Stoppage | BR7: Home Penalty
A8: Penalty | J8: Shot-Blocked | S8: ShootoutShot_Saved | X8: s | AB8: OffensivePlay_Possession-CrashNet | AK8: Defensive_PlayPossession-BeatMiddle | AZ8: ZoneExit | BF8: LeadToFailedBreakout | BM8: Intermission | BR8: Away Penalty
A9: PenaltyShot_Shootout | J9: Shot-BlockedSameTeam | AB9: OffensivePlay_Possession-Delay | AK9: Defensive_PlayPossession-BeatWide | AZ9: ZoneEntry | BF9: LeadToFailedZoneEntry | BM9: DelayedPenalty | BR9: Home Goalie Stoppage
A10: Stoppage | E10: Save Freeze | J10: Shot-Deflected | S10: Stoppage_Period | AB10: OffensivePlay_Possession-Deke | AK10: Defensive_PlayPossession-BeatDeke | AZ10: Clear | BM10: GameStart | BR10: Away Goalie Stoppage
A11: Hit | J11: Shot-DeflectedOnNet | S11: Stoppage_Play | AB11: OffensivePlay_Possession-Chip | AK11: Defensive_PlayPossession-BeatSpeed | BR11: Home Offside
A12: Possession | J12: Shot-Tipped | S12: Stoppage_Other | AB12: OffensivePlay_Possession-Other | AK12: Defensive_PlayPossession-Pressure | BR12: Home Icing
A13: LoosePuck | J13: Pass-Completed | S13: Stoppage_GameEnd | AB13: OffensivePlay_Possession-Speed | AK13: Defensive_PlayPossession-Zone | BR13: Away Offside
A14: Save | E14: Shot, Stoppage, Deadice | J14: Pass-Missed | AB14: OffensivePlay_Possession-OpenIceDeke | AK14: Defensive_PlayPossession-ManOnMan | BR14: Away Icing
A15: TeamPossessionChange | J15: Pass-Deflected | S15: Save_Rebound | AB15: OffensivePlay_Possession-EndToEndRush | AK15: Defensive_PlayPossession-Tracker | BR15: Clock Problem
A16: Rebound | E16: Shot, Save | J16: Pass-Intercepted | S16: Save_Freeze | AB16: OffensivePlay_Possession-FrontofNet | AK16: Defensive_PlayPossession-Surf | BR16: Puck Frozen
A17: DeadIce | J17: Turnover-Giveaway | S17: Save_Played | AB17: OffensivePlay_Possession-CutBack | AK17: Defensive_PlayPossession-StickCheck | BR17: Puck in Crowd
A18: Play | J18: Turnover-Takeaway | AB18: OffensivePlay_Possession-Wheel | AK18: Defensive_PlayPass-PassIntercepted | BR18: Goalie Stopped (after SOG)
A19: Timeout | J19: Zone-Entry | S19: Pass-Stretch | X19: s/u | AB19: OffensivePlay_Possession-ForecedOutside | AK19: Defensive_PlayPass-InShotPassLane | BR19: Referee or Linesperson
A20: Intermission | J20: Zone-Exit | S20: Pass-Rim/Wrap | X20: s/u | AB20: OffensivePlay_Pass-AssistPrimary | AK20: Defensive_PlayShot-BoxOut | BR20: High Stick
A21: Clockstop | J21: Zone-Keepin | S21: Pass-Backhand | X21: s/u | AB21: OffensivePlay_Pass-AssistSecondary | AK21: Defensive_PlayShot-BlockedShot | BR21: Objects on Ice
A22: GameStart | J22: Zone_Entryfailed | S22: Pass-Forehand | X22: s/u | AB22: OffensivePlay_Pass-AssistTertiary | AK22: Defensive_PlayShot-FrontofNet | BR22: Hand Pass
A23: GameEnd | J23: Zone_ExitFailed | S23: Pass-Bank | X23: s/u | AB23: OffensivePlay_Pass-GiveAndGo | AK23: Defensive_PlayZone-ClearingAttempt | BR23: Premature Substitution
A24: Penalty_Delayed | J24: Zone_KeepinFailed | S24: Pass-Dump | X24: s/u | AB24: OffensivePlay_Pass-Reverse | AK24: Defensive_PlayZone-ZoneEntryDenial | BR24: Puck in Netting
A25: Zone_Change | J25: Penalty | S25: Pass-Tipped | X25: s/u | AB25: OffensivePlay_Pass-QuickUp | AK25: Defensive_PlayZone-ZoneExitDenial | BR25: Puck in Benches
J26: Penalty-Offsetting | S26: Pass-Lob | X26: s/u | AB26: OffensivePlay_Pass-SecondTouch | AK26: Defensive_PlayZone-PenaltyKillClear | BR26: Net Dislodged Offensive Skater
J27: Stoppage-Freeze | S27: Pass-Drop | X27: s/u | AB27: OffensivePlay_Pass-ReceiverMissed | AK27: Defensive_PlayZone-PuckRetrievalDumpIn | BR27: Puck Frzn-Goalie-Bynd Ctr
J28: Stoppage-OutfofPlay | S28: Pass-Deflected/TippedShot | X28: s/u | AB28: OffensivePlay_Shot-Screen | AK28: Defensive_PlayZone-PuckRetrievalShot | BR28: Skater Puck Frozen
J29: Stoppage-PeriodEnd | S29: Pass-ReceiverMissed | X29: s/u | AB29: OffensivePlay_Zone-Breakout | AK29: Defensive_PlayZone-PuckRetreivalTurnover | BR29: Valid stoppage type reasons (reason):
J30: Stoppage-Goal | S30: Pass-OneTouch | X30: s/u | AB30: OffensivePlay_Zone-DumpChase | AK30: Defensive_PlayZone-PuckRetreivalPass | BR30: TV timeout
J31: Stoppage-Penalty | S31: Pass-SecondTouch | X31: s/u | AB31: OffensivePlay_Zone-Forecheck | AK31: Defensive_PlayZone-PuckRetrievalRebound | BR31: Home Timeout
J32: Shootout-OnNet | S32: Pass-QuickUp | X32: s/u | AB32: OffensivePlay_Zone-Dump/RimInZone | AK32: Defensive_PlayZone-PuckRecoveryDumpIn | BR32: Visitor Timeout
J33: Shootout-Missed | S33: Pass-GiveAndGo | X33: s/u | AB33: OffensivePlay_Zone-DumpInAttempt | AK33: Defensive_PlayZone-PuckRecoveryShot | BR33: Player Injury
J34: Shootout-Saved | S34: Pass-Reverse | X34: s/u | AB34: OffensivePlay_Zone-Breakout | AK34: Defensive_PlayZone-PuckRecoveryTurnover | BR34: Official Injury
J35: PenaltyShot-OnNet | S35: Pass-Other | X35: s/u | AB35: OffensivePlay_Zone-Cycle | AK35: Defensive_PlayZone-PuckRecoveryPass | BR35: Rink Repair
J36: PenaltyShot-Missed | AB36: OffensivePlay_Zone-PuckRetrievalDumpIn | AK36: Defensive_PlayZone-PuckRecoveryRebound | BR36: Ice problem
J37: PenaltyShot-Saved | S37: Giveaway-Misplayed | AB37: OffensivePlay_Zone-PuckRetrievalShot | AK37: Defensive_PlayZone-ForcedDumpin/Clear | BR37: Player Equipment
J38: LoosePuck-Forecheck | S38: Giveaway-BattleLost | AB38: OffensivePlay_Zone-PuckRetreivalTurnover | AK38: Offensive_Zone-AttemptedKeepin | BR38: Video Review
J39: LoosePuck-Battle | S39: Giveaway-PassIntercepted | AB39: OffensivePlay_Zone-PuckRetreivalPass | AK39: Defensive_Zone-AttemptedBreakOutPass | BR39: Chlg Hm - off-side
J40: Save-Rebound | S40: Giveaway-PassMissed | AB40: OffensivePlay_Zone-PuckRetreivalRebound | AK40: Defensive_Zone-AttemptedBreakOutRush | BR40: Chlg Vis - off-side
...

Sheet Lists
A1: EventType | C1: EventTypeDetail | E1: EventTypeDetail2 | G1: OffensivePlay | I1: DefensivePlay | K1: Team | N1: NHL Net | O1: Max | P1: Min | Q1: Total Max | R1: Total Min | T1: Play | U1: Faceoff | V1: Shot | W1: Pass | X1: Goal | Y1: Turnover | Z1: Zone Entry/Exit | AA1: Penalty | AB1: PenaltyShot/Shootout | AC1: Stoppage | AD1: LoosePuck | AE1: Save | AF1: Pass-Completed | AG1: Pass-Missed | AH1: Pass-Deflected | AI1: Pass-Intercepted | AJ1: Turnover-Giveaway | AK1: Turnover-Takeaway | AL1: Zone-Entry | AM1: Zone-Exit | AN1: Zone-Keepin | AO1: Penalty-Major | AP1: Penalty-Minor | AQ1: Penalty-Offsetting | AR1: Stoppage-Play | AS1: Stoppage-Period | AT1: Stoppage-Other | AU1: Shootout-OnNet | AV1: Shootout-Missed | AW1: Shootout-Saved | AX1: PenaltyShot-OnNet | AY1: PenaltyShot-Missed | AZ1: PenaltyShot-Saved | BA1: Save-Rebound | BB1: Save-Freeze | BC1: Shot_OnNetSaved | BD1: Shot_Missed | BE1: Shot_Blocked | BF1: Shot_BlockedSameTeam | BG1: Shot_Deflected | BH1: Shot_DeflectedOnNetSaved | BI1: Shot_TippedOnNetSaved | BJ1: Shot_OnNetGoal | BK1: Shot_TippedGoal | BL1: Shot_DeflectedGoal | BM1: Goal_Scored | BN1: Goal_Shootout | BO1: Goal_PenaltyShot | BP1: Save_Played | BQ1: Rebound | BR1: Play_Offensive | BS1: Play_Defensive | BT1: Possession | BU1: Faceoff | BV1: None | BW1: Shot_MissedPost | CA1: shift_start | CC1: shift_end | CE1: label | CG1: play_detail1 | CH1: play_detail2 | CL1: Offensive | CM1: Defensive | CO1: Offensive | CQ1: Defensive | CS1: play_tag1 | CU1: play_tag2 | CW1: Context | CY1: Offensive | DD1: Defensive | DG1: Zone-EntryFailed | DH1: Zone-ExitFailed | DI1: Zone-KeepinFailed
K2: Home | L2: =K3 -> Away | N2: X | O2: 36 | P2: -36 | Q2: =O2+O4 -> 38.375 | R2: =P2-O4 -> -38.375 | T2: Play_Offensive | U2: Faceoff_AfterPenalty | V2: Shot_OnNetSaved | W2: Pass_Completed | X2: Goal_Scored | Y2: Turnover_Giveaway | Z2: Zone_Entry | AA2: Penalty_Minor | AB2: PenaltyShot_OnNet | AC2: Stoppage_Period | AD2: LoosePuck_Forecheck | AE2: Save_Rebound | AF2: Pass-Stretch | AG2: Pass-Stretch | AH2: Pass-Stretch | AI2: Pass-Stretch | AJ2: Giveaway-Misplayed | AK2: Takeaway-BattleWon | AL2: ZoneEntry-Rush | AM2: ZoneExit-Rush | AN2: Zone-KeepIn | AO2: Penalty-Bench Penalty | AP2: Penalty-Bench Penalty | AQ2: Penalty-Bench Penalty | AR2: Stoppage-Icing | AS2: Stoppage-StartofShootout | AT2: Stoppage-ObjectsonIce | AU2: Shot-Wrist | AV2: Shot-Wrist | AW2: Shot-Wrist | AX2: Shot-Wrist | AY2: Shot-Wrist | AZ2: Shot-Wrist | BA2: Save-Glove | BB2: Save-Glove | BC2: Shot-Wrist | BD2: Shot-Wrist | BE2: Shot-Wrist | BF2: Shot-Wrist | BG2: Shot-Deflection | BH2: Shot-Deflection | BI2: Shot-Tip | BJ2: Shot-Wrist | BL2: Shot-Deflection | BM2: Goal-Wrist | BN2: Goal-Wrist | BO2: Goal-Wrist | BP2: Save-Glove | BQ2: Rebound_TeamRecovered | BS2: Play-PokeCheck | BT2: Breakaway | BU2: Shot | BV2: All | BW2: Shot-Wrist | BX2: event_team_player_1 | BY2: e | CA2: PeriodStart | CC2: - | CE2: Assist-Primary | CG2: OffensivePlay-DriveMiddle | CJ2: Offensive | CL2: OffensivePlay-Drive | CO2: =CY2&CZ2&"-"&DA2 -> OffensivePlay_Possession-DriveMiddle | CQ2: =DD2&DE2&"-"&DF2 -> Defensive_PlayPossession-PokeCheck | CS2: LowToHigh | CU2: Rush | CW2: LeadToBreakout | CY2: OffensivePlay_ | CZ2: Possession | DA2: DriveMiddle | DD2: Defensive_Play | DE2: Possession | DF2: PokeCheck | DG2: ZoneEntry-Rush | DH2: ZoneExit-Rush | DI2: Zone-KeepIn
A3: Faceoff | B3: None | C3: Faceoff | E3: Shot-Wrist | G3: DriveMiddle | I3: PokeCheck | K3: Away | L3: =K2 -> Home | N3: Y | O3: 24 | P3: -24 | Q3: =O3+O5 -> 26.375 | R3: -24 | T3: Play_Defensive | U3: Faceoff_AfterGoal | V3: Shot_Missed | W3: Pass_Missed | X3: Goal_Shootout | Y3: Turnover_Takeaway | Z3: Zone_Exit | AA3: Penalty_Offsetting | AB3: PenaltyShot_Missed | AC3: Stoppage_Play | AD3: LoosePuck_Battle | AE3: Save_Freeze | AF3: Pass-Rim/Wrap | AG3: Pass-Rim/Wrap | AH3: Pass-Rim/Wrap | AI3: Pass-Rim/Wrap | AJ3: Giveaway-BattleLost | AK3: Takeaway-PokeCheck | AL3: ZoneEntry-Pass | AM3: ZoneExit-Pass | AN3: Zone-Pinch | AO3: Penalty-Boarding | AP3: Penalty-Boarding | AQ3: Penalty-Boarding | AR3: Stoppage-Offsides | AS3: Stoppage-PeriodStart | AT3: Stoppage-HomeTimeout | AU3: Shot-Slap | AV3: Shot-Slap | AW3: Shot-Slap | AX3: Shot-Slap | AY3: Shot-Slap | AZ3: Shot-Slap | BA3: Save-Blocker | BB3: Save-Blocker | BC3: Shot-Slap | BD3: Shot-Slap | BE3: Shot-Slap | BF3: Shot-Slap | BG3: Shot-Wrist | BH3: Shot-Wrist | BI3: Shot-Wrist | BJ3: Shot-Slap | BK3: Shot-Wrist | BL3: Shot-Wrist | BM3: Goal-Slap | BN3: Goal-Slap | BO3: Goal-Slap | BP3: Save-Blocker | BQ3: Rebound_OppTeamRecovered | BR3: Play-DriveMiddle | BS3: Play-PokeCheckFailed | BT3: PuckRetrieval | BU3: Pass | BV3: Involved | BW3: Shot-Slap | BX3: event_team_player_2 | BY3: o | CA3: FaceoffAfterGoal | CC3: Period Start | CE3: Assist-Secondary | CG3: OffensivePlay-DriveWide | CJ3: Defensive | CO3: =CY3&CZ3&"-"&DA3 -> OffensivePlay_Possession-DriveWide | CQ3: =DD3&DE3&"-"&DF3 -> Defensive_PlayPossession-SeperateFromPuck | CS3: HighToLow | CU3: Cycle | CW3: LeadToZoneEntry | CY3: OffensivePlay_ | CZ3: Possession | DA3: DriveWide | DD3: Defensive_Play | DE3: Possession | DF3: SeperateFromPuck | DG3: ZoneEntry-Pass | DH3: ZoneExit-Pass | DI3: Zone-Pinch
A4: Shot | C4: Faceoff-AfterPenalty | E4: Shot-Slap | G4: DriveWide | I4: PokeCheckFailed | N4: PostX | O4: 2.375 | U4: Faceoff_PeriodStart | V4: Shot_Blocked | W4: Pass_Deflected | X4: Goal_PenaltyShot | Z4: Zone_Keepin | AA4: Penalty_Major | AB4: PenaltyShot_Saved | AC4: Stoppage_Other | AE4: Save_Played | AF4: Pass-Backhand | AG4: Pass-Backhand | AH4: Pass-Backhand | AI4: Pass-Backhand | AJ4: Giveaway-PassIntercepted | AK4: Takeaway-PassIntercepted | AL4: ZoneEntry-DumpIn | AM4: ZoneExit-Clear | AN4: Zone-Other | AO4: Penalty-Charging | AP4: Penalty-Charging | AQ4: Penalty-Charging | AR4: Stoppage-ClockProblem | AS4: Stoppage-PeriodEnd | AT4: Stoppage-VisitorTimeout | AU4: Shot-Backhand | AV4: Shot-Backhand | AW4: Shot-Backhand | AX4: Shot-Backhand | AY4: Shot-Backhand | AZ4: Shot-Backhand | BA4: Save-LeftPad | BB4: Save-LeftPad | BC4: Shot-Backhand | BD4: Shot-Backhand | BE4: Shot-Backhand | BF4: Shot-Backhand | BG4: Shot-Slap | BH4: Shot-Slap | BI4: Shot-Slap | BJ4: Shot-Backhand | BK4: Shot-Slap | BL4: Shot-Slap | BM4: Goal-Backhand | BN4: Goal-Backhand | BO4: Goal-Backhand | BP4: Save-LeftPad | BQ4: Rebound_ShotGenerated | BR4: Play-DriveWide | BS4: Play-SeperateFromPuck | BT4: PuckRecovery | BU4: Goal | BV4: All | BW4: Shot-Backhand | BX4: event_team_player_3 | CA4: GameStart | CC4: Period End | CE4: Breakout | CG4: OffensivePlay-DriveCorner | CO4: =CY4&CZ4&"-"&DA4 -> OffensivePlay_Possession-DriveCorner | CQ4: =DD4&DE4&"-"&DF4 -> Defensive_PlayPossession-Backcheck | CS4: CrossIce | CU4: Forecheck | CW4: LeadToTurnover | CY4: OffensivePlay_ | CZ4: Possession | DA4: DriveCorner | DD4: Defensive_Play | DE4: Possession | DF4: Backcheck | DG4: ZoneEntry-DumpIn | DH4: ZoneExit-Clear | DI4: Zone-Other
A5: Pass | C5: Faceoff-AfterGoal | E5: Shot-Backhand | G5: DriveCorner | I5: SeperateFromPuck | N5: PostY | O5: 2.375 | U5: Faceoff_AfterStoppage | V5: Shot_BlockedSameTeam | W5: Pass_Intercepted | Z5: Zone_Entryfailed | AB5: ShootoutShot_OnNet | AC5: Stoppage_GameEnd | AF5: Pass-Forehand | AG5: Pass-Forehand | AH5: Pass-Forehand | AI5: Pass-Forehand | AJ5: Giveaway-PassMissed | AK5: Takeaway-PassBlocked | AL5: ZoneEntry-Chip | AM5: ZoneExit-Chip | AO5: Penalty-CrossChecking | AP5: Penalty-CrossChecking | AQ5: Penalty-CrossChecking | AR5: Stoppage-HighStick | AT5: Stoppage-RinkRepair | AU5: Shot-Snap | AV5: Shot-Snap | AW5: Shot-Snap | AX5: Shot-Snap | AY5: Shot-Snap | AZ5: Shot-Snap | BA5: Save-RightPad | BB5: Save-RightPad | BC5: Shot-Snap | BD5: Shot-Snap | BE5: Shot-Snap | BF5: Shot-Snap | BG5: Shot-Backhand | BH5: Shot-Backhand | BI5: Shot-Backhand | BJ5: Shot-Snap | BK5: Shot-Backhand | BL5: Shot-Backhand | BM5: Goal-Tip | BN5: Goal-Snap | BO5: Goal-Snap | BP5: Save-RightPad | BQ5: Rebound_FlurryGenerated | BR5: Play-DriveCorner | BS5: Play-Backcheck | BT5: Regroup | BU5: Turnover | BV5: Involved | BW5: Shot-Snap | BX5: event_team_player_4 | CA5: FaceoffAfterPenalty | CC5: Puck Out of Play | CE5: End-to-End-Rush | CG5: OffensivePlay-DriveNetMiddle | CO5: =CY5&CZ5&"-"&DA5 -> OffensivePlay_Possession-DriveNetMiddle | CQ5: =DD5&DE5&"-"&DF5 -> Defensive_PlayPossession-FroceWide | CS5: Slot | CU5: Dumpin | CW5: LeadToShot | CY5: OffensivePlay_ | CZ5: Possession | DA5: DriveNetMiddle | DD5: Defensive_Play | DE5: Possession | DF5: FroceWide | DG5: ZoneEntry-Chip | DH5: ZoneExit-Chip
A6: Goal | C6: Faceoff-PeriodStart | E6: Shot-Tip | G6: DriveNetMiddle | I6: Backcheck | U6: Faceoff_GameStart | V6: Shot_Deflected | Z6: Zone_ExitFailed | AB6: ShootoutShot_Missed | AF6: Pass-Bank | AG6: Pass-Bank | AH6: Pass-Bank | AI6: Pass-Bank | AJ6: Giveaway-PassBlocked | AK6: Takeaway-ShotBlocked | AL6: ZoneEntry-FromExitClear | AM6: ZoneExit-PassMiss/Misplay | AO6: Penalty-DelayofGame | AP6: Penalty-DelayofGame | AQ6: Penalty-DelayofGame | AR6: Stoppage-HandPass | AT6: Stoppage-PlayerEquipment | AU6: Shot-WrapAround | AV6: Shot-WrapAround | AW6: Shot-WrapAround | AX6: Shot-WrapAround | AY6: Shot-WrapAround | AZ6: Shot-WrapAround | BA6: Save-Stick | BB6: Save-Stick | BC6: Shot-WrapAround | BD6: Shot-WrapAround | BE6: Shot-WrapAround | BF6: Shot-WrapAround | BG6: Shot-Snap | BH6: Shot-Snap | BI6: Shot-Snap | BJ6: Shot-WrapAround | BK6: Shot-Snap | BL6: Shot-Snap | BM6: Goal-Snap | BN6: Goal-WrapAround | BO6: Goal-WrapAround | BP6: Save-Stick | BR6: Play-DriveNetMiddle | BS6: Play-FroceWide | BU6: Zone_Entry_Exit | BV6: Involved | BW6: Shot-WrapAround | BX6: event_team_player_5 | CA6: OtherFaceoff | CC6: Injury | CG6: OffensivePlay-DriveNetWide | CO6: =CY6&CZ6&"-"&DA6 -> OffensivePlay_Possession-DriveNetWide | CQ6: =DD6&DE6&"-"&DF6 -> Defensive_PlayPossession-Contain | CU6: Regroup | CW6: LeadToGoal | CY6: OffensivePlay_ | CZ6: Possession | DA6: DriveNetWide | DD6: Defensive_Play | DE6: Possession | DF6: Contain | DG6: ZoneEntry-FromExitClear | DH6: ZoneExit-PassMiss/Misplay
A7: Turnover | C7: Shot-OnNet | E7: Shot-Snap | G7: DriveNetWide | I7: FroceWide | V7: Shot_DeflectedOnNetSaved | Z7: Zone_KeepinFailed | AB7: ShootoutShot_Saved | AF7: Pass-Dump | AG7: Pass-Dump | AH7: Pass-Dump | AI7: Pass-Dump | AJ7: Giveaway-PassReceiverMissed | AK7: Takeaway-ZoneClear/Dump | AL7: ZoneEntry-PassMiss/Misplay | AM7: ZoneExit-OppTeam | AO7: Penalty-Diving | AP7: Penalty-Diving | AQ7: Penalty-Diving | AR7: Stoppage-NetDislodged | AT7: Stoppage-Challenge | AU7: Shot-Bat | AV7: Shot-Bat | AW7: Shot-Bat | AX7: Shot-Bat | AY7: Shot-Bat | AZ7: Shot-Bat | BA7: Save-Scramble | BB7: Save-Scramble | BC7: Shot-Bat | BD7: Shot-Bat | BE7: Shot-Bat | BF7: Shot-Bat | BG7: Shot-WrapAround | BH7: Shot-WrapAround | BI7: Shot-WrapAround | BJ7: Shot-Bat | BK7: Shot-WrapAround | BL7: Shot-WrapAround | BM7: Goal-WrapAround | BN7: Goal-Bat | BO7: Goal-Bat | BP7: Save-Scramble | BR7: Play-DriveNetWide | BS7: Play-Contain | BU7: Penalty | BV7: Involved | BW7: Shot-Bat | BX7: event_team_player_6 | CA7: DeadIce/Stoppage | CC7: Home Penalty | CG7: OffensivePlay-CrashNet | CO7: =CY7&CZ7&"-"&DA7 -> OffensivePlay_Possession-CrashNet | CQ7: =DD7&DE7&"-"&DF7 -> Defensive_PlayPossession-BeatMiddle | CU7: Counter | CW7: LeadToPenalty | CY7: OffensivePlay_ | CZ7: Possession | DA7: CrashNet | DD7: Defensive_Play | DE7: Possession | DF7: BeatMiddle | DG7: ZoneEntry-PassMiss/Misplay | DH7: ZoneExit-OppTeam
A8: Zone_Entry_Exit | C8: Shot-Missed | E8: Shot-WrapAround | G8: CrashNet | I8: Contain | V8: Shot_Tipped | AF8: Pass-Tipped | AG8: Pass-Tipped | AH8: Pass-Tipped | AI8: Pass-Tipped | AJ8: Giveaway-ShotBlocked | AK8: Takeaway-AttemptedZoneClear/Dump | AL8: ZoneEntry-OppTeam | AM8: ZoneExit-Lob | AO8: Penalty-Elbowing | AP8: Penalty-Elbowing | AQ8: Penalty-Elbowing | AR8: Stoppage-Injury | AT8: Stoppage-Other | AU8: Shot-Cradle | AV8: Shot-Cradle | AW8: Shot-Cradle | AX8: Shot-Cradle | AY8: Shot-Cradle | AZ8: Shot-Cradle | BA8: Save-Butterfly | BB8: Save-Butterfly | BC8: Shot-Cradle | BD8: Shot-Cradle | BE8: Shot-Cradle | BF8: Shot-Cradle | BG8: Shot-Bat | BH8: Shot-Bat | BI8: Shot-Bat | BJ8: Shot-Cradle | BK8: Shot-Bat | BL8: Shot-Bat | BM8: Goal-Bat | BN8: Goal-Cradle | BO8: Goal-Cradle | BP8: Save-Butterfly | BR8: Play-CrashNet | BS8: Play-BeatMiddle | BU8: PenaltyShot_Shootout | BV8: Involved | BW8: Shot-Cradle | BX8: opp_team_player_1 | CA8: Intermission | CC8: Away Penalty | CG8: OffensivePlay-Delay | CO8: =CY8&CZ8&"-"&DA8 -> OffensivePlay_Possession-Delay | CQ8: =DD8&DE8&"-"&DF8 -> Defensive_PlayPossession-BeatWide | CU8: ZoneExit | CW8: LeadToFailedBreakout | CY8: OffensivePlay_ | CZ8: Possession | DA8: Delay | DD8: Defensive_Play | DE8: Possession | DF8: BeatWide | DG8: ZoneEntry-OppTeam | DH8: ZoneExit-Lob
A9: Penalty | C9: Shot-Blocked | E9: Shot-Bat | G9: Delay | I9: BeatMiddle | V9: Shot_TippedOnNetSaved | AF9: Pass-Lob | AG9: Pass-Lob | AH9: Pass-Lob | AI9: Pass-Lob | AJ9: Giveaway-ShotMissed | AK9: Takeaway-Other | AL9: ZoneEntry-Lob | AM9: ZoneExit-CausedTurnover | AO9: Penalty-GoalieInterference | AP9: Penalty-GoalieInterference | AQ9: Penalty-GoalieInterference | AR9: Stoppage-GoalieStoppage | AU9: Shot-Poke | AV9: Shot-Poke | AW9: Shot-Poke | AX9: Shot-Poke | AY9: Shot-Poke | AZ9: Shot-Poke | BA9: Save-Chest | BB9: Save-Chest | BC9: Shot-Poke | BD9: Shot-Poke | BE9: Shot-Poke | BF9: Shot-Poke | BG9: Shot-Cradle | BH9: Shot-Cradle | BI9: Shot-Cradle | BJ9: Shot-Poke | BK9: Shot-Cradle | BL9: Shot-Cradle | BM9: Goal-Cradle | BN9: Goal-Poke | BO9: Goal-Poke | BP9: Save-Chest | BR9: Play-Delay | BS9: Play-BeatWide | BU9: Stoppage | BV9: None | BW9: Shot-Poke | BX9: opp_team_player_2 | CA9: DelayedPenalty | CC9: Home Goalie Stoppage | CG9: OffensivePlay-Deke | CO9: =CY9&CZ9&"-"&DA9 -> OffensivePlay_Possession-Deke | CQ9: =DD9&DE9&"-"&DF9 -> Defensive_PlayPossession-BeatDeke | CU9: ZoneEntry | CW9: LeadToFailedZoneEntry | CY9: OffensivePlay_ | CZ9: Possession | DA9: Deke | DD9: Defensive_Play | DE9: Possession | DF9: BeatDeke | DG9: ZoneEntry-Lob | DH9: ZoneExit-CausedTurnover
A10: PenaltyShot_Shootout | C10: Shot-BlockedSameTeam | E10: Shot-Cradle | G10: Deke | I10: BeatWide | V10: Shot_OnNetGoal | AF10: Pass-Drop | AG10: Pass-Drop | AH10: Pass-Drop | AI10: Pass-Drop | AJ10: Giveaway-ZoneClear/Dump | AL10: ZoneEntry-RushBreakaway | AM10: ZoneExit-PenaltyKillClear | AO10: Penalty-HighSticking | AP10: Penalty-HighSticking | AQ10: Penalty-HighSticking | AR10: Stoppage-PuckOutofPlay | AU10: Shot-BetweenLegs | AV10: Shot-BetweenLegs | AW10: Shot-BetweenLegs | AX10: Shot-BetweenLegs | AY10: Shot-BetweenLegs | AZ10: Shot-BetweenLegs | BA10: Save-Shoulder | BB10: Save-Shoulder | BC10: Shot-BetweenLegs | BD10: Shot-BetweenLegs | BE10: Shot-BetweenLegs | BF10: Shot-BetweenLegs | BG10: Shot-Poke | BH10: Shot-Poke | BI10: Shot-Poke | BJ10: Shot-BetweenLegs | BK10: Shot-Poke | BL10: Shot-Poke | BM10: Goal-Poke | BN10: Goal-BetweenLegs | BO10: Goal-BetweenLegs | BP10: Save-Other | BR10: Play-Deke | BS10: Play-BeatDeke | BU10: Hit | BV10: Involved | BW10: Shot-BetweenLegs | BX10: opp_team_player_3 | CA10: GameStart | CC10: Away Goalie Stoppage | CG10: OffensivePlay-Chip | CO10: =CY10&CZ10&"-"&DA10 -> OffensivePlay_Possession-Chip | CQ10: =DD10&DE10&"-"&DF10 -> Defensive_PlayPossession-BeatSpeed | CU10: Clear | CY10: OffensivePlay_ | CZ10: Possession | DA10: Chip | DD10: Defensive_Play | DE10: Possession | DF10: BeatSpeed | DG10: ZoneEntry-RushBreakaway | DH10: ZoneExit-PenaltyKillClear
A11: Stoppage | C11: Shot-Deflected | E11: Shot-Poke | G11: Chip | I11: BeatDeke | V11: Shot_OnNetTippedGoal | AF11: Pass-Deflected/TippedShot | AG11: Pass-Deflected/TippedShot | AH11: Pass-Deflected/TippedShot | AI11: Pass-Deflected/TippedShot | AJ11: Giveaway-AttemptedZoneClear/Dump | AL11: ZoneEntry-CausedTurnover | AM11: ZoneExit-Shot | AO11: Penalty-Holding | AP11: Penalty-Holding | AQ11: Penalty-Holding | AR11: Stoppage-Penalty | AU11: Shot-Tip | AV11: Shot-Tip | AW11: Shot-Other | AX11: Shot-Other | AY11: Shot-Other | AZ11: Shot-Other | BA11: Save-Skate | BB11: Save-Skate | BC11: Shot-Dumpin | BD11: Shot-Dumpin | BE11: Shot-Dumpin | BF11: Shot-Dumpin | BG11: Shot-BetweenLegs | BH11: Shot-BetweenLegs | BI11: Shot-BetweenLegs | BJ11: Shot-Dumpin | BK11: Shot-BetweenLegs | BL11: Shot-BetweenLegs | BM11: Goal-BetweenLegs | BN11: Goal-Other | BO11: Goal-Other | BR11: Play-Chip | BS11: Play-BeatSpeed | BU11: Possession | BV11: Involved | BW11: Shot-Dumpin | BX11: opp_team_player_4 | CC11: Home Offside | CG11: OffensivePlay-Other | CO11: =CY11&CZ11&"-"&DA11 -> OffensivePlay_Possession-Other | CQ11: =DD11&DE11&"-"&DF11 -> Defensive_PlayPossession-Pressure | CY11: OffensivePlay_ | CZ11: Possession | DA11: Other | DD11: Defensive_Play | DE11: Possession | DF11: Pressure | DG11: ZoneEntry-CausedTurnover | DH11: ZoneExit-Other
A12: Hit | C12: Shot-DeflectedOnNet | E12: Shot-BetweenLegs | G12: Other | I12: BeatSpeed | V12: Shot_OnNetDeflectedGoal | AF12: Pass-ReceiverMissed | AG12: Pass-ReceiverMissed | AH12: Pass-ReceiverMissed | AI12: Pass-ReceiverMissed | AJ12: Giveaway-ZoneEntry/ExitMisplay | AL12: ZoneEntry-PenaltyKillClear | AM12: ZoneExit-Other | AO12: Penalty-Interference | AP12: Penalty-Interference | AQ12: Penalty-Interference | AR12: Stoppage-Goal | AU12: Shot-Other | AV12: Shot-Other | BA12: Save-Other | BB12: Save-Other | BC12: Shot-OneTime | BD12: Shot-OneTime | BE12: Shot-OneTime | BF12: Shot-OneTime | BG12: Shot-Dumpin | BH12: Shot-Dumpin | BI12: Shot-Dumpin | BJ12: Shot-OneTime | BK12: Shot-Dumpin | BL12: Shot-Dumpin | BM12: Goal-Dumpin | BR12: Play-Other | BS12: Play-BoxOut | BU12: LoosePuck | BV12: None | BW12: Shot-OneTime | BX12: opp_team_player_5 | CC12: Home Icing | CG12: OffensivePlay-DumpChase | CO12: =CY12&CZ12&"-"&DA12 -> OffensivePlay_Possession-Speed | CQ12: =DD12&DE12&"-"&DF12 -> Defensive_PlayPossession-Zone | CY12: OffensivePlay_ | CZ12: Possession | DA12: Speed | DD12: Defensive_Play | DE12: Possession | DF12: Zone | DG12: ZoneEntry-PenaltyKillClear
A13: Possession | C13: Shot-Tipped | E13: Shot-Dumpin | G13: DumpChase | I13: BoxOut | V13: Shot_Goal | AF13: Pass-OneTouch | AG13: Pass-Other | AH13: Pass-Other | AI13: Pass-Other | AJ13: Giveaway-DumpInZone | AL13: ZoneEntry-Shot | AO13: Penalty-Hooking | AP13: Penalty-Fighting | AQ13: Penalty-Fighting | BC13: Shot-Tip | BD13: Shot_Tipped | BE13: Shot_Tipped | BF13: Shot_Tipped | BG13: Shot-OneTime | BH13: Shot-OneTime | BI13: Shot-OneTime | BJ13: Shot-Other | BK13: Shot-OneTime | BL13: Shot-OneTime | BM13: Goal-Deflection | BR13: Play-DumpChase | BS13: Play-AttemptedClear | BU13: Save | BV13: Involved | BW13: Shot_Tipped | BX13: opp_team_player_6 | CC13: Away Offside | CG13: OffensivePlay-Forecheck | CO13: =CY13&CZ13&"-"&DA13 -> OffensivePlay_Possession-OpenIceDeke | CQ13: =DD13&DE13&"-"&DF13 -> Defensive_PlayPossession-ManOnMan | CY13: OffensivePlay_ | CZ13: Possession | DA13: OpenIceDeke | DD13: Defensive_Play | DE13: Possession | DF13: ManOnMan | DG13: ZoneEntry-Other
A14: LoosePuck | C14: Pass-Completed | E14: Shot-Deflection | G14: Forecheck | I14: Other | V14: Shot_MissedPost | AF14: Pass-SecondTouch | AG14: Pass-SecondTouch | AH14: Pass-SecondTouch | AI14: Pass-SecondTouch | AJ14: Giveaway-Other | AL14: ZoneEntry-Other | AO14: Penalty-Roughing | AP14: Penalty-Hooking | AQ14: Penalty-Hooking | BC14: Shot-Other | BD14: Shot-Other | BE14: Shot-Other | BF14: Shot-Other | BG14: Shot-Other | BH14: Shot-Other | BI14: Shot-Other | BJ14: Shot-Deflection | BK14: Shot-Other | BL14: Shot-Other | BM14: Goal-OneTime | BR14: Play-Forecheck | BS14: Play-Other | BU14: TeamPossessionChange | BV14: None | BW14: Shot-Other | CC14: Away Icing | CG14: OffensivePlay-Speed | CO14: =CY14&CZ14&"-"&DA14 -> OffensivePlay_Possession-EndToEndRush | CQ14: =DD14&DE14&"-"&DF14 -> Defensive_PlayPossession-Tracker | CY14: OffensivePlay_ | CZ14: Possession | DA14: EndToEndRush | DD14: Defensive_Play | DE14: Possession | DF14: Tracker
A15: Save | C15: Pass-Missed | E15: Shot-OneTime | G15: Speed | AF15: Pass-QuickUp | AG15: Pass-QuickUp | AH15: Pass-QuickUp | AI15: Pass-QuickUp | AO15: Penalty-Slashing | AP15: Penalty-Roughing | AQ15: Penalty-Roughing | BJ15: Shot-Tip | BM15: Goal-Other | BR15: Play-Speed | BU15: Rebound | BV15: Invoived | CC15: Clock Problem | CG15: OffensivePlay-Dump/RimInZone | CO15: =CY15&CZ15&"-"&DA15 -> OffensivePlay_Possession-FrontofNet | CQ15: =DD15&DE15&"-"&DF15 -> Defensive_PlayPossession-Surf | CY15: OffensivePlay_ | CZ15: Possession | DA15: FrontofNet | DD15: Defensive_Play | DE15: Possession | DF15: Surf
A16: TeamPossessionChange | C16: Pass-Deflected | E16: Shot-Other | AF16: Pass-GiveAndGo | AG16: Pass-GiveAndGo | AH16: Pass-GiveAndGo | AI16: Pass-GiveAndGo | AO16: Penalty-TooManyMenontheIce | AP16: Penalty-Slashing | AQ16: Penalty-Slashing | BR16: Play-Dump/RimInZone | CC16: Puck Frozen | CG16: DefensivePlay-PokeCheck | CO16: =CY16&CZ16&"-"&DA16 -> OffensivePlay_Possession-CutBack | CQ16: =DD16&DE16&"-"&DF16 -> Defensive_PlayPossession-StickCheck | CY16: OffensivePlay_ | CZ16: Possession | DA16: CutBack | DD16: Defensive_Play | DE16: Possession | DF16: StickCheck
A17: Rebound | C17: Pass-Intercepted | E17: Pass-Stretch | AF17: Pass-Reverse | AG17: Pass-Reverse | AH17: Pass-Reverse | AI17: Pass-Reverse | AO17: Penalty-Tripping | AP17: Penalty-Misconduct | AQ17: Penalty-Misconduct | CC17: Puck in Crowd | CG17: DefensivePlay-PokeCheckFailed | CO17: =CY17&CZ17&"-"&DA17 -> OffensivePlay_Possession-Wheel | CQ17: =DD18&DE18&"-"&DF18 -> Defensive_PlayPass-PassIntercepted | CY17: OffensivePlay_ | CZ17: Possession | DA17: Wheel | DD17: Defensive_Play | DE17: Pass | DF17: PassBlocked
A18: DeadIce | C18: Turnover-Giveaway | E18: Pass-Rim/Wrap | AF18: Pass-Other | AG18: Pass-Other | AH18: Pass-Other | AI18: Pass-Other | AO18: Penalty-Other | AP18: Penalty-TooManyMenontheIce | AQ18: Penalty-TooManyMenontheIce | CC18: Goalie Stopped (after SOG) | CG18: DefensivePlay-SeperateFromPuck | CO18: =CY18&CZ18&"-"&DA18 -> OffensivePlay_Possession-ForecedOutside | CQ18: =DD19&DE19&"-"&DF19 -> Defensive_PlayPass-InShotPassLane | CY18: OffensivePlay_ | CZ18: Possession | DA18: ForecedOutside | DD18: Defensive_Play | DE18: Pass | DF18: PassIntercepted
A19: Play | C19: Turnover-Takeaway | E19: Pass-Backhand | AP19: Penalty-Tripping | AQ19: Penalty-Tripping | CC19: Referee or Linesperson | CG19: DefensivePlay-Backcheck | CO19: =CY19&CZ19&"-"&DA19 -> OffensivePlay_Pass-AssistPrimary | CQ19: =DD20&DE20&"-"&DF20 -> Defensive_PlayShot-BoxOut | CY19: OffensivePlay_ | CZ19: Pass | DA19: AssistPrimary | DD19: Defensive_Play | DE19: Pass | DF19: InShotPassLane
A20: Timeout | C20: Zone-Entry | E20: Pass-Forehand | AP20: Penalty-UnsportsmanlikeConduct | AQ20: Penalty-UnsportsmanlikeConduct | CC20: High Stick | CG20: DefensivePlay-FroceWide | CO20: =CY20&CZ20&"-"&DA20 -> OffensivePlay_Pass-AssistSecondary | CQ20: =DD21&DE21&"-"&DF21 -> Defensive_PlayShot-BlockedShot | CY20: OffensivePlay_ | CZ20: Pass | DA20: AssistSecondary | DD20: Defensive_Play | DE20: Shot | DF20: BoxOut
A21: Intermission | C21: Zone-Exit | E21: Pass-Bank | AP21: Penalty-Other | AQ21: Penalty-Other | CC21: Objects on Ice | CG21: DefensivePlay-Contain | CO21: =CY21&CZ21&"-"&DA21 -> OffensivePlay_Pass-AssistTertiary | CQ21: =DD22&DE22&"-"&DF22 -> Defensive_PlayShot-FrontofNet | CY21: OffensivePlay_ | CZ21: Pass | DA21: AssistTertiary | DD21: Defensive_Play | DE21: Shot | DF21: BlockedShot
A22: Clockstop | C22: Zone-Keepin | E22: Pass-Other | CC22: Hand Pass | CG22: DefensivePlay-BeatMiddle | CO22: =CY22&CZ22&"-"&DA22 -> OffensivePlay_Pass-GiveAndGo | CQ22: =DD23&DE23&"-"&DF23 -> Defensive_PlayZone-ClearingAttempt | CY22: OffensivePlay_ | CZ22: Pass | DA22: GiveAndGo | DD22: Defensive_Play | DE22: Shot | DF22: FrontofNet
A23: GameStart | C23: Penalty | E23: Giveaway-Misplayed | CC23: Premature Substitution | CG23: DefensivePlay-BeatWide | CO23: =CY23&CZ23&"-"&DA23 -> OffensivePlay_Pass-Reverse | CQ23: =DD24&DE24&"-"&DF24 -> Defensive_PlayZone-ZoneEntryDenial | CY23: OffensivePlay_ | CZ23: Pass | DA23: Reverse | DD23: Defensive_Play | DE23: Zone | DF23: ClearingAttempt
A24: GameEnd | C24: Penalty-Offsetting | E24: Giveaway-BattleLost | CC24: Puck in Netting | CG24: DefensivePlay-BeatDeke | CO24: =CY24&CZ24&"-"&DA24 -> OffensivePlay_Pass-QuickUp | CQ24: =DD25&DE25&"-"&DF25 -> Defensive_PlayZone-ZoneExitDenial | CY24: OffensivePlay_ | CZ24: Pass | DA24: QuickUp | DD24: Defensive_Play | DE24: Zone | DF24: ZoneEntryDenial
A25: Penalty_Delayed | C25: Stoppage-Freeze | E25: Giveaway-PassIntercepted | CC25: Puck in Benches | CG25: DefensivePlay-BeatSpeed | CO25: =CY25&CZ25&"-"&DA25 -> OffensivePlay_Pass-SecondTouch | CQ25: =DD26&DE26&"-"&DF26 -> Defensive_PlayZone-PenaltyKillClear | CY25: OffensivePlay_ | CZ25: Pass | DA25: SecondTouch | DD25: Defensive_Play | DE25: Zone | DF25: ZoneExitDenial
A26: Zone_Change | C26: Stoppage-OutfofPlay | E26: Giveaway-PassMissed | CC26: Net Dislodged Offensive Skater | CG26: DefensivePlay-BoxOut | CO26: =CY26&CZ26&"-"&DA26 -> OffensivePlay_Pass-ReceiverMissed | CQ26: =DD27&DE27&"-"&DF27 -> Defensive_PlayZone-PuckRetrievalDumpIn | CY26: OffensivePlay_ | CZ26: Pass | DA26: ReceiverMissed | DD26: Defensive_Play | DE26: Zone | DF26: PenaltyKillClear
C27: Stoppage-PeriodEnd | E27: Giveaway-PassBlocked | CC27: Puck Frzn-Goalie-Bynd Ctr | CG27: DefensivePlay-AttemptedClear | CO27: =CY27&CZ27&"-"&DA27 -> OffensivePlay_Shot-Screen | CQ27: =DD28&DE28&"-"&DF28 -> Defensive_PlayZone-PuckRetrievalShot | CY27: OffensivePlay_ | CZ27: Shot | DA27: Screen | DD27: Defensive_Play | DE27: Zone | DF27: PuckRetrievalDumpIn
C28: Stoppage-Goal | E28: Giveaway-ShotBlocked | CC28: Skater Puck Frozen | CG28: DefensivePlay-Other | CO28: =CY28&CZ28&"-"&DA28 -> OffensivePlay_Zone-Breakout | CQ28: =DD29&DE29&"-"&DF29 -> Defensive_PlayZone-PuckRetreivalTurnover | CY28: OffensivePlay_ | CZ28: Zone | DA28: Breakout | DD28: Defensive_Play | DE28: Zone | DF28: PuckRetrievalShot
C29: Stoppage-Penalty | E29: Giveaway-ShotMissed | CC29: Valid stoppage type reasons (reason): | CG29: OffensivePlay-Shot | CO29: =CY29&CZ29&"-"&DA29 -> OffensivePlay_Zone-DumpChase | CQ29: =DD30&DE30&"-"&DF30 -> Defensive_PlayZone-PuckRetreivalPass | CY29: OffensivePlay_ | CZ29: Zone | DA29: DumpChase | DD29: Defensive_Play | DE29: Zone | DF29: PuckRetreivalTurnover
C30: Shootout-OnNet | E30: Giveaway-Other | CC30: TV timeout | CG30: OffensivePlay-Pass | CO30: =CY30&CZ30&"-"&DA30 -> OffensivePlay_Zone-Forecheck | CQ30: =DD31&DE31&"-"&DF31 -> Defensive_PlayZone-PuckRetrievalRebound | CY30: OffensivePlay_ | CZ30: Zone | DA30: Forecheck | DD30: Defensive_Play | DE30: Zone | DF30: PuckRetreivalPass
C31: Shootout-Missed | E31: Takeaway-BattleWon | CC31: Home Timeout | CG31: OffensivePlay_Breakout | CO31: =CY31&CZ31&"-"&DA31 -> OffensivePlay_Zone-Dump/RimInZone | CQ31: =DD32&DE32&"-"&DF32 -> Defensive_PlayZone-PuckRecoveryDumpIn | CY31: OffensivePlay_ | CZ31: Zone | DA31: Dump/RimInZone | DD31: Defensive_Play | DE31: Zone | DF31: PuckRetrievalRebound
C32: Shootout-Saved | E32: Takeaway-PokeCheck | CC32: Visitor Timeout | CG32: OffensivePlay-AssistPrimary | CO32: =CY32&CZ32&"-"&DA32 -> OffensivePlay_Zone-DumpInAttempt | CQ32: =DD33&DE33&"-"&DF33 -> Defensive_PlayZone-PuckRecoveryShot | CY32: OffensivePlay_ | CZ32: Zone | DA32: DumpInAttempt | DD32: Defensive_Play | DE32: Zone | DF32: PuckRecoveryDumpIn
C33: PenaltyShot-OnNet | E33: Takeaway-PassIntercepted | CC33: Player Injury | CG33: OffensivePlay-AssistSecondary | CO33: =CY33&CZ33&"-"&DA33 -> OffensivePlay_Zone-Breakout | CQ33: =DD34&DE34&"-"&DF34 -> Defensive_PlayZone-PuckRecoveryTurnover | CY33: OffensivePlay_ | CZ33: Zone | DA33: Breakout | DD33: Defensive_Play | DE33: Zone | DF33: PuckRecoveryShot
C34: PenaltyShot-Missed | E34: Takeaway-PassBlocked | CC34: Official Injury | CG34: DefensivePlay-BlockedShot | CO34: =CY34&CZ34&"-"&DA34 -> OffensivePlay_Zone-Cycle | CQ34: =DD35&DE35&"-"&DF35 -> Defensive_PlayZone-PuckRecoveryPass | CY34: OffensivePlay_ | CZ34: Zone | DA34: Cycle | DD34: Defensive_Play | DE34: Zone | DF34: PuckRecoveryTurnover
C35: PenaltyShot-Saved | E35: Takeaway-ShotBlocked | CC35: Rink Repair | CG35: DefensivePlay-PassBlocked | CO35: =CY35&CZ35&"-"&DA35 -> OffensivePlay_Zone-PuckRetrievalDumpIn | CQ35: =DD36&DE36&"-"&DF36 -> Defensive_PlayZone-PuckRecoveryRebound | CY35: OffensivePlay_ | CZ35: Zone | DA35: PuckRetrievalDumpIn | DD35: Defensive_Play | DE35: Zone | DF35: PuckRecoveryPass
C36: LoosePuck-Forecheck | E36: Takeaway-Other | CC36: Ice problem | CG36: DefensivePlay-PassIntercepted | CO36: =CY36&CZ36&"-"&DA36 -> OffensivePlay_Zone-PuckRetrievalShot | CQ36: =DD37&DE37&"-"&DF37 -> Defensive_PlayZone-ForcedDumpin/Clear | CY36: OffensivePlay_ | CZ36: Zone | DA36: PuckRetrievalShot | DD36: Defensive_Play | DE36: Zone | DF36: PuckRecoveryRebound
C37: LoosePuck-Battle | E37: ZoneEntry-Rush | CC37: Player Equipment | CG37: OffensivePlay-FrontofNet | CO37: =CY37&CZ37&"-"&DA37 -> OffensivePlay_Zone-PuckRetreivalTurnover | CQ37: Offensive_Zone-AttemptedKeepin | CY37: OffensivePlay_ | CZ37: Zone | DA37: PuckRetreivalTurnover | DD37: Defensive_Play | DE37: Zone | DF37: ForcedDumpin/Clear
C38: Save-Rebound | E38: ZoneEntry-Pass | CC38: Video Review | CG38: DefensivePlay-FrontofNet | CO38: =CY38&CZ38&"-"&DA38 -> OffensivePlay_Zone-PuckRetreivalPass | CQ38: Defensive_Zone-AttemptedBreakOutPass | CY38: OffensivePlay_ | CZ38: Zone | DA38: PuckRetreivalPass
C39: Save-Freeze | E39: ZoneEntry-DumpIn | CC39: Chlg Hm - off-side | CG39: OffensivePlay-DumpInAttempt | CO39: =CY39&CZ39&"-"&DA39 -> OffensivePlay_Zone-PuckRetreivalRebound | CQ39: Defensive_Zone-AttemptedBreakOutRush | CY39: OffensivePlay_ | CZ39: Zone | DA39: PuckRetreivalRebound
C40: Save | E40: ZoneExit-Rush | CC40: Chlg Vis - off-side | CG40: DefensivePlay-ClearingAttempt | CO40: =CY40&CZ40&"-"&DA40 -> OffensivePlay_Zone-PuckRetreivalShot | CQ40: Defensive_Zone-AttemptedBreakOutClear | CY40: OffensivePlay_ | CZ40: Zone | DA40: PuckRetreivalShot
...

Sheet events
A1: event_index | B1: linked_event_index_ | C1: linked_event_index | D1: tracking_event_index | E1: sequence_index | F1: play_index | G1: zone_change_index | H1: Period | I1: event_start_min_ | J1: event_start_sec_ | K1: event_end_min_ | L1: event_end_sec_ | M1: event_start_min | N1: event_start_sec | O1: event_end_min | P1: event_end_sec | Q1: Team_ | R1: Player | S1: role_abrev_binary | T1: role_abrev | U1: Type_ | V1: event_detail_ | W1: event_detail_2_ | X1: successful | Y1: play_detail1 | Z1: play_detail2 | AA1: play_detail_successful | AB1: context | AC1: play_tag1 | AD1: play_tag2 | AE1: high_danger | AF1: event_team_zone | AG1: home_team_zone | AH1: away_team_zone | AI1: forced_forcer | AJ1: pressured_pressurer | AK1: Team | AL1: Team__ | AM1: Type | AN1: event_detail | AO1: event_detail_2 | AP1: side_of_puck | AQ1: game_id | AR1: home_team | AS1: away_team | AT1: duration | AU1: time_start_total_seconds | AV1: time_end_total_seconds | AW1: shift_index | AX1: player_role | AY1: role_number | AZ1: running_intermission_duration | BA1: period_start_total_running_seconds | BB1: running_video_time | BC1: event_running_start | BD1: event_running_end | BE1: event_id | BF1: linked_event_id | BG1: play_id | BH1: sequence_id | BI1: zone_change_id | BJ1: next_event | BK1: last_event | BL1: next_faceoff | BM1: last_faceoff | BN1: next_team_zone_entry | BO1: last_team_zone_entry | BP1: next_team_zone_exit | BQ1: next_team_zone_exit | BR1: next_team_shot | BS1: last_team_shot | BT1: next_team_goal | BU1: last_team_goal | BV1: associated_faceoff_id | BW1: associated_pass_id1 | BX1: associated_pass_id2 | BY1: associated_pass_id3 | BZ1: associated_pass_id4 | CA1: associated_zone_entry | CB1: assocaited_zone_exit | CC1: assocaited_penalty | CD1: assocaited_shot1 | CE1: assocaited_shot2 | CF1: assocaited_shot3 | CG1: assocaited_shot4 | CH1: associated_save1 | CI1: associated_save2 | CJ1: associated_save3 | CK1: associated_save4 | CL1: associated_turnover1 | CM1: associated_turnover2 | CN1: associated_turnover3 | CO1: associated_turnover4 | CP1: assocaited_possession1 | CQ1: assocaited_possession2 | CR1: assocaited_possession3 | CS1: assocaited_possession4 | CT1: associated_breakout | CU1: assocaited_assist_primary | CV1: assocaited_assist_secondary | CW1: faceoff_id | CX1: pass_id | CY1: turnover_id | CZ1: shot_id | DA1: save_id | DB1: rebound_id | DC1: goal_id | DD1: penalty_id | DE1: zone_entry_id | DF1: zone_exit_id | DG1: possession_id | DH1: pre_shot_pass | DI1: failed_entry | DJ1: failed_exit | DK1: retreival_lead_to_breakout | DL1: botched_retreivals | DM1: possession_change
A2: 0 | C2: =IF(B2<>"",9000+B2,"") | D2: =IF(C2<>"",C2,B2) -> 0 | H2: 1 | O2: =IF(K2<>"",K2,IF($A2=$A1,O1,"")) | P2: =IF(L2<>"",L2,IF($A2=$A1,P1,"")) | S2: x | T2: =IF(S2="x","",IF(S2=1,"e","o")) | U2: GameStart | V2: Faceoff_GameStart | AG2: =IF(Q2="","",IF(Q2="Home",AF2,"")) | AK2: =IF(Q2="H","Home",IF(Q2="A","Away","")) | AM2: =IF(U2<>"",U2,IF(A2=A1,U2,"")) -> GameStart | AQ2: 18987 | AR2: Velodrome | AS2: Outcan | BA2: 0 | BB2: 0 | BC2: =IF(BB2<5,0,BB2-5) -> 0 | BD2: =BC2+AT2+5 -> 5 | BE2: ="EVE"&$AQ2&(1000+$A2) -> EVE189871000 | BF2: =IF(C2<>"","LEVE"&$AQ2&(9000+$C2),"") | BG2: =IF(F2<>"","PLAY"&$AQ2&(1000+$F2),"") | BH2: =IF(E2<>"","SEQ"&$AQ2&(1000+$E2),"") | BI2: =IF(G2<>"","ZCHG"&$AQ2&(1000+$G2),"") | BJ2: ="EVE"&$AQ2&(1000+$A2+1) -> EVE189871001 | BK2: =IF(A2>0,"EVE"&$AQ2&(1000+$A2-1),"") | CW2: =IF(U2="Faceoff","FACE"&AQ2&(1000+A2),"")
A3: 1 | C3: =IF(B3<>"",9000+B3,"") | D3: =IF(C3<>"",C3,B3) -> 0 | E3: 1 | G3: 1 | H3: =IF(U3="Intermission",H2+1,H2) -> 1 | I3: 18 | J3: 00 | M3: =IF(I3<>"",I3,IF($A3=$A2,M2,M3)) -> 18 | N3: =IF($A3=$A2,N2,J3) -> 00 | O3: =IF(K3<>"",K3,IF($A3=$A2,O2,"")) | P3: =IF(L3<>"",L3,IF($A3=$A2,P2,"")) | Q3: a | R3: 77 | S3: 1 | T3: =IF(S3="x","",IF(S3=1,"e","o")) -> e | U3: Faceoff | V3: Faceoff_PeriodStart | AF3: n | AG3: =IF($Q3="","",IF(AF3="","",IF($Q3="Home",$AF3,IF($AF3="n","n",IF($AF3="d","o",IF($AF3="o","d","")))))) -> n | AH3: =IF($Q3="","",IF(AF3="","",IF($Q3="Away",$AF3,IF($AF3="n","n",IF($AF3="d","o",IF($AF3="o","d","")))))) -> n | AK3: =IF(AL3="H","Home",IF(AL3="A","Away","")) -> Away | AL3: =IF($Q3<>"",$Q3,IF($A3=$A2,AL2,"")) -> a | AM3: =IF($U3<>"",$U3,IF($A3=$A2,AM2,"")) -> Faceoff | AN3: =IF(V3<>"",V3,IF($A3=$A2,AN2,"")) -> Faceoff_PeriodStart | AO3: =IF(W3<>"",W3,IF($A3=$A2,AO2,"")) | AP3: =IF(AND(T3="e",OR(AM3="Save",AN3="Turnover_Takeaway",AN3="Play_Defensive")),"Defensive",IF(AND(T3="o",OR(AM3="Save",AN3="Turnover_Takeaway",AN3="Play_Defensive")),"Offensive",IF(OR(AM3="Deadice",AM3="Stoppage",AM3="Intermission"),"",IF(T3="e","Offensive",IF(T3="o","Defensive",""))))) -> Offensive | AQ3: 18988 | AR3: Velodrome | AS3: Outcan | AT3: =IF(AND(O3="",P3=""),0,((M3*60)+N3)-((O3*60)+P3)) -> 0 | AU3: =(M3*60)+N3 -> 1080 | AV3: =IF(AND(O3="",P3=""),AU3,((O3*60)+P3)) -> 1080 | AW3: {=_xlfn._xlws.FILTER(shifts!A:A,(shifts!B:B=events!H3)*(shifts!AG:AG>=events!AU3)*(shifts!AH:AH<=events!AV3))} -> 1 | AX3: =IF(T3="e","event_team_player_"&AY3,IF(T3="o","opp_team_player_"&AY3,"")) -> event_team_player_1 | AY3: =COUNTIFS(A$3:A3,"="&A3,T$3:T3,"="&T3) -> 1 | AZ3: =SUMIFS(AT3:AT3,U3:U3,"=Intermission") -> 0 | BA3: =IF(H3=1,0,IF(H3=2,1080+AZ3,IF(H3=3,(1080*2)+AZ3,0))) -> 0 | BB3: =IF(U3="Intermission",BB2,((1080)-((M3*60)+N3))+BA3) -> 0 | BC3: =IF(BB3<5,0,BB3-5) -> 0 | BD3: =BC3+AT3+5 -> 5 | BE3: ="EVE"&$AQ3&(1000+$A3) -> EVE189881001 | BF3: =IF(C3<>"","LEVE"&$AQ3&(9000+$C3),"") | BG3: =IF(F3<>"","PLAY"&$AQ3&(1000+$F3),"") | BH3: =IF(E3<>"","SEQ"&$AQ3&(1000+$E3),"") -> SEQ189881001 | BI3: =IF(G3<>"","ZONE"&$AQ3&(1000+$G3),"") -> ZONE189881001 | BJ3: ="EVE"&$AQ3&(1000+$A3+1) -> EVE189881002 | BK3: =IF(A3>0,"EVE"&$AQ3&(1000+$A3-1),"") -> EVE189881000 | CW3: =IF(U3="Faceoff","FACE"&AQ3&(1000+A3),"") -> FACE189881001
A4: 1 | C4: =IF(B4<>"",9000+B4,"") | D4: =IF(C4<>"",C4,B4) -> 0 | E4: 1 | G4: 1 | H4: =IF(U4="Intermission",H3+1,H3) -> 1 | M4: =IF(I4<>"",I4,IF($A4=$A3,M3,M4)) -> 18 | N4: =IF($A4=$A3,N3,J4) -> 00 | O4: =IF(K4<>"",K4,IF($A4=$A3,O3,"")) | P4: =IF(L4<>"",L4,IF($A4=$A3,P3,"")) | R4: 4 | S4: 1 | T4: =IF(S4="x","",IF(S4=1,"e","o")) -> e | AG4: =IF($Q4="","",IF(AF4="","",IF($Q4="Home",$AF4,IF($AF4="n","n",IF($AF4="d","o",IF($AF4="o","d","")))))) | AH4: =IF($Q4="","",IF(AF4="","",IF($Q4="Away",$AF4,IF($AF4="n","n",IF($AF4="d","o",IF($AF4="o","d","")))))) | AK4: =IF(AL4="H","Home",IF(AL4="A","Away","")) -> Away | AL4: =IF($Q4<>"",$Q4,IF($A4=$A3,AL3,"")) -> a | AM4: =IF(U4<>"",U4,IF($A4=$A3,AM3,"")) -> Faceoff | AN4: =IF(V4<>"",V4,IF($A4=$A3,AN3,"")) -> Faceoff_PeriodStart | AO4: =IF(W4<>"",W4,IF($A4=$A3,AO3,"")) | AP4: =IF(AND(T4="e",OR(AM4="Save",AN4="Turnover_Takeaway",AN4="Play_Defensive")),"Defensive",IF(AND(T4="o",OR(AM4="Save",AN4="Turnover_Takeaway",AN4="Play_Defensive")),"Offensive",IF(OR(AM4="Deadice",AM4="Stoppage",AM4="Intermission"),"",IF(T4="e","Offensive",IF(T4="o","Defensive",""))))) -> Offensive | AQ4: 18989 | AR4: Velodrome | AS4: Outcan | AT4: =IF(AND(O4="",P4=""),0,((M4*60)+N4)-((O4*60)+P4)) -> 0 | AU4: =(M4*60)+N4 -> 1080 | AV4: =IF(AND(O4="",P4=""),AU4,((O4*60)+P4)) -> 1080 | AW4: {=_xlfn._xlws.FILTER(shifts!A:A,(shifts!B:B=events!H4)*(shifts!AG:AG>=events!AU4)*(shifts!AH:AH<=events!AV4))} -> 1 | AX4: =IF(T4="e","event_team_player_"&AY4,IF(T4="o","opp_team_player_"&AY4,"")) -> event_team_player_2 | AY4: =COUNTIFS(A$3:A4,"="&A4,T$3:T4,"="&T4) -> 2 | AZ4: =SUMIFS(AT4:AT4,U4:U4,"=Intermission") -> 0 | BA4: =IF(H4=1,0,IF(H4=2,1080+AZ4,IF(H4=3,(1080*2)+AZ4,0))) -> 0 | BB4: =IF(U4="Intermission",BB3,((1080)-((M4*60)+N4))+BA4) -> 0 | BC4: =IF(BB4<5,0,BB4-5) -> 0 | BD4: =BC4+AT4+5 -> 5 | BE4: ="EVE"&$AQ4&(1000+$A4) -> EVE189891001 | BF4: =IF(C4<>"","LEVE"&$AQ4&(9000+$C4),"") | BG4: =IF(F4<>"","PLAY"&$AQ4&(1000+$F4),"") | BH4: =IF(E4<>"","SEQ"&$AQ4&(1000+$E4),"") -> SEQ189891001 | BI4: =IF(G4<>"","ZONE"&$AQ4&(1000+$G4),"") -> ZONE189891001 | CW4: =IF(U4="Faceoff","FACE"&AQ4&(1000+A4),"")
A5: 1 | C5: =IF(B5<>"",9000+B5,"") | D5: =IF(C5<>"",C5,B5) -> 0 | E5: 1 | G5: 1 | H5: =IF(U5="Intermission",H4+1,H4) -> 1 | M5: =IF(I5<>"",I5,IF($A5=$A4,M4,M5)) -> 18 | N5: =IF($A5=$A4,N4,J5) -> 00 | O5: =IF(K5<>"",K5,IF($A5=$A4,O4,"")) | P5: =IF(L5<>"",L5,IF($A5=$A4,P4,"")) | R5: 70 | T5: =IF(S5="x","",IF(S5=1,"e","o")) -> o | AG5: =IF($Q5="","",IF(AF5="","",IF($Q5="Home",$AF5,IF($AF5="n","n",IF($AF5="d","o",IF($AF5="o","d","")))))) | AH5: =IF($Q5="","",IF(AF5="","",IF($Q5="Away",$AF5,IF($AF5="n","n",IF($AF5="d","o",IF($AF5="o","d","")))))) | AM5: =IF(U5<>"",U5,IF($A5=$A4,AM4,"")) -> Faceoff | AN5: =IF(V5<>"",V5,IF($A5=$A4,AN4,"")) -> Faceoff_PeriodStart | AO5: =IF(W5<>"",W5,IF($A5=$A4,AO4,"")) | AP5: =IF(AND(T5="e",OR(AM5="Save",AN5="Turnover_Takeaway",AN5="Play_Defensive")),"Defensive",IF(AND(T5="o",OR(AM5="Save",AN5="Turnover_Takeaway",AN5="Play_Defensive")),"Offensive",IF(OR(AM5="Deadice",AM5="Stoppage",AM5="Intermission"),"",IF(T5="e","Offensive",IF(T5="o","Defensive",""))))) -> Defensive | AQ5: 18990 | AR5: Velodrome | AS5: Outcan | AT5: =IF(AND(O5="",P5=""),0,((M5*60)+N5)-((O5*60)+P5)) -> 0 | AZ5: =SUMIFS(AT5:AT5,U5:U5,"=Intermission") -> 0 | BA5: =IF(H5=1,0,IF(H5=2,1080+AZ5,IF(H5=3,(1080*2)+AZ5,0))) -> 0 | BB5: =IF(U5="Intermission",BB4,((1080)-((M5*60)+N5))+BA5) -> 0 | BC5: =IF(BB5<5,0,BB5-5) -> 0 | BD5: =BC5+AT5+5 -> 5 | BE5: ="EVE"&$AQ5&(1000+$A5) -> EVE189901001 | BF5: =IF(C5<>"","LEVE"&$AQ5&(9000+$C5),"") | BG5: =IF(F5<>"","PLAY"&$AQ5&(1000+$F5),"") | BH5: =IF(E5<>"","SEQ"&$AQ5&(1000+$E5),"") -> SEQ189901001 | BI5: =IF(G5<>"","ZONE"&$AQ5&(1000+$G5),"") -> ZONE189901001
A6: 2 | C6: =IF(B6<>"",9000+B6,"") | D6: =IF(C6<>"",C6,B6) -> 0 | E6: 1 | G6: 2 | H6: =IF(U6="Intermission",H5+1,H5) -> 1 | Q6: h | S6: 1 | T6: =IF(S6="x","",IF(S6=1,"e","o")) -> e | U6: Zone_Entry_Exit | V6: Zone_Entry | W6: ZoneEntry-OppTeam | AM6: =IF(U6<>"",U6,IF($A6=$A5,AM5,"")) -> Zone_Entry_Exit | AN6: =IF(V6<>"",V6,IF($A6=$A5,AN5,"")) -> Zone_Entry | AP6: =IF(AND(T6="e",OR(AM6="Save",AN6="Turnover_Takeaway",AN6="Play_Defensive")),"Defensive",IF(AND(T6="o",OR(AM6="Save",AN6="Turnover_Takeaway",AN6="Play_Defensive")),"Offensive",IF(OR(AM6="Deadice",AM6="Stoppage",AM6="Intermission"),"",IF(T6="e","Offensive",IF(T6="o","Defensive",""))))) -> Offensive | BE6: ="EVE"&$AQ6&(1000+$A6) -> EVE1002 | BF6: =IF(C6<>"","LEVE"&$AQ6&(9000+$C6),"") | BG6: =IF(F6<>"","PLAY"&$AQ6&(1000+$F6),"") | BH6: =IF(E6<>"","SEQ"&$AQ6&(1000+$E6),"") -> SEQ1001 | BI6: =IF(G6<>"","ZONE"&$AQ6&(1000+$G6),"") -> ZONE1002
A7: 4 | B7: 1 | C7: =IF(B7<>"",9000+B7,"") -> 9001 | D7: =IF(C7<>"",C7,B7) -> 9001 | E7: 1 | G7: 2 | H7: =IF(U7="Intermission",H6+1,H6) -> 1 | I7: 17 | J7: 59 | Q7: a | R7: 4 | S7: 1 | T7: =IF(S7="x","",IF(S7=1,"e","o")) -> e | U7: Pass | V7: Pass_Missed | W7: Pass-Forehand | X7: u | AF7: d | AI7: 1 | AJ7: 1 | AM7: =IF(U7<>"",U7,IF($A7=$A6,AM6,"")) -> Pass | AN7: =IF(V7<>"",V7,IF($A7=$A6,AN6,"")) -> Pass_Missed | AP7: =IF(AND(T7="e",OR(AM7="Save",AN7="Turnover_Takeaway",AN7="Play_Defensive")),"Defensive",IF(AND(T7="o",OR(AM7="Save",AN7="Turnover_Takeaway",AN7="Play_Defensive")),"Offensive",IF(OR(AM7="Deadice",AM7="Stoppage",AM7="Intermission"),"",IF(T7="e","Offensive",IF(T7="o","Defensive",""))))) -> Offensive
A8: 4 | B8: 1 | C8: =IF(B8<>"",9000+B8,"") -> 9001 | D8: =IF(C8<>"",C8,B8) -> 9001 | E8: 1 | G8: 2 | H8: =IF(U8="Intermission",H7+1,H7) -> 1 | R8: 25 | S8: 1 | T8: =IF(S8="x","",IF(S8=1,"e","o")) -> e | X8: u | AM8: =IF(U8<>"",U8,IF($A8=$A7,AM7,"")) -> Pass | AN8: =IF(V8<>"",V8,IF($A8=$A7,AN7,"")) -> Pass_Missed | AP8: =IF(AND(T8="e",OR(AM8="Save",AN8="Turnover_Takeaway",AN8="Play_Defensive")),"Defensive",IF(AND(T8="o",OR(AM8="Save",AN8="Turnover_Takeaway",AN8="Play_Defensive")),"Offensive",IF(OR(AM8="Deadice",AM8="Stoppage",AM8="Intermission"),"",IF(T8="e","Offensive",IF(T8="o","Defensive",""))))) -> Offensive
A9: 4 | B9: 1 | C9: =IF(B9<>"",9000+B9,"") -> 9001 | D9: =IF(C9<>"",C9,B9) -> 9001 | E9: 1 | G9: 2 | H9: =IF(U9="Intermission",H8+1,H8) -> 1 | R9: 70 | T9: =IF(S9="x","",IF(S9=1,"e","o")) -> o | X9: u | AM9: =IF(U9<>"",U9,IF($A9=$A8,AM8,"")) -> Pass | AN9: =IF(V9<>"",V9,IF($A9=$A8,AN8,"")) -> Pass_Missed | AP9: =IF(AND(T9="e",OR(AM9="Save",AN9="Turnover_Takeaway",AN9="Play_Defensive")),"Defensive",IF(AND(T9="o",OR(AM9="Save",AN9="Turnover_Takeaway",AN9="Play_Defensive")),"Offensive",IF(OR(AM9="Deadice",AM9="Stoppage",AM9="Intermission"),"",IF(T9="e","Offensive",IF(T9="o","Defensive",""))))) -> Defensive
A10: 5 | B10: 1 | C10: =IF(B10<>"",9000+B10,"") -> 9001 | D10: =IF(C10<>"",C10,B10) -> 9001 | E10: 1 | G10: 2 | H10: =IF(U10="Intermission",H9+1,H9) -> 1 | I10: 17 | J10: 59 | Q10: h | R10: 4 | S10: 1 | T10: =IF(S10="x","",IF(S10=1,"e","o")) -> e | U10: Turnover | V10: Turnover_Giveaway | W10: Giveaway-PassMissed | AF10: d | AI10: 1 | AM10: =IF(U10<>"",U10,IF($A10=$A9,AM9,"")) -> Turnover | AN10: =IF(V10<>"",V10,IF($A10=$A9,AN9,"")) -> Turnover_Giveaway | AP10: =IF(AND(T10="e",OR(AM10="Save",AN10="Turnover_Takeaway",AN10="Play_Defensive")),"Defensive",IF(AND(T10="o",OR(AM10="Save",AN10="Turnover_Takeaway",AN10="Play_Defensive")),"Offensive",IF(OR(AM10="Deadice",AM10="Stoppage",AM10="Intermission"),"",IF(T10="e","Offensive",IF(T10="o","Defensive",""))))) -> Offensive
A11: 5 | B11: 1 | C11: =IF(B11<>"",9000+B11,"") -> 9001 | D11: =IF(C11<>"",C11,B11) -> 9001 | E11: 1 | G11: 2 | H11: =IF(U11="Intermission",H10+1,H10) -> 1 | R11: 25 | S11: 1 | T11: =IF(S11="x","",IF(S11=1,"e","o")) -> e | AM11: =IF(U11<>"",U11,IF($A11=$A10,AM10,"")) -> Turnover | AN11: =IF(V11<>"",V11,IF($A11=$A10,AN10,"")) -> Turnover_Giveaway | AP11: =IF(AND(T11="e",OR(AM11="Save",AN11="Turnover_Takeaway",AN11="Play_Defensive")),"Defensive",IF(AND(T11="o",OR(AM11="Save",AN11="Turnover_Takeaway",AN11="Play_Defensive")),"Offensive",IF(OR(AM11="Deadice",AM11="Stoppage",AM11="Intermission"),"",IF(T11="e","Offensive",IF(T11="o","Defensive",""))))) -> Offensive
A12: 6 | B12: 2 | C12: =IF(B12<>"",9000+B12,"") -> 9002 | D12: =IF(C12<>"",C12,B12) -> 9002 | E12: 2 | G12: 3 | H12: =IF(U12="Intermission",H11+1,H11) -> 1 | I12: 17 | J12: 57 | Q12: h | R12: 14 | S12: 1 | T12: =IF(S12="x","",IF(S12=1,"e","o")) -> e | U12: Zone_Entry_Exit | V12: Zone_Keepin | W12: Zone-KeepIn | Y12: OffensivePlay_Zone-Dump/RimInZone | AA12: u | AF12: o | AJ12: 1 | AM12: =IF(U12<>"",U12,IF($A12=$A11,AM11,"")) -> Zone_Entry_Exit | AN12: =IF(V12<>"",V12,IF($A12=$A11,AN11,"")) -> Zone_Keepin | AP12: =IF(AND(T12="e",OR(AM12="Save",AN12="Turnover_Takeaway",AN12="Play_Defensive")),"Defensive",IF(AND(T12="o",OR(AM12="Save",AN12="Turnover_Takeaway",AN12="Play_Defensive")),"Offensive",IF(OR(AM12="Deadice",AM12="Stoppage",AM12="Intermission"),"",IF(T12="e","Offensive",IF(T12="o","Defensive",""))))) -> Offensive
A13: 6 | B13: 2 | C13: =IF(B13<>"",9000+B13,"") -> 9002 | D13: =IF(C13<>"",C13,B13) -> 9002 | E13: 2 | G13: 3 | H13: =IF(U13="Intermission",H12+1,H12) -> 1 | R13: 77 | T13: =IF(S13="x","",IF(S13=1,"e","o")) -> o | AJ13: 1 | AM13: =IF(U13<>"",U13,IF($A13=$A12,AM12,"")) -> Zone_Entry_Exit | AN13: =IF(V13<>"",V13,IF($A13=$A12,AN12,"")) -> Zone_Keepin | AP13: =IF(AND(T13="e",OR(AM13="Save",AN13="Turnover_Takeaway",AN13="Play_Defensive")),"Defensive",IF(AND(T13="o",OR(AM13="Save",AN13="Turnover_Takeaway",AN13="Play_Defensive")),"Offensive",IF(OR(AM13="Deadice",AM13="Stoppage",AM13="Intermission"),"",IF(T13="e","Offensive",IF(T13="o","Defensive",""))))) -> Defensive
A14: 6 | B14: 2 | C14: =IF(B14<>"",9000+B14,"") -> 9002 | D14: =IF(C14<>"",C14,B14) -> 9002 | E14: 2 | G14: 3 | H14: =IF(U14="Intermission",H13+1,H13) -> 1 | R14: 25 | T14: =IF(S14="x","",IF(S14=1,"e","o")) -> o | AM14: =IF(U14<>"",U14,IF($A14=$A13,AM13,"")) -> Zone_Entry_Exit | AN14: =IF(V14<>"",V14,IF($A14=$A13,AN13,"")) -> Zone_Keepin | AP14: =IF(AND(T14="e",OR(AM14="Save",AN14="Turnover_Takeaway",AN14="Play_Defensive")),"Defensive",IF(AND(T14="o",OR(AM14="Save",AN14="Turnover_Takeaway",AN14="Play_Defensive")),"Offensive",IF(OR(AM14="Deadice",AM14="Stoppage",AM14="Intermission"),"",IF(T14="e","Offensive",IF(T14="o","Defensive",""))))) -> Defensive
A15: 7 | B15: 2 | C15: =IF(B15<>"",9000+B15,"") -> 9002 | D15: =IF(C15<>"",C15,B15) -> 9002 | E15: 2 | G15: 3 | H15: =IF(U15="Intermission",H14+1,H14) -> 1 | I15: 17 | J15: 55 | Q15: h | R15: 14 | S15: 1 | T15: =IF(S15="x","",IF(S15=1,"e","o")) -> e | U15: Turnover | V15: Turnover_Giveaway | W15: Giveaway-DumpInZone | AF15: o | AI15: 1 | AJ15: 1 | AM15: =IF(U15<>"",U15,IF($A15=$A14,AM14,"")) -> Turnover | AN15: =IF(V15<>"",V15,IF($A15=$A14,AN14,"")) -> Turnover_Giveaway | AP15: =IF(AND(T15="e",OR(AM15="Save",AN15="Turnover_Takeaway",AN15="Play_Defensive")),"Defensive",IF(AND(T15="o",OR(AM15="Save",AN15="Turnover_Takeaway",AN15="Play_Defensive")),"Offensive",IF(OR(AM15="Deadice",AM15="Stoppage",AM15="Intermission"),"",IF(T15="e","Offensive",IF(T15="o","Defensive",""))))) -> Offensive
A16: 8 | C16: =IF(B16<>"",9000+B16,"") | D16: =IF(C16<>"",C16,B16) | E16: 2 | F16: 1 | G16: 3 | H16: =IF(U16="Intermission",H15+1,H15) -> 1 | I16: 17 | J16: 50 | K16: 17 | L16: 48 | Q16: a | R16: 68 | S16: 1 | T16: =IF(S16="x","",IF(S16=1,"e","o")) -> e | U16: Possession | Y16: OffensivePlay_Possession-CutBack | AA16: s | AF16: d | AJ16: 1 | AM16: =IF(U16<>"",U16,IF($A16=$A15,AM15,"")) -> Possession | AN16: =IF(V16<>"",V16,IF($A16=$A15,AN15,"")) | AP16: =IF(AND(T16="e",OR(AM16="Save",AN16="Turnover_Takeaway",AN16="Play_Defensive")),"Defensive",IF(AND(T16="o",OR(AM16="Save",AN16="Turnover_Takeaway",AN16="Play_Defensive")),"Offensive",IF(OR(AM16="Deadice",AM16="Stoppage",AM16="Intermission"),"",IF(T16="e","Offensive",IF(T16="o","Defensive",""))))) -> Offensive
A17: 8 | C17: =IF(B17<>"",9000+B17,"") | D17: =IF(C17<>"",C17,B17) | E17: 2 | F17: 1 | G17: 3 | H17: =IF(U17="Intermission",H16+1,H16) -> 1 | R17: 70 | T17: =IF(S17="x","",IF(S17=1,"e","o")) -> o | Y17: Defensive_PlayPossession-StickCheck | AJ17: 1 | AM17: =IF(U17<>"",U17,IF($A17=$A16,AM16,"")) -> Possession | AN17: =IF(V17<>"",V17,IF($A17=$A16,AN16,"")) | AP17: =IF(AND(T17="e",OR(AM17="Save",AN17="Turnover_Takeaway",AN17="Play_Defensive")),"Defensive",IF(AND(T17="o",OR(AM17="Save",AN17="Turnover_Takeaway",AN17="Play_Defensive")),"Offensive",IF(OR(AM17="Deadice",AM17="Stoppage",AM17="Intermission"),"",IF(T17="e","Offensive",IF(T17="o","Defensive",""))))) -> Defensive
A18: 9 | B18: 3 | C18: =IF(B18<>"",9000+B18,"") -> 9003 | D18: =IF(C18<>"",C18,B18) -> 9003 | E18: 2 | F18: 1 | G18: 3 | H18: =IF(U18="Intermission",H17+1,H17) -> 1 | I18: 17 | J18: 48 | Q18: a | R18: 68 | S18: 1 | T18: =IF(S18="x","",IF(S18=1,"e","o")) -> e | U18: Pass | V18: Pass_Completed | W18: Pass-Forehand | X18: s | Y18: OffensivePlay_Zone-Breakout | AA18: s | AF18: d | AM18: =IF(U18<>"",U18,IF($A18=$A17,AM17,"")) -> Pass | AN18: =IF(V18<>"",V18,IF($A18=$A17,AN17,"")) -> Pass_Completed | AP18: =IF(AND(T18="e",OR(AM18="Save",AN18="Turnover_Takeaway",AN18="Play_Defensive")),"Defensive",IF(AND(T18="o",OR(AM18="Save",AN18="Turnover_Takeaway",AN18="Play_Defensive")),"Offensive",IF(OR(AM18="Deadice",AM18="Stoppage",AM18="Intermission"),"",IF(T18="e","Offensive",IF(T18="o","Defensive",""))))) -> Offensive
