Workbook
Name DEfensive: Lists!$CQ:$CQ
Name EventType: Lists!$A$2:$A$16
Name Faceoff: Lists!$U$2:$U$1048576
Name Goal: Lists!$X$2:$X$1048576
Name Goal_PenaltyShot: Lists!$BO$2:$BO$1048576
Name Goal_Scored: Lists!$BM$2:$BM$1048576
Name Goal_Shootout: Lists!$BN$2:$BN$1048576
Name LoosePuck: Lists!$AD$2:$AD$1048576
Name Offensive: Lists!$CO:$CO
Name Pass: Lists!$W$2:$W$1048576
Name Pass_Completed: Lists!$AF$2:$AF$1048576
Name Pass_Deflected: Lists!$AH$2:$AH$1048576
Name Pass_Intercepted: Lists!$AI$2:$AI$1048576
Name Pass_Missed: Lists!$AG$2:$AG$1048576
Name Penalty: Lists!$AA$2:$AA$1048576
Name Penalty_Major: Lists!$AO$2:$AO$1048576
Name Penalty_Minor: Lists!$AP$2:$AP$1048576
Name Penalty_Offsetting: Lists!$AQ$2:$AQ$1048576
Name PenaltyShot_Missed: Lists!$AY$2:$AY$1048576
Name PenaltyShot_OnNet: Lists!$AX$2:$AX$1048576
Name PenaltyShot_Saved: Lists!$AZ$2:$AZ$1048576
Name PenaltyShot_Shootout: Lists!$AB$2:$AB$1048576
Name Play: Lists!$T:$T
Name Play_Defensive: Lists!$BS:$BS
Name Play_Offensive: Lists!$BR:$BR
Name Possession: Lists!$BT:$BT
Name Rebound: Lists!$BQ$2:$BQ$1048576
Name Save: Lists!$AE$2:$AE$1048576
Name Save_Freeze: Lists!$BB$2:$BB$1048576
Name Save_Played: Lists!$BP:$BP
Name Save_Rebound: Lists!$BA$2:$BA$1048576
Name Shootout_Missed: Lists!$AV$2:$AV$1048576
Name Shootout_OnNet: Lists!$AU$2:$AU$1048576
Name Shootout_Saved: Lists!$AW$2:$AW$1048576
Name Shot: Lists!$V$2:$V$1048576
Name Shot_Blocked: Lists!$BE$2:$BE$1048576
Name Shot_BlockedSameTeam: Lists!$BF$2:$BF$1048576
Name Shot_Deflected: Lists!$BG$2:$BG$1048576
Name Shot_DeflectedGoal: Lists!$BL$2:$BL$1048576
Name Shot_DeflectedOnNetSaved: Lists!$BH$2:$BH$1048576
Name Shot_Missed: Lists!$BD$2:$BD$1048576
Name Shot_OnNetGoal: Lists!$BJ$2:$BJ$1048576
Name Shot_OnNetSaved: Lists!$BC$2:$BC$1048576
Name Shot_TippedGoal: Lists!$BK$2:$BK$1048576
Name Shot_TippedOnNetSaved: Lists!$BI$2:$BI$1048576
Name Stoppage: Lists!$AC$2:$AC$1048576
Name Stoppage_Other: Lists!$AT$2:$AT$1048576
Name Stoppage_Period: Lists!$AS$2:$AS$1048576
Name Stoppage_Play: Lists!$AR$2:$AR$1048576
Name Turnover: Lists!$Y$2:$Y$1048576
Name Turnover_Giveaway: Lists!$AJ$2:$AJ$1048576
Name Turnover_Takeaway: Lists!$AK$2:$AK$1048576
Name Zone_Entry: Lists!$AL$2:$AL$1048576
Name Zone_Entry_Exit: Lists!$Z$2:$Z$1048576
Name Zone_Exit: Lists!$AM$2:$AM$1048576
Name Zone_Keepin: Lists!$AN$2:$AN$1048576

Sheet Rules
A1: Play | B1: NextPlay | C1: EventPlayers | D1: OppPlayers | E1: OnIcePlayers | I1: SequecnceDefinition | J1: Loose puck to loose puck
A2: Goal | B2: Stoppage | C2: Scorer | D2: Goalie, Defenders in Front | E2: All
A3: Stoppage | B3: Faceoff | C3: Winner, Next Player to Touch | D3: Loser | E3: None | I3: PlayDefinition | J3: Series of possession, passes that lead to shot or zone entry/exit
A4: Pass_Intercepted, Pass/ShotMissed Other Team Possession | B4: Turnover | C4: Passer/Shooter, Intended Recipient | D4: Intercepteor/Blocker | E4: In Play
A5: Turnover | B5: ChangePossession | C5: Player who turned over | D5: Player who received turnover | E5: In Play
A6: ShotSaved | B6: Save
A9: Zone breakout pass also add pass
A10: Turnover (any kind) also add pass/shot/etc
A11: Zone dumoin/clear that results in turnover list both

Sheet Lists
A1: EventType | C1: EventTypeDetail | E1: EventTypeDetail2 | G1: OffensivePlay | I1: DefensivePlay | K1: Team | N1: NHL Net | O1: Max | P1: Min | Q1: Total Max | R1: Total Min | T1: Play | U1: Faceoff | V1: Shot | W1: Pass | X1: Goal | Y1: Turnover | Z1: Zone Entry/Exit | AA1: Penalty | AB1: PenaltyShot/Shootout | AC1: Stoppage | AD1: LoosePuck | AE1: Save | AF1: Pass-Completed | AG1: Pass-Missed | AH1: Pass-Deflected | AI1: Pass-Intercepted | AJ1: Turnover-Giveaway | AK1: Turnover-Takeaway | AL1: Zone-Entry | AM1: Zone-Exit | AN1: Zone-Keepin | AO1: Penalty-Major | AP1: Penalty-Minor | AQ1: Penalty-Offsetting | AR1: Stoppage-Play | AS1: Stoppage-Period | AT1: Stoppage-Other | AU1: Shootout-OnNet | AV1: Shootout-Missed | AW1: Shootout-Saved | AX1: PenaltyShot-OnNet | AY1: PenaltyShot-Missed | AZ1: PenaltyShot-Saved | BA1: Save-Rebound | BB1: Save-Freeze | BC1: Shot_OnNetSaved | BD1: Shot_Missed | BE1: Shot_Blocked | BF1: Shot_BlockedSameTeam | BG1: Shot_Deflected | BH1: Shot_DeflectedOnNetSaved | BI1: Shot_TippedOnNetSaved | BJ1: Shot_OnNetGoal | BK1: Shot_TippedGoal | BL1: Shot_DeflectedGoal | BM1: Goal_Scored | BN1: Goal_Shootout | BO1: Goal_PenaltyShot | BP1: Save_Played | BQ1: Rebound | BR1: Play_Offensive | BS1: Play_Defensive | BT1: Possession | BU1: Faceoff | BV1: None | CA1: shift_start | CC1: shift_end | CE1: label | CG1: play_detail1 | CH1: play_detail2 | CL1: Offensive | CM1: Defensive | CO1: Offensive | CQ1: Defensive
K2: Home | L2: =K3 -> Away | N2: X | O2: 36 | P2: -36 | Q2: =O2+O4 -> 38.375 | R2: =P2-O4 -> -38.375 | T2: Play_Offensive | U2: Faceoff_AfterPenalty | V2: Shot_OnNetSaved | W2: Pass_Completed | X2: Goal_Scored | Y2: Turnover_Giveaway | Z2: Zone_Entry | AA2: Penalty_Minor | AB2: PenaltyShot_OnNet | AC2: Stoppage_Period | AD2: LoosePuck_Forecheck | AE2: Save_Rebound | AF2: Pass-Stretch | AG2: Pass-Stretch | AH2: Pass-Stretch | AI2: Pass-Stretch | AJ2: Giveaway-Misplayed | AK2: Takeaway-BattleWon | AL2: ZoneEntry-Rush | AM2: ZoneExit-Rush | AN2: Zone-KeepIn | AO2: Penalty-Bench Penalty | AP2: Penalty-Bench Penalty | AQ2: Penalty-Bench Penalty | AR2: Stoppage-Icing | AS2: Stoppage-StartofShootout | AT2: Stoppage-ObjectsonIce | AU2: Shot-Wrist | AV2: Shot-Wrist | AW2: Shot-Wrist | AX2: Shot-Wrist | AY2: Shot-Wrist | AZ2: Shot-Wrist | BA2: Save-Glove | BB2: Save-Glove | BC2: Shot-Wrist | BD2: Shot-Wrist | BE2: Shot-Wrist | BF2: Shot-Wrist | BG2: Shot-Deflection | BH2: Shot-Deflection | BI2: Shot-Tip | BJ2: Shot-Wrist | BL2: Shot-Deflection | BM2: Goal-Wrist | BN2: Goal-Wrist | BO2: Goal-Wrist | BP2: Save-Glove | BQ2: Rebound_TeamRecovered | BS2: Play-PokeCheck | BT2: Breakaway | BU2: Shot | BV2: All | BX2: event_team_player_1 | BY2: e | CA2: PeriodStart | CC2: - | CE2: Assist-Primary | CG2: OffensivePlay-DriveMiddle | CJ2: Offensive | CL2: OffensivePlay-Drive | CO2: OffensivePlay-DriveMiddle | CQ2: DefensivePlay-PokeCheck
A3: Faceoff | B3: None | C3: Faceoff | E3: Shot-Wrist | G3: DriveMiddle | I3: PokeCheck | K3: Away | L3: =K2 -> Home | N3: Y | O3: 24 | P3: -24 | Q3: =O3+O5 -> 26.375 | R3: -24 | T3: Play_Defensive | U3: Faceoff_AfterGoal | V3: Shot_Missed | W3: Pass_Missed | X3: Goal_Shootout | Y3: Turnover_Takeaway | Z3: Zone_Exit | AA3: Penalty_Offsetting | AB3: PenaltyShot_Missed | AC3: Stoppage_Play | AD3: LoosePuck_Battle | AE3: Save_Freeze | AF3: Pass-Rim/Wrap | AG3: Pass-Rim/Wrap | AH3: Pass-Rim/Wrap | AI3: Pass-Rim/Wrap | AJ3: Giveaway-BattleLost | AK3: Takeaway-PokeCheck | AL3: ZoneEntry-Pass | AM3: ZoneExit-Pass | AN3: Zone-Pinch | AO3: Penalty-Boarding | AP3: Penalty-Boarding | AQ3: Penalty-Boarding | AR3: Stoppage-Offsides | AS3: Stoppage-PeriodStart | AT3: Stoppage-HomeTimeout | AU3: Shot-Slap | AV3: Shot-Slap | AW3: Shot-Slap | AX3: Shot-Slap | AY3: Shot-Slap | AZ3: Shot-Slap | BA3: Save-Blocker | BB3: Save-Blocker | BC3: Shot-Slap | BD3: Shot-Slap | BE3: Shot-Slap | BF3: Shot-Slap | BG3: Shot-Wrist | BH3: Shot-Wrist | BI3: Shot-Wrist | BJ3: Shot-Slap | BK3: Shot-Wrist | BL3: Shot-Wrist | BM3: Goal-Slap | BN3: Goal-Slap | BO3: Goal-Slap | BP3: Save-Blocker | BQ3: Rebound_OppTeamRecovered | BR3: Play-DriveMiddle | BS3: Play-PokeCheckFailed | BU3: Pass | BV3: Involved | BX3: event_team_player_2 | BY3: o | CA3: FaceoffAfterGoal | CC3: Period Start | CE3: Assist-Secondary | CG3: OffensivePlay-DriveWide | CJ3: Defensive | CO3: OffensivePlay-DriveWide | CQ3: DefensivePlay-PokeCheckFailed
A4: Shot | C4: Faceoff-AfterPenalty | E4: Shot-Slap | G4: DriveWide | I4: PokeCheckFailed | N4: PostX | O4: 2.375 | U4: Faceoff_PeriodStart | V4: Shot_Blocked | W4: Pass_Deflected | X4: Goal_PenaltyShot | Z4: Zone_Keepin | AA4: Penalty_Major | AB4: PenaltyShot_Saved | AC4: Stoppage_Other | AE4: Save_Played | AF4: Pass-Backhand | AG4: Pass-Backhand | AH4: Pass-Backhand | AI4: Pass-Backhand | AJ4: Giveaway-PassIntercepted | AK4: Takeaway-PassIntercepted | AL4: ZoneEntry-DumpIn | AM4: ZoneExit-Clear | AN4: Zone-Other | AO4: Penalty-Charging | AP4: Penalty-Charging | AQ4: Penalty-Charging | AR4: Stoppage-ClockProblem | AS4: Stoppage-PeriodEnd | AT4: Stoppage-VisitorTimeout | AU4: Shot-Backhand | AV4: Shot-Backhand | AW4: Shot-Backhand | AX4: Shot-Backhand | AY4: Shot-Backhand | AZ4: Shot-Backhand | BA4: Save-LeftPad | BB4: Save-LeftPad | BC4: Shot-Backhand | BD4: Shot-Backhand | BE4: Shot-Backhand | BF4: Shot-Backhand | BG4: Shot-Slap | BH4: Shot-Slap | BI4: Shot-Slap | BJ4: Shot-Backhand | BK4: Shot-Slap | BL4: Shot-Slap | BM4: Goal-Backhand | BN4: Goal-Backhand | BO4: Goal-Backhand | BP4: Save-LeftPad | BQ4: Rebound_ShotGenerated | BR4: Play-DriveWide | BS4: Play-SeperateFromPuck | BU4: Goal | BV4: All | BX4: event_team_player_3 | CA4: GameStart | CC4: Period End | CE4: Breakout | CG4: OffensivePlay-DriveCorner | CO4: OffensivePlay-DriveCorner | CQ4: DefensivePlay-SeperateFromPuck
A5: Pass | C5: Faceoff-AfterGoal | E5: Shot-Backhand | G5: DriveCorner | I5: SeperateFromPuck | N5: PostY | O5: 2.375 | U5: Faceoff_AfterStoppage | V5: Shot_BlockedSameTeam | W5: Pass_Intercepted | AB5: ShootoutShot_OnNet | AC5: Stoppage_GameEnd | AF5: Pass-Forehand | AG5: Pass-Forehand | AH5: Pass-Forehand | AI5: Pass-Forehand | AJ5: Giveaway-PassMissed | AK5: Takeaway-PassBlocked | AL5: ZoneEntry-Chip | AM5: ZoneExit-Chip | AO5: Penalty-CrossChecking | AP5: Penalty-CrossChecking | AQ5: Penalty-CrossChecking | AR5: Stoppage-HighStick | AT5: Stoppage-RinkRepair | AU5: Shot-Snap | AV5: Shot-Snap | AW5: Shot-Snap | AX5: Shot-Snap | AY5: Shot-Snap | AZ5: Shot-Snap | BA5: Save-RightPad | BB5: Save-RightPad | BC5: Shot-Snap | BD5: Shot-Snap | BE5: Shot-Snap | BF5: Shot-Snap | BG5: Shot-Backhand | BH5: Shot-Backhand | BI5: Shot-Backhand | BJ5: Shot-Snap | BK5: Shot-Backhand | BL5: Shot-Backhand | BM5: Goal-Tip | BN5: Goal-Snap | BO5: Goal-Snap | BP5: Save-RightPad | BQ5: Rebound_FlurryGenerated | BR5: Play-DriveCorner | BS5: Play-Backcheck | BU5: Turnover | BV5: Involved | BX5: event_team_player_4 | CA5: FaceoffAfterPenalty | CC5: Puck Out of Play | CE5: End-to-End-Rush | CG5: OffensivePlay-DriveNetMiddle | CO5: OffensivePlay-DriveNetMiddle | CQ5: DefensivePlay-Backcheck
A6: Goal | C6: Faceoff-PeriodStart | E6: Shot-Tip | G6: DriveNetMiddle | I6: Backcheck | U6: Faceoff_GameStart | V6: Shot_Deflected | AB6: ShootoutShot_Missed | AF6: Pass-Bank | AG6: Pass-Bank | AH6: Pass-Bank | AI6: Pass-Bank | AJ6: Giveaway-PassBlocked | AK6: Takeaway-ShotBlocked | AL6: ZoneEntry-FromExitClear | AM6: ZoneExit-PassMiss/Misplay | AO6: Penalty-DelayofGame | AP6: Penalty-DelayofGame | AQ6: Penalty-DelayofGame | AR6: Stoppage-HandPass | AT6: Stoppage-PlayerEquipment | AU6: Shot-WrapAround | AV6: Shot-WrapAround | AW6: Shot-WrapAround | AX6: Shot-WrapAround | AY6: Shot-WrapAround | AZ6: Shot-WrapAround | BA6: Save-Stick | BB6: Save-Stick | BC6: Shot-WrapAround | BD6: Shot-WrapAround | BE6: Shot-WrapAround | BF6: Shot-WrapAround | BG6: Shot-Snap | BH6: Shot-Snap | BI6: Shot-Snap | BJ6: Shot-WrapAround | BK6: Shot-Snap | BL6: Shot-Snap | BM6: Goal-Snap | BN6: Goal-WrapAround | BO6: Goal-WrapAround | BP6: Save-Stick | BR6: Play-DriveNetMiddle | BS6: Play-FroceWide | BU6: Zone_Entry_Exit | BV6: Involved | BX6: event_team_player_5 | CA6: OtherFaceoff | CC6: Injury | CG6: OffensivePlay-DriveNetWide | CO6: OffensivePlay-DriveNetWide | CQ6: DefensivePlay-FroceWide
A7: Turnover | C7: Shot-OnNet | E7: Shot-Snap | G7: DriveNetWide | I7: FroceWide | V7: Shot_DeflectedOnNetSaved | AB7: ShootoutShot_Saved | AF7: Pass-Dump | AG7: Pass-Dump | AH7: Pass-Dump | AI7: Pass-Dump | AJ7: Giveaway-PassReceiverMissed | AK7: Takeaway-ZoneClear/Dump | AL7: ZoneEntry-PassMiss/Misplay | AM7: ZoneExit-OppTeam | AO7: Penalty-Diving | AP7: Penalty-Diving | AQ7: Penalty-Diving | AR7: Stoppage-NetDislodged | AT7: Stoppage-Challenge | AU7: Shot-Bat | AV7: Shot-Bat | AW7: Shot-Bat | AX7: Shot-Bat | AY7: Shot-Bat | AZ7: Shot-Bat | BA7: Save-Scramble | BB7: Save-Scramble | BC7: Shot-Bat | BD7: Shot-Bat | BE7: Shot-Bat | BF7: Shot-Bat | BG7: Shot-WrapAround | BH7: Shot-WrapAround | BI7: Shot-WrapAround | BJ7: Shot-Bat | BK7: Shot-WrapAround | BL7: Shot-WrapAround | BM7: Goal-WrapAround | BN7: Goal-Bat | BO7: Goal-Bat | BP7: Save-Scramble | BR7: Play-DriveNetWide | BS7: Play-Contain | BU7: Penalty | BV7: Involved | BX7: event_team_player_6 | CA7: DeadIce/Stoppage | CC7: Home Penalty | CG7: OffensivePlay-CrashNet | CO7: OffensivePlay-CrashNet | CQ7: DefensivePlay-Contain
A8: Zone_Entry_Exit | C8: Shot-Missed | E8: Shot-WrapAround | G8: CrashNet | I8: Contain | V8: Shot_Tipped | AF8: Pass-Tipped | AG8: Pass-Tipped | AH8: Pass-Tipped | AI8: Pass-Tipped | AJ8: Giveaway-ShotBlocked | AK8: Takeaway-AttemptedZoneClear/Dump | AL8: ZoneEntry-OppTeam | AM8: ZoneExit-Lob | AO8: Penalty-Elbowing | AP8: Penalty-Elbowing | AQ8: Penalty-Elbowing | AR8: Stoppage-Injury | AT8: Stoppage-Other | AU8: Shot-Cradle | AV8: Shot-Cradle | AW8: Shot-Cradle | AX8: Shot-Cradle | AY8: Shot-Cradle | AZ8: Shot-Cradle | BA8: Save-Butterfly | BB8: Save-Butterfly | BC8: Shot-Cradle | BD8: Shot-Cradle | BE8: Shot-Cradle | BF8: Shot-Cradle | BG8: Shot-Bat | BH8: Shot-Bat | BI8: Shot-Bat | BJ8: Shot-Cradle | BK8: Shot-Bat | BL8: Shot-Bat | BM8: Goal-Bat | BN8: Goal-Cradle | BO8: Goal-Cradle | BP8: Save-Butterfly | BR8: Play-CrashNet | BS8: Play-BeatMiddle | BU8: PenaltyShot_Shootout | BV8: Involved | BX8: opp_team_player_1 | CA8: Intermission | CC8: Away Penalty | CG8: OffensivePlay-Delay | CO8: OffensivePlay-Delay | CQ8: DefensivePlay-BeatMiddle
A9: Penalty | C9: Shot-Blocked | E9: Shot-Bat | G9: Delay | I9: BeatMiddle | V9: Shot_TippedOnNetSaved | AF9: Pass-Lob | AG9: Pass-Lob | AH9: Pass-Lob | AI9: Pass-Lob | AJ9: Giveaway-ShotMissed | AK9: Takeaway-Other | AL9: ZoneEntry-Lob | AM9: ZoneExit-CausedTurnover | AO9: Penalty-GoalieInterference | AP9: Penalty-GoalieInterference | AQ9: Penalty-GoalieInterference | AR9: Stoppage-GoalieStoppage | AU9: Shot-Poke | AV9: Shot-Poke | AW9: Shot-Poke | AX9: Shot-Poke | AY9: Shot-Poke | AZ9: Shot-Poke | BA9: Save-Chest | BB9: Save-Chest | BC9: Shot-Poke | BD9: Shot-Poke | BE9: Shot-Poke | BF9: Shot-Poke | BG9: Shot-Cradle | BH9: Shot-Cradle | BI9: Shot-Cradle | BJ9: Shot-Poke | BK9: Shot-Cradle | BL9: Shot-Cradle | BM9: Goal-Cradle | BN9: Goal-Poke | BO9: Goal-Poke | BP9: Save-Chest | BR9: Play-Delay | BS9: Play-BeatWide | BU9: Stoppage | BV9: None | BX9: opp_team_player_2 | CA9: DelayedPenalty | CC9: Home Goalie Stoppage | CG9: OffensivePlay-Deke | CO9: OffensivePlay-Deke | CQ9: DefensivePlay-BeatWide
A10: PenaltyShot_Shootout | C10: Shot-BlockedSameTeam | E10: Shot-Cradle | G10: Deke | I10: BeatWide | V10: Shot_OnNetGoal | AF10: Pass-Drop | AG10: Pass-Drop | AH10: Pass-Drop | AI10: Pass-Drop | AJ10: Giveaway-ZoneClear/Dump | AL10: ZoneEntry-RushBreakaway | AM10: ZoneExit-Other | AO10: Penalty-HighSticking | AP10: Penalty-HighSticking | AQ10: Penalty-HighSticking | AR10: Stoppage-PuckOutofPlay | AU10: Shot-BetweenLegs | AV10: Shot-BetweenLegs | AW10: Shot-BetweenLegs | AX10: Shot-BetweenLegs | AY10: Shot-BetweenLegs | AZ10: Shot-BetweenLegs | BA10: Save-Shoulder | BB10: Save-Shoulder | BC10: Shot-BetweenLegs | BD10: Shot-BetweenLegs | BE10: Shot-BetweenLegs | BF10: Shot-BetweenLegs | BG10: Shot-Poke | BH10: Shot-Poke | BI10: Shot-Poke | BJ10: Shot-BetweenLegs | BK10: Shot-Poke | BL10: Shot-Poke | BM10: Goal-Poke | BN10: Goal-BetweenLegs | BO10: Goal-BetweenLegs | BP10: Save-Other | BR10: Play-Deke | BS10: Play-BeatDeke | BU10: Hit | BV10: Involved | BX10: opp_team_player_3 | CA10: GameStart | CC10: Away Goalie Stoppage | CG10: OffensivePlay-Chip | CO10: OffensivePlay-Chip | CQ10: DefensivePlay-BeatDeke
A11: Stoppage | C11: Shot-Deflected | E11: Shot-Poke | G11: Chip | I11: BeatDeke | V11: Shot_OnNetTippedGoal | AF11: Pass-Deflected/TippedShot | AG11: Pass-Deflected/TippedShot | AH11: Pass-Deflected/TippedShot | AI11: Pass-Deflected/TippedShot | AJ11: Giveaway-AttemptedZoneClear/Dump | AL11: ZoneEntry-CausedTurnover | AO11: Penalty-Holding | AP11: Penalty-Holding | AQ11: Penalty-Holding | AR11: Stoppage-Penalty | AU11: Shot-Tip | AV11: Shot-Tip | AW11: Shot-Other | AX11: Shot-Other | AY11: Shot-Other | AZ11: Shot-Other | BA11: Save-Skate | BB11: Save-Skate | BC11: Shot-Dumpin | BD11: Shot-Dumpin | BE11: Shot-Dumpin | BF11: Shot-Dumpin | BG11: Shot-BetweenLegs | BH11: Shot-BetweenLegs | BI11: Shot-BetweenLegs | BJ11: Shot-Dumpin | BK11: Shot-BetweenLegs | BL11: Shot-BetweenLegs | BM11: Goal-BetweenLegs | BN11: Goal-Other | BO11: Goal-Other | BR11: Play-Chip | BS11: Play-BeatSpeed | BU11: Possession | BV11: Involved | BX11: opp_team_player_4 | CC11: Home Offside | CG11: OffensivePlay-Other | CO11: OffensivePlay-Other | CQ11: DefensivePlay-BeatSpeed
A12: Hit | C12: Shot-DeflectedOnNet | E12: Shot-BetweenLegs | G12: Other | I12: BeatSpeed | V12: Shot_OnNetDeflectedGoal | AF12: Pass-ReceiverMissed | AG12: Pass-ReceiverMissed | AH12: Pass-ReceiverMissed | AI12: Pass-ReceiverMissed | AJ12: Giveaway-ZoneEntry/ExitMisplay | AL12: ZoneEntry-Other | AO12: Penalty-Interference | AP12: Penalty-Interference | AQ12: Penalty-Interference | AR12: Stoppage-Goal | AU12: Shot-Other | AV12: Shot-Other | BA12: Save-Other | BB12: Save-Other | BC12: Shot-OneTime | BD12: Shot-OneTime | BE12: Shot-OneTime | BF12: Shot-OneTime | BG12: Shot-Dumpin | BH12: Shot-Dumpin | BI12: Shot-Dumpin | BJ12: Shot-OneTime | BK12: Shot-Dumpin | BL12: Shot-Dumpin | BM12: Goal-Dumpin | BR12: Play-Other | BS12: Play-BoxOut | BU12: LoosePuck | BV12: None | BX12: opp_team_player_5 | CC12: Home Icing | CG12: OffensivePlay-DumpChase | CO12: OffensivePlay-DumpChase | CQ12: DefensivePlay-BoxOut
A13: Possession | C13: Shot-Tipped | E13: Shot-Dumpin | G13: DumpChase | I13: BoxOut | V13: Shot_Goal | AF13: Pass-Other | AG13: Pass-Other | AH13: Pass-Other | AI13: Pass-Other | AJ13: Giveaway-DumpInZone | AO13: Penalty-Hooking | AP13: Penalty-Fighting | AQ13: Penalty-Fighting | BC13: Shot-Tip | BD13: Shot_Tipped | BE13: Shot_Tipped | BF13: Shot_Tipped | BG13: Shot-OneTime | BH13: Shot-OneTime | BI13: Shot-OneTime | BJ13: Shot-Other | BK13: Shot-OneTime | BL13: Shot-OneTime | BM13: Goal-Deflection | BR13: Play-DumpChase | BS13: Play-AttemptedClear | BU13: Save | BV13: Involved | BX13: opp_team_player_6 | CC13: Away Offside | CG13: OffensivePlay-Forecheck | CO13: OffensivePlay-Forecheck | CQ13: DefensivePlay-AttemptedClear
A14: LoosePuck | C14: Pass-Completed | E14: Shot-Deflection | G14: Forecheck | I14: Other | AJ14: Giveaway-Other | AO14: Penalty-Roughing | AP14: Penalty-Hooking | AQ14: Penalty-Hooking | BC14: Shot-Other | BD14: Shot-Other | BE14: Shot-Other | BF14: Shot-Other | BG14: Shot-Other | BH14: Shot-Other | BI14: Shot-Other | BJ14: Shot-Deflection | BK14: Shot-Other | BL14: Shot-Other | BM14: Goal-OneTime | BR14: Play-Forecheck | BS14: Play-Other | BU14: TeamPossessionChange | BV14: None | CC14: Away Icing | CG14: OffensivePlay-Speed | CO14: OffensivePlay-Speed | CQ14: DefensivePlay-Other
A15: Save | C15: Pass-Missed | E15: Shot-OneTime | G15: Speed | AO15: Penalty-Slashing | AP15: Penalty-Roughing | AQ15: Penalty-Roughing | BJ15: Shot-Tip | BM15: Goal-Other | BR15: Play-Speed | BU15: Rebound | BV15: Invoived | CC15: Clock Problem | CG15: OffensivePlay-Dump/RimInZone | CO15: OffensivePlay-Dump/RimInZone | CQ15: DefensivePlay-BlockedShot
A16: TeamPossessionChange | C16: Pass-Deflected | E16: Shot-Other | AO16: Penalty-TooManyMenontheIce | AP16: Penalty-Slashing | AQ16: Penalty-Slashing | BR16: Play-Dump/RimInZone | CC16: Puck Frozen | CG16: DefensivePlay-PokeCheck | CO16: OffensivePlay-Shot | CQ16: DefensivePlay-PassBlocked
A17: Rebound | C17: Pass-Intercepted | E17: Pass-Stretch | AO17: Penalty-Tripping | AP17: Penalty-Misconduct | AQ17: Penalty-Misconduct | CC17: Puck in Crowd | CG17: DefensivePlay-PokeCheckFailed | CO17: OffensivePlay-Pass | CQ17: DefensivePlay-PassIntercepted
A18: DeadIce | C18: Turnover-Giveaway | E18: Pass-Rim/Wrap | AO18: Penalty-Other | AP18: Penalty-TooManyMenontheIce | AQ18: Penalty-TooManyMenontheIce | CC18: Goalie Stopped (after SOG) | CG18: DefensivePlay-SeperateFromPuck | CO18: OffensivePlay-Breakout | CQ18: OffensivePlay-FrontofNet
A19: Play | C19: Turnover-Takeaway | E19: Pass-Backhand | AP19: Penalty-Tripping | AQ19: Penalty-Tripping | CC19: Referee or Linesperson | CG19: DefensivePlay-Backcheck | CO19: OffensivePlay-AssistPrimary | CQ19: DefensivePlay-FrontofNet
A20: Timeout | C20: Zone-Entry | E20: Pass-Forehand | AP20: Penalty-UnsportsmanlikeConduct | AQ20: Penalty-UnsportsmanlikeConduct | CC20: High Stick | CG20: DefensivePlay-FroceWide | CO20: OffensivePlay-AssistSecondary | CQ20: OffensivePlay-DumpInAttempt
A21: Intermission | C21: Zone-Exit | E21: Pass-Bank | AP21: Penalty-Other | AQ21: Penalty-Other | CC21: Objects on Ice | CG21: DefensivePlay-Contain | CO21: OffensivePlay-OpenIceDeke | CQ21: DefensivePlay-ClearingAttempt
A22: Clockstop | C22: Zone-Keepin | E22: Pass-Other | CC22: Hand Pass | CG22: DefensivePlay-BeatMiddle | CO22: OffensivePlay-PuckRetrievalDumpIn | CQ22: DefensivePlay-PuckRetrievalDumpIn
A23: GameStart | C23: Penalty | E23: Giveaway-Misplayed | CC23: Premature Substitution | CG23: DefensivePlay-BeatWide | CO23: OffensivePlay-PuckRetrievalShot | CQ23: DefensivePlay-PuckRetrievalShot
A24: GameEnd | C24: Penalty-Offsetting | E24: Giveaway-BattleLost | CC24: Puck in Netting | CG24: DefensivePlay-BeatDeke | CO24: OffensivePlay-PuckRetreivalTurnover | CQ24: DefensivePlay-PuckRetreivalTurnover
A25: Penalty_Delayed | C25: Stoppage-Freeze | E25: Giveaway-PassIntercepted | CC25: Puck in Benches | CG25: DefensivePlay-BeatSpeed | CO25: OffensivePlay-PuckRetreivalPass | CQ25: DefensivePlay-PuckRetreivalPass
C26: Stoppage-OutfofPlay | E26: Giveaway-PassMissed | CC26: Net Dislodged Offensive Skater | CG26: DefensivePlay-BoxOut | CO26: OffensivePlay-Cycle | CQ26: DefnsivePlay-ForceedDumpin/Clear
C27: Stoppage-PeriodEnd | E27: Giveaway-PassBlocked | CC27: Puck Frzn-Goalie-Bynd Ctr | CG27: DefensivePlay-AttemptedClear | CO27: OffensivePlay-EndToEndRush | CQ27: DefensivePlay-Pressure
C28: Stoppage-Goal | E28: Giveaway-ShotBlocked | CC28: Skater Puck Frozen | CG28: DefensivePlay-Other | CQ28: DefensivePlay-ZoneEntryDenial
C29: Stoppage-Penalty | E29: Giveaway-ShotMissed | CC29: Valid stoppage type reasons (reason): | CG29: OffensivePlay-Shot | CQ29: DefensivePlay-ZoneExitDenial
C30: Shootout-OnNet | E30: Giveaway-Other | CC30: TV timeout | CG30: OffensivePlay-Pass
C31: Shootout-Missed | E31: Takeaway-BattleWon | CC31: Home Timeout | CG31: OffensivePlay_Breakout
C32: Shootout-Saved | E32: Takeaway-PokeCheck | CC32: Visitor Timeout | CG32: OffensivePlay-AssistPrimary
C33: PenaltyShot-OnNet | E33: Takeaway-PassIntercepted | CC33: Player Injury | CG33: OffensivePlay-AssistSecondary
C34: PenaltyShot-Missed | E34: Takeaway-PassBlocked | CC34: Official Injury | CG34: DefensivePlay-BlockedShot
C35: PenaltyShot-Saved | E35: Takeaway-ShotBlocked | CC35: Rink Repair | CG35: DefensivePlay-PassBlocked
C36: LoosePuck-Forecheck | E36: Takeaway-Other | CC36: Ice problem | CG36: DefensivePlay-PassIntercepted
C37: LoosePuck-Battle | E37: ZoneEntry-Rush | CC37: Player Equipment | CG37: OffensivePlay-FrontofNet
C38: Save-Rebound | E38: ZoneEntry-Pass | CC38: Video Review | CG38: DefensivePlay-FrontofNet
C39: Save-Freeze | E39: ZoneEntry-DumpIn | CC39: Chlg Hm - off-side | CG39: OffensivePlay-DumpInAttempt
C40: Save | E40: ZoneExit-Rush | CC40: Chlg Vis - off-side | CG40: DefensivePlay-ClearingAttempt
...

Sheet events
A1: event_index | B1: linked_event_index | C1: sequence_index | D1: play_index | E1: Period | F1: event_start_min_ | G1: event_start_sec_ | H1: event_end_min_ | I1: event_end_sec_ | J1: event_start_min | K1: event_start_sec | L1: event_end_min | M1: event_end_sec | N1: Team | O1: Player | P1: role_abrev | Q1: Type_ | R1: event_detail_ | S1: event_detail_2_ | T1: successful | U1: play_detail1 | V1: play_detail2 | W1: play_detail_successful | X1: event_team_zone | Y1: home_team_zone | Z1: away_team_zone | AA1: forced | AB1: pressure | AC1: Type | AD1: event_detail | AE1: event_detail_2 | AF1: side_of_puck | AG1: game_id | AH1: home_team | AI1: away_team | AJ1: duration | AK1: time_start_total_seconds | AL1: time_end_total_seconds | AM1: shift_index | AN1: player_role | AO1: role_number | AP1: running_intermission_duration | AQ1: period_start_total_running_seconds | AR1: running_video_time | AS1: event_running_start | AT1: event_running_end | AU1: event_id | AV1: play_id | AW1: sequence_id | AX1: next_event | AY1: last_event | AZ1: next_faceoff | BA1: last_faceoff | BB1: next_team_zone_entry | BC1: last_team_zone_entry | BD1: next_team_zone_exit | BE1: next_team_zone_exit | BF1: next_team_shot | BG1: last_team_shot | BH1: next_team_goal | BI1: last_team_goal | BJ1: associated_faceoff_id | BK1: associated_pass_id1 | BL1: associated_pass_id2 | BM1: associated_pass_id3 | BN1: associated_pass_id4 | BO1: associated_zone_entry | BP1: assocaited_zone_exit | BQ1: assocaited_penalty | BR1: assocaited_shot1 | BS1: assocaited_shot2 | BT1: assocaited_shot3 | BU1: assocaited_shot4 | BV1: associated_save1 | BW1: associated_save2 | BX1: associated_save3 | BY1: associated_save4 | BZ1: associated_turnover1 | CA1: associated_turnover2 | CB1: associated_turnover3 | CC1: associated_turnover4 | CD1: assocaited_possession1 | CE1: assocaited_possession2 | CF1: assocaited_possession3 | CG1: assocaited_possession4 | CH1: associated_breakout | CI1: assocaited_assist_primary | CJ1: assocaited_assist_secondary | CK1: faceoff_id | CL1: pass_id | CM1: turnover_id | CN1: shot_id | CO1: save_id | CP1: rebound_id | CQ1: goal_id | CR1: penalty_id | CS1: zone_entry_id | CT1: zone_exit_id | CU1: possession_id | CV1: pre_shot_pass | CW1: failed_entry | CX1: failed_exit | CY1: retreival_lead_to_breakout | CZ1: botched_retreivals | DA1: possession_change
A2: 0 | E2: 1 | L2: =IF(H2<>"",H2,IF($A2=$A1,L1,"")) | M2: =IF(I2<>"",I2,IF($A2=$A1,M1,"")) | Q2: GameStart | R2: Faceoff_GameStart | Y2: =IF(N2="","",IF(N2="Home",X2,"")) | AC2: =IF(Q2<>"",Q2,IF(A2=A1,Q2,"")) -> GameStart | AG2: 18981 | AH2: Nelson | AI2: Velodrome | AQ2: 0 | AR2: 0 | AS2: =IF(AR2<5,0,AR2-5) -> 0 | AT2: =AS2+AJ2+5 -> 5
A3: 1 | E3: =IF(Q3="Intermission",E2+1,E2) -> 1 | F3: 18 | G3: 00 | J3: =IF(F3<>"",F3,IF($A3=$A2,J2,J3)) -> 18 | K3: =IF($A3=$A2,K2,G3) -> 00 | L3: =IF(H3<>"",H3,IF($A3=$A2,L2,"")) | M3: =IF(I3<>"",I3,IF($A3=$A2,M2,"")) | N3: Away | O3: 70 | P3: e | Q3: Faceoff | R3: Faceoff_PeriodStart | Y3: =IF($N3="","",IF(X3="","",IF($N3="Home",$X3,IF($X3="n","n",IF($X3="d","o",IF($X3="o","d","")))))) | Z3: =IF($N3="","",IF(X3="","",IF($N3="Away",$X3,IF($X3="n","n",IF($X3="d","o",IF($X3="o","d","")))))) | AC3: =IF(Q3<>"",Q3,IF($A3=$A2,AC2,"")) -> Faceoff | AD3: =IF(R3<>"",R3,IF($A3=$A2,AD2,"")) -> Faceoff_PeriodStart | AE3: =IF(S3<>"",S3,IF($A3=$A2,AE2,"")) | AF3: =IF(AND(P3="e",OR(AC3="Save",AD3="Turnover_Takeaway",AD3="Play_Defensive")),"Defensive",IF(AND(P3="o",OR(AC3="Save",AD3="Turnover_Takeaway",AD3="Play_Defensive")),"Offensive",IF(OR(AC3="Deadice",AC3="Stoppage",AC3="Intermission"),"",IF(P3="e","Offensive",IF(P3="o","Defensive",""))))) -> Offensive | AG3: =AG2 -> 18981 | AH3: =AH2 -> Nelson | AI3: =AI2 -> Velodrome | AJ3: =IF(AND(L3="",M3=""),0,((J3*60)+K3)-((L3*60)+M3)) -> 0 | AK3: =(J3*60)+K3 -> 1080 | AL3: =IF(AND(L3="",M3=""),AK3,((L3*60)+M3)) -> 1080 | AM3: {=_xlfn._xlws.FILTER(shifts!A:A,(shifts!B:B=events!E3)*(shifts!AG:AG>=events!AK3)*(shifts!AH:AH<=events!AL3))} -> 1 | AN3: =IF(P3="e","event_team_player_"&AO3,IF(P3="o","opp_team_player_"&AO3,"")) -> event_team_player_1 | AO3: =COUNTIFS(A$3:A3,"="&A3,P$3:P3,"="&P3) -> 1 | AP3: =SUMIFS(AJ3:AJ3,Q3:Q3,"=Intermission") -> 0 | AQ3: =IF(E3=1,0,IF(E3=2,1080+AP3,IF(E3=3,(1080*2)+AP3,0))) -> 0 | AR3: =IF(Q3="Intermission",AR2,((1080)-((J3*60)+K3))+AQ3) -> 0 | AS3: =IF(AR3<5,0,AR3-5) -> 0 | AT3: =AS3+AJ3+5 -> 5
A4: 1 | E4: =IF(Q4="Intermission",E3+1,E3) -> 1 | J4: =IF(F4<>"",F4,IF($A4=$A3,J3,J4)) -> 18 | K4: =IF($A4=$A3,K3,G4) -> 00 | L4: =IF(H4<>"",H4,IF($A4=$A3,L3,"")) | M4: =IF(I4<>"",I4,IF($A4=$A3,M3,"")) | N4: =IF(A4=A3,N3,"") -> Away | O4: 87 | P4: e | Y4: =IF($N4="","",IF(X4="","",IF($N4="Home",$X4,IF($X4="n","n",IF($X4="d","o",IF($X4="o","d","")))))) | Z4: =IF($N4="","",IF(X4="","",IF($N4="Away",$X4,IF($X4="n","n",IF($X4="d","o",IF($X4="o","d","")))))) | AC4: =IF(Q4<>"",Q4,IF($A4=$A3,AC3,"")) -> Faceoff | AD4: =IF(R4<>"",R4,IF($A4=$A3,AD3,"")) -> Faceoff_PeriodStart | AE4: =IF(S4<>"",S4,IF($A4=$A3,AE3,"")) | AF4: =IF(AND(P4="e",OR(AC4="Save",AD4="Turnover_Takeaway",AD4="Play_Defensive")),"Defensive",IF(AND(P4="o",OR(AC4="Save",AD4="Turnover_Takeaway",AD4="Play_Defensive")),"Offensive",IF(OR(AC4="Deadice",AC4="Stoppage",AC4="Intermission"),"",IF(P4="e","Offensive",IF(P4="o","Defensive",""))))) -> Offensive | AG4: =AG3 -> 18981 | AH4: =AH3 -> Nelson | AI4: =AI3 -> Velodrome | AJ4: =IF(AND(L4="",M4=""),0,((J4*60)+K4)-((L4*60)+M4)) -> 0 | AK4: =(J4*60)+K4 -> 1080 | AL4: =IF(AND(L4="",M4=""),AK4,((L4*60)+M4)) -> 1080 | AM4: {=_xlfn._xlws.FILTER(shifts!A:A,(shifts!B:B=events!E4)*(shifts!AG:AG>=events!AK4)*(shifts!AH:AH<=events!AL4))} -> 1 | AN4: =IF(P4="e","event_team_player_"&AO4,IF(P4="o","opp_team_player_"&AO4,"")) -> event_team_player_2 | AO4: =COUNTIFS(A$3:A4,"="&A4,P$3:P4,"="&P4) -> 2 | AP4: =SUMIFS(AJ4:AJ4,Q4:Q4,"=Intermission") -> 0 | AQ4: =IF(E4=1,0,IF(E4=2,1080+AP4,IF(E4=3,(1080*2)+AP4,0))) -> 0 | AR4: =IF(Q4="Intermission",AR3,((1080)-((J4*60)+K4))+AQ4) -> 0 | AS4: =IF(AR4<5,0,AR4-5) -> 0 | AT4: =AS4+AJ4+5 -> 5
A5: 1 | E5: =IF(Q5="Intermission",E4+1,E4) -> 1 | J5: =IF(F5<>"",F5,IF($A5=$A4,J4,J5)) -> 18 | K5: =IF($A5=$A4,K4,G5) -> 00 | L5: =IF(H5<>"",H5,IF($A5=$A4,L4,"")) | M5: =IF(I5<>"",I5,IF($A5=$A4,M4,"")) | N5: =IF(A5=A4,N4,"") -> Away | O5: 10 | P5: o | Y5: =IF($N5="","",IF(X5="","",IF($N5="Home",$X5,IF($X5="n","n",IF($X5="d","o",IF($X5="o","d","")))))) | Z5: =IF($N5="","",IF(X5="","",IF($N5="Away",$X5,IF($X5="n","n",IF($X5="d","o",IF($X5="o","d","")))))) | AC5: =IF(Q5<>"",Q5,IF($A5=$A4,AC4,"")) -> Faceoff | AD5: =IF(R5<>"",R5,IF($A5=$A4,AD4,"")) -> Faceoff_PeriodStart | AE5: =IF(S5<>"",S5,IF($A5=$A4,AE4,"")) | AF5: =IF(AND(P5="e",OR(AC5="Save",AD5="Turnover_Takeaway",AD5="Play_Defensive")),"Defensive",IF(AND(P5="o",OR(AC5="Save",AD5="Turnover_Takeaway",AD5="Play_Defensive")),"Offensive",IF(OR(AC5="Deadice",AC5="Stoppage",AC5="Intermission"),"",IF(P5="e","Offensive",IF(P5="o","Defensive",""))))) -> Defensive | AG5: =AG4 -> 18981 | AH5: =AH4 -> Nelson | AI5: =AI4 -> Velodrome | AJ5: =IF(AND(L5="",M5=""),0,((J5*60)+K5)-((L5*60)+M5)) -> 0 | AP5: =SUMIFS(AJ5:AJ5,Q5:Q5,"=Intermission") -> 0 | AQ5: =IF(E5=1,0,IF(E5=2,1080+AP5,IF(E5=3,(1080*2)+AP5,0))) -> 0 | AR5: =IF(Q5="Intermission",AR4,((1080)-((J5*60)+K5))+AQ5) -> 0 | AS5: =IF(AR5<5,0,AR5-5) -> 0 | AT5: =AS5+AJ5+5 -> 5
A6: 2 | E6: =IF(Q6="Intermission",E5+1,E5) -> 1 | F6: 17 | G6: 59 | H6: 17 | I6: 56 | J6: =IF(F6<>"",F6,IF($A6=$A5,J5,J6)) -> 17 | K6: =IF($A6=$A5,K5,G6) -> 59 | L6: =IF(H6<>"",H6,IF($A6=$A5,L5,"")) -> 17 | M6: =IF(I6<>"",I6,IF($A6=$A5,M5,"")) -> 56 | N6: Away | O6: 87 | P6: e | Q6: Possession | Y6: =IF($N6="","",IF(X6="","",IF($N6="Home",$X6,IF($X6="n","n",IF($X6="d","o",IF($X6="o","d","")))))) | Z6: =IF($N6="","",IF(X6="","",IF($N6="Away",$X6,IF($X6="n","n",IF($X6="d","o",IF($X6="o","d","")))))) | AC6: =IF(Q6<>"",Q6,IF($A6=$A5,AC5,"")) -> Possession | AD6: =IF(R6<>"",R6,IF($A6=$A5,AD5,"")) | AE6: =IF(S6<>"",S6,IF($A6=$A5,AE5,"")) | AF6: =IF(AND(P6="e",OR(AC6="Save",AD6="Turnover_Takeaway",AD6="Play_Defensive")),"Defensive",IF(AND(P6="o",OR(AC6="Save",AD6="Turnover_Takeaway",AD6="Play_Defensive")),"Offensive",IF(OR(AC6="Deadice",AC6="Stoppage",AC6="Intermission"),"",IF(P6="e","Offensive",IF(P6="o","Defensive",""))))) -> Offensive | AG6: =AG5 -> 18981 | AH6: =AH5 -> Nelson | AI6: =AI5 -> Velodrome | AJ6: =IF(AND(L6="",M6=""),0,((J6*60)+K6)-((L6*60)+M6)) -> 3 | AP6: =SUMIFS(AJ6:AJ6,Q6:Q6,"=Intermission") -> 0 | AQ6: =IF(E6=1,0,IF(E6=2,1080+AP6,IF(E6=3,(1080*2)+AP6,0))) -> 0 | AR6: =IF(Q6="Intermission",AR5,((1080)-((J6*60)+K6))+AQ6) -> 1 | AS6: =IF(AR6<5,0,AR6-5) -> 0 | AT6: =AS6+AJ6+5 -> 8
A7: 2 | E7: =IF(Q7="Intermission",E6+1,E6) -> 1 | J7: =IF(F7<>"",F7,IF($A7=$A6,J6,J7)) -> 17 | K7: =IF($A7=$A6,K6,G7) -> 59 | L7: =IF(H7<>"",H7,IF($A7=$A6,L6,"")) -> 17 | M7: =IF(I7<>"",I7,IF($A7=$A6,M6,"")) -> 56 | N7: =IF(A7=A6,N6,"") -> Away | O7: 15 | P7: o | Y7: =IF($N7="","",IF(X7="","",IF($N7="Home",$X7,IF($X7="n","n",IF($X7="d","o",IF($X7="o","d","")))))) | Z7: =IF($N7="","",IF(X7="","",IF($N7="Away",$X7,IF($X7="n","n",IF($X7="d","o",IF($X7="o","d","")))))) | AC7: =IF(Q7<>"",Q7,IF($A7=$A6,AC6,"")) -> Possession | AD7: =IF(R7<>"",R7,IF($A7=$A6,AD6,"")) | AE7: =IF(S7<>"",S7,IF($A7=$A6,AE6,"")) | AF7: =IF(AND(P7="e",OR(AC7="Save",AD7="Turnover_Takeaway",AD7="Play_Defensive")),"Defensive",IF(AND(P7="o",OR(AC7="Save",AD7="Turnover_Takeaway",AD7="Play_Defensive")),"Offensive",IF(OR(AC7="Deadice",AC7="Stoppage",AC7="Intermission"),"",IF(P7="e","Offensive",IF(P7="o","Defensive",""))))) -> Defensive | AG7: =AG6 -> 18981 | AH7: =AH6 -> Nelson | AI7: =AI6 -> Velodrome | AJ7: =IF(AND(L7="",M7=""),0,((J7*60)+K7)-((L7*60)+M7)) -> 3 | AP7: =SUMIFS(AJ7:AJ7,Q7:Q7,"=Intermission") -> 0 | AQ7: =IF(E7=1,0,IF(E7=2,1080+AP7,IF(E7=3,(1080*2)+AP7,0))) -> 0 | AR7: =IF(Q7="Intermission",AR6,((1080)-((J7*60)+K7))+AQ7) -> 1 | AS7: =IF(AR7<5,0,AR7-5) -> 0 | AT7: =AS7+AJ7+5 -> 8
A8: 3 | E8: =IF(Q8="Intermission",E7+1,E7) -> 1 | F8: 17 | G8: 56 | H8: 17 | I8: 55 | J8: =IF(F8<>"",F8,IF($A8=$A7,J7,J8)) -> 17 | K8: =IF($A8=$A7,K7,G8) -> 56 | L8: =IF(H8<>"",H8,IF($A8=$A7,L7,"")) -> 17 | M8: =IF(I8<>"",I8,IF($A8=$A7,M7,"")) -> 55 | N8: Away | O8: 87 | P8: e | Q8: Zone_Entry_Exit | R8: Zone_Entry | S8: ZoneEntry-Rush | Y8: =IF($N8="","",IF(X8="","",IF($N8="Home",$X8,IF($X8="n","n",IF($X8="d","o",IF($X8="o","d","")))))) | Z8: =IF($N8="","",IF(X8="","",IF($N8="Away",$X8,IF($X8="n","n",IF($X8="d","o",IF($X8="o","d","")))))) | AC8: =IF(Q8<>"",Q8,IF($A8=$A7,AC7,"")) -> Zone_Entry_Exit | AD8: =IF(R8<>"",R8,IF($A8=$A7,AD7,"")) -> Zone_Entry | AE8: =IF(S8<>"",S8,IF($A8=$A7,AE7,"")) -> ZoneEntry-Rush | AF8: =IF(AND(P8="e",OR(AC8="Save",AD8="Turnover_Takeaway",AD8="Play_Defensive")),"Defensive",IF(AND(P8="o",OR(AC8="Save",AD8="Turnover_Takeaway",AD8="Play_Defensive")),"Offensive",IF(OR(AC8="Deadice",AC8="Stoppage",AC8="Intermission"),"",IF(P8="e","Offensive",IF(P8="o","Defensive",""))))) -> Offensive | AG8: =AG7 -> 18981 | AH8: =AH7 -> Nelson | AI8: =AI7 -> Velodrome | AJ8: =IF(AND(L8="",M8=""),0,((J8*60)+K8)-((L8*60)+M8)) -> 1 | AP8: =SUMIFS(AJ8:AJ8,Q8:Q8,"=Intermission") -> 0 | AQ8: =IF(E8=1,0,IF(E8=2,1080+AP8,IF(E8=3,(1080*2)+AP8,0))) -> 0 | AR8: =IF(Q8="Intermission",AR7,((1080)-((J8*60)+K8))+AQ8) -> 4 | AS8: =IF(AR8<5,0,AR8-5) -> 0 | AT8: =AS8+AJ8+5 -> 6
A9: 3 | E9: =IF(Q9="Intermission",E8+1,E8) -> 1 | J9: =IF(F9<>"",F9,IF($A9=$A8,J8,J9)) -> 17 | K9: =IF($A9=$A8,K8,G9) -> 56 | L9: =IF(H9<>"",H9,IF($A9=$A8,L8,"")) -> 17 | M9: =IF(I9<>"",I9,IF($A9=$A8,M8,"")) -> 55 | N9: =IF(A9=A8,N8,"") -> Away | O9: 15 | P9: o | Y9: =IF($N9="","",IF(X9="","",IF($N9="Home",$X9,IF($X9="n","n",IF($X9="d","o",IF($X9="o","d","")))))) | Z9: =IF($N9="","",IF(X9="","",IF($N9="Away",$X9,IF($X9="n","n",IF($X9="d","o",IF($X9="o","d","")))))) | AC9: =IF(Q9<>"",Q9,IF($A9=$A8,AC8,"")) -> Zone_Entry_Exit | AD9: =IF(R9<>"",R9,IF($A9=$A8,AD8,"")) -> Zone_Entry | AE9: =IF(S9<>"",S9,IF($A9=$A8,AE8,"")) -> ZoneEntry-Rush | AF9: =IF(AND(P9="e",OR(AC9="Save",AD9="Turnover_Takeaway",AD9="Play_Defensive")),"Defensive",IF(AND(P9="o",OR(AC9="Save",AD9="Turnover_Takeaway",AD9="Play_Defensive")),"Offensive",IF(OR(AC9="Deadice",AC9="Stoppage",AC9="Intermission"),"",IF(P9="e","Offensive",IF(P9="o","Defensive",""))))) -> Defensive | AG9: =AG8 -> 18981 | AH9: =AH8 -> Nelson | AI9: =AI8 -> Velodrome | AJ9: =IF(AND(L9="",M9=""),0,((J9*60)+K9)-((L9*60)+M9)) -> 1 | AP9: =SUMIFS(AJ9:AJ9,Q9:Q9,"=Intermission") -> 0 | AQ9: =IF(E9=1,0,IF(E9=2,1080+AP9,IF(E9=3,(1080*2)+AP9,0))) -> 0 | AR9: =IF(Q9="Intermission",AR8,((1080)-((J9*60)+K9))+AQ9) -> 4 | AS9: =IF(AR9<5,0,AR9-5) -> 0 | AT9: =AS9+AJ9+5 -> 6
A10: 3 | E10: =IF(Q10="Intermission",E9+1,E9) -> 1 | J10: =IF(F10<>"",F10,IF($A10=$A9,J9,J10)) -> 17 | K10: =IF($A10=$A9,K9,G10) -> 56 | L10: =IF(H10<>"",H10,IF($A10=$A9,L9,"")) -> 17 | M10: =IF(I10<>"",I10,IF($A10=$A9,M9,"")) -> 55 | N10: =IF(A10=A9,N9,"") -> Away | O10: 23 | P10: o | Y10: =IF($N10="","",IF(X10="","",IF($N10="Home",$X10,IF($X10="n","n",IF($X10="d","o",IF($X10="o","d","")))))) | Z10: =IF($N10="","",IF(X10="","",IF($N10="Away",$X10,IF($X10="n","n",IF($X10="d","o",IF($X10="o","d","")))))) | AC10: =IF(Q10<>"",Q10,IF($A10=$A9,AC9,"")) -> Zone_Entry_Exit | AD10: =IF(R10<>"",R10,IF($A10=$A9,AD9,"")) -> Zone_Entry | AE10: =IF(S10<>"",S10,IF($A10=$A9,AE9,"")) -> ZoneEntry-Rush | AF10: =IF(AND(P10="e",OR(AC10="Save",AD10="Turnover_Takeaway",AD10="Play_Defensive")),"Defensive",IF(AND(P10="o",OR(AC10="Save",AD10="Turnover_Takeaway",AD10="Play_Defensive")),"Offensive",IF(OR(AC10="Deadice",AC10="Stoppage",AC10="Intermission"),"",IF(P10="e","Offensive",IF(P10="o","Defensive",""))))) -> Defensive | AG10: =AG9 -> 18981 | AH10: =AH9 -> Nelson | AI10: =AI9 -> Velodrome | AJ10: =IF(AND(L10="",M10=""),0,((J10*60)+K10)-((L10*60)+M10)) -> 1 | AP10: =SUMIFS(AJ10:AJ10,Q10:Q10,"=Intermission") -> 0 | AQ10: =IF(E10=1,0,IF(E10=2,1080+AP10,IF(E10=3,(1080*2)+AP10,0))) -> 0 | AR10: =IF(Q10="Intermission",AR9,((1080)-((J10*60)+K10))+AQ10) -> 4 | AS10: =IF(AR10<5,0,AR10-5) -> 0 | AT10: =AS10+AJ10+5 -> 6
A11: 3 | E11: =IF(Q11="Intermission",E10+1,E10) -> 1 | J11: =IF(F11<>"",F11,IF($A11=$A10,J10,J11)) -> 17 | K11: =IF($A11=$A10,K10,G11) -> 56 | L11: =IF(H11<>"",H11,IF($A11=$A10,L10,"")) -> 17 | M11: =IF(I11<>"",I11,IF($A11=$A10,M10,"")) -> 55 | N11: =IF(A11=A10,N10,"") -> Away | O11: 37 | P11: o | Y11: =IF($N11="","",IF(X11="","",IF($N11="Home",$X11,IF($X11="n","n",IF($X11="d","o",IF($X11="o","d","")))))) | Z11: =IF($N11="","",IF(X11="","",IF($N11="Away",$X11,IF($X11="n","n",IF($X11="d","o",IF($X11="o","d","")))))) | AC11: =IF(Q11<>"",Q11,IF($A11=$A10,AC10,"")) -> Zone_Entry_Exit | AD11: =IF(R11<>"",R11,IF($A11=$A10,AD10,"")) -> Zone_Entry | AE11: =IF(S11<>"",S11,IF($A11=$A10,AE10,"")) -> ZoneEntry-Rush | AF11: =IF(AND(P11="e",OR(AC11="Save",AD11="Turnover_Takeaway",AD11="Play_Defensive")),"Defensive",IF(AND(P11="o",OR(AC11="Save",AD11="Turnover_Takeaway",AD11="Play_Defensive")),"Offensive",IF(OR(AC11="Deadice",AC11="Stoppage",AC11="Intermission"),"",IF(P11="e","Offensive",IF(P11="o","Defensive",""))))) -> Defensive | AG11: =AG10 -> 18981 | AH11: =AH10 -> Nelson | AI11: =AI10 -> Velodrome | AJ11: =IF(AND(L11="",M11=""),0,((J11*60)+K11)-((L11*60)+M11)) -> 1 | AP11: =SUMIFS(AJ11:AJ11,Q11:Q11,"=Intermission") -> 0 | AQ11: =IF(E11=1,0,IF(E11=2,1080+AP11,IF(E11=3,(1080*2)+AP11,0))) -> 0 | AR11: =IF(Q11="Intermission",AR10,((1080)-((J11*60)+K11))+AQ11) -> 4 | AS11: =IF(AR11<5,0,AR11-5) -> 0 | AT11: =AS11+AJ11+5 -> 6
A12: 4 | E12: =IF(Q12="Intermission",E11+1,E11) -> 1 | F12: 17 | G12: 55 | J12: =IF(F12<>"",F12,IF($A12=$A11,J11,J12)) -> 17 | K12: =IF($A12=$A11,K11,G12) -> 55 | L12: =IF(H12<>"",H12,IF($A12=$A11,L11,"")) | M12: =IF(I12<>"",I12,IF($A12=$A11,M11,"")) | N12: Away | O12: 87 | P12: e | Q12: Shot | R12: Shot_Missed | S12: Shot-Wrist | Y12: =IF($N12="","",IF(X12="","",IF($N12="Home",$X12,IF($X12="n","n",IF($X12="d","o",IF($X12="o","d","")))))) | Z12: =IF($N12="","",IF(X12="","",IF($N12="Away",$X12,IF($X12="n","n",IF($X12="d","o",IF($X12="o","d","")))))) | AC12: =IF(Q12<>"",Q12,IF($A12=$A11,AC11,"")) -> Shot | AD12: =IF(R12<>"",R12,IF($A12=$A11,AD11,"")) -> Shot_Missed | AE12: =IF(S12<>"",S12,IF($A12=$A11,AE11,"")) -> Shot-Wrist | AF12: =IF(AND(P12="e",OR(AC12="Save",AD12="Turnover_Takeaway",AD12="Play_Defensive")),"Defensive",IF(AND(P12="o",OR(AC12="Save",AD12="Turnover_Takeaway",AD12="Play_Defensive")),"Offensive",IF(OR(AC12="Deadice",AC12="Stoppage",AC12="Intermission"),"",IF(P12="e","Offensive",IF(P12="o","Defensive",""))))) -> Offensive | AG12: =AG11 -> 18981 | AH12: =AH11 -> Nelson | AI12: =AI11 -> Velodrome | AJ12: =IF(AND(L12="",M12=""),0,((J12*60)+K12)-((L12*60)+M12)) -> 0 | AP12: =SUMIFS(AJ12:AJ12,Q12:Q12,"=Intermission") -> 0 | AQ12: =IF(E12=1,0,IF(E12=2,1080+AP12,IF(E12=3,(1080*2)+AP12,0))) -> 0 | AR12: =IF(Q12="Intermission",AR11,((1080)-((J12*60)+K12))+AQ12) -> 5 | AS12: =IF(AR12<5,0,AR12-5) -> 0 | AT12: =AS12+AJ12+5 -> 5
A13: 4 | E13: =IF(Q13="Intermission",E12+1,E12) -> 1 | J13: =IF(F13<>"",F13,IF($A13=$A12,J12,J13)) -> 17 | K13: =IF($A13=$A12,K12,G13) -> 55 | L13: =IF(H13<>"",H13,IF($A13=$A12,L12,"")) | M13: =IF(I13<>"",I13,IF($A13=$A12,M12,"")) | N13: =IF(A13=A12,N12,"") -> Away | O13: 37 | P13: o | Y13: =IF($N13="","",IF(X13="","",IF($N13="Home",$X13,IF($X13="n","n",IF($X13="d","o",IF($X13="o","d","")))))) | Z13: =IF($N13="","",IF(X13="","",IF($N13="Away",$X13,IF($X13="n","n",IF($X13="d","o",IF($X13="o","d","")))))) | AC13: =IF(Q13<>"",Q13,IF($A13=$A12,AC12,"")) -> Shot | AD13: =IF(R13<>"",R13,IF($A13=$A12,AD12,"")) -> Shot_Missed | AE13: =IF(S13<>"",S13,IF($A13=$A12,AE12,"")) -> Shot-Wrist | AF13: =IF(AND(P13="e",OR(AC13="Save",AD13="Turnover_Takeaway",AD13="Play_Defensive")),"Defensive",IF(AND(P13="o",OR(AC13="Save",AD13="Turnover_Takeaway",AD13="Play_Defensive")),"Offensive",IF(OR(AC13="Deadice",AC13="Stoppage",AC13="Intermission"),"",IF(P13="e","Offensive",IF(P13="o","Defensive",""))))) -> Defensive | AG13: =AG12 -> 18981 | AH13: =AH12 -> Nelson | AI13: =AI12 -> Velodrome | AJ13: =IF(AND(L13="",M13=""),0,((J13*60)+K13)-((L13*60)+M13)) -> 0 | AP13: =SUMIFS(AJ13:AJ13,Q13:Q13,"=Intermission") -> 0 | AQ13: =IF(E13=1,0,IF(E13=2,1080+AP13,IF(E13=3,(1080*2)+AP13,0))) -> 0 | AR13: =IF(Q13="Intermission",AR12,((1080)-((J13*60)+K13))+AQ13) -> 5 | AS13: =IF(AR13<5,0,AR13-5) -> 0 | AT13: =AS13+AJ13+5 -> 5
A14: 5 | E14: =IF(Q14="Intermission",E13+1,E13) -> 1 | F14: 17 | G14: 55 | J14: =IF(F14<>"",F14,IF($A14=$A13,J13,J14)) -> 17 | K14: =IF($A14=$A13,K13,G14) -> 55 | L14: =IF(H14<>"",H14,IF($A14=$A13,L13,"")) | M14: =IF(I14<>"",I14,IF($A14=$A13,M13,"")) | N14: Away | O14: 87 | P14: e | Q14: Turnover | R14: Turnover_Giveaway | S14: Giveaway-ShotMissed | Y14: =IF($N14="","",IF(X14="","",IF($N14="Home",$X14,IF($X14="n","n",IF($X14="d","o",IF($X14="o","d","")))))) | Z14: =IF($N14="","",IF(X14="","",IF($N14="Away",$X14,IF($X14="n","n",IF($X14="d","o",IF($X14="o","d","")))))) | AC14: =IF(Q14<>"",Q14,IF($A14=$A13,AC13,"")) -> Turnover | AD14: =IF(R14<>"",R14,IF($A14=$A13,AD13,"")) -> Turnover_Giveaway | AE14: =IF(S14<>"",S14,IF($A14=$A13,AE13,"")) -> Giveaway-ShotMissed | AF14: =IF(AND(P14="e",OR(AC14="Save",AD14="Turnover_Takeaway",AD14="Play_Defensive")),"Defensive",IF(AND(P14="o",OR(AC14="Save",AD14="Turnover_Takeaway",AD14="Play_Defensive")),"Offensive",IF(OR(AC14="Deadice",AC14="Stoppage",AC14="Intermission"),"",IF(P14="e","Offensive",IF(P14="o","Defensive",""))))) -> Offensive | AG14: =AG13 -> 18981 | AH14: =AH13 -> Nelson | AI14: =AI13 -> Velodrome | AJ14: =IF(AND(L14="",M14=""),0,((J14*60)+K14)-((L14*60)+M14)) -> 0 | AP14: =SUMIFS(AJ14:AJ14,Q14:Q14,"=Intermission") -> 0 | AQ14: =IF(E14=1,0,IF(E14=2,1080+AP14,IF(E14=3,(1080*2)+AP14,0))) -> 0 | AR14: =IF(Q14="Intermission",AR13,((1080)-((J14*60)+K14))+AQ14) -> 5 | AS14: =IF(AR14<5,0,AR14-5) -> 0 | AT14: =AS14+AJ14+5 -> 5
A15: 6 | E15: =IF(Q15="Intermission",E14+1,E14) -> 1 | F15: 17 | G15: 52 | J15: =IF(F15<>"",F15,IF($A15=$A14,J14,J15)) -> 17 | K15: =IF($A15=$A14,K14,G15) -> 52 | L15: =IF(H15<>"",H15,IF($A15=$A14,L14,"")) | M15: =IF(I15<>"",I15,IF($A15=$A14,M14,"")) | N15: Home | O15: 23 | P15: e | Q15: Pass | R15: Pass_Completed | S15: Pass-Forehand | Y15: =IF($N15="","",IF(X15="","",IF($N15="Home",$X15,IF($X15="n","n",IF($X15="d","o",IF($X15="o","d","")))))) | Z15: =IF($N15="","",IF(X15="","",IF($N15="Away",$X15,IF($X15="n","n",IF($X15="d","o",IF($X15="o","d","")))))) | AC15: =IF(Q15<>"",Q15,IF($A15=$A14,AC14,"")) -> Pass | AD15: =IF(R15<>"",R15,IF($A15=$A14,AD14,"")) -> Pass_Completed | AE15: =IF(S15<>"",S15,IF($A15=$A14,AE14,"")) -> Pass-Forehand | AF15: =IF(AND(P15="e",OR(AC15="Save",AD15="Turnover_Takeaway",AD15="Play_Defensive")),"Defensive",IF(AND(P15="o",OR(AC15="Save",AD15="Turnover_Takeaway",AD15="Play_Defensive")),"Offensive",IF(OR(AC15="Deadice",AC15="Stoppage",AC15="Intermission"),"",IF(P15="e","Offensive",IF(P15="o","Defensive",""))))) -> Offensive | AG15: =AG14 -> 18981 | AH15: =AH14 -> Nelson | AI15: =AI14 -> Velodrome | AJ15: =IF(AND(L15="",M15=""),0,((J15*60)+K15)-((L15*60)+M15)) -> 0 | AP15: =SUMIFS(AJ15:AJ15,Q15:Q15,"=Intermission") -> 0 | AQ15: =IF(E15=1,0,IF(E15=2,1080+AP15,IF(E15=3,(1080*2)+AP15,0))) -> 0 | AR15: =IF(Q15="Intermission",AR14,((1080)-((J15*60)+K15))+AQ15) -> 8 | AS15: =IF(AR15<5,0,AR15-5) -> 3 | AT15: =AS15+AJ15+5 -> 8
A16: 6 | E16: =IF(Q16="Intermission",E15+1,E15) -> 1 | J16: =IF(F16<>"",F16,IF($A16=$A15,J15,J16)) -> 17 | K16: =IF($A16=$A15,K15,G16) -> 52 | L16: =IF(H16<>"",H16,IF($A16=$A15,L15,"")) | M16: =IF(I16<>"",I16,IF($A16=$A15,M15,"")) | N16: =IF(A16=A15,N15,"") -> Home | O16: 16 | P16: e | Y16: =IF($N16="","",IF(X16="","",IF($N16="Home",$X16,IF($X16="n","n",IF($X16="d","o",IF($X16="o","d","")))))) | Z16: =IF($N16="","",IF(X16="","",IF($N16="Away",$X16,IF($X16="n","n",IF($X16="d","o",IF($X16="o","d","")))))) | AC16: =IF(Q16<>"",Q16,IF($A16=$A15,AC15,"")) -> Pass | AD16: =IF(R16<>"",R16,IF($A16=$A15,AD15,"")) -> Pass_Completed | AE16: =IF(S16<>"",S16,IF($A16=$A15,AE15,"")) -> Pass-Forehand | AF16: =IF(AND(P16="e",OR(AC16="Save",AD16="Turnover_Takeaway",AD16="Play_Defensive")),"Defensive",IF(AND(P16="o",OR(AC16="Save",AD16="Turnover_Takeaway",AD16="Play_Defensive")),"Offensive",IF(OR(AC16="Deadice",AC16="Stoppage",AC16="Intermission"),"",IF(P16="e","Offensive",IF(P16="o","Defensive",""))))) -> Offensive | AG16: =AG15 -> 18981 | AH16: =AH15 -> Nelson | AI16: =AI15 -> Velodrome | AJ16: =IF(AND(L16="",M16=""),0,((J16*60)+K16)-((L16*60)+M16)) -> 0 | AP16: =SUMIFS(AJ16:AJ16,Q16:Q16,"=Intermission") -> 0 | AQ16: =IF(E16=1,0,IF(E16=2,1080+AP16,IF(E16=3,(1080*2)+AP16,0))) -> 0 | AR16: =IF(Q16="Intermission",AR15,((1080)-((J16*60)+K16))+AQ16) -> 8 | AS16: =IF(AR16<5,0,AR16-5) -> 3 | AT16: =AS16+AJ16+5 -> 8
A17: 7 | E17: =IF(Q17="Intermission",E16+1,E16) -> 1 | F17: 17 | G17: 51 | H17: 17 | I17: 48 | J17: =IF(F17<>"",F17,IF($A17=$A16,J16,J17)) -> 17 | K17: =IF($A17=$A16,K16,G17) -> 51 | L17: =IF(H17<>"",H17,IF($A17=$A16,L16,"")) -> 17 | M17: =IF(I17<>"",I17,IF($A17=$A16,M16,"")) -> 48 | N17: Home | O17: 16 | P17: e | Q17: Possession | Y17: =IF($N17="","",IF(X17="","",IF($N17="Home",$X17,IF($X17="n","n",IF($X17="d","o",IF($X17="o","d","")))))) | Z17: =IF($N17="","",IF(X17="","",IF($N17="Away",$X17,IF($X17="n","n",IF($X17="d","o",IF($X17="o","d","")))))) | AC17: =IF(Q17<>"",Q17,IF($A17=$A16,AC16,"")) -> Possession | AD17: =IF(R17<>"",R17,IF($A17=$A16,AD16,"")) | AE17: =IF(S17<>"",S17,IF($A17=$A16,AE16,"")) | AF17: =IF(AND(P17="e",OR(AC17="Save",AD17="Turnover_Takeaway",AD17="Play_Defensive")),"Defensive",IF(AND(P17="o",OR(AC17="Save",AD17="Turnover_Takeaway",AD17="Play_Defensive")),"Offensive",IF(OR(AC17="Deadice",AC17="Stoppage",AC17="Intermission"),"",IF(P17="e","Offensive",IF(P17="o","Defensive",""))))) -> Offensive | AG17: =AG16 -> 18981 | AH17: =AH16 -> Nelson | AI17: =AI16 -> Velodrome | AJ17: =IF(AND(L17="",M17=""),0,((J17*60)+K17)-((L17*60)+M17)) -> 3 | AP17: =SUMIFS(AJ17:AJ17,Q17:Q17,"=Intermission") -> 0 | AQ17: =IF(E17=1,0,IF(E17=2,1080+AP17,IF(E17=3,(1080*2)+AP17,0))) -> 0 | AR17: =IF(Q17="Intermission",AR16,((1080)-((J17*60)+K17))+AQ17) -> 9 | AS17: =IF(AR17<5,0,AR17-5) -> 4 | AT17: =AS17+AJ17+5 -> 12
A18: 7 | E18: =IF(Q18="Intermission",E17+1,E17) -> 1 | J18: =IF(F18<>"",F18,IF($A18=$A17,J17,J18)) -> 17 | K18: =IF($A18=$A17,K17,G18) -> 51 | L18: =IF(H18<>"",H18,IF($A18=$A17,L17,"")) -> 17 | M18: =IF(I18<>"",I18,IF($A18=$A17,M17,"")) -> 48 | N18: =IF(A18=A17,N17,"") -> Home | O18: 70 | P18: o | Y18: =IF($N18="","",IF(X18="","",IF($N18="Home",$X18,IF($X18="n","n",IF($X18="d","o",IF($X18="o","d","")))))) | Z18: =IF($N18="","",IF(X18="","",IF($N18="Away",$X18,IF($X18="n","n",IF($X18="d","o",IF($X18="o","d","")))))) | AC18: =IF(Q18<>"",Q18,IF($A18=$A17,AC17,"")) -> Possession | AD18: =IF(R18<>"",R18,IF($A18=$A17,AD17,"")) | AE18: =IF(S18<>"",S18,IF($A18=$A17,AE17,"")) | AF18: =IF(AND(P18="e",OR(AC18="Save",AD18="Turnover_Takeaway",AD18="Play_Defensive")),"Defensive",IF(AND(P18="o",OR(AC18="Save",AD18="Turnover_Takeaway",AD18="Play_Defensive")),"Offensive",IF(OR(AC18="Deadice",AC18="Stoppage",AC18="Intermission"),"",IF(P18="e","Offensive",IF(P18="o","Defensive",""))))) -> Defensive | AG18: =AG17 -> 18981 | AH18: =AH17 -> Nelson | AI18: =AI17 -> Velodrome | AJ18: =IF(AND(L18="",M18=""),0,((J18*60)+K18)-((L18*60)+M18)) -> 3 | AP18: =SUMIFS(AJ18:AJ18,Q18:Q18,"=Intermission") -> 0 | AQ18: =IF(E18=1,0,IF(E18=2,1080+AP18,IF(E18=3,(1080*2)+AP18,0))) -> 0 | AR18: =IF(Q18="Intermission",AR17,((1080)-((J18*60)+K18))+AQ18) -> 9 | AS18: =IF(AR18<5,0,AR18-5) -> 4 | AT18: =AS18+AJ18+5 -> 12
A19: 8 | E19: =IF(Q19="Intermission",E18+1,E18) -> 1 | F19: 17 | G19: 48 | J19: =IF(F19<>"",F19,IF($A19=$A18,J18,J19)) -> 17 | K19: =IF($A19=$A18,K18,G19) -> 48 | L19: =IF(H19<>"",H19,IF($A19=$A18,L18,"")) | M19: =IF(I19<>"",I19,IF($A19=$A18,M18,"")) | N19: Home | O19: 16 | P19: e | Q19: Turnover | R19: Turnover_Giveaway | S19: Giveaway-Misplayed | Y19: =IF($N19="","",IF(X19="","",IF($N19="Home",$X19,IF($X19="n","n",IF($X19="d","o",IF($X19="o","d","")))))) | Z19: =IF($N19="","",IF(X19="","",IF($N19="Away",$X19,IF($X19="n","n",IF($X19="d","o",IF($X19="o","d","")))))) | AC19: =IF(Q19<>"",Q19,IF($A19=$A18,AC18,"")) -> Turnover | AD19: =IF(R19<>"",R19,IF($A19=$A18,AD18,"")) -> Turnover_Giveaway | AE19: =IF(S19<>"",S19,IF($A19=$A18,AE18,"")) -> Giveaway-Misplayed | AF19: =IF(AND(P19="e",OR(AC19="Save",AD19="Turnover_Takeaway",AD19="Play_Defensive")),"Defensive",IF(AND(P19="o",OR(AC19="Save",AD19="Turnover_Takeaway",AD19="Play_Defensive")),"Offensive",IF(OR(AC19="Deadice",AC19="Stoppage",AC19="Intermission"),"",IF(P19="e","Offensive",IF(P19="o","Defensive",""))))) -> Offensive | AG19: =AG18 -> 18981 | AH19: =AH18 -> Nelson | AI19: =AI18 -> Velodrome | AJ19: =IF(AND(L19="",M19=""),0,((J19*60)+K19)-((L19*60)+M19)) -> 0 | AP19: =SUMIFS(AJ19:AJ19,Q19:Q19,"=Intermission") -> 0 | AQ19: =IF(E19=1,0,IF(E19=2,1080+AP19,IF(E19=3,(1080*2)+AP19,0))) -> 0 | AR19: =IF(Q19="Intermission",AR18,((1080)-((J19*60)+K19))+AQ19) -> 12 | AS19: =IF(AR19<5,0,AR19-5) -> 7 | AT19: =AS19+AJ19+5 -> 12
A20: 8 | E20: =IF(Q20="Intermission",E19+1,E19) -> 1 | J20: =IF(F20<>"",F20,IF($A20=$A19,J19,J20)) -> 17 | K20: =IF($A20=$A19,K19,G20) -> 48 | L20: =IF(H20<>"",H20,IF($A20=$A19,L19,"")) | M20: =IF(I20<>"",I20,IF($A20=$A19,M19,"")) | N20: =IF(A20=A19,N19,"") -> Home | O20: 70 | P20: o | Y20: =IF($N20="","",IF(X20="","",IF($N20="Home",$X20,IF($X20="n","n",IF($X20="d","o",IF($X20="o","d","")))))) | Z20: =IF($N20="","",IF(X20="","",IF($N20="Away",$X20,IF($X20="n","n",IF($X20="d","o",IF($X20="o","d","")))))) | AC20: =IF(Q20<>"",Q20,IF($A20=$A19,AC19,"")) -> Turnover | AD20: =IF(R20<>"",R20,IF($A20=$A19,AD19,"")) -> Turnover_Giveaway | AE20: =IF(S20<>"",S20,IF($A20=$A19,AE19,"")) -> Giveaway-Misplayed | AF20: =IF(AND(P20="e",OR(AC20="Save",AD20="Turnover_Takeaway",AD20="Play_Defensive")),"Defensive",IF(AND(P20="o",OR(AC20="Save",AD20="Turnover_Takeaway",AD20="Play_Defensive")),"Offensive",IF(OR(AC20="Deadice",AC20="Stoppage",AC20="Intermission"),"",IF(P20="e","Offensive",IF(P20="o","Defensive",""))))) -> Defensive | AG20: =AG19 -> 18981 | AH20: =AH19 -> Nelson | AI20: =AI19 -> Velodrome | AJ20: =IF(AND(L20="",M20=""),0,((J20*60)+K20)-((L20*60)+M20)) -> 0 | AP20: =SUMIFS(AJ20:AJ20,Q20:Q20,"=Intermission") -> 0 | AQ20: =IF(E20=1,0,IF(E20=2,1080+AP20,IF(E20=3,(1080*2)+AP20,0))) -> 0 | AR20: =IF(Q20="Intermission",AR19,((1080)-((J20*60)+K20))+AQ20) -> 12 | AS20: =IF(AR20<5,0,AR20-5) -> 7 | AT20: =AS20+AJ20+5 -> 12
A21: 9 | E21: =IF(Q21="Intermission",E20+1,E20) -> 1 | F21: 17 | G21: 48 | J21: =IF(F21<>"",F21,IF($A21=$A20,J20,J21)) -> 17 | K21: =IF($A21=$A20,K20,G21) -> 48 | L21: =IF(H21<>"",H21,IF($A21=$A20,L20,"")) | M21: =IF(I21<>"",I21,IF($A21=$A20,M20,"")) | N21: Away | O21: 22 | P21: e | Q21: Zone_Entry_Exit | R21: Zone_Keepin | S21: Zone-KeepIn | Y21: =IF($N21="","",IF(X21="","",IF($N21="Home",$X21,IF($X21="n","n",IF($X21="d","o",IF($X21="o","d","")))))) | Z21: =IF($N21="","",IF(X21="","",IF($N21="Away",$X21,IF($X21="n","n",IF($X21="d","o",IF($X21="o","d","")))))) | AC21: =IF(Q21<>"",Q21,IF($A21=$A20,AC20,"")) -> Zone_Entry_Exit | AD21: =IF(R21<>"",R21,IF($A21=$A20,AD20,"")) -> Zone_Keepin | AE21: =IF(S21<>"",S21,IF($A21=$A20,AE20,"")) -> Zone-KeepIn | AF21: =IF(AND(P21="e",OR(AC21="Save",AD21="Turnover_Takeaway",AD21="Play_Defensive")),"Defensive",IF(AND(P21="o",OR(AC21="Save",AD21="Turnover_Takeaway",AD21="Play_Defensive")),"Offensive",IF(OR(AC21="Deadice",AC21="Stoppage",AC21="Intermission"),"",IF(P21="e","Offensive",IF(P21="o","Defensive",""))))) -> Offensive | AG21: =AG20 -> 18981 | AH21: =AH20 -> Nelson | AI21: =AI20 -> Velodrome | AJ21: =IF(AND(L21="",M21=""),0,((J21*60)+K21)-((L21*60)+M21)) -> 0 | AP21: =SUMIFS(AJ21:AJ21,Q21:Q21,"=Intermission") -> 0 | AQ21: =IF(E21=1,0,IF(E21=2,1080+AP21,IF(E21=3,(1080*2)+AP21,0))) -> 0 | AR21: =IF(Q21="Intermission",AR20,((1080)-((J21*60)+K21))+AQ21) -> 12 | AS21: =IF(AR21<5,0,AR21-5) -> 7 | AT21: =AS21+AJ21+5 -> 12
A22: 10 | E22: =IF(Q22="Intermission",E21+1,E21) -> 1 | F22: 17 | G22: 48 | J22: =IF(F22<>"",F22,IF($A22=$A21,J21,J22)) -> 17 | K22: =IF($A22=$A21,K21,G22) -> 48 | L22: =IF(H22<>"",H22,IF($A22=$A21,L21,"")) | M22: =IF(I22<>"",I22,IF($A22=$A21,M21,"")) | N22: Away | O22: 22 | P22: e | Q22: Turnover | R22: Turnover_Giveaway | S22: Giveaway-AttemptedZoneClear/Dump | Y22: =IF($N22="","",IF(X22="","",IF($N22="Home",$X22,IF($X22="n","n",IF($X22="d","o",IF($X22="o","d","")))))) | Z22: =IF($N22="","",IF(X22="","",IF($N22="Away",$X22,IF($X22="n","n",IF($X22="d","o",IF($X22="o","d","")))))) | AC22: =IF(Q22<>"",Q22,IF($A22=$A21,AC21,"")) -> Turnover | AD22: =IF(R22<>"",R22,IF($A22=$A21,AD21,"")) -> Turnover_Giveaway | AE22: =IF(S22<>"",S22,IF($A22=$A21,AE21,"")) -> Giveaway-AttemptedZoneClear/Dump | AF22: =IF(AND(P22="e",OR(AC22="Save",AD22="Turnover_Takeaway",AD22="Play_Defensive")),"Defensive",IF(AND(P22="o",OR(AC22="Save",AD22="Turnover_Takeaway",AD22="Play_Defensive")),"Offensive",IF(OR(AC22="Deadice",AC22="Stoppage",AC22="Intermission"),"",IF(P22="e","Offensive",IF(P22="o","Defensive",""))))) -> Offensive | AG22: =AG21 -> 18981 | AH22: =AH21 -> Nelson | AI22: =AI21 -> Velodrome | AJ22: =IF(AND(L22="",M22=""),0,((J22*60)+K22)-((L22*60)+M22)) -> 0 | AP22: =SUMIFS(AJ22:AJ22,Q22:Q22,"=Intermission") -> 0 | AQ22: =IF(E22=1,0,IF(E22=2,1080+AP22,IF(E22=3,(1080*2)+AP22,0))) -> 0 | AR22: =IF(Q22="Intermission",AR21,((1080)-((J22*60)+K22))+AQ22) -> 12 | AS22: =IF(AR22<5,0,AR22-5) -> 7 | AT22: =AS22+AJ22+5 -> 12
A23: 10 | E23: =IF(Q23="Intermission",E22+1,E22) -> 1 | J23: =IF(F23<>"",F23,IF($A23=$A22,J22,J23)) -> 17 | K23: =IF($A23=$A22,K22,G23) -> 48 | L23: =IF(H23<>"",H23,IF($A23=$A22,L22,"")) | M23: =IF(I23<>"",I23,IF($A23=$A22,M22,"")) | N23: =IF(A23=A22,N22,"") -> Away | O23: 16 | P23: o | Y23: =IF($N23="","",IF(X23="","",IF($N23="Home",$X23,IF($X23="n","n",IF($X23="d","o",IF($X23="o","d","")))))) | Z23: =IF($N23="","",IF(X23="","",IF($N23="Away",$X23,IF($X23="n","n",IF($X23="d","o",IF($X23="o","d","")))))) | AC23: =IF(Q23<>"",Q23,IF($A23=$A22,AC22,"")) -> Turnover | AD23: =IF(R23<>"",R23,IF($A23=$A22,AD22,"")) -> Turnover_Giveaway | AE23: =IF(S23<>"",S23,IF($A23=$A22,AE22,"")) -> Giveaway-AttemptedZoneClear/Dump | AF23: =IF(AND(P23="e",OR(AC23="Save",AD23="Turnover_Takeaway",AD23="Play_Defensive")),"Defensive",IF(AND(P23="o",OR(AC23="Save",AD23="Turnover_Takeaway",AD23="Play_Defensive")),"Offensive",IF(OR(AC23="Deadice",AC23="Stoppage",AC23="Intermission"),"",IF(P23="e","Offensive",IF(P23="o","Defensive",""))))) -> Defensive | AG23: =AG22 -> 18981 | AH23: =AH22 -> Nelson | AI23: =AI22 -> Velodrome | AJ23: =IF(AND(L23="",M23=""),0,((J23*60)+K23)-((L23*60)+M23)) -> 0 | AP23: =SUMIFS(AJ23:AJ23,Q23:Q23,"=Intermission") -> 0 | AQ23: =IF(E23=1,0,IF(E23=2,1080+AP23,IF(E23=3,(1080*2)+AP23,0))) -> 0 | AR23: =IF(Q23="Intermission",AR22,((1080)-((J23*60)+K23))+AQ23) -> 12 | AS23: =IF(AR23<5,0,AR23-5) -> 7 | AT23: =AS23+AJ23+5 -> 12
A24: 11 | E24: =IF(Q24="Intermission",E23+1,E23) -> 1 | F24: 17 | G24: 47 | H24: 17 | I24: 46 | J24: =IF(F24<>"",F24,IF($A24=$A23,J23,J24)) -> 17 | K24: =IF($A24=$A23,K23,G24) -> 47 | L24: =IF(H24<>"",H24,IF($A24=$A23,L23,"")) -> 17 | M24: =IF(I24<>"",I24,IF($A24=$A23,M23,"")) -> 46 | N24: Home | O24: 16 | P24: e | Q24: Zone_Entry_Exit | R24: Zone_Exit | S24: ZoneExit-Rush | Y24: =IF($N24="","",IF(X24="","",IF($N24="Home",$X24,IF($X24="n","n",IF($X24="d","o",IF($X24="o","d","")))))) | Z24: =IF($N24="","",IF(X24="","",IF($N24="Away",$X24,IF($X24="n","n",IF($X24="d","o",IF($X24="o","d","")))))) | AC24: =IF(Q24<>"",Q24,IF($A24=$A23,AC23,"")) -> Zone_Entry_Exit | AD24: =IF(R24<>"",R24,IF($A24=$A23,AD23,"")) -> Zone_Exit | AE24: =IF(S24<>"",S24,IF($A24=$A23,AE23,"")) -> ZoneExit-Rush | AF24: =IF(AND(P24="e",OR(AC24="Save",AD24="Turnover_Takeaway",AD24="Play_Defensive")),"Defensive",IF(AND(P24="o",OR(AC24="Save",AD24="Turnover_Takeaway",AD24="Play_Defensive")),"Offensive",IF(OR(AC24="Deadice",AC24="Stoppage",AC24="Intermission"),"",IF(P24="e","Offensive",IF(P24="o","Defensive",""))))) -> Offensive | AG24: =AG23 -> 18981 | AH24: =AH23 -> Nelson | AI24: =AI23 -> Velodrome | AJ24: =IF(AND(L24="",M24=""),0,((J24*60)+K24)-((L24*60)+M24)) -> 1 | AP24: =SUMIFS(AJ24:AJ24,Q24:Q24,"=Intermission") -> 0 | AQ24: =IF(E24=1,0,IF(E24=2,1080+AP24,IF(E24=3,(1080*2)+AP24,0))) -> 0 | AR24: =IF(Q24="Intermission",AR23,((1080)-((J24*60)+K24))+AQ24) -> 13 | AS24: =IF(AR24<5,0,AR24-5) -> 8 | AT24: =AS24+AJ24+5 -> 14
A25: 11 | E25: =IF(Q25="Intermission",E24+1,E24) -> 1 | J25: =IF(F25<>"",F25,IF($A25=$A24,J24,J25)) -> 17 | K25: =IF($A25=$A24,K24,G25) -> 47 | L25: =IF(H25<>"",H25,IF($A25=$A24,L24,"")) -> 17 | M25: =IF(I25<>"",I25,IF($A25=$A24,M24,"")) -> 46 | N25: Home | O25: 70 | P25: o | Y25: =IF($N25="","",IF(X25="","",IF($N25="Home",$X25,IF($X25="n","n",IF($X25="d","o",IF($X25="o","d","")))))) | Z25: =IF($N25="","",IF(X25="","",IF($N25="Away",$X25,IF($X25="n","n",IF($X25="d","o",IF($X25="o","d","")))))) | AC25: =IF(Q25<>"",Q25,IF($A25=$A24,AC24,"")) -> Zone_Entry_Exit | AD25: =IF(R25<>"",R25,IF($A25=$A24,AD24,"")) -> Zone_Exit | AE25: =IF(S25<>"",S25,IF($A25=$A24,AE24,"")) -> ZoneExit-Rush | AF25: =IF(AND(P25="e",OR(AC25="Save",AD25="Turnover_Takeaway",AD25="Play_Defensive")),"Defensive",IF(AND(P25="o",OR(AC25="Save",AD25="Turnover_Takeaway",AD25="Play_Defensive")),"Offensive",IF(OR(AC25="Deadice",AC25="Stoppage",AC25="Intermission"),"",IF(P25="e","Offensive",IF(P25="o","Defensive",""))))) -> Defensive | AG25: =AG24 -> 18981 | AH25: =AH24 -> Nelson | AI25: =AI24 -> Velodrome | AJ25: =IF(AND(L25="",M25=""),0,((J25*60)+K25)-((L25*60)+M25)) -> 1 | AP25: =SUMIFS(AJ25:AJ25,Q25:Q25,"=Intermission") -> 0 | AQ25: =IF(E25=1,0,IF(E25=2,1080+AP25,IF(E25=3,(1080*2)+AP25,0))) -> 0 | AR25: =IF(Q25="Intermission",AR24,((1080)-((J25*60)+K25))+AQ25) -> 13 | AS25: =IF(AR25<5,0,AR25-5) -> 8 | AT25: =AS25+AJ25+5 -> 14
