Workbook
Name DEfensive: Lists!$BL:$BL
Name EventType: Lists!$A$2:$A$16
Name Faceoff: Lists!$G$2:$G$1048576
Name Goal: Lists!$J$2:$J$1048576
Name Goal_PenaltyShot: Lists!$BA$2:$BA$1048576
Name Goal_Scored: Lists!$AY$2:$AY$1048576
Name Goal_Shootout: Lists!$AZ$2:$AZ$1048576
Name LoosePuck: Lists!$P$2:$P$1048576
Name Offensive: Lists!$BK:$BK
Name Pass: Lists!$I$2:$I$1048576
Name Pass_Completed: Lists!$R$2:$R$1048576
Name Pass_Deflected: Lists!$T$2:$T$1048576
Name Pass_Intercepted: Lists!$U$2:$U$1048576
Name Pass_Missed: Lists!$S$2:$S$1048576
Name Penalty: Lists!$M$2:$M$1048576
Name Penalty_Major: Lists!$AA$2:$AA$1048576
Name Penalty_Minor: Lists!$AB$2:$AB$1048576
Name Penalty_Offsetting: Lists!$AC$2:$AC$1048576
Name PenaltyShot_Missed: Lists!$AK$2:$AK$1048576
Name PenaltyShot_OnNet: Lists!$AJ$2:$AJ$1048576
Name PenaltyShot_Saved: Lists!$AL$2:$AL$1048576
Name PenaltyShot_Shootout: Lists!$N$2:$N$1048576
Name Play: Lists!$F:$F
Name Play_Defensive: Lists!$BE:$BE
Name Play_Offensive: Lists!$BD:$BD
Name Possession: Lists!$BF:$BF
Name Rebound: Lists!$BC$2:$BC$1048576
Name Save: Lists!$Q$2:$Q$1048576
Name Save_Freeze: Lists!$AN$2:$AN$1048576
Name Save_Played: Lists!$BB:$BB
Name Save_Rebound: Lists!$AM$2:$AM$1048576
Name Shootout_Missed: Lists!$AH$2:$AH$1048576
Name Shootout_OnNet: Lists!$AG$2:$AG$1048576
Name Shootout_Saved: Lists!$AI$2:$AI$1048576
Name Shot: Lists!$H$2:$H$1048576
Name Shot_Blocked: Lists!$AQ$2:$AQ$1048576
Name Shot_BlockedSameTeam: Lists!$AR$2:$AR$1048576
Name Shot_Deflected: Lists!$AS$2:$AS$1048576
Name Shot_DeflectedGoal: Lists!$AX$2:$AX$1048576
Name Shot_DeflectedOnNetSaved: Lists!$AT$2:$AT$1048576
Name Shot_Missed: Lists!$AP$2:$AP$1048576
Name Shot_MissedPost: Lists!$BH:$BH
Name Shot_OnNetGoal: Lists!$AV$2:$AV$1048576
Name Shot_OnNetSaved: Lists!$AO$2:$AO$1048576
Name Shot_TippedGoal: Lists!$AW$2:$AW$1048576
Name Shot_TippedOnNetSaved: Lists!$AU$2:$AU$1048576
Name Stoppage: Lists!$O$2:$O$1048576
Name Stoppage_Other: Lists!$AF$2:$AF$1048576
Name Stoppage_Period: Lists!$AE$2:$AE$1048576
Name Stoppage_Play: Lists!$AD$2:$AD$1048576
Name Turnover: Lists!$K$2:$K$1048576
Name Turnover_Giveaway: Lists!$V$2:$V$1048576
Name Turnover_Takeaway: Lists!$W$2:$W$1048576
Name Zone_Entry: Lists!$X$2:$X$1048576
Name Zone_Entry_Exit: Lists!$L$2:$L$1048576
Name Zone_EntryFailed: Lists!$BM:$BM
Name Zone_Exit: Lists!$Y$2:$Y$1048576
Name Zone_ExitFailed: Lists!$BN:$BN
Name Zone_Keepin: Lists!$Z$2:$Z$1048576

Sheet examples
A1: shift_index | B1: Period | C1: shift_start_min | D1: shift_start_sec | E1: shift_end_min | F1: shift_end_sec | G1: shift_start_type | H1: shift_stop_type | I1: home_forward_1 | J1: home_forward_2 | K1: home_forward_3 | L1: home_defense_1 | M1: home_defense_2 | N1: home_xtra | O1: home_goalie | P1: away_forward_1 | Q1: away_forward_2 | R1: away_forward_3 | S1: away_defense_1 | T1: away_defense_2 | U1: away_xtra | V1: away_goalie | W1: stoppage_time | X1: home_ozone_start | Y1: home_ozone_end | Z1: home_dzone_start | AA1: home_dzone_end | AB1: home_nzone_start | AC1: home_nzone_end | AD1: game_id | AE1: home_team | AF1: away_team | AG1: shift_start_total_seconds | AH1: shift_end_total_seconds | AI1: shift_duration | AJ1: home_team_strength | AK1: away_team_strength | AL1: home_team_en | AM1: away_team_en | AN1: home_team_pk | AO1: home_team_pp | AP1: away_team_pp | AQ1: away_team_pk | AR1: situation | AS1: strength | AT1: home_goals | AU1: away_goals | AV1: period_start_total_running_seconds | AW1: running_video_time | AX1: shift_start_running_time | AY1: shift_end_running_time
A2: 40 | B2: 1 | C2: 2 | D2: 07 | E2: 0 | F2: 35 | G2: OtherFaceoff | H2: Away Goalie Stopped (after Home SOG) | I2: 42 | J2: 14 | K2: 61 | L2: 22 | M2: 9 | O2: 39 | P2: 91 | Q2: 80 | R2: 89 | S2: 4 | T2: 25 | V2: 30 | Y2: 1
A3: 41 | B3: 1 | C3: 0 | D3: 35 | E3: 0 | F3: 0.01 | G3: OtherFaceoff | H3: Period End | I3: 42 | J3: 14 | K3: 61 | L3: 22 | M3: 9 | O3: 39 | P3: 77 | Q3: 13 | R3: 68 | S3: 4 | T3: 25 | V3: 30 | Y3: 1
A4: 42 | B4: 1 | G4: Intermission
A5: 43 | B5: 2 | C5: 18 | D5: 0 | E5: 17 | F5: 18 | G5: PeriodStart | H5: Away Goalie Stopped (after Home SOG) | I5: 70 | J5: 14 | K5: 55 | L5: 91 | M5: 84 | O5: 39 | P5: 77 | Q5: 13 | R5: 68 | S5: 44 | T5: 18 | V5: 30 | Y5: 1
A8: 105 | B8: 3 | C8: 1 | D8: 01 | E8: 0 | F8: 49 | I8: 42 | J8: 24 | K8: 61 | L8: 91 | M8: 84 | O8: 39 | P8: 77 | Q8: 12 | R8: 68 | S8: 44 | T8: 18 | V8: 30 | AA8: 1
A9: 106 | B9: 3 | C9: 0 | D9: 49 | E9: 0 | F9: 0.01 | H9: GameEnd | I9: 42 | J9: 24 | K9: 61 | L9: 91 | M9: 84 | O9: 39 | P9: 77 | Q9: 12 | R9: 56 | S9: 44 | T9: 18 | U9: 3 | AA9: 1
A10: 107 | B10: 3 | C10: 0 | D10: 0.01
A25: event_index | B25: linked_event_index_ | C25: linked_event_index | D25: tracking_event_index | E25: sequence_index | F25: play_index | G25: zone_change_index | H25: Period | I25: event_start_min_ | J25: event_start_sec_ | K25: event_end_min_ | L25: event_end_sec_ | M25: event_start_min | N25: event_start_sec | O25: event_end_min | P25: event_end_sec | Q25: Team_ | R25: Player | S25: role_abrev_binary | T25: role_abrev | U25: Type_ | V25: event_detail_ | W25: event_detail_2_ | X25: successful | Y25: play_detail1 | Z25: play_detail2 | AA25: play_detail_successful | AB25: context | AC25: play_tag1 | AD25: play_tag2 | AE25: high_danger | AF25: event_team_zone | AG25: home_team_zone | AH25: away_team_zone | AI25: forced_forcer | AJ25: pressured_pressurer
A27: 599 | H27: 1 | I27: 0 | J27: 01 | Q27: a | R27: 13 | S27: 1 | T27: e | U27: Shot | V27: Shot_Missed | W27: Shot-Backhand | X27: u | AF27: o | AJ27: 1 | AM27: Shot | AN27: Shot_Missed | AP27: Offensive
A28: 599 | H28: 1 | R28: 9 | T28: o | Y28: Defensive_PlayPossession-StickCheck | AA28: s | AJ28: 1 | AM28: Shot | AN28: Shot_Missed | AP28: Defensive
A29: 600 | H29: 1 | I29: 0 | J29: 00 | T29: o | U29: Stoppage | V29: Stoppage_Period | W29: Stoppage-PeriodEnd | AM29: Stoppage | AN29: Stoppage_Period
A30: 601 | H30: 2 | I30: 56 | J30: 46 | K30: 55 | L30: 39 | T30: o | U30: Intermission | AM30: Intermission
A31: 602 | H31: 2 | I31: 18 | J31: 00 | Q31: h | R31: 70 | S31: 1 | T31: e | U31: Faceoff | V31: Faceoff_PeriodStart | AF31: n | AM31: Faceoff | AN31: Faceoff_PeriodStart | AP31: Offensive
A34: 1438 | B34: 223 | H34: 3 | I34: 5 | J34: 55 | Q34: h | R34: 61 | S34: 1 | T34: e | U34: Shot | V34: Shot_Goal | AF34: o | AM34: Shot | AN34: Shot_Goal | AP34: Offensive
A35: 1438 | B35: 223 | H35: 3 | R35: 30 | T35: o | AM35: Shot | AN35: Shot_Goal | AP35: Defensive
A36: 1439 | B36: 223 | H36: 3 | I36: 5 | J36: 55 | Q36: h | R36: 61 | S36: 1 | T36: e | U36: Goal | V36: Goal_Scored | W36: Goal-Wrist | AF36: o | AM36: Goal | AN36: Goal_Scored | AP36: Offensive
A37: 1439 | B37: 223 | H37: 3 | R37: 30 | T37: o | AM37: Goal | AN37: Goal_Scored | AP37: Defensive
A38: 1440 | B38: 223 | H38: 3 | I38: 5 | J38: 55 | Q38: h | R38: 61 | S38: 1 | T38: e | U38: Stoppage | V38: Stoppage_Play | W38: Stoppage-Goal | AF38: o | AJ38: 1 | AM38: Stoppage | AN38: Stoppage_Play
A39: 1441 | B39: 223 | H39: 3 | I39: 5 | J39: 55 | K39: 5 | L39: 31 | Q39: h | R39: 61 | S39: 1 | T39: e | U39: DeadIce | AF39: o | AJ39: 1 | AM39: DeadIce
A43: 1590 | H43: 3 | I43: 0 | J43: 26 | Q43: h | R43: 84 | S43: 1 | T43: e | U43: Penalty_Delayed | AF43: d | AJ43: 1 | AM43: Penalty_Delayed | AP43: Offensive
A44: 1590 | H44: 3 | R44: 3 | T44: o | AJ44: 1 | AM44: Penalty_Delayed | AP44: Defensive
A45: 1591 | B45: 247 | H45: 3 | I45: 0 | J45: 25 | Q45: a | R45: 18 | S45: 1 | T45: e | U45: Shot | V45: Shot_OnNetSaved | W45: Shot-Wrist | X45: s | AF45: o | AM45: Shot | AN45: Shot_OnNetSaved | AP45: Offensive
A46: 1591 | B46: 247 | H46: 3 | R46: 77 | S46: 1 | T46: e | Y46: OffensivePlay_Shot-Screen | AM46: Shot | AN46: Shot_OnNetSaved | AP46: Offensive
A47: 1591 | B47: 247 | H47: 3 | R47: 39 | T47: o | AM47: Shot | AN47: Shot_OnNetSaved | AP47: Defensive
A48: 1592 | B48: 247 | H48: 3 | I48: 0 | J48: 25 | Q48: h | R48: 39 | S48: 1 | T48: e | U48: Save | V48: Save_Rebound | W48: Save-Blocker | AF48: d | AM48: Save | AN48: Save_Rebound | AP48: Defensive
A49: 1592 | B49: 247 | H49: 3 | R49: 18 | T49: o | AM49: Save | AN49: Save_Rebound | AP49: Offensive
A50: 1592 | B50: 247 | H50: 3 | R50: 77 | T50: o | Y50: OffensivePlay_Shot-Screen | AM50: Save | AN50: Save_Rebound | AP50: Offensive
A51: 1593 | B51: 247 | H51: 3 | I51: 0 | J51: 25 | Q51: h | R51: 39 | S51: 1 | T51: e | AF51: d | AP51: Offensive
A52: 1594 | H52: 3 | I52: 0 | J52: 21 | Q52: a | R52: 56 | S52: 1 | T52: e | U52: Possession | V52: PuckRecovery | X52: u | Y52: OffensivePlay_Zone-PuckRecoveryShot | AA52: u | AF52: o | AM52: Possession | AN52: PuckRecovery | AP52: Offensive
A53: 1595 | H53: 3 | I53: 0 | J53: 21 | Q53: a | R53: 56 | S53: 1 | T53: e | U53: Pass | V53: Pass_Missed | W53: Pass-Forehand | X53: u | Y53: OffensivePlay_Pass-SecondTouch | AA53: u | AF53: o | AJ53: 1 | AM53: Pass | AN53: Pass_Missed | AP53: Offensive
A54: 1595 | H54: 3 | R54: 3 | S54: 1 | T54: e | AM54: Pass | AN54: Pass_Missed | AP54: Offensive
A55: 1595 | H55: 3 | R55: 91 | T55: o | AJ55: 1 | AM55: Pass | AN55: Pass_Missed | AP55: Defensive
A56: 1596 | H56: 3 | I56: 0 | J56: 21 | Q56: h | S56: 1 | T56: e | U56: Zone_Entry_Exit | V56: Zone_Exit | W56: ZoneExit-OppTeam | AF56: d | AM56: Zone_Entry_Exit | AN56: Zone_Exit | AP56: Offensive
A57: 1597 | H57: 3 | I57: 0 | J57: 17 | K57: 0 | L57: 15 | Q57: a | R57: 44 | S57: 1 | T57: e | U57: Possession | V57: PuckRecovery | X57: s | Y57: OffensivePlay_Zone-PuckRecoveryTurnover | AA57: s | AF57: n | AM57: Possession | AN57: PuckRecovery | AP57: Offensive
A58: 1598 | H58: 3 | I58: 0 | J58: 15 | Q58: a | R58: 44 | S58: 1 | T58: e | U58: Pass | V58: Pass_Completed | W58: Pass-Forehand | X58: s | AF58: n | AM58: Pass | AN58: Pass_Completed | AP58: Offensive
A59: 1598 | H59: 3 | R59: 18 | S59: 1 | T59: e | AM59: Pass | AN59: Pass_Completed | AP59: Offensive
A60: 1599 | H60: 3 | I60: 0 | J60: 14 | Q60: a | R60: 18 | S60: 1 | T60: e | U60: Zone_Entry_Exit | V60: Zone_Entry | W60: ZoneEntry-Rush | X60: u | AF60: o | AJ60: 1 | AM60: Zone_Entry_Exit | AN60: Zone_Entry | AP60: Offensive
A61: 1599 | H61: 3 | R61: 24 | T61: o | AJ61: 1 | AM61: Zone_Entry_Exit | AN61: Zone_Entry | AP61: Defensive
A62: 1600 | H62: 3 | I62: 0 | J62: 12 | Q62: h | R62: 24 | S62: 1 | T62: e | U62: Turnover | V62: Turnover_Takeaway | W62: Takeaway-BattleWon | X62: s | Y62: Defensive_PlayPossession-SeperateFromPuck | AA62: s | AF62: d | AJ62: 1 | AM62: Turnover | AN62: Turnover_Takeaway | AP62: Defensive
...

Sheet Sheet1
A1: duration | C1: context
A2: time_start_total_seconds | C2: play_tag1
A3: time_end_total_seconds | C3: play_tag2
A4: shift_index | C4: high_danger
A5: player_role
A6: role_number
A7: running_intermission_duration
A8: period_start_total_running_seconds
A9: running_video_time
A10: event_running_start
A11: event_running_end
A12: event_id
A13: linked_event_id
A14: play_id
A15: sequence_id
A16: zone_change_id
... A72: possession_change

Sheet Rules
A1: EventType | B1: Definition | C1: Next Event | D1: Uses | E1: Linked Events | F1: Successful/Unsuccessful | G1: Successful Def | J1: EventTypeDetail | K1: Definition | L1: Next Event | M1: Uses | N1: Linked Events | O1: Successful/Unsuccessful | P1: Successful Def | S1: EventTypeDetail2 | T1: Definition | U1: Next Event | V1: Uses | W1: Linked Events | X1: Successful/Unsuccessful | Y1: Successful Def | AC1: Definition | AD1: Next Event | AE1: Uses | AF1: Linked Events | AG1: Successful/Unsuccessful | AH1: Successful Def | AL1: Definition | AM1: Next Event | AN1: Uses | AO1: Linked Events | AP1: Linked Events | AQ1: Successful/Unsuccessful | AR1: Successful Def | AT1: play_tag1 | AU1: Definition | AV1: Next Event | AW1: Uses | AX1: Linked Events | AZ1: play_tag2 | BA1: Definition | BB1: Next Event | BC1: Uses | BD1: Linked Events | BF1: Context | BG1: Definition | BH1: Next Event | BI1: Uses | BJ1: Linked Events | BM1: shift_start | BN1: Definition | BO1: Next Event | BP1: Linked Events | BR1: shift_end | BS1: Definition | BT1: Next Event | BU1: Linked Events
A2: Faceoff | J2: Faceoff | S2: PenaltyShot/Shootout | AB2: Offensive | AH2: sucessful if next play positive | AK2: Defensive | AR2: sucessful if next play positive | AT2: LowToHigh | AZ2: Rush | BF2: LeadToBreakout | BM2: PeriodStart | BR2: -
A3: Shot | E3: Save | J3: Faceoff-AfterPenalty | S3: PenaltyShot_OnNet | X3: s | AB3: OffensivePlay_Possession-DriveMiddle | AK3: Defensive_PlayPossession-PokeCheck | AT3: HighToLow | AZ3: Cycle | BF3: LeadToZoneEntry | BM3: FaceoffAfterGoal | BR3: Period Start
A4: Pass | J4: Faceoff-AfterGoal | S4: PenaltyShot_Missed | X4: u | AB4: OffensivePlay_Possession-DriveWide | AK4: Defensive_PlayPossession-SeperateFromPuck | AT4: CrossIce | AZ4: Forecheck | BF4: LeadToTurnover | BM4: GameStart | BR4: Period End
A5: Goal | E5: Shot | J5: Faceoff-PeriodStart | S5: PenaltyShot_Saved | X5: s | AB5: OffensivePlay_Possession-DriveCorner | AK5: Defensive_PlayPossession-Backcheck | AT5: Slot | AZ5: Dumpin | BF5: LeadToShot | BM5: FaceoffAfterPenalty | BR5: Puck Out of Play
A6: Turnover | E6: Pass, Shot, Play | J6: Shot-OnNet | S6: ShootoutShot_OnNet | X6: s | AB6: OffensivePlay_Possession-DriveNetMiddle | AK6: Defensive_PlayPossession-FroceWide | AZ6: Regroup | BF6: LeadToGoal | BM6: OtherFaceoff | BR6: Injury
A7: Zone_Entry_Exit | E7: Pass, Turnover, Attempted Failed, Keepins | J7: Shot-Missed | S7: ShootoutShot_Missed | X7: u | AB7: OffensivePlay_Possession-DriveNetWide | AK7: Defensive_PlayPossession-Contain | AZ7: Counter | BF7: LeadToPenalty | BM7: DeadIce/Stoppage | BR7: Home Penalty
A8: Penalty | J8: Shot-Blocked | S8: ShootoutShot_Saved | X8: s | AB8: OffensivePlay_Possession-CrashNet | AK8: Defensive_PlayPossession-BeatMiddle | AZ8: ZoneExit | BF8: LeadToFailedBreakout | BM8: Intermission | BR8: Away Penalty
A9: PenaltyShot_Shootout | J9: Shot-BlockedSameTeam | AB9: OffensivePlay_Possession-Delay | AK9: Defensive_PlayPossession-BeatWide | AZ9: ZoneEntry | BF9: LeadToFailedZoneEntry | BM9: DelayedPenalty | BR9: Home Goalie Stoppage
A10: Stoppage | E10: Save Freeze | J10: Shot-Deflected | S10: Stoppage_Period | AB10: OffensivePlay_Possession-Deke | AK10: Defensive_PlayPossession-BeatDeke | AZ10: Clear | BM10: GameStart | BR10: Away Goalie Stoppage
A11: Hit | J11: Shot-DeflectedOnNet | S11: Stoppage_Play | AB11: OffensivePlay_Possession-Chip | AK11: Defensive_PlayPossession-BeatSpeed | BR11: Home Offside
A12: Possession | J12: Shot-Tipped | S12: Stoppage_Other | AB12: OffensivePlay_Possession-Other | AK12: Defensive_PlayPossession-Pressure | BR12: Home Icing
A13: LoosePuck | J13: Pass-Completed | S13: Stoppage_GameEnd | AB13: OffensivePlay_Possession-Speed | AK13: Defensive_PlayPossession-Zone | BR13: Away Offside
A14: Save | E14: Shot, Stoppage, Deadice | J14: Pass-Missed | AB14: OffensivePlay_Possession-OpenIceDeke | AK14: Defensive_PlayPossession-ManOnMan | BR14: Away Icing
A15: TeamPossessionChange | J15: Pass-Deflected | S15: Save_Rebound | AB15: OffensivePlay_Possession-EndToEndRush | AK15: Defensive_PlayPossession-Tracker | BR15: Clock Problem
A16: Rebound | E16: Shot, Save | J16: Pass-Intercepted | S16: Save_Freeze | AB16: OffensivePlay_Possession-FrontofNet | AK16: Defensive_PlayPossession-Surf | BR16: Puck Frozen
A17: DeadIce | J17: Turnover-Giveaway | S17: Save_Played | AB17: OffensivePlay_Possession-CutBack | AK17: Defensive_PlayPossession-StickCheck | BR17: Puck in Crowd
A18: Play | J18: Turnover-Takeaway | AB18: OffensivePlay_Possession-Wheel | AK18: Defensive_PlayPass-PassIntercepted | BR18: Goalie Stopped (after SOG)
A19: Timeout | J19: Zone-Entry | S19: Pass-Stretch | X19: s/u | AB19: OffensivePlay_Possession-ForecedOutside | AK19: Defensive_PlayPass-InShotPassLane | BR19: Referee or Linesperson
A20: Intermission | J20: Zone-Exit | S20: Pass-Rim/Wrap | X20: s/u | AB20: OffensivePlay_Pass-AssistPrimary | AK20: Defensive_PlayShot-BoxOut | BR20: High Stick
A21: Clockstop | J21: Zone-Keepin | S21: Pass-Backhand | X21: s/u | AB21: OffensivePlay_Pass-AssistSecondary | AK21: Defensive_PlayShot-BlockedShot | BR21: Objects on Ice
A22: GameStart | J22: Zone_Entryfailed | S22: Pass-Forehand | X22: s/u | AB22: OffensivePlay_Pass-AssistTertiary | AK22: Defensive_PlayShot-FrontofNet | BR22: Hand Pass
A23: GameEnd | J23: Zone_ExitFailed | S23: Pass-Bank | X23: s/u | AB23: OffensivePlay_Pass-GiveAndGo | AK23: Defensive_PlayZone-ClearingAttempt | BR23: Premature Substitution
A24: Penalty_Delayed | J24: Zone_KeepinFailed | S24: Pass-Dump | X24: s/u | AB24: OffensivePlay_Pass-Reverse | AK24: Defensive_PlayZone-ZoneEntryDenial | BR24: Puck in Netting
A25: Zone_Change | J25: Penalty | S25: Pass-Tipped | X25: s/u | AB25: OffensivePlay_Pass-QuickUp | AK25: Defensive_PlayZone-ZoneExitDenial | BR25: Puck in Benches
J26: Penalty-Offsetting | S26: Pass-Lob | X26: s/u | AB26: OffensivePlay_Pass-SecondTouch | AK26: Defensive_PlayZone-PenaltyKillClear | BR26: Net Dislodged Offensive Skater
J27: Stoppage-Freeze | S27: Pass-Drop | X27: s/u | AB27: OffensivePlay_Pass-ReceiverMissed | AK27: Defensive_PlayZone-PuckRetrievalDumpIn | BR27: Puck Frzn-Goalie-Bynd Ctr
J28: Stoppage-OutfofPlay | S28: Pass-Deflected/TippedShot | X28: s/u | AB28: OffensivePlay_Shot-Screen | AK28: Defensive_PlayZone-PuckRetrievalShot | BR28: Skater Puck Frozen
J29: Stoppage-PeriodEnd | S29: Pass-ReceiverMissed | X29: s/u | AB29: OffensivePlay_Zone-Breakout | AK29: Defensive_PlayZone-PuckRetreivalTurnover | BR29: Valid stoppage type reasons (reason):
J30: Stoppage-Goal | S30: Pass-OneTouch | X30: s/u | AB30: OffensivePlay_Zone-DumpChase | AK30: Defensive_PlayZone-PuckRetreivalPass | BR30: TV timeout
J31: Stoppage-Penalty | S31: Pass-SecondTouch | X31: s/u | AB31: OffensivePlay_Zone-Forecheck | AK31: Defensive_PlayZone-PuckRetrievalRebound | BR31: Home Timeout
J32: Shootout-OnNet | S32: Pass-QuickUp | X32: s/u | AB32: OffensivePlay_Zone-Dump/RimInZone | AK32: Defensive_PlayZone-PuckRecoveryDumpIn | BR32: Visitor Timeout
J33: Shootout-Missed | S33: Pass-GiveAndGo | X33: s/u | AB33: OffensivePlay_Zone-DumpInAttempt | AK33: Defensive_PlayZone-PuckRecoveryShot | BR33: Player Injury
J34: Shootout-Saved | S34: Pass-Reverse | X34: s/u | AB34: OffensivePlay_Zone-Breakout | AK34: Defensive_PlayZone-PuckRecoveryTurnover | BR34: Official Injury
J35: PenaltyShot-OnNet | S35: Pass-Other | X35: s/u | AB35: OffensivePlay_Zone-Cycle | AK35: Defensive_PlayZone-PuckRecoveryPass | BR35: Rink Repair
J36: PenaltyShot-Missed | AB36: OffensivePlay_Zone-PuckRetrievalDumpIn | AK36: Defensive_PlayZone-PuckRecoveryRebound | BR36: Ice problem
J37: PenaltyShot-Saved | S37: Giveaway-Misplayed | AB37: OffensivePlay_Zone-PuckRetrievalShot | AK37: Defensive_PlayZone-ForcedDumpin/Clear | BR37: Player Equipment
J38: LoosePuck-Forecheck | S38: Giveaway-BattleLost | AB38: OffensivePlay_Zone-PuckRetreivalTurnover | AK38: Offensive_Zone-AttemptedKeepin | BR38: Video Review
J39: LoosePuck-Battle | S39: Giveaway-PassIntercepted | AB39: OffensivePlay_Zone-PuckRetreivalPass | AK39: Defensive_Zone-AttemptedBreakOutPass | BR39: Chlg Hm - off-side
J40: Save-Rebound | S40: Giveaway-PassMissed | AB40: OffensivePlay_Zone-PuckRetreivalRebound | AK40: Defensive_Zone-AttemptedBreakOutRush | BR40: Chlg Vis - off-side
...

Sheet Lists
A1: EventType | B1: EventTypeDetail | C1: EventTypeDetail2 | D1: OffensivePlay | E1: DefensivePlay | F1: Play | G1: Faceoff | H1: Shot | I1: Pass | J1: Goal | K1: Turnover | L1: Zone_Entry_Exit | M1: Penalty | N1: PenaltyShot/Shootout | O1: Stoppage | P1: LoosePuck | Q1: Save | R1: Pass_Completed | S1: Pass_Missed | T1: Pass_Deflected | U1: Pass_Intercepted | V1: Turnover_Giveaway | W1: Turnover_Takeaway | X1: Zone_Entry | Y1: Zone_Exit | Z1: Zone_Keepin | AA1: Penalty_Major | AB1: Penalty_Minor | AC1: Penalty_Offsetting | AD1: Stoppage_Play | AE1: Stoppage_Period | AF1: Stoppage_Other | AG1: Shootout_OnNet | AH1: Shootout_Missed | AI1: Shootout_Saved | AJ1: PenaltyShot_OnNet | AK1: PenaltyShot_Missed | AL1: PenaltyShot_Saved | AM1: Save_Rebound | AN1: Save_Freeze | AO1: Shot_OnNetSaved | AP1: Shot_Missed | AQ1: Shot_Blocked | AR1: Shot_BlockedSameTeam | AS1: Shot_Deflected | AT1: Shot_DeflectedOnNetSaved | AU1: Shot_TippedOnNetSaved | AV1: Shot_OnNetGoal | AW1: Shot_TippedGoal | AX1: Shot_DeflectedGoal | AY1: Goal_Scored | AZ1: Goal_Shootout | BA1: Goal_PenaltyShot | BB1: Save_Played | BC1: Rebound | BD1: Play_Offensive | BE1: Play_Defensive | BF1: Possession | BG1: Faceoff | BH1: Shot_MissedPost | BI1: shift_start | BJ1: shift_end | BK1: Offensive | BL1: Defensive | BM1: Zone_EntryFailed | BN1: Zone_ExitFailed | BO1: Zone_KeepinFailed | BQ1: play_details
F2: Play_Offensive | G2: Faceoff_AfterPenalty | H2: Shot_OnNetSaved | I2: Pass_Completed | J2: Goal_Scored | K2: Turnover_Giveaway | L2: Zone_Entry | M2: Penalty_Minor | N2: PenaltyShot_OnNet | O2: Stoppage_Period | P2: LoosePuck_Forecheck | Q2: Save_Rebound | R2: Pass-Stretch | S2: Pass-Stretch | T2: Pass-Stretch | U2: Pass-Stretch | V2: Giveaway-Misplayed | W2: Takeaway-BattleWon | X2: ZoneEntry-Rush | Y2: ZoneExit-Rush | Z2: Zone-KeepIn | AA2: Penalty-Bench Penalty | AB2: Penalty-Bench Penalty | AC2: Penalty-Bench Penalty | AD2: Stoppage-Icing | AE2: Stoppage-StartofShootout | AF2: Stoppage-ObjectsonIce | AG2: Shot-Wrist | AH2: Shot-Wrist | AI2: Shot-Wrist | AJ2: Shot-Wrist | AK2: Shot-Wrist | AL2: Shot-Wrist | AM2: Save-Glove | AN2: Save-Glove | AO2: Shot-Wrist | AP2: Shot-Wrist | AQ2: Shot-Wrist | AR2: Shot-Wrist | AS2: Shot-Deflection | AT2: Shot-Deflection | AU2: Shot-Tip | AV2: Shot-Wrist | AX2: Shot-Deflection | AY2: Goal-Wrist | AZ2: Goal-Wrist | BA2: Goal-Wrist | BB2: Save-Glove | BC2: Rebound_TeamRecovered | BE2: Play-PokeCheck | BF2: Breakaway | BG2: Shot | BH2: Shot-Wrist | BI2: PeriodStart | BJ2: - | BK2: AssistPrimary | BL2: AttemptedBlockedShot | BM2: ZoneEntry-Rush | BN2: ZoneExit-Rush | BO2: Zone-KeepIn | BQ2: {=_xlfn._xlws.SORT(_xlfn.UNIQUE(BK2:BK1000))} -> AssistPrimary
A3: Faceoff | B3: Faceoff | C3: Shot-Wrist | D3: DriveMiddle | E3: PokeCheck | F3: Play_Defensive | G3: Faceoff_AfterGoal | H3: Shot_Missed | I3: Pass_Missed | J3: Goal_Shootout | K3: Turnover_Takeaway | L3: Zone_Exit | M3: Penalty_Offsetting | N3: PenaltyShot_Missed | O3: Stoppage_Play | P3: LoosePuck_Battle | Q3: Save_Freeze | R3: Pass-Rim/Wrap | S3: Pass-Rim/Wrap | T3: Pass-Rim/Wrap | U3: Pass-Rim/Wrap | V3: Giveaway-BattleLost | W3: Takeaway-PokeCheck | X3: ZoneEntry-Pass | Y3: ZoneExit-Pass | Z3: Zone-Pinch | AA3: Penalty-Boarding | AB3: Penalty-Boarding | AC3: Penalty-Boarding | AD3: Stoppage-Offsides | AE3: Stoppage-PeriodStart | AF3: Stoppage-HomeTimeout | AG3: Shot-Slap | AH3: Shot-Slap | AI3: Shot-Slap | AJ3: Shot-Slap | AK3: Shot-Slap | AL3: Shot-Slap | AM3: Save-Blocker | AN3: Save-Blocker | AO3: Shot-Slap | AP3: Shot-Slap | AQ3: Shot-Slap | AR3: Shot-Slap | AS3: Shot-Wrist | AT3: Shot-Wrist | AU3: Shot-Wrist | AV3: Shot-Slap | AW3: Shot-Wrist | AX3: Shot-Wrist | AY3: Goal-Slap | AZ3: Goal-Slap | BA3: Goal-Slap | BB3: Save-Blocker | BC3: Rebound_OppTeamRecovered | BD3: Play-DriveMiddle | BE3: Play-PokeCheckFailed | BF3: PuckRetrieval | BG3: Pass | BH3: Shot-Slap | BI3: FaceoffAfterGoal | BJ3: Period Start | BK3: AssistSecondary | BL3: AttemptedBreakOutClear | BM3: ZoneEntry-Pass | BN3: ZoneExit-Pass | BO3: Zone-Pinch | BQ3: AssistSecondary
A4: Shot | B4: Faceoff-AfterPenalty | C4: Shot-Slap | D4: DriveWide | E4: PokeCheckFailed | G4: Faceoff_PeriodStart | H4: Shot_Blocked | I4: Pass_Deflected | J4: Goal_PenaltyShot | L4: Zone_Keepin | M4: Penalty_Major | N4: PenaltyShot_Saved | O4: Stoppage_Other | Q4: Save_Played | R4: Pass-Backhand | S4: Pass-Backhand | T4: Pass-Backhand | U4: Pass-Backhand | V4: Giveaway-PassIntercepted | W4: Takeaway-PassIntercepted | X4: ZoneEntry-DumpIn | Y4: ZoneExit-Clear | Z4: Zone-Other | AA4: Penalty-Charging | AB4: Penalty-Charging | AC4: Penalty-Charging | AD4: Stoppage-ClockProblem | AE4: Stoppage-PeriodEnd | AF4: Stoppage-VisitorTimeout | AG4: Shot-Backhand | AH4: Shot-Backhand | AI4: Shot-Backhand | AJ4: Shot-Backhand | AK4: Shot-Backhand | AL4: Shot-Backhand | AM4: Save-LeftPad | AN4: Save-LeftPad | AO4: Shot-Backhand | AP4: Shot-Backhand | AQ4: Shot-Backhand | AR4: Shot-Backhand | AS4: Shot-Slap | AT4: Shot-Slap | AU4: Shot-Slap | AV4: Shot-Backhand | AW4: Shot-Slap | AX4: Shot-Slap | AY4: Goal-Backhand | AZ4: Goal-Backhand | BA4: Goal-Backhand | BB4: Save-LeftPad | BC4: Rebound_ShotGenerated | BD4: Play-DriveWide | BE4: Play-SeperateFromPuck | BF4: PuckRecovery | BG4: Goal | BH4: Shot-Backhand | BI4: GameStart | BJ4: Period End | BK4: AssistTertiary | BL4: AttemptedBreakOutPass | BM4: ZoneEntry-DumpIn | BN4: ZoneExit-Clear | BO4: Zone-Other | BQ4: AssistTertiary
A5: Pass | B5: Faceoff-AfterGoal | C5: Shot-Backhand | D5: DriveCorner | E5: SeperateFromPuck | G5: Faceoff_AfterStoppage | H5: Shot_BlockedSameTeam | I5: Pass_Intercepted | L5: Zone_Entryfailed | N5: ShootoutShot_OnNet | O5: Stoppage_GameEnd | R5: Pass-Forehand | S5: Pass-Forehand | T5: Pass-Forehand | U5: Pass-Forehand | V5: Giveaway-PassMissed | W5: Takeaway-PassBlocked | X5: ZoneEntry-Chip | Y5: ZoneExit-Chip | AA5: Penalty-CrossChecking | AB5: Penalty-CrossChecking | AC5: Penalty-CrossChecking | AD5: Stoppage-HighStick | AF5: Stoppage-RinkRepair | AG5: Shot-Snap | AH5: Shot-Snap | AI5: Shot-Snap | AJ5: Shot-Snap | AK5: Shot-Snap | AL5: Shot-Snap | AM5: Save-RightPad | AN5: Save-RightPad | AO5: Shot-Snap | AP5: Shot-Snap | AQ5: Shot-Snap | AR5: Shot-Snap | AS5: Shot-Backhand | AT5: Shot-Backhand | AU5: Shot-Backhand | AV5: Shot-Snap | AW5: Shot-Backhand | AX5: Shot-Backhand | AY5: Goal-Tip | AZ5: Goal-Snap | BA5: Goal-Snap | BB5: Save-RightPad | BC5: Rebound_FlurryGenerated | BD5: Play-DriveCorner | BE5: Play-Backcheck | BF5: Regroup | BG5: Turnover | BH5: Shot-Snap | BI5: FaceoffAfterPenalty | BJ5: Puck Out of Play | BK5: AttemptedBreakOutClear | BL5: AttemptedBreakOutRush | BM5: ZoneEntry-Chip | BN5: ZoneExit-Chip | BQ5: AttemptedBlockedShot
A6: Goal | B6: Faceoff-PeriodStart | C6: Shot-Tip | D6: DriveNetMiddle | E6: Backcheck | G6: Faceoff_GameStart | H6: Shot_Deflected | L6: Zone_ExitFailed | N6: ShootoutShot_Missed | R6: Pass-Bank | S6: Pass-Bank | T6: Pass-Bank | U6: Pass-Bank | V6: Giveaway-PassBlocked | W6: Takeaway-ShotBlocked | X6: ZoneEntry-FromExitClear | Y6: ZoneExit-PassMiss/Misplay | AA6: Penalty-DelayofGame | AB6: Penalty-DelayofGame | AC6: Penalty-DelayofGame | AD6: Stoppage-HandPass | AF6: Stoppage-PlayerEquipment | AG6: Shot-WrapAround | AH6: Shot-WrapAround | AI6: Shot-WrapAround | AJ6: Shot-WrapAround | AK6: Shot-WrapAround | AL6: Shot-WrapAround | AM6: Save-Stick | AN6: Save-Stick | AO6: Shot-WrapAround | AP6: Shot-WrapAround | AQ6: Shot-WrapAround | AR6: Shot-WrapAround | AS6: Shot-Snap | AT6: Shot-Snap | AU6: Shot-Snap | AV6: Shot-WrapAround | AW6: Shot-Snap | AX6: Shot-Snap | AY6: Goal-Snap | AZ6: Goal-WrapAround | BA6: Goal-WrapAround | BB6: Save-Stick | BD6: Play-DriveNetMiddle | BE6: Play-FroceWide | BG6: Zone_Entry_Exit | BH6: Shot-WrapAround | BI6: OtherFaceoff | BJ6: Injury | BK6: AttemptedBreakOutPass | BL6: AttemptedEntryDumpIn | BM6: ZoneEntry-FromExitClear | BN6: ZoneExit-PassMiss/Misplay | BQ6: AttemptedBreakOutClear
A7: Turnover | B7: Shot-OnNet | C7: Shot-Snap | D7: DriveNetWide | E7: FroceWide | H7: Shot_DeflectedOnNetSaved | L7: Zone_KeepinFailed | N7: ShootoutShot_Saved | R7: Pass-Dump | S7: Pass-Dump | T7: Pass-Dump | U7: Pass-Dump | V7: Giveaway-PassReceiverMissed | W7: Takeaway-ZoneClear/Dump | X7: ZoneEntry-PassMiss/Misplay | Y7: ZoneExit-OppTeam | AA7: Penalty-Diving | AB7: Penalty-Diving | AC7: Penalty-Diving | AD7: Stoppage-NetDislodged | AF7: Stoppage-Challenge | AG7: Shot-Bat | AH7: Shot-Bat | AI7: Shot-Bat | AJ7: Shot-Bat | AK7: Shot-Bat | AL7: Shot-Bat | AM7: Save-Scramble | AN7: Save-Scramble | AO7: Shot-Bat | AP7: Shot-Bat | AQ7: Shot-Bat | AR7: Shot-Bat | AS7: Shot-WrapAround | AT7: Shot-WrapAround | AU7: Shot-WrapAround | AV7: Shot-Bat | AW7: Shot-WrapAround | AX7: Shot-WrapAround | AY7: Goal-WrapAround | AZ7: Goal-Bat | BA7: Goal-Bat | BB7: Save-Scramble | BD7: Play-DriveNetWide | BE7: Play-Contain | BG7: Penalty | BH7: Shot-Bat | BI7: DeadIce/Stoppage | BJ7: Home Penalty | BK7: AttemptedBreakOutRush | BL7: AttemptedEntryPass | BM7: ZoneEntry-PassMiss/Misplay | BN7: ZoneExit-OppTeam | BQ7: AttemptedBreakOutPass
A8: Zone_Entry_Exit | B8: Shot-Missed | C8: Shot-WrapAround | D8: CrashNet | E8: Contain | H8: Shot_Tipped | R8: Pass-Tipped | S8: Pass-Tipped | T8: Pass-Tipped | U8: Pass-Tipped | V8: Giveaway-ShotBlocked | W8: Takeaway-AttemptedZoneClear/Dump | X8: ZoneEntry-OppTeam | Y8: ZoneExit-Lob | AA8: Penalty-Elbowing | AB8: Penalty-Elbowing | AC8: Penalty-Elbowing | AD8: Stoppage-Injury | AF8: Stoppage-Other | AG8: Shot-Cradle | AH8: Shot-Cradle | AI8: Shot-Cradle | AJ8: Shot-Cradle | AK8: Shot-Cradle | AL8: Shot-Cradle | AM8: Save-Butterfly | AN8: Save-Butterfly | AO8: Shot-Cradle | AP8: Shot-Cradle | AQ8: Shot-Cradle | AR8: Shot-Cradle | AS8: Shot-Bat | AT8: Shot-Bat | AU8: Shot-Bat | AV8: Shot-Cradle | AW8: Shot-Bat | AX8: Shot-Bat | AY8: Goal-Bat | AZ8: Goal-Cradle | BA8: Goal-Cradle | BB8: Save-Butterfly | BD8: Play-CrashNet | BE8: Play-BeatMiddle | BG8: PenaltyShot_Shootout | BH8: Shot-Cradle | BI8: Intermission | BJ8: Away Penalty | BK8: AttemptedEntryDumpIn | BL8: AttemptedEntryRush | BM8: ZoneEntry-OppTeam | BN8: ZoneExit-Lob | BQ8: AttemptedBreakOutRush
A9: Penalty | B9: Shot-Blocked | C9: Shot-Bat | D9: Delay | E9: BeatMiddle | H9: Shot_TippedOnNetSaved | R9: Pass-Lob | S9: Pass-Lob | T9: Pass-Lob | U9: Pass-Lob | V9: Giveaway-ShotMissed | W9: Takeaway-Other | X9: ZoneEntry-Lob | Y9: ZoneExit-CausedTurnover | AA9: Penalty-GoalieInterference | AB9: Penalty-GoalieInterference | AC9: Penalty-GoalieInterference | AD9: Stoppage-GoalieStoppage | AG9: Shot-Poke | AH9: Shot-Poke | AI9: Shot-Poke | AJ9: Shot-Poke | AK9: Shot-Poke | AL9: Shot-Poke | AM9: Save-Chest | AN9: Save-Chest | AO9: Shot-Poke | AP9: Shot-Poke | AQ9: Shot-Poke | AR9: Shot-Poke | AS9: Shot-Cradle | AT9: Shot-Cradle | AU9: Shot-Cradle | AV9: Shot-Poke | AW9: Shot-Cradle | AX9: Shot-Cradle | AY9: Goal-Cradle | AZ9: Goal-Poke | BA9: Goal-Poke | BB9: Save-Chest | BD9: Play-Delay | BE9: Play-BeatWide | BG9: Stoppage | BH9: Shot-Poke | BI9: DelayedPenalty | BJ9: Home Goalie Stoppage | BK9: AttemptedEntryPass | BL9: AttemptedKeepin | BM9: ZoneEntry-Lob | BN9: ZoneExit-CausedTurnover | BQ9: AttemptedEntryDumpIn
A10: PenaltyShot_Shootout | B10: Shot-BlockedSameTeam | C10: Shot-Cradle | D10: Deke | E10: BeatWide | H10: Shot_OnNetGoal | R10: Pass-Drop | S10: Pass-Drop | T10: Pass-Drop | U10: Pass-Drop | V10: Giveaway-ZoneClear/Dump | X10: ZoneEntry-RushBreakaway | Y10: ZoneExit-PenaltyKillClear | AA10: Penalty-HighSticking | AB10: Penalty-HighSticking | AC10: Penalty-HighSticking | AD10: Stoppage-PuckOutofPlay | AG10: Shot-BetweenLegs | AH10: Shot-BetweenLegs | AI10: Shot-BetweenLegs | AJ10: Shot-BetweenLegs | AK10: Shot-BetweenLegs | AL10: Shot-BetweenLegs | AM10: Save-Shoulder | AN10: Save-Shoulder | AO10: Shot-BetweenLegs | AP10: Shot-BetweenLegs | AQ10: Shot-BetweenLegs | AR10: Shot-BetweenLegs | AS10: Shot-Poke | AT10: Shot-Poke | AU10: Shot-Poke | AV10: Shot-BetweenLegs | AW10: Shot-Poke | AX10: Shot-Poke | AY10: Goal-Poke | AZ10: Goal-BetweenLegs | BA10: Goal-BetweenLegs | BB10: Save-Other | BD10: Play-Deke | BE10: Play-BeatDeke | BG10: Hit | BH10: Shot-BetweenLegs | BI10: GameStart | BJ10: Away Goalie Stoppage | BK10: AttemptedEntryRush | BL10: Backcheck | BM10: ZoneEntry-RushBreakaway | BN10: ZoneExit-PenaltyKillClear | BQ10: AttemptedEntryPass
A11: Stoppage | B11: Shot-Deflected | C11: Shot-Poke | D11: Chip | E11: BeatDeke | H11: Shot_OnNetTippedGoal | R11: Pass-Deflected/TippedShot | S11: Pass-Deflected/TippedShot | T11: Pass-Deflected/TippedShot | U11: Pass-Deflected/TippedShot | V11: Giveaway-AttemptedZoneClear/Dump | X11: ZoneEntry-CausedTurnover | Y11: ZoneExit-Shot | AA11: Penalty-Holding | AB11: Penalty-Holding | AC11: Penalty-Holding | AD11: Stoppage-Penalty | AG11: Shot-Tip | AH11: Shot-Tip | AI11: Shot-Other | AJ11: Shot-Other | AK11: Shot-Other | AL11: Shot-Other | AM11: Save-Skate | AN11: Save-Skate | AO11: Shot-Dumpin | AP11: Shot-Dumpin | AQ11: Shot-Dumpin | AR11: Shot-Dumpin | AS11: Shot-BetweenLegs | AT11: Shot-BetweenLegs | AU11: Shot-BetweenLegs | AV11: Shot-Dumpin | AW11: Shot-BetweenLegs | AX11: Shot-BetweenLegs | AY11: Goal-BetweenLegs | AZ11: Goal-Other | BA11: Goal-Other | BD11: Play-Chip | BE11: Play-BeatSpeed | BG11: Possession | BH11: Shot-Dumpin | BJ11: Home Offside | BK11: AttemptedKeepin | BL11: BeatDeke | BM11: ZoneEntry-CausedTurnover | BN11: ZoneExit-Other | BQ11: AttemptedEntryRush
A12: Hit | B12: Shot-DeflectedOnNet | C12: Shot-BetweenLegs | D12: Other | E12: BeatSpeed | H12: Shot_OnNetDeflectedGoal | R12: Pass-ReceiverMissed | S12: Pass-ReceiverMissed | T12: Pass-ReceiverMissed | U12: Pass-ReceiverMissed | V12: Giveaway-ZoneEntry/ExitMisplay | X12: ZoneEntry-PenaltyKillClear | Y12: ZoneExit-Other | AA12: Penalty-Interference | AB12: Penalty-Interference | AC12: Penalty-Interference | AD12: Stoppage-Goal | AG12: Shot-Other | AH12: Shot-Other | AM12: Save-Other | AN12: Save-Other | AO12: Shot-OneTime | AP12: Shot-OneTime | AQ12: Shot-OneTime | AR12: Shot-OneTime | AS12: Shot-Dumpin | AT12: Shot-Dumpin | AU12: Shot-Dumpin | AV12: Shot-OneTime | AW12: Shot-Dumpin | AX12: Shot-Dumpin | AY12: Goal-Dumpin | BD12: Play-Other | BE12: Play-BoxOut | BG12: LoosePuck | BH12: Shot-OneTime | BJ12: Home Icing | BK12: Breakout | BL12: BeatFake | BM12: ZoneEntry-PenaltyKillClear | BQ12: AttemptedKeepin
A13: Possession | B13: Shot-Tipped | C13: Shot-Dumpin | D13: DumpChase | E13: BoxOut | H13: Shot_Goal | R13: Pass-OneTouch | S13: Pass-Other | T13: Pass-Other | U13: Pass-Other | V13: Giveaway-DumpInZone | X13: ZoneEntry-Shot | AA13: Penalty-Hooking | AB13: Penalty-Fighting | AC13: Penalty-Fighting | AO13: Shot-Tip | AP13: Shot_Tipped | AQ13: Shot_Tipped | AR13: Shot_Tipped | AS13: Shot-OneTime | AT13: Shot-OneTime | AU13: Shot-OneTime | AV13: Shot-Other | AW13: Shot-OneTime | AX13: Shot-OneTime | AY13: Goal-Deflection | BD13: Play-DumpChase | BE13: Play-AttemptedClear | BG13: Save | BH13: Shot_Tipped | BJ13: Away Offside | BK13: Breakout | BL13: BeatMiddle | BM13: ZoneEntry-Other | BQ13: AttemptedPass
A14: LoosePuck | B14: Pass-Completed | C14: Shot-Deflection | D14: Forecheck | E14: Other | H14: Shot_MissedPost | R14: Pass-SecondTouch | S14: Pass-SecondTouch | T14: Pass-SecondTouch | U14: Pass-SecondTouch | V14: Giveaway-Other | X14: ZoneEntry-Other | AA14: Penalty-Roughing | AB14: Penalty-Hooking | AC14: Penalty-Hooking | AO14: Shot-Other | AP14: Shot-Other | AQ14: Shot-Other | AR14: Shot-Other | AS14: Shot-Other | AT14: Shot-Other | AU14: Shot-Other | AV14: Shot-Deflection | AW14: Shot-Other | AX14: Shot-Other | AY14: Goal-OneTime | BD14: Play-Forecheck | BE14: Play-Other | BG14: TeamPossessionChange | BH14: Shot-Other | BJ14: Away Icing | BK14: CededZoneEntry | BL14: BeatSpeed | BQ14: AttemptedShot
A15: Save | B15: Pass-Missed | C15: Shot-OneTime | D15: Speed | R15: Pass-QuickUp | S15: Pass-QuickUp | T15: Pass-QuickUp | U15: Pass-QuickUp | AA15: Penalty-Slashing | AB15: Penalty-Roughing | AC15: Penalty-Roughing | AV15: Shot-Tip | AY15: Goal-Other | BD15: Play-Speed | BG15: Rebound | BJ15: Clock Problem | BK15: CededZoneExit | BL15: BeatWide | BQ15: AttemptedTip/Deflection
A16: TeamPossessionChange | B16: Pass-Deflected | C16: Shot-Other | R16: Pass-GiveAndGo | S16: Pass-GiveAndGo | T16: Pass-GiveAndGo | U16: Pass-GiveAndGo | AA16: Penalty-TooManyMenontheIce | AB16: Penalty-Slashing | AC16: Penalty-Slashing | BD16: Play-Dump/RimInZone | BJ16: Puck Frozen | BK16: Chip | BL16: BlockedShot | BQ16: Backcheck
A17: Rebound | B17: Pass-Intercepted | C17: Pass-Stretch | R17: Pass-Reverse | S17: Pass-Reverse | T17: Pass-Reverse | U17: Pass-Reverse | AA17: Penalty-Tripping | AB17: Penalty-Misconduct | AC17: Penalty-Misconduct | BJ17: Puck in Crowd | BK17: CrashNet | BL17: BoxOut | BQ17: BeatDeke
A18: DeadIce | B18: Turnover-Giveaway | C18: Pass-Rim/Wrap | R18: Pass-Other | S18: Pass-Other | T18: Pass-Other | U18: Pass-Other | AA18: Penalty-Other | AB18: Penalty-TooManyMenontheIce | AC18: Penalty-TooManyMenontheIce | BJ18: Goalie Stopped (after SOG) | BK18: CutBack | BL18: CededZoneEntry | BQ18: BeatFake
A19: Play | B19: Turnover-Takeaway | C19: Pass-Backhand | AB19: Penalty-Tripping | AC19: Penalty-Tripping | BJ19: Referee or Linesperson | BK19: Cycle | BL19: CededZoneExit | BQ19: BeatMiddle
A20: Timeout | B20: Zone-Entry | C20: Pass-Forehand | AB20: Penalty-UnsportsmanlikeConduct | AC20: Penalty-UnsportsmanlikeConduct | BJ20: High Stick | BK20: Deke | BL20: ClearingAttempt | BQ20: BeatSpeed
A21: Intermission | B21: Zone-Exit | C21: Pass-Bank | AB21: Penalty-Other | AC21: Penalty-Other | BJ21: Objects on Ice | BK21: Delay | BL21: Contain | BQ21: BeatWide
A22: Clockstop | B22: Zone-Keepin | C22: Pass-Other | BJ22: Hand Pass | BK22: DriveCorner | BL22: ForcedDumpin/Clear | BQ22: BlockedShot
A23: GameStart | B23: Penalty | C23: Giveaway-Misplayed | BJ23: Premature Substitution | BK23: DriveMiddle | BL23: ForcedLostPossession | BQ23: BoxOut
A24: GameEnd | B24: Penalty-Offsetting | C24: Giveaway-BattleLost | BJ24: Puck in Netting | BK24: DriveNetMiddle | BL24: ForcedMissedPass | BQ24: Breakout
A25: Penalty_Delayed | B25: Stoppage-Freeze | C25: Giveaway-PassIntercepted | BJ25: Puck in Benches | BK25: DriveNetWide | BL25: ForcedMissedShot | BQ25: CededZoneEntry
A26: Zone_Change | B26: Stoppage-OutfofPlay | C26: Giveaway-PassMissed | BJ26: Net Dislodged Offensive Skater | BK26: DriveWide | BL26: ForcedTurnover | BQ26: CededZoneExit
B27: Stoppage-PeriodEnd | C27: Giveaway-PassBlocked | BJ27: Puck Frzn-Goalie-Bynd Ctr | BK27: Dump/RimInZone | BL27: ForceWide | BQ27: Chip
B28: Stoppage-Goal | C28: Giveaway-ShotBlocked | BJ28: Skater Puck Frozen | BK28: DumpChase | BL28: Forecheck | BQ28: ClearingAttempt
B29: Stoppage-Penalty | C29: Giveaway-ShotMissed | BJ29: Valid stoppage type reasons (reason): | BK29: DumpInAttempt | BL29: FrontofNet | BQ29: Contain
B30: Shootout-OnNet | C30: Giveaway-Other | BJ30: TV timeout | BK30: EndToEndRush | BL30: GapControl | BQ30: CrashNet
B31: Shootout-Missed | C31: Takeaway-BattleWon | BJ31: Home Timeout | BK31: FakeShot | BL31: InShotPassLane | BQ31: CutBack
B32: Shootout-Saved | C32: Takeaway-PokeCheck | BJ32: Visitor Timeout | BK32: ForecedOutside | BL32: LoosePuckBattleLost | BQ32: Cycle
B33: PenaltyShot-OnNet | C33: Takeaway-PassIntercepted | BJ33: Player Injury | BK33: Forecheck | BL33: LoosePuckBattleWon | BQ33: DeflectedShot
B34: PenaltyShot-Missed | C34: Takeaway-PassBlocked | BJ34: Official Injury | BK34: FrontofNet | BL34: ManOnMan | BQ34: Deke
B35: PenaltyShot-Saved | C35: Takeaway-ShotBlocked | BJ35: Rink Repair | BK35: GiveAndGo | BL35: PassDeflected | BQ35: Delay
B36: LoosePuck-Forecheck | C36: Takeaway-Other | BJ36: Ice problem | BK36: LoosePuckBattleLost | BL36: PassIntercepted | BQ36: DelayedOffside
B37: LoosePuck-Battle | C37: ZoneEntry-Rush | BJ37: Player Equipment | BK37: LoosePuckBattleWon | BL37: PenaltyKillClear | BQ37: DriveCorner
B38: Save-Rebound | C38: ZoneEntry-Pass | BJ38: Video Review | BK38: LostPuck | BL38: PokeCheck | BQ38: DriveMiddle
... B43: Faceoff-GameStart | C43: Zone-KeepIn | BJ43: Chlg League - off-side | BK43: RecoveryRetreivalFaceoff | BL43: PuckRecoveryPass | BQ43: DumpChase
C44: Zone-Pinch | BJ44: Chlg League - goal interference | BK44: RecoveryRetreivalOther | BL44: PuckRecoveryRebound | BQ44: DumpInAttempt
...

Sheet events
A1: event_index_flag_ | B1: sequence_index_flag_ | C1: play_index_flag_ | D1: linked_event_index_flag_ | E1: event_start_min_ | F1: event_start_sec_ | G1: event_end_min_ | H1: event_end_sec_ | I1: player_game_number_ | J1: event_team_zone_ | K1: event_type_ | L1: event_detail_ | M1: event_detail_2_ | N1: event_successful_ | O1: play_detail1_ | P1: play_detail2_ | Q1: play_detail_successful_ | R1: pressured_pressurer_ | S1: event_index_ | T1: linked_event_index_ | U1: sequence_index_ | V1: play_index_ | W1: team_ | X1: player_game_number | Y1: role_abrev_binary_ | Z1: period | AA1: event_index | AB1: linked_event_index | AC1: tracking_event_index | AD1: event_start_min | AE1: event_start_sec | AF1: event_end_min | AG1: event_end_sec | AH1: role_abrev | AI1: event_team_zone2_ | AJ1: event_team_zone | AK1: home_team_zone_ | AL1: away_team_zone_ | AM1: team_venue_ | AN1: team_venue_abv_ | AO1: home_team_zone | AP1: away_team_zone | AQ1: team_venue | AR1: team_venue_abv | AS1: side_of_puck | AT1: sequence_index | AU1: play_index | AV1: play_detail1 | AW1: play_detail_2 | AX1: play_detail_successful | AY1: pressured_pressurer | AZ1: zone_change_index | BA1: game_id | BB1: home_team | BC1: away_team | BD1: Type | BE1: event_detail | BF1: event_detail_2 | BG1: event_successful | BH1: shift_index | BI1: duration | BJ1: time_start_total_seconds | BK1: time_end_total_seconds | BL1: running_intermission_duration | BM1: period_start_total_running_seconds | BN1: running_video_time | BO1: event_running_start | BP1: event_running_end | BQ1: player_role | BR1: role_number | BS1: player_id | BT1: player_team
K2: GameStart | S2: 0 | Y2: x | Z2: 1 | AA2: =S2+1000 -> 1000 | AB2: =IF(T2<>"",9000+T2,"") | AC2: =IF(AB2<>"",AB2,S2+1000) -> 1000 | AF2: =IF(G2<>"",G2,IF($S2=$S1,AF1,"")) | AG2: =IF(H2<>"",H2,IF($S2=$S1,AG1,"")) | AH2: =IF(Y2="x","",IF(Y2=1,"e","o")) | AI2: =IF($J2<>"",$J2,IF($AC2=$AC1,AI1,"")) | AJ2: =IF($J2<>"",$J2,IF($AC2=$AC1,AJ1,"")) | AK2: =IF($W2="","",IF($AI2="","",IF($W2="h",$AI2,IF($AI2="n","n",IF(AND($W2="a",$AI2="d"),"o",IF(AND($W2="a",$AI2="o"),"d")))))) | AL2: =IF($W2="","",IF(J2="","",IF(AK2="n","n",IF(AK2="d","o",IF(AK2="o","d",""))))) | AM2: =IF(AN2="H","Home",IF(AN2="A","Away","")) | AN2: =IF($W2<>"",$W2,IF($AC2=$AC1,AN1,"")) | AO2: =IF(AK2<>"",AK2,IF($AC2=$AC1,AO1,"")) | AP2: =IF(AL2<>"",AL2,IF($AC2=$AC1,AP1,"")) | AQ2: =IF(AM2<>"",AM2,IF($AC2=$AC1,AQ1,"")) | AR2: =IF(AN2<>"",AN2,IF($AC2=$AC1,AR1,"")) | AS2: =IF(AND(AH2="e",OR(BD2="Save",BE2="Turnover_Takeaway",BE2="Play_Defensive")),"Defensive",IF(AND(AH2="o",OR(BD2="Save",BE2="Turnover_Takeaway",BE2="Play_Defensive")),"Offensive",IF(OR(BD2="Deadice",BD2="Stoppage",BD2="Intermission"),"",IF(AH2="e","Offensive",IF(AH2="o","Defensive",""))))) | AT2: =IF(U2<>"",U2+5000,"") | AU2: =IF(V2<>"",V2+6000,"") | AV2: {=IFERROR(IF(O2<>"",O2,IF(OR($S2="",$T2=""),"",IF(O2<>"",O2,IF($T2<>"",_xlfn._xlws.FILTER(O:O,($BT:$BT=$BT2)*($I:$I=$I2)*($T:$T=$T2)*($S:$S=_xlfn.MINIFS($S:$S,$T:$T,"="&$T2)),"")))))&"",IF(O2="","",""))&""} | AW2: {=IFERROR(IF(P2<>"",P2,IF(OR($S2="",$T2=""),"",IF($T2<>"",_xlfn._xlws.FILTER(P:P,($BT:$BT=$BT2)*($I:$I=$I2)*($T:$T=$T2)*($S:$S=_xlfn.MINIFS($S:$S,$T:$T,"="&$T2)),""))))&"",IF(P2="","",""))&""} | AX2: {=IFERROR(IF(Q2<>"",Q2,IF(OR($S2="",$T2=""),"",IF($T2<>"",_xlfn._xlws.FILTER(Q:Q,($BT:$BT=$BT2)*($I:$I=$I2)*($T:$T=$T2)*($S:$S=_xlfn.MINIFS($S:$S,$T:$T,"="&$T2)),""))))&"",IF(Q2="","",""))&""} | AY2: {=IFERROR(IF(R2<>"",R2,IF(OR($S2="",$T2=""),"",IF($T2<>"",_xlfn._xlws.FILTER(R:R,($BT:$BT=$BT2)*($I:$I=$I2)*($T:$T=$T2)*($S:$S=_xlfn.MINIFS($S:$S,$T:$T,"="&$T2)),""))))&"",IF(R2="","",""))&""} | AZ2: 1 | BA2: 18969 | BB2: Platinum | BC2: Velodrome | BD2: =IF(K2<>"",K2,IF(S2=S1,K2,"")) -> GameStart | BM2: 0 | BN2: 0 | BO2: =IF(BN2<5,0,BN2-5) -> 0 | BP2: =BO2+BI2+5 -> 5 | BS2: =IFERROR(VLOOKUP(BA2&BT2&I2,game_rosters!U:W,3,FALSE),"") | BT2: =IF(AQ2="","",IF(AND(AQ2="Away",AH2="e"),BC2,IF(AND(AQ2="Home",AH2="e"),BB2,IF(AND(AQ2="Away",AH2="o"),BB2,IF(AND(AQ2="Home",AH2="o"),BC2)))))
A3: 1 | E3: 18 | F3: 00 | I3: 53 | J3: n | K3: Faceoff | L3: Faceoff_GameStart | N3: =IF(K3="","",IF(K3="Goal","s",IF(AND(K3="Zone_Entry_Exit",OR(ISNUMBER(SEARCH("fail",L3)),ISNUMBER(SEARCH("FromExitClear",M3)),ISNUMBER(SEARCH("miss",M3)))),"u",IF(AND(K3="Zone_Entry_Exit",OR(NOT(ISNUMBER(SEARCH("fail",L3))),NOT(ISNUMBER(SEARCH("FromExitClear",M3))),NOT(ISNUMBER(SEARCH("miss",M3))))),"s",IF(AND(OR(K3="Shot",K3="Pass"),OR(ISNUMBER(SEARCH("complete",L3)),ISNUMBER(SEARCH("goal",L3)),ISNUMBER(SEARCH("OnNet",L3)))),"s",IF(L3="Turnover_Giveaway","u",IF(AND(OR(K3="Shot",K3="Pass"),OR(ISNUMBER(SEARCH("fail",L3)),NOT(ISNUMBER(SEARCH("complete",L3))),NOT(ISNUMBER(SEARCH("OnNet",L3))))),"u",""))))))) | Q3: =IF(O3="","",IF(AND(N3<>"",OR(O3<>"",P3<>"")),N3,IF(OR(ISNUMBER(SEARCH("attemp",O3)),ISNUMBER(SEARCH("mis",O3)),ISNUMBER(SEARCH("fail",O3)),ISNUMBER(SEARCH("loss",O3)),ISNUMBER(SEARCH("lost",O3)),ISNUMBER(SEARCH("attemp",P3)),ISNUMBER(SEARCH("mis",P3)),ISNUMBER(SEARCH("fail",P3)),ISNUMBER(SEARCH("loss",P3)),ISNUMBER(SEARCH("lost",P3))),"u",""))) | S3: =IF(A3=1,MAX($S$2:$S2)+1,IF($I3<>"",$S2,"")) -> 1 | T3: =IF(D3=1,MAX($T$2:$T2)+1,IF(S3=S2,$T2,IF(D3="x",T2,IF(D2="x","","")))) | U3: =IF(B3=1,MAX($U$2:$U2)+1,IF(AND($T3<>"",$T3=$T2),$U2,IF(B3="x",U2,""))) | V3: =IF(C3=1,MAX($V$2:$V2)+1,IF(AND($T3<>"",$T3=$T2),$U2,IF(C3="x",V2,""))) | W3: {=_xlfn._xlws.FILTER(game_rosters!AB:AB,(game_rosters!J:J=events!X3)*(K3<>""))} -> h | X3: {=IF($I3<>"",$I3,INDEX($I$1:$I3,ROW()-COUNTIFS($T$1:$T3,"="&$T3,$S$1:$S3,"<"&$S3)))} -> 53 | Y3: {=IFERROR(IF(_xlfn._xlws.FILTER(game_rosters!$J:$J,(game_rosters!$G:$G=events!$AM3)*(game_rosters!$J:$J=events!$X3))>0,1,""),"")} -> 1 | Z3: =IF(K3="Intermission",Z2+1,Z2) -> 1 | AA3: =S3+1000 -> 1001 | AB3: =IF(T3<>"",9000+T3,"") | AC3: =IF(AB3<>"",AB3,S3+1000) -> 1001 | AD3: =IF(E3<>"",E3,IF($AC3=$AC2,AD2,IF(AF2<>"",AF2,IF(AD2<>"",AD2,"")))) -> 18 | AE3: =IF(F3<>"",F3,IF($AC3=$AC2,AE2,IF(AG2<>"",AG2,IF(AE2<>"",AE2,"")))) -> 00 | AF3: =IF(G3<>"",G3,IF($AC3=$AC2,AF2,IF(H3="","",AD3))) | AH3: =IF(Y3="x","",IF(Y3=1,"e","o")) -> e | AI3: =IF($J3<>"",$J3,IF($AC3=$AC2,AI2,"")) -> n | AJ3: =IF($J3<>"",$J3,IF($AC3=$AC2,AJ2,"")) -> n | AK3: =IF($W3="","",IF($AI3="","",IF($W3="h",$AI3,IF($AI3="n","n",IF(AND($W3="a",$AI3="d"),"o",IF(AND($W3="a",$AI3="o"),"d")))))) -> n | AL3: =IF($W3="","",IF(J3="","",IF(AK3="n","n",IF(AK3="d","o",IF(AK3="o","d",""))))) -> n | AM3: =IF(AN3="H","Home",IF(AN3="A","Away","")) -> Home | AN3: =IF($W3<>"",$W3,IF($AC3=$AC2,AN2,"")) -> h | AO3: =IF(AK3<>"",AK3,IF($AC3=$AC2,AO2,"")) -> n | AP3: =IF(AL3<>"",AL3,IF($AC3=$AC2,AP2,"")) -> n | AQ3: =IF(AM3<>"",AM3,IF($AC3=$AC2,AQ2,"")) -> Home | AR3: =IF(AN3<>"",AN3,IF($AC3=$AC2,AR2,"")) -> h | AS3: =IF(AND(AH3="e",OR(BD3="Save",BE3="Turnover_Takeaway",BE3="Play_Defensive")),"Defensive",IF(AND(AH3="o",OR(BD3="Save",BE3="Turnover_Takeaway",BE3="Play_Defensive")),"Offensive",IF(OR(BD3="Deadice",BD3="Stoppage",BD3="Intermission"),"",IF(AH3="e","Offensive",IF(AH3="o","Defensive",""))))) -> Offensive | AT3: =IF(U3<>"",U3+5000,"") | AU3: =IF(V3<>"",V3+6000,"") | AV3: {=IFERROR(IF(O3<>"",O3,IF(OR($S3="",$T3=""),"",IF(O3<>"",O3,IF($T3<>"",_xlfn._xlws.FILTER(O:O,($BT:$BT=$BT3)*($I:$I=$I3)*($T:$T=$T3)*($S:$S=_xlfn.MINIFS($S:$S,$T:$T,"="&$T3)),"")))))&"",IF(O3="","",""))&""} | AW3: {=IFERROR(IF(P3<>"",P3,IF(OR($S3="",$T3=""),"",IF($T3<>"",_xlfn._xlws.FILTER(P:P,($BT:$BT=$BT3)*($I:$I=$I3)*($T:$T=$T3)*($S:$S=_xlfn.MINIFS($S:$S,$T:$T,"="&$T3)),""))))&"",IF(P3="","",""))&""} | AX3: {=IFERROR(IF(Q3<>"",Q3,IF(OR($S3="",$T3=""),"",IF($T3<>"",_xlfn._xlws.FILTER(Q:Q,($BT:$BT=$BT3)*($I:$I=$I3)*($T:$T=$T3)*($S:$S=_xlfn.MINIFS($S:$S,$T:$T,"="&$T3)),""))))&"",IF(Q3="","",""))&""} | AY3: {=IFERROR(IF(R3<>"",R3,IF(OR($S3="",$T3=""),"",IF($T3<>"",_xlfn._xlws.FILTER(R:R,($BT:$BT=$BT3)*($I:$I=$I3)*($T:$T=$T3)*($S:$S=_xlfn.MINIFS($S:$S,$T:$T,"="&$T3)),""))))&"",IF(R3="","",""))&""} | AZ3: =IF(OR(L3="Zone_Entry",L3="Zone_Exit"),AZ2+1,AZ2) -> 1 | BA3: =BA2 -> 18969 | BB3: =BB2 -> Platinum | BC3: =BC2 -> Velodrome | BD3: =IF($K3<>"",$K3,IF($S3=$S2,BD2,"")) -> Faceoff | BE3: =IF(L3<>"",L3,IF($S3=$S2,BE2,"")) -> Faceoff_GameStart | BF3: =IF(M3<>"",M3,IF($S3=$S2,BF2,"")) | BG3: =IF($N3<>"",$N3,IF($S3=$S2,BG2,"")) | BH3: {=IFERROR(_xlfn._xlws.FILTER(shifts!A:A,(shifts!B:B=events!Z3)*(shifts!AG:AG>=events!BJ3)*(shifts!AH:AH<=events!BK3)),BH2)} -> 1 | BI3: =IF(AND(AF3="",AG3=""),0,((AD3*60)+AE3)-((AF3*60)+AG3)) -> 0 | BJ3: =(AD3*60)+AE3 -> 1080 | BK3: =IF(AND(AF3="",AG3=""),BJ3,((AF3*60)+AG3)) -> 1080 | BL3: =SUMIFS(BI$2:BI3,K$2:K3,"=Intermission")+SUMIFS(BI$2:BI3,K$2:K3,"=Timeout") -> 0 | BM3: =IF(Z3=1,0,IF(Z3=2,1080+BL3,IF(Z3=3,(1080*2)+BL3,0))) -> 0 | BN3: =IF(K3="Intermission",BN2,((1080)-((AD3*60)+AE3))+BM3) -> 0 | BO3: =IF(BN3<5,0,BN3-5) -> 0 | BP3: =BO3+BI3+5 -> 5 | BQ3: =IF(AH3="e","event_team_player_"&BR3,IF(AH3="o","opp_team_player_"&BR3,"")) -> event_team_player_1 | BR3: =COUNTIFS(S$3:S3,"="&S3,AH$3:AH3,"="&AH3) -> 1 | BS3: =IFERROR(VLOOKUP(BA3&BT3&X3,game_rosters!U:W,3,FALSE),"") -> P100192 | BT3: =IF(AQ3="","",IF(AND(AQ3="Away",AH3="e"),BC3,IF(AND(AQ3="Home",AH3="e"),BB3,IF(AND(AQ3="Away",AH3="o"),BB3,IF(AND(AQ3="Home",AH3="o"),BC3))))) -> Platinum
I4: 21 | N4: =IF(K4="","",IF(K4="Goal","s",IF(AND(K4="Zone_Entry_Exit",OR(ISNUMBER(SEARCH("fail",L4)),ISNUMBER(SEARCH("FromExitClear",M4)),ISNUMBER(SEARCH("miss",M4)))),"u",IF(AND(K4="Zone_Entry_Exit",OR(NOT(ISNUMBER(SEARCH("fail",L4))),NOT(ISNUMBER(SEARCH("FromExitClear",M4))),NOT(ISNUMBER(SEARCH("miss",M4))))),"s",IF(AND(OR(K4="Shot",K4="Pass"),OR(ISNUMBER(SEARCH("complete",L4)),ISNUMBER(SEARCH("goal",L4)),ISNUMBER(SEARCH("OnNet",L4)))),"s",IF(L4="Turnover_Giveaway","u",IF(AND(OR(K4="Shot",K4="Pass"),OR(ISNUMBER(SEARCH("fail",L4)),NOT(ISNUMBER(SEARCH("complete",L4))),NOT(ISNUMBER(SEARCH("OnNet",L4))))),"u",""))))))) | Q4: =IF(O4="","",IF(AND(N4<>"",OR(O4<>"",P4<>"")),N4,IF(OR(ISNUMBER(SEARCH("attemp",O4)),ISNUMBER(SEARCH("mis",O4)),ISNUMBER(SEARCH("fail",O4)),ISNUMBER(SEARCH("loss",O4)),ISNUMBER(SEARCH("lost",O4)),ISNUMBER(SEARCH("attemp",P4)),ISNUMBER(SEARCH("mis",P4)),ISNUMBER(SEARCH("fail",P4)),ISNUMBER(SEARCH("loss",P4)),ISNUMBER(SEARCH("lost",P4))),"u",""))) | S4: =IF(A4=1,MAX($S$2:$S3)+1,IF($I4<>"",$S3,"")) -> 1 | T4: =IF(D4=1,MAX($T$2:$T3)+1,IF(S4=S3,$T3,IF(D4="x",T3,IF(D3="x","","")))) | U4: =IF(B4=1,MAX($U$2:$U3)+1,IF(AND($T4<>"",$T4=$T3),$U3,IF(B4="x",U3,""))) | V4: =IF(C4=1,MAX($V$2:$V3)+1,IF(AND($T4<>"",$T4=$T3),$U3,IF(C4="x",V3,""))) | W4: {=IFERROR(_xlfn._xlws.FILTER(game_rosters!AB:AB,(game_rosters!J:J=events!X4)*(K4<>"")),"")} | X4: {=IF($I4<>"",$I4,INDEX($I:$I,ROW()-COUNTIFS($T:$T,"="&$T4,$S:$S,"<>"&$S4)))} -> 21 | Y4: {=IFERROR(IF(_xlfn._xlws.FILTER(game_rosters!$J:$J,(game_rosters!$G:$G=events!$AM4)*(game_rosters!$J:$J=events!$X4))>0,1,""),"")} -> 1 | Z4: =IF(K4="Intermission",Z3+1,Z3) -> 1 | AA4: =S4+1000 -> 1001 | AB4: =IF(T4<>"",9000+T4,"") | AC4: =IF(AB4<>"",AB4,S4+1000) -> 1001 | AD4: =IF(E4<>"",E4,IF($AC4=$AC3,AD3,IF(AF3<>"",AF3,IF(AD3<>"",AD3,"")))) -> 18 | AE4: =IF(F4<>"",F4,IF($AC4=$AC3,AE3,IF(AG3<>"",AG3,IF(AE3<>"",AE3,"")))) -> 00 | AF4: =IF(G4<>"",G4,IF($AC4=$AC3,AF3,IF(H4="","",AD4))) | AH4: =IF(Y4="x","",IF(Y4=1,"e","o")) -> e | AI4: =IF($J4<>"",$J4,IF($AC4=$AC3,AI3,"")) -> n | AJ4: =IF($J4<>"",$J4,IF($AC4=$AC3,AJ3,"")) -> n | AK4: =IF($W4="","",IF($AI4="","",IF($W4="h",$AI4,IF($AI4="n","n",IF(AND($W4="a",$AI4="d"),"o",IF(AND($W4="a",$AI4="o"),"d")))))) | AL4: =IF($W4="","",IF(J4="","",IF(AK4="n","n",IF(AK4="d","o",IF(AK4="o","d",""))))) | AM4: =IF(AN4="H","Home",IF(AN4="A","Away","")) -> Home | AN4: =IF($W4<>"",$W4,IF($AC4=AC3,AN3,"")) -> h | AO4: =IF(AK4<>"",AK4,IF($AC4=AC3,AO3,"")) -> n | AP4: =IF(AL4<>"",AL4,IF($AC4=AC3,AP3,"")) -> n | AQ4: =IF(AM4<>"",AM4,IF($AC4=#REF!,#REF!,"")) -> Home | AR4: =IF(AN4<>"",AN4,IF($AC4=AC3,AQ3,"")) -> h | AS4: =IF(AND(AH4="e",OR(BD4="Save",BE4="Turnover_Takeaway",BE4="Play_Defensive")),"Defensive",IF(AND(AH4="o",OR(BD4="Save",BE4="Turnover_Takeaway",BE4="Play_Defensive")),"Offensive",IF(OR(BD4="Deadice",BD4="Stoppage",BD4="Intermission"),"",IF(AH4="e","Offensive",IF(AH4="o","Defensive",""))))) -> Offensive | AT4: =IF(U4<>"",U4+5000,"") | AU4: =IF(V4<>"",V4+6000,"") | AV4: {=IFERROR(IF(O4<>"",O4,IF(OR($S4="",$T4=""),"",IF(O4<>"",O4,IF($T4<>"",_xlfn._xlws.FILTER(O:O,($BT:$BT=$BT4)*($I:$I=$I4)*($T:$T=$T4)*($S:$S=_xlfn.MINIFS($S:$S,$T:$T,"="&$T4)),"")))))&"",IF(O4="","",""))&""} | AW4: {=IFERROR(IF(P4<>"",P4,IF(OR($S4="",$T4=""),"",IF($T4<>"",_xlfn._xlws.FILTER(P:P,($BT:$BT=$BT4)*($I:$I=$I4)*($T:$T=$T4)*($S:$S=_xlfn.MINIFS($S:$S,$T:$T,"="&$T4)),""))))&"",IF(P4="","",""))&""} | AX4: {=IFERROR(IF(Q4<>"",Q4,IF(OR($S4="",$T4=""),"",IF($T4<>"",_xlfn._xlws.FILTER(Q:Q,($BT:$BT=$BT4)*($I:$I=$I4)*($T:$T=$T4)*($S:$S=_xlfn.MINIFS($S:$S,$T:$T,"="&$T4)),""))))&"",IF(Q4="","",""))&""} | AY4: {=IFERROR(IF(R4<>"",R4,IF(OR($S4="",$T4=""),"",IF($T4<>"",_xlfn._xlws.FILTER(R:R,($BT:$BT=$BT4)*($I:$I=$I4)*($T:$T=$T4)*($S:$S=_xlfn.MINIFS($S:$S,$T:$T,"="&$T4)),""))))&"",IF(R4="","",""))&""} | BF4: =IF(M4<>"",M4,IF($S4=$S3,BF3,"")) | BG4: =IF($N4<>"",$N4,IF($S4=$S3,BG3,"")) | BH4: {=IFERROR(_xlfn._xlws.FILTER(shifts!A:A,(shifts!B:B=events!Z4)*(shifts!AG:AG>=events!BJ4)*(shifts!AH:AH<=events!BK4)),BH3)} -> 1 | BI4: =IF(AND(AF4="",AG4=""),0,((AD4*60)+AE4)-((AF4*60)+AG4)) -> 0 | BJ4: =(AD4*60)+AE4 -> 1080 | BK4: =IF(AND(AF4="",AG4=""),BJ4,((AF4*60)+AG4)) -> 1080 | BL4: =SUMIFS(BI$2:BI4,K$2:K4,"=Intermission")+SUMIFS(BI$2:BI4,K$2:K4,"=Timeout") -> 0 | BM4: =IF(Z4=1,0,IF(Z4=2,1080+BL4,IF(Z4=3,(1080*2)+BL4,0))) -> 0 | BN4: =IF(K4="Intermission",BN3,((1080)-((AD4*60)+AE4))+BM4) -> 0 | BO4: =IF(BN4<5,0,BN4-5) -> 0 | BP4: =BO4+BI4+5 -> 5 | BQ4: =IF(AH4="e","event_team_player_"&BR4,IF(AH4="o","opp_team_player_"&BR4,"")) -> event_team_player_2 | BR4: =COUNTIFS(S$3:S4,"="&S4,AH$3:AH4,"="&AH4) -> 2 | BS4: =IFERROR(VLOOKUP(BA4&BT4&X4,game_rosters!U:W,3,FALSE),"") | BT4: =IF(AQ4="","",IF(AND(AQ4="Away",AH4="e"),BC4,IF(AND(AQ4="Home",AH4="e"),BB4,IF(AND(AQ4="Away",AH4="o"),BB4,IF(AND(AQ4="Home",AH4="o"),BC4))))) -> 0
A5: =IF(K5<>"",1,IF(D5="x","x","")) | J5: =IF(OR(K5="Goal",K5="Shot",L5="Zone_Entry",M5="Stoppage-Goal",M4="Stoppage-Goal"),"o",IF(OR(K5="Save",K5="Rebound",L5="Zone_Exit",M5="Stoppage-GoalieStoppage",M4="Stoppage-GoalieStoppage"),"d",IF(OR(L5="Faceoff_AfterGoal",L5="Faceoff_PeriodStart",698="Faceoff_GameStart",M4="Stoppage-Goal"),"n",""))) | N5: =IF(K5="","",IF(K5="Goal","s",IF(AND(K5="Zone_Entry_Exit",OR(ISNUMBER(SEARCH("fail",L5)),ISNUMBER(SEARCH("FromExitClear",M5)),ISNUMBER(SEARCH("miss",M5)))),"u",IF(AND(K5="Zone_Entry_Exit",OR(NOT(ISNUMBER(SEARCH("fail",L5))),NOT(ISNUMBER(SEARCH("FromExitClear",M5))),NOT(ISNUMBER(SEARCH("miss",M5))))),"s",IF(AND(OR(K5="Shot",K5="Pass"),OR(ISNUMBER(SEARCH("complete",L5)),ISNUMBER(SEARCH("goal",L5)),ISNUMBER(SEARCH("OnNet",L5)))),"s",IF(L5="Turnover_Giveaway","u",IF(AND(OR(K5="Shot",K5="Pass"),OR(ISNUMBER(SEARCH("fail",L5)),NOT(ISNUMBER(SEARCH("complete",L5))),NOT(ISNUMBER(SEARCH("OnNet",L5))))),"u",""))))))) | Q5: =IF(O5="","",IF(AND(N5<>"",OR(O5<>"",P5<>"")),N5,IF(OR(ISNUMBER(SEARCH("attemp",O5)),ISNUMBER(SEARCH("beat",O5)),ISNUMBER(SEARCH("mis",O5)),ISNUMBER(SEARCH("fail",O5)),ISNUMBER(SEARCH("loss",O5)),ISNUMBER(SEARCH("lost",O5)),ISNUMBER(SEARCH("attemp",P5)),ISNUMBER(SEARCH("mis",P5)),ISNUMBER(SEARCH("fail",P5)),ISNUMBER(SEARCH("loss",P5)),ISNUMBER(SEARCH("beat",P5)),ISNUMBER(SEARCH("lost",P5))),"u",""))) | S5: =IF(A5=1,MAX(S$2:S4)+1,IF(OR(I5<>"",A5="x"),#REF!,"")) | T5: =IF(D5=1,MAX($T$2:$T4)+1,IF(S5=$S4,$S4,IF($D5="x",T4,IF($D4="x","","")))) | U5: =IF(B5=1,MAX($U$2:$U4)+1,IF(AND($T5<>"",$T5=$T4),$U4,IF(B5="x",U4,""))) | V5: =IF(C5=1,MAX($V$2:$V4)+1,IF(AND($T5<>"",$T5=$T4),$U4,IF(C5="x",V4,""))) | W5: {=IFERROR(_xlfn._xlws.FILTER(game_rosters!AB:AB,(game_rosters!J:J=events!X5)*(K5<>"")),"")} | X5: {=IF(S5="","",IF($I5<>"",$I5,INDEX($I$2:$I4,ROW()-COUNTIFS($T$2:$T4,"="&$T5,$S$2:$S4,"<>"&$S5)-1)))} | AH5: =IF(Y5="x","",IF(Y5=1,"e","o")) -> o | AI5: =IF($J5<>"",$J5,IF($AC5=$AC4,AI4,"")) | AJ5: =IF($J5<>"",$J5,IF($AC5=AC4,AJ4,"")) | AK5: =IF($W5="","",IF($AI5="","",IF($W5="h",$AI5,IF($AI5="n","n",IF(AND($W5="a",$AI5="d"),"o",IF(AND($W5="a",$AI5="o"),"d")))))) | AL5: =IF($W5="","",IF(J5="","",IF(AK5="n","n",IF(AK5="d","o",IF(AK5="o","d",""))))) | AM5: =IF(AN5="H","Home",IF(AN5="A","Away","")) | AN5: =IF($W5<>"",$W5,IF($AC5=AC4,AN4,"")) | AO5: =IF(AK5<>"",AK5,IF($AC5=AC4,AO4,"")) | AP5: =IF(AL5<>"",AL5,IF($AC5=AC4,AP4,"")) | AQ5: =IF(AM5<>"",AM5,IF($AC5=AC4,AQ4,"")) | AR5: =IF(AN5<>"",AN5,IF($AC5=AC4,AQ4,"")) | AS5: =IF(AND(AH5="e",OR(BD5="Save",BE5="Turnover_Takeaway",BE5="Play_Defensive")),"Defensive",IF(AND(AH5="o",OR(BD5="Save",BE5="Turnover_Takeaway",BE5="Play_Defensive")),"Offensive",IF(OR(BD5="Deadice",BD5="Stoppage",BD5="Intermission"),"",IF(AH5="e","Offensive",IF(AH5="o","Defensive",""))))) -> Defensive
A6: =IF(K6<>"",1,IF(D6="x","x","")) | J6: =IF(OR(K6="Goal",K6="Shot",L6="Zone_Entry",M6="Stoppage-Goal",M5="Stoppage-Goal"),"o",IF(OR(K6="Save",K6="Rebound",L6="Zone_Exit",M6="Stoppage-GoalieStoppage",M5="Stoppage-GoalieStoppage"),"d",IF(OR(L6="Faceoff_AfterGoal",L6="Faceoff_PeriodStart",698="Faceoff_GameStart",M5="Stoppage-Goal"),"n",""))) | N6: =IF(K6="","",IF(K6="Goal","s",IF(AND(K6="Zone_Entry_Exit",OR(ISNUMBER(SEARCH("fail",L6)),ISNUMBER(SEARCH("FromExitClear",M6)),ISNUMBER(SEARCH("miss",M6)))),"u",IF(AND(K6="Zone_Entry_Exit",OR(NOT(ISNUMBER(SEARCH("fail",L6))),NOT(ISNUMBER(SEARCH("FromExitClear",M6))),NOT(ISNUMBER(SEARCH("miss",M6))))),"s",IF(AND(OR(K6="Shot",K6="Pass"),OR(ISNUMBER(SEARCH("complete",L6)),ISNUMBER(SEARCH("goal",L6)),ISNUMBER(SEARCH("OnNet",L6)))),"s",IF(L6="Turnover_Giveaway","u",IF(AND(OR(K6="Shot",K6="Pass"),OR(ISNUMBER(SEARCH("fail",L6)),NOT(ISNUMBER(SEARCH("complete",L6))),NOT(ISNUMBER(SEARCH("OnNet",L6))))),"u",""))))))) | Q6: =IF(O6="","",IF(AND(N6<>"",OR(O6<>"",P6<>"")),N6,IF(OR(ISNUMBER(SEARCH("attemp",O6)),ISNUMBER(SEARCH("beat",O6)),ISNUMBER(SEARCH("mis",O6)),ISNUMBER(SEARCH("fail",O6)),ISNUMBER(SEARCH("loss",O6)),ISNUMBER(SEARCH("lost",O6)),ISNUMBER(SEARCH("attemp",P6)),ISNUMBER(SEARCH("mis",P6)),ISNUMBER(SEARCH("fail",P6)),ISNUMBER(SEARCH("loss",P6)),ISNUMBER(SEARCH("beat",P6)),ISNUMBER(SEARCH("lost",P6))),"u",""))) | S6: =IF(A6=1,MAX(S$2:S5)+1,IF(OR(I6<>"",A6="x"),S5,"")) | T6: =IF(D6=1,MAX($T$2:$T5)+1,IF(S6=$S5,$S5,IF($D6="x",T5,IF($D5="x","","")))) | U6: =IF(B6=1,MAX($U$2:$U5)+1,IF(AND($T6<>"",$T6=$T5),$U5,IF(B6="x",U5,""))) | V6: =IF(C6=1,MAX($V$2:$V5)+1,IF(AND($T6<>"",$T6=$T5),$U5,IF(C6="x",V5,""))) | W6: {=IFERROR(_xlfn._xlws.FILTER(game_rosters!AB:AB,(game_rosters!J:J=events!X6)*(K6<>"")),"")} | X6: {=IF(S6="","",IF($I6<>"",$I6,INDEX($I$2:$I5,ROW()-COUNTIFS($T$2:$T5,"="&$T6,$S$2:$S5,"<>"&$S6)-1)))} | AH6: =IF(Y6="x","",IF(Y6=1,"e","o")) -> o | AI6: =IF($J6<>"",$J6,IF($AC6=$AC5,AI5,"")) | AJ6: =IF($J6<>"",$J6,IF($AC6=AC5,AJ5,"")) | AK6: =IF($W6="","",IF($AI6="","",IF($W6="h",$AI6,IF($AI6="n","n",IF(AND($W6="a",$AI6="d"),"o",IF(AND($W6="a",$AI6="o"),"d")))))) | AL6: =IF($W6="","",IF(J6="","",IF(AK6="n","n",IF(AK6="d","o",IF(AK6="o","d",""))))) | AM6: =IF(AN6="H","Home",IF(AN6="A","Away","")) | AN6: =IF($W6<>"",$W6,IF($AC6=AC5,AN5,"")) | AO6: =IF(AK6<>"",AK6,IF($AC6=AC5,AO5,"")) | AP6: =IF(AL6<>"",AL6,IF($AC6=AC5,AP5,"")) | AQ6: =IF(AM6<>"",AM6,IF($AC6=AC5,AQ5,"")) | AR6: =IF(AN6<>"",AN6,IF($AC6=AC5,AQ5,"")) | AS6: =IF(AND(AH6="e",OR(BD6="Save",BE6="Turnover_Takeaway",BE6="Play_Defensive")),"Defensive",IF(AND(AH6="o",OR(BD6="Save",BE6="Turnover_Takeaway",BE6="Play_Defensive")),"Offensive",IF(OR(BD6="Deadice",BD6="Stoppage",BD6="Intermission"),"",IF(AH6="e","Offensive",IF(AH6="o","Defensive",""))))) -> Defensive
