Workbook
Name EventType: Lists!$A$2:$A$16
Name Faceoff: Lists!$U$2:$U$1048576
Name Goal: Lists!$X$2:$X$1048576
Name Goal_PenaltyShot: Lists!$BO$2:$BO$1048576
Name Goal_Scored: Lists!$BM$2:$BM$1048576
Name Goal_Shootout: Lists!$BN$2:$BN$1048576
Name LoosePuck: Lists!$AD$2:$AD$1048576
Name Pass: Lists!$W$2:$W$1048576
Name Pass_Completed: Lists!$AF$2:$AF$1048576
Name Pass_Deflected: Lists!$AH$2:$AH$1048576
Name Pass_Intercepted: Lists!$AI$2:$AI$1048576
Name Pass_Missed: Lists!$AG$2:$AG$1048576
Name Penalty: Lists!$AA$2:$AA$1048576
Name Penalty_Major: Lists!$AO$2:$AO$1048576
Name Penalty_Minor: Lists!$AP$2:$AP$1048576
Name Penalty_Offsetting: Lists!$AQ$2:$AQ$1048576
Name PenaltyShot_Missed: Lists!$AY$2:$AY$1048576
Name PenaltyShot_OnNet: Lists!$AX$2:$AX$1048576
Name PenaltyShot_Saved: Lists!$AZ$2:$AZ$1048576
Name PenaltyShot_Shootout: Lists!$AB$2:$AB$1048576
Name Play: Lists!$T:$T
Name Play_Defensive: Lists!$BS:$BS
Name Play_Offensive: Lists!$BR:$BR
Name Rebound: Lists!$BQ$2:$BQ$1048576
Name Save: Lists!$AE$2:$AE$1048576
Name Save_Freeze: Lists!$BB$2:$BB$1048576
Name Save_Played: Lists!$BP:$BP
Name Save_Rebound: Lists!$BA$2:$BA$1048576
Name Shootout_Missed: Lists!$AV$2:$AV$1048576
Name Shootout_OnNet: Lists!$AU$2:$AU$1048576
Name Shootout_Saved: Lists!$AW$2:$AW$1048576
Name Shot: Lists!$V$2:$V$1048576
Name Shot_Blocked: Lists!$BE$2:$BE$1048576
Name Shot_BlockedSameTeam: Lists!$BF$2:$BF$1048576
Name Shot_Deflected: Lists!$BG$2:$BG$1048576
Name Shot_DeflectedGoal: Lists!$BL$2:$BL$1048576
Name Shot_DeflectedOnNetSaved: Lists!$BH$2:$BH$1048576
Name Shot_Missed: Lists!$BD$2:$BD$1048576
Name Shot_OnNetGoal: Lists!$BJ$2:$BJ$1048576
Name Shot_OnNetSaved: Lists!$BC$2:$BC$1048576
Name Shot_TippedGoal: Lists!$BK$2:$BK$1048576
Name Shot_TippedOnNetSaved: Lists!$BI$2:$BI$1048576
Name Stoppage: Lists!$AC$2:$AC$1048576
Name Stoppage_Other: Lists!$AT$2:$AT$1048576
Name Stoppage_Period: Lists!$AS$2:$AS$1048576
Name Stoppage_Play: Lists!$AR$2:$AR$1048576
Name Turnover: Lists!$Y$2:$Y$1048576
Name Turnover_Giveaway: Lists!$AJ$2:$AJ$1048576
Name Turnover_Takeaway: Lists!$AK$2:$AK$1048576
Name Zone_Entry: Lists!$AL$2:$AL$1048576
Name Zone_Entry_Exit: Lists!$Z$2:$Z$1048576
Name Zone_Exit: Lists!$AM$2:$AM$1048576
Name Zone_Keepin: Lists!$AN$2:$AN$1048576

Sheet Rules
A1: Play | B1: NextPlay | C1: EventPlayers | D1: OppPlayers | E1: OnIcePlayers | I1: SequecnceDefinition | J1: Loose puck to loose puck
A2: Goal | B2: Stoppage | C2: Scorer | D2: Goalie, Defenders in Front | E2: All
A3: Stoppage | B3: Faceoff | C3: Winner, Next Player to Touch | D3: Loser | E3: None | I3: PlayDefinition | J3: Series of possession, passes that lead to shot or zone entry/exit
A4: Pass_Intercepted, Pass/ShotMissed Other Team Possession | B4: Turnover | C4: Passer/Shooter, Intended Recipient | D4: Intercepteor/Blocker | E4: In Play
A5: Turnover | B5: ChangePossession | C5: Player who turned over | D5: Player who received turnover | E5: In Play
A6: ShotSaved | B6: Save
A9: Zone breakout pass also add pass
A10: Turnover (any kind) also add pass/shot/etc
A11: Zone dumoin/clear that results in turnover list both

Sheet Lists
A1: EventType | C1: EventTypeDetail | E1: EventTypeDetail2 | G1: OffensivePlay | I1: DefensivePlay | K1: Team | N1: NHL Net | O1: Max | P1: Min | Q1: Total Max | R1: Total Min | T1: Play | U1: Faceoff | V1: Shot | W1: Pass | X1: Goal | Y1: Turnover | Z1: Zone Entry/Exit | AA1: Penalty | AB1: PenaltyShot/Shootout | AC1: Stoppage | AD1: LoosePuck | AE1: Save | AF1: Pass-Completed | AG1: Pass-Missed | AH1: Pass-Deflected | AI1: Pass-Intercepted | AJ1: Turnover-Giveaway | AK1: Turnover-Takeaway | AL1: Zone-Entry | AM1: Zone-Exit | AN1: Zone-Keepin | AO1: Penalty-Major | AP1: Penalty-Minor | AQ1: Penalty-Offsetting | AR1: Stoppage-Play | AS1: Stoppage-Period | AT1: Stoppage-Other | AU1: Shootout-OnNet | AV1: Shootout-Missed | AW1: Shootout-Saved | AX1: PenaltyShot-OnNet | AY1: PenaltyShot-Missed | AZ1: PenaltyShot-Saved | BA1: Save-Rebound | BB1: Save-Freeze | BC1: Shot_OnNetSaved | BD1: Shot_Missed | BE1: Shot_Blocked | BF1: Shot_BlockedSameTeam | BG1: Shot_Deflected | BH1: Shot_DeflectedOnNetSaved | BI1: Shot_TippedOnNetSaved | BJ1: Shot_OnNetGoal | BK1: Shot_TippedGoal | BL1: Shot_DeflectedGoal | BM1: Goal_Scored | BN1: Goal_Shootout | BO1: Goal_PenaltyShot | BP1: Save_Played | BQ1: Rebound | BR1: Play_Offensive | BS1: Play_Defensive | BU1: Faceoff | BV1: None | CA1: shift_start | CC1: shift_end
K2: Home | L2: =K3 -> Away | N2: X | O2: 36 | P2: -36 | Q2: =O2+O4 -> 38.375 | R2: =P2-O4 -> -38.375 | T2: Play_Offensive | U2: Faceoff_AfterPenalty | V2: Shot_OnNetSaved | W2: Pass_Completed | X2: Goal_Scored | Y2: Turnover_Giveaway | Z2: Zone_Entry | AA2: Penalty_Minor | AB2: PenaltyShot_OnNet | AC2: Stoppage_Period | AD2: LoosePuck_Forecheck | AE2: Save_Rebound | AF2: Pass-Stretch | AG2: Pass-Stretch | AH2: Pass-Stretch | AI2: Pass-Stretch | AJ2: Giveaway-Misplayed | AK2: Takeaway-BattleWon | AL2: ZoneEntry-Rush | AM2: ZoneExit-Rush | AN2: Zone-KeepIn | AO2: Penalty-Bench Penalty | AP2: Penalty-Bench Penalty | AQ2: Penalty-Bench Penalty | AR2: Stoppage-Icing | AS2: Stoppage-StartofShootout | AT2: Stoppage-ObjectsonIce | AU2: Shot-Wrist | AV2: Shot-Wrist | AW2: Shot-Wrist | AX2: Shot-Wrist | AY2: Shot-Wrist | AZ2: Shot-Wrist | BA2: Save-Glove | BB2: Save-Glove | BC2: Shot-Wrist | BD2: Shot-Wrist | BE2: Shot-Wrist | BF2: Shot-Wrist | BG2: Shot-Deflection | BH2: Shot-Deflection | BI2: Shot-Tip | BJ2: Shot-Wrist | BL2: Shot-Deflection | BM2: Goal-Wrist | BN2: Goal-Wrist | BO2: Goal-Wrist | BP2: Save-Glove | BQ2: Rebound_TeamRecovered | BU2: Shot | BV2: All | BX2: event_team_player_1 | BY2: e | CA2: PeriodStart | CC2: -
A3: Faceoff | B3: None | C3: Faceoff | E3: Shot-Wrist | G3: DriveMiddle | I3: PokeCheck | K3: Away | L3: =K2 -> Home | N3: Y | O3: 24 | P3: -24 | Q3: =O3+O5 -> 26.375 | R3: -24 | T3: Play_Defensive | U3: Faceoff_AfterGoal | V3: Shot_Missed | W3: Pass_Missed | X3: Goal_Shootout | Y3: Turnover_Takeaway | Z3: Zone_Exit | AA3: Penalty_Offsetting | AB3: PenaltyShot_Missed | AC3: Stoppage_Play | AD3: LoosePuck_Battle | AE3: Save_Freeze | AF3: Pass-Rim/Wrap | AG3: Pass-Rim/Wrap | AH3: Pass-Rim/Wrap | AI3: Pass-Rim/Wrap | AJ3: Giveaway-BattleLost | AK3: Takeaway-PokeCheck | AL3: ZoneEntry-Pass | AM3: ZoneExit-Pass | AN3: Zone-Pinch | AO3: Penalty-Boarding | AP3: Penalty-Boarding | AQ3: Penalty-Boarding | AR3: Stoppage-Offsides | AS3: Stoppage-PeriodStart | AT3: Stoppage-HomeTimeout | AU3: Shot-Slap | AV3: Shot-Slap | AW3: Shot-Slap | AX3: Shot-Slap | AY3: Shot-Slap | AZ3: Shot-Slap | BA3: Save-Blocker | BB3: Save-Blocker | BC3: Shot-Slap | BD3: Shot-Slap | BE3: Shot-Slap | BF3: Shot-Slap | BG3: Shot-Wrist | BH3: Shot-Wrist | BI3: Shot-Wrist | BJ3: Shot-Slap | BK3: Shot-Wrist | BL3: Shot-Wrist | BM3: Goal-Slap | BN3: Goal-Slap | BO3: Goal-Slap | BP3: Save-Blocker | BQ3: Rebound_OppTeamRecovered | BR3: DriveMiddle | BS3: PokeCheck | BU3: Pass | BV3: Involved | BX3: event_team_player_2 | BY3: o | CA3: FaceoffAfterGoal | CC3: Period Start
A4: Shot | C4: Faceoff-AfterPenalty | E4: Shot-Slap | G4: DriveWide | I4: PokeCheckFailed | N4: PostX | O4: 2.375 | U4: Faceoff_PeriodStart | V4: Shot_Blocked | W4: Pass_Deflected | X4: Goal_PenaltyShot | Z4: Zone_Keepin | AA4: Penalty_Major | AB4: PenaltyShot_Saved | AC4: Stoppage_Other | AE4: Save_Played | AF4: Pass-Backhand | AG4: Pass-Backhand | AH4: Pass-Backhand | AI4: Pass-Backhand | AJ4: Giveaway-PassIntercepted | AK4: Takeaway-PassIntercepted | AL4: ZoneEntry-DumpIn | AM4: ZoneExit-Clear | AN4: Zone-Other | AO4: Penalty-Charging | AP4: Penalty-Charging | AQ4: Penalty-Charging | AR4: Stoppage-ClockProblem | AS4: Stoppage-PeriodEnd | AT4: Stoppage-VisitorTimeout | AU4: Shot-Backhand | AV4: Shot-Backhand | AW4: Shot-Backhand | AX4: Shot-Backhand | AY4: Shot-Backhand | AZ4: Shot-Backhand | BA4: Save-LeftPad | BB4: Save-LeftPad | BC4: Shot-Backhand | BD4: Shot-Backhand | BE4: Shot-Backhand | BF4: Shot-Backhand | BG4: Shot-Slap | BH4: Shot-Slap | BI4: Shot-Slap | BJ4: Shot-Backhand | BK4: Shot-Slap | BL4: Shot-Slap | BM4: Goal-Backhand | BN4: Goal-Backhand | BO4: Goal-Backhand | BP4: Save-LeftPad | BQ4: Rebound_ShotGenerated | BR4: DriveWide | BS4: PokeCheckFailed | BU4: Goal | BV4: All | BX4: event_team_player_3 | CA4: GameStart | CC4: Period End
A5: Pass | C5: Faceoff-AfterGoal | E5: Shot-Backhand | G5: DriveCorner | I5: SeperateFromPuck | N5: PostY | O5: 2.375 | U5: Faceoff_AfterStoppage | V5: Shot_BlockedSameTeam | W5: Pass_Intercepted | AB5: ShootoutShot_OnNet | AC5: Stoppage_GameEnd | AF5: Pass-Forehand | AG5: Pass-Forehand | AH5: Pass-Forehand | AI5: Pass-Forehand | AJ5: Giveaway-PassMissed | AK5: Takeaway-PassBlocked | AL5: ZoneEntry-Chip | AM5: ZoneExit-Chip | AO5: Penalty-CrossChecking | AP5: Penalty-CrossChecking | AQ5: Penalty-CrossChecking | AR5: Stoppage-HighStick | AT5: Stoppage-RinkRepair | AU5: Shot-Snap | AV5: Shot-Snap | AW5: Shot-Snap | AX5: Shot-Snap | AY5: Shot-Snap | AZ5: Shot-Snap | BA5: Save-RightPad | BB5: Save-RightPad | BC5: Shot-Snap | BD5: Shot-Snap | BE5: Shot-Snap | BF5: Shot-Snap | BG5: Shot-Backhand | BH5: Shot-Backhand | BI5: Shot-Backhand | BJ5: Shot-Snap | BK5: Shot-Backhand | BL5: Shot-Backhand | BM5: Goal-Tip | BN5: Goal-Snap | BO5: Goal-Snap | BP5: Save-RightPad | BQ5: Rebound_FlurryGenerated | BR5: DriveCorner | BS5: SeperateFromPuck | BU5: Turnover | BV5: Involved | BX5: event_team_player_4 | CA5: FaceoffAfterPenalty | CC5: Puck Out of Play
A6: Goal | C6: Faceoff-PeriodStart | E6: Shot-Tip | G6: DriveNetMiddle | I6: Backcheck | U6: Faceoff_GameStart | V6: Shot_Deflected | AB6: ShootoutShot_Missed | AF6: Pass-Bank | AG6: Pass-Bank | AH6: Pass-Bank | AI6: Pass-Bank | AJ6: Giveaway-PassBlocked | AK6: Takeaway-ShotBlocked | AL6: ZoneEntry-FromExitClear | AM6: ZoneExit-PassMiss/Misplay | AO6: Penalty-DelayofGame | AP6: Penalty-DelayofGame | AQ6: Penalty-DelayofGame | AR6: Stoppage-HandPass | AT6: Stoppage-PlayerEquipment | AU6: Shot-WrapAround | AV6: Shot-WrapAround | AW6: Shot-WrapAround | AX6: Shot-WrapAround | AY6: Shot-WrapAround | AZ6: Shot-WrapAround | BA6: Save-Stick | BB6: Save-Stick | BC6: Shot-WrapAround | BD6: Shot-WrapAround | BE6: Shot-WrapAround | BF6: Shot-WrapAround | BG6: Shot-Snap | BH6: Shot-Snap | BI6: Shot-Snap | BJ6: Shot-WrapAround | BK6: Shot-Snap | BL6: Shot-Snap | BM6: Goal-Snap | BN6: Goal-WrapAround | BO6: Goal-WrapAround | BP6: Save-Stick | BR6: DriveNetMiddle | BS6: Backcheck | BU6: Zone_Entry_Exit | BV6: Involved | BX6: event_team_player_5 | CA6: OtherFaceoff | CC6: Injury
A7: Turnover | C7: Shot-OnNet | E7: Shot-Snap | G7: DriveNetWide | I7: FroceWide | V7: Shot_DeflectedOnNetSaved | AB7: ShootoutShot_Saved | AF7: Pass-Dump | AG7: Pass-Dump | AH7: Pass-Dump | AI7: Pass-Dump | AJ7: Giveaway-ShotBlocked | AK7: Takeaway-ZoneClear/Dump | AL7: ZoneEntry-PassMiss/Misplay | AM7: ZoneExit-OppTeam | AO7: Penalty-Diving | AP7: Penalty-Diving | AQ7: Penalty-Diving | AR7: Stoppage-NetDislodged | AT7: Stoppage-Challenge | AU7: Shot-Bat | AV7: Shot-Bat | AW7: Shot-Bat | AX7: Shot-Bat | AY7: Shot-Bat | AZ7: Shot-Bat | BA7: Save-Scramble | BB7: Save-Scramble | BC7: Shot-Bat | BD7: Shot-Bat | BE7: Shot-Bat | BF7: Shot-Bat | BG7: Shot-WrapAround | BH7: Shot-WrapAround | BI7: Shot-WrapAround | BJ7: Shot-Bat | BK7: Shot-WrapAround | BL7: Shot-WrapAround | BM7: Goal-WrapAround | BN7: Goal-Bat | BO7: Goal-Bat | BP7: Save-Scramble | BR7: DriveNetWide | BS7: FroceWide | BU7: Penalty | BV7: Involved | BX7: event_team_player_6 | CA7: DeadIce/Stoppage | CC7: Home Penalty
A8: Zone_Entry_Exit | C8: Shot-Missed | E8: Shot-WrapAround | G8: CrashNet | I8: Contain | V8: Shot_Tipped | AF8: Pass-Tipped | AG8: Pass-Tipped | AH8: Pass-Tipped | AI8: Pass-Tipped | AJ8: Giveaway-ShotMissed | AK8: Takeaway-AttemptedZoneClear/Dump | AL8: ZoneEntry-OppTeam | AM8: ZoneExit-Lob | AO8: Penalty-Elbowing | AP8: Penalty-Elbowing | AQ8: Penalty-Elbowing | AR8: Stoppage-Injury | AT8: Stoppage-Other | AU8: Shot-Cradle | AV8: Shot-Cradle | AW8: Shot-Cradle | AX8: Shot-Cradle | AY8: Shot-Cradle | AZ8: Shot-Cradle | BA8: Save-Butterfly | BB8: Save-Butterfly | BC8: Shot-Cradle | BD8: Shot-Cradle | BE8: Shot-Cradle | BF8: Shot-Cradle | BG8: Shot-Bat | BH8: Shot-Bat | BI8: Shot-Bat | BJ8: Shot-Cradle | BK8: Shot-Bat | BL8: Shot-Bat | BM8: Goal-Bat | BN8: Goal-Cradle | BO8: Goal-Cradle | BP8: Save-Butterfly | BR8: CrashNet | BS8: Contain | BU8: PenaltyShot_Shootout | BV8: Involved | BX8: opp_team_player_1 | CA8: Intermission | CC8: Away Penalty
A9: Penalty | C9: Shot-Blocked | E9: Shot-Bat | G9: Delay | I9: BeatMiddle | V9: Shot_TippedOnNetSaved | AF9: Pass-Lob | AG9: Pass-Lob | AH9: Pass-Lob | AI9: Pass-Lob | AJ9: Giveaway-ZoneClear/Dump | AK9: Takeaway-Other | AL9: ZoneEntry-Lob | AM9: ZoneExit-Other | AO9: Penalty-GoalieInterference | AP9: Penalty-GoalieInterference | AQ9: Penalty-GoalieInterference | AR9: Stoppage-GoalieStoppage | AU9: Shot-Poke | AV9: Shot-Poke | AW9: Shot-Poke | AX9: Shot-Poke | AY9: Shot-Poke | AZ9: Shot-Poke | BA9: Save-Chest | BB9: Save-Chest | BC9: Shot-Poke | BD9: Shot-Poke | BE9: Shot-Poke | BF9: Shot-Poke | BG9: Shot-Cradle | BH9: Shot-Cradle | BI9: Shot-Cradle | BJ9: Shot-Poke | BK9: Shot-Cradle | BL9: Shot-Cradle | BM9: Goal-Cradle | BN9: Goal-Poke | BO9: Goal-Poke | BP9: Save-Chest | BR9: Delay | BS9: BeatMiddle | BU9: Stoppage | BV9: None | BX9: opp_team_player_2 | CC9: Home Goalie Stoppage
A10: PenaltyShot_Shootout | C10: Shot-BlockedSameTeam | E10: Shot-Cradle | G10: Deke | I10: BeatWide | V10: Shot_OnNetGoal | AF10: Pass-Drop | AG10: Pass-Drop | AH10: Pass-Drop | AI10: Pass-Drop | AJ10: Giveaway-AttemptedZoneClear/Dump | AL10: ZoneEntry-RushBreakaway | AO10: Penalty-HighSticking | AP10: Penalty-HighSticking | AQ10: Penalty-HighSticking | AR10: Stoppage-PuckOutofPlay | AU10: Shot-BetweenLegs | AV10: Shot-BetweenLegs | AW10: Shot-BetweenLegs | AX10: Shot-BetweenLegs | AY10: Shot-BetweenLegs | AZ10: Shot-BetweenLegs | BA10: Save-Other | BB10: Save-Other | BC10: Shot-BetweenLegs | BD10: Shot-BetweenLegs | BE10: Shot-BetweenLegs | BF10: Shot-BetweenLegs | BG10: Shot-Poke | BH10: Shot-Poke | BI10: Shot-Poke | BJ10: Shot-BetweenLegs | BK10: Shot-Poke | BL10: Shot-Poke | BM10: Goal-Poke | BN10: Goal-BetweenLegs | BO10: Goal-BetweenLegs | BP10: Save-Other | BR10: Deke | BS10: BeatWide | BU10: Hit | BV10: Involved | BX10: opp_team_player_3 | CC10: Away Goalie Stoppage
A11: Stoppage | C11: Shot-Deflected | E11: Shot-Poke | G11: Chip | I11: BeatDeke | V11: Shot_OnNetTippedGoal | AF11: Pass-Other | AG11: Pass-Other | AH11: Pass-Other | AI11: Pass-Other | AJ11: Giveaway-ZoneEntry/ExitMisplay | AL11: ZoneEntry-Other | AO11: Penalty-Holding | AP11: Penalty-Holding | AQ11: Penalty-Holding | AR11: Stoppage-Penalty | AU11: Shot-Other | AV11: Shot-Other | AW11: Shot-Other | AX11: Shot-Other | AY11: Shot-Other | AZ11: Shot-Other | BC11: Shot-Dumpin | BD11: Shot-Dumpin | BE11: Shot-Dumpin | BF11: Shot-Dumpin | BG11: Shot-BetweenLegs | BH11: Shot-BetweenLegs | BI11: Shot-BetweenLegs | BJ11: Shot-Dumpin | BK11: Shot-BetweenLegs | BL11: Shot-BetweenLegs | BM11: Goal-BetweenLegs | BN11: Goal-Other | BO11: Goal-Other | BR11: Chip | BS11: BeatDeke | BU11: Possession | BV11: Involved | BX11: opp_team_player_4 | CC11: Home Offside
A12: Hit | C12: Shot-DeflectedOnNet | E12: Shot-BetweenLegs | G12: Other | I12: BeatSpeed | V12: Shot_OnNetDeflectedGoal | AJ12: Giveaway-DumpInZone | AO12: Penalty-Interference | AP12: Penalty-Interference | AQ12: Penalty-Interference | AR12: Stoppage-Goal | BC12: Shot-OneTime | BD12: Shot-OneTime | BE12: Shot-OneTime | BF12: Shot-OneTime | BG12: Shot-Dumpin | BH12: Shot-Dumpin | BI12: Shot-Dumpin | BJ12: Shot-OneTime | BK12: Shot-Dumpin | BL12: Shot-Dumpin | BM12: Goal-Dumpin | BR12: Other | BS12: BeatSpeed | BU12: LoosePuck | BV12: None | BX12: opp_team_player_5 | CC12: Home Icing
A13: Possession | C13: Shot-Tipped | E13: Shot-Dumpin | G13: DumpChase | I13: BoxOut | V13: Shot_Goal | AJ13: Giveaway-Other | AO13: Penalty-Hooking | AP13: Penalty-Fighting | AQ13: Penalty-Fighting | BC13: Shot-Other | BD13: Shot_Tipped | BE13: Shot_Tipped | BF13: Shot_Tipped | BG13: Shot-OneTime | BH13: Shot-OneTime | BI13: Shot-OneTime | BJ13: Shot-Other | BK13: Shot-OneTime | BL13: Shot-OneTime | BM13: Goal-Deflection | BR13: DumpChase | BS13: BoxOut | BU13: Save | BV13: Involved | BX13: opp_team_player_6 | CC13: Away Offside
A14: LoosePuck | C14: Pass-Completed | E14: Shot-Deflection | G14: Forecheck | I14: Other | AO14: Penalty-Roughing | AP14: Penalty-Hooking | AQ14: Penalty-Hooking | BD14: Shot-Other | BE14: Shot-Other | BF14: Shot-Other | BG14: Shot-Other | BH14: Shot-Other | BI14: Shot-Other | BJ14: Shot-Deflection | BK14: Shot-Other | BL14: Shot-Other | BM14: Goal-OneTime | BR14: Forecheck | BS14: Other | BU14: TeamPossessionChange | BV14: None | CC14: Away Icing
A15: Save | C15: Pass-Missed | E15: Shot-OneTime | G15: Speed | AO15: Penalty-Slashing | AP15: Penalty-Roughing | AQ15: Penalty-Roughing | BJ15: Shot-Tip | BM15: Goal-Other | BR15: Speed | BU15: Rebound | BV15: Invoived | CC15: Clock Problem
A16: TeamPossessionChange | C16: Pass-Deflected | E16: Shot-Other | AO16: Penalty-TooManyMenontheIce | AP16: Penalty-Slashing | AQ16: Penalty-Slashing | CC16: Puck Frozen
A17: Rebound | C17: Pass-Intercepted | E17: Pass-Stretch | AO17: Penalty-Tripping | AP17: Penalty-Misconduct | AQ17: Penalty-Misconduct | CC17: Puck in Crowd
A18: DeadIce | C18: Turnover-Giveaway | E18: Pass-Rim/Wrap | AO18: Penalty-Other | AP18: Penalty-TooManyMenontheIce | AQ18: Penalty-TooManyMenontheIce | CC18: Goalie Stopped (after SOG)
A19: Play | C19: Turnover-Takeaway | E19: Pass-Backhand | AP19: Penalty-Tripping | AQ19: Penalty-Tripping | CC19: Referee or Linesperson
A20: Timeout | C20: Zone-Entry | E20: Pass-Forehand | AP20: Penalty-UnsportsmanlikeConduct | AQ20: Penalty-UnsportsmanlikeConduct | CC20: High Stick
A21: Intermission | C21: Zone-Exit | E21: Pass-Bank | AP21: Penalty-Other | AQ21: Penalty-Other | CC21: Objects on Ice
A22: Clockstop | C22: Zone-Keepin | E22: Pass-Other | CC22: Hand Pass
A23: GameStart | C23: Penalty | E23: Giveaway-Misplayed | CC23: Premature Substitution
A24: GameEnd | C24: Penalty-Offsetting | E24: Giveaway-BattleLost | CC24: Puck in Netting
C25: Stoppage-Freeze | E25: Giveaway-PassIntercepted | CC25: Puck in Benches
C26: Stoppage-OutfofPlay | E26: Giveaway-PassMissed | CC26: Net Dislodged Offensive Skater
C27: Stoppage-PeriodEnd | E27: Giveaway-PassBlocked | CC27: Puck Frzn-Goalie-Bynd Ctr
C28: Stoppage-Goal | E28: Giveaway-ShotBlocked | CC28: Skater Puck Frozen
C29: Stoppage-Penalty | E29: Giveaway-ShotMissed | CC29: Valid stoppage type reasons (reason):
C30: Shootout-OnNet | E30: Giveaway-Other | CC30: TV timeout
C31: Shootout-Missed | E31: Takeaway-BattleWon | CC31: Home Timeout
C32: Shootout-Saved | E32: Takeaway-PokeCheck | CC32: Visitor Timeout
C33: PenaltyShot-OnNet | E33: Takeaway-PassIntercepted | CC33: Player Injury
C34: PenaltyShot-Missed | E34: Takeaway-PassBlocked | CC34: Official Injury
C35: PenaltyShot-Saved | E35: Takeaway-ShotBlocked | CC35: Rink Repair
C36: LoosePuck-Forecheck | E36: Takeaway-Other | CC36: Ice problem
... C43: Faceoff-GameStart | E43: Zone-KeepIn | CC43: Chlg League - off-side
E44: Zone-Pinch | CC44: Chlg League - goal interference
E45: Zone-Other | CC45: Switch sides
E46: Save-Glove | CC46: Chlg Hm - Missed stoppage
...

Sheet events
A1: event_index | B1: sequence_index | C1: play_index | D1: Period | E1: event_start_min | F1: event_start_sec | G1: event_end_min | H1: event_end_sec | I1: Team | J1: Player | K1: role_abrev | L1: Type | M1: event_detail | N1: event_detail_2 | O1: offensive_play | P1: defensive_play | Q1: game_id | R1: home_team | S1: away_team | T1: duration | U1: time_start_total_seconds | V1: time_end_total_seconds | W1: shift_index | X1: player_role | Y1: role_number | Z1: running_intermission_duration | AA1: period_start_total_running_seconds | AB1: running_video_time | AC1: event_running_start | AD1: event_running_end
A2: 0 | D2: 1 | L2: GameStart | M2: Faceoff_GameStart | Q2: 18976 | R2: Velodrome | S2: HollowBrook | AA2: 0 | AB2: 0 | AC2: 0 | AD2: 0
A3: 1 | D3: 1 | E3: 18 | F3: 0 | I3: Away | J3: 11 | K3: e | L3: Faceoff | M3: Faceoff_GameStart | Q3: 18977 | R3: Velodrome | S3: HollowBrook | T3: =IF(AND(G3="",H3=""),0,((E3*60)+F3)-((G3*60)+H3)) -> 0 | U3: =(E3*60)+F3 -> 1080 | V3: =IF(AND(G3="",H3=""),U3,((G3*60)+H3)) -> 1080 | W3: {=_xlfn._xlws.FILTER(shifts!A:A,(shifts!B:B=events!D3)*(shifts!AH:AH>=events!U3)*(shifts!AI:AI<=events!V3))} -> 1 | X3: =IF(K3="e","event_team_player_"&Y3,IF(K3="o","opp_team_player_"&Y3,"")) -> event_team_player_1 | Y3: =COUNTIFS(A$3:A3,"="&A3,K$3:K3,"="&K3) -> 1 | Z3: =SUMIFS(T3:T3,L3:L3,"=Intermission") -> 0 | AA3: =IF(D3=1,0,IF(D3=2,1080+Z3,IF(D3=3,(1080*2)+Z3,0))) -> 0 | AB3: =((1080*D3)-((E3*60)+F3)*D3)+Z3 -> 0 | AC3: =IF(L2="GameStart",0,AA3+Z3) -> 0 | AD3: =AC3+5 -> 5
A4: 1 | D4: =IF(L4="Intermission",D3+1,D3) -> 1 | E4: 18 | F4: 0 | I4: Away | J4: 27 | K4: e | L4: Faceoff | M4: Faceoff_GameStart | Q4: 18977 | R4: Velodrome | S4: HollowBrook | T4: =IF(AND(G4="",H4=""),0,((E4*60)+F4)-((G4*60)+H4)) -> 0 | U4: =(E4*60)+F4 -> 1080 | V4: =IF(AND(G4="",H4=""),U4,((G4*60)+H4)) -> 1080 | W4: {=_xlfn._xlws.FILTER(shifts!A:A,(shifts!B:B=events!D4)*(shifts!AH:AH>=events!U4)*(shifts!AI:AI<=events!V4))} -> 1 | X4: =IF(K4="e","event_team_player_"&Y4,IF(K4="o","opp_team_player_"&Y4,"")) -> event_team_player_2 | Y4: =COUNTIFS(A$3:A4,"="&A4,K$3:K4,"="&K4) -> 2 | Z4: =SUMIFS(T$3:T4,L$3:L4,"=Intermission")+SUMIFS(T$3:T4,L$3:L4,"=Timeout")+SUMIFS(T$3:T4,L$3:L4,"=Clockstop") -> 0 | AA4: =IF(D4=1,0,IF(D4=2,1080+Z4,IF(D4=3,(1080*2)+Z4,0))) -> 0 | AB4: =((1080*D4)-((E4*60)+F4)*D4)+Z4 -> 0 | AC4: =IF(L3="GameStart",0,AA4+Z4) -> 0 | AD4: =AC4+5 -> 5
A5: 1 | D5: =IF(L5="Intermission",D4+1,D4) -> 1 | E5: 18 | F5: 0 | I5: Away | J5: 70 | K5: o | L5: Faceoff | M5: Faceoff_GameStart | Q5: 18977 | R5: Velodrome | S5: HollowBrook | T5: =IF(AND(G5="",H5=""),0,((E5*60)+F5)-((G5*60)+H5)) -> 0 | U5: =(E5*60)+F5 -> 1080 | V5: =IF(AND(G5="",H5=""),U5,((G5*60)+H5)) -> 1080 | W5: {=_xlfn._xlws.FILTER(shifts!A:A,(shifts!B:B=events!D5)*(shifts!AH:AH>=events!U5)*(shifts!AI:AI<=events!V5))} -> 1 | X5: =IF(K5="e","event_team_player_"&Y5,IF(K5="o","opp_team_player_"&Y5,"")) -> opp_team_player_1 | Y5: =COUNTIFS(A$3:A5,"="&A5,K$3:K5,"="&K5) -> 1 | Z5: =SUMIFS(T$3:T5,L$3:L5,"=Intermission")+SUMIFS(T$3:T5,L$3:L5,"=Timeout")+SUMIFS(T$3:T5,L$3:L5,"=Clockstop") -> 0 | AA5: =IF(D5=1,0,IF(D5=2,1080+Z5,IF(D5=3,(1080*2)+Z5,0))) -> 0 | AB5: =((1080*D5)-((E5*60)+F5)*D5)+Z5 -> 0 | AC5: =IF(L4="GameStart",0,AA5+Z5) -> 0 | AD5: =AC5+5 -> 5
A6: 2 | D6: =IF(L6="Intermission",D5+1,D5) -> 1 | E6: 17 | F6: 58 | I6: Away | J6: 27 | K6: e | L6: Pass | M6: Pass-Completed | N6: Pass-Forehand | Q6: 18977 | R6: Velodrome | S6: HollowBrook | T6: =IF(AND(G6="",H6=""),0,((E6*60)+F6)-((G6*60)+H6)) -> 0 | U6: =(E6*60)+F6 -> 1078 | V6: =IF(AND(G6="",H6=""),U6,((G6*60)+H6)) -> 1078 | W6: {=_xlfn._xlws.FILTER(shifts!A:A,(shifts!B:B=events!D6)*(shifts!AH:AH>=events!U6)*(shifts!AI:AI<=events!V6))} -> 1 | X6: =IF(K6="e","event_team_player_"&Y6,IF(K6="o","opp_team_player_"&Y6,"")) -> event_team_player_1 | Y6: =COUNTIFS(A$3:A6,"="&A6,K$3:K6,"="&K6) -> 1 | Z6: =SUMIFS(T$3:T6,L$3:L6,"=Intermission")+SUMIFS(T$3:T6,L$3:L6,"=Timeout")+SUMIFS(T$3:T6,L$3:L6,"=Clockstop") -> 0 | AA6: =IF(D6=1,0,IF(D6=2,1080+Z6,IF(D6=3,(1080*2)+Z6,0))) -> 0 | AB6: =((1080*D6)-((E6*60)+F6)*D6)+Z6 -> 2 | AC6: =IF(L5="GameStart",0,AA6+Z6) -> 0 | AD6: =AC6+5 -> 5
A7: 2 | D7: =IF(L7="Intermission",D6+1,D6) -> 1 | E7: 17 | F7: 58 | I7: Away | J7: 33 | K7: e | L7: Pass | M7: Pass-Completed | N7: Pass-Forehand | Q7: 18977 | R7: Velodrome | S7: HollowBrook | T7: =IF(AND(G7="",H7=""),0,((E7*60)+F7)-((G7*60)+H7)) -> 0 | U7: =(E7*60)+F7 -> 1078 | V7: =IF(AND(G7="",H7=""),U7,((G7*60)+H7)) -> 1078 | W7: {=_xlfn._xlws.FILTER(shifts!A:A,(shifts!B:B=events!D7)*(shifts!AH:AH>=events!U7)*(shifts!AI:AI<=events!V7))} -> 1 | X7: =IF(K7="e","event_team_player_"&Y7,IF(K7="o","opp_team_player_"&Y7,"")) -> event_team_player_2 | Y7: =COUNTIFS(A$3:A7,"="&A7,K$3:K7,"="&K7) -> 2 | Z7: =SUMIFS(T$3:T7,L$3:L7,"=Intermission")+SUMIFS(T$3:T7,L$3:L7,"=Timeout")+SUMIFS(T$3:T7,L$3:L7,"=Clockstop") -> 0 | AA7: =IF(D7=1,0,IF(D7=2,1080+Z7,IF(D7=3,(1080*2)+Z7,0))) -> 0 | AB7: =((1080*D7)-((E7*60)+F7)*D7)+Z7 -> 2 | AC7: =IF(L6="GameStart",0,AA7+Z7) -> 0
A8: 3 | D8: =IF(L8="Intermission",D7+1,D7) -> 1 | E8: 17 | F8: 58 | I8: Away | J8: 33 | K8: e | L8: Pass | M8: Pass-Completed | N8: Pass-Forehand | Q8: 18977 | R8: Velodrome | S8: HollowBrook | T8: =IF(AND(G8="",H8=""),0,((E8*60)+F8)-((G8*60)+H8)) -> 0 | U8: =(E8*60)+F8 -> 1078 | V8: =IF(AND(G8="",H8=""),U8,((G8*60)+H8)) -> 1078 | W8: {=_xlfn._xlws.FILTER(shifts!A:A,(shifts!B:B=events!D8)*(shifts!AH:AH>=events!U8)*(shifts!AI:AI<=events!V8))} -> 1 | X8: =IF(K8="e","event_team_player_"&Y8,IF(K8="o","opp_team_player_"&Y8,"")) -> event_team_player_1 | Y8: =COUNTIFS(A$3:A8,"="&A8,K$3:K8,"="&K8) -> 1 | Z8: =SUMIFS(T$3:T8,L$3:L8,"=Intermission")+SUMIFS(T$3:T8,L$3:L8,"=Timeout")+SUMIFS(T$3:T8,L$3:L8,"=Clockstop") -> 0 | AA8: =IF(D8=1,0,IF(D8=2,1080+Z8,IF(D8=3,(1080*2)+Z8,0))) -> 0 | AB8: =((1080*D8)-((E8*60)+F8)*D8)+Z8 -> 2 | AC8: =IF(L7="GameStart",0,AA8+Z8) -> 0
A9: 3 | D9: =IF(L9="Intermission",D8+1,D8) -> 1 | E9: 17 | F9: 58 | I9: Away | J9: 27 | K9: e | L9: Pass | M9: Pass-Completed | N9: Pass-Forehand | Q9: 18977 | R9: Velodrome | S9: HollowBrook | T9: =IF(AND(G9="",H9=""),0,((E9*60)+F9)-((G9*60)+H9)) -> 0 | U9: =(E9*60)+F9 -> 1078 | V9: =IF(AND(G9="",H9=""),U9,((G9*60)+H9)) -> 1078 | W9: {=_xlfn._xlws.FILTER(shifts!A:A,(shifts!B:B=events!D9)*(shifts!AH:AH>=events!U9)*(shifts!AI:AI<=events!V9))} -> 1 | X9: =IF(K9="e","event_team_player_"&Y9,IF(K9="o","opp_team_player_"&Y9,"")) -> event_team_player_2 | Y9: =COUNTIFS(A$3:A9,"="&A9,K$3:K9,"="&K9) -> 2 | Z9: =SUMIFS(T$3:T9,L$3:L9,"=Intermission")+SUMIFS(T$3:T9,L$3:L9,"=Timeout")+SUMIFS(T$3:T9,L$3:L9,"=Clockstop") -> 0 | AA9: =IF(D9=1,0,IF(D9=2,1080+Z9,IF(D9=3,(1080*2)+Z9,0))) -> 0 | AB9: =((1080*D9)-((E9*60)+F9)*D9)+Z9 -> 2 | AC9: =IF(L8="GameStart",0,AA9+Z9) -> 0
A10: 4 | D10: =IF(L10="Intermission",D9+1,D9) -> 1 | E10: 17 | F10: 55 | G10: 17 | H10: 53 | I10: Away | J10: 27 | K10: e | L10: Possession | Q10: 18977 | R10: Velodrome | S10: HollowBrook | T10: =IF(AND(G10="",H10=""),0,((E10*60)+F10)-((G10*60)+H10)) -> 2 | U10: =(E10*60)+F10 -> 1075 | V10: =IF(AND(G10="",H10=""),U10,((G10*60)+H10)) -> 1073 | W10: {=_xlfn._xlws.FILTER(shifts!A:A,(shifts!B:B=events!D10)*(shifts!AH:AH>=events!U10)*(shifts!AI:AI<=events!V10))} -> 1 | X10: =IF(K10="e","event_team_player_"&Y10,IF(K10="o","opp_team_player_"&Y10,"")) -> event_team_player_1 | Y10: =COUNTIFS(A$3:A10,"="&A10,K$3:K10,"="&K10) -> 1 | Z10: =SUMIFS(T$3:T10,L$3:L10,"=Intermission")+SUMIFS(T$3:T10,L$3:L10,"=Timeout")+SUMIFS(T$3:T10,L$3:L10,"=Clockstop") -> 0 | AA10: =IF(D10=1,0,IF(D10=2,1080+Z10,IF(D10=3,(1080*2)+Z10,0))) -> 0 | AB10: =((1080*D10)-((E10*60)+F10)*D10)+Z10 -> 5 | AC10: =IF(L9="GameStart",0,AA10+Z10) -> 0
A11: 5 | D11: =IF(L11="Intermission",D10+1,D10) -> 1 | E11: 17 | F11: 50 | I11: Away | J11: 33 | K11: e | L11: Pass | M11: Pass-Missed | N11: Pass-Forehand | Q11: 18977 | R11: Velodrome | S11: HollowBrook | T11: =IF(AND(G11="",H11=""),0,((E11*60)+F11)-((G11*60)+H11)) -> 0 | U11: =(E11*60)+F11 -> 1070 | V11: =IF(AND(G11="",H11=""),U11,((G11*60)+H11)) -> 1070 | W11: {=_xlfn._xlws.FILTER(shifts!A:A,(shifts!B:B=events!D11)*(shifts!AH:AH>=events!U11)*(shifts!AI:AI<=events!V11))} -> 1 | X11: =IF(K11="e","event_team_player_"&Y11,IF(K11="o","opp_team_player_"&Y11,"")) -> event_team_player_1 | Y11: =COUNTIFS(A$3:A11,"="&A11,K$3:K11,"="&K11) -> 1 | Z11: =SUMIFS(T$3:T11,L$3:L11,"=Intermission")+SUMIFS(T$3:T11,L$3:L11,"=Timeout")+SUMIFS(T$3:T11,L$3:L11,"=Clockstop") -> 0 | AA11: =IF(D11=1,0,IF(D11=2,1080+Z11,IF(D11=3,(1080*2)+Z11,0))) -> 0 | AB11: =((1080*D11)-((E11*60)+F11)*D11)+Z11 -> 10 | AC11: =IF(L10="GameStart",0,AA11+Z11) -> 0
A12: 5 | D12: =IF(L12="Intermission",D11+1,D11) -> 1 | E12: 17 | F12: 50 | I12: Away | J12: 27 | K12: e | L12: Pass | M12: Pass-Missed | N12: Pass-Forehand | Q12: 18977 | R12: Velodrome | S12: HollowBrook | T12: =IF(AND(G12="",H12=""),0,((E12*60)+F12)-((G12*60)+H12)) -> 0 | U12: =(E12*60)+F12 -> 1070 | V12: =IF(AND(G12="",H12=""),U12,((G12*60)+H12)) -> 1070 | W12: {=_xlfn._xlws.FILTER(shifts!A:A,(shifts!B:B=events!D12)*(shifts!AH:AH>=events!U12)*(shifts!AI:AI<=events!V12))} -> 1 | X12: =IF(K12="e","event_team_player_"&Y12,IF(K12="o","opp_team_player_"&Y12,"")) -> event_team_player_2 | Y12: =COUNTIFS(A$3:A12,"="&A12,K$3:K12,"="&K12) -> 2 | Z12: =SUMIFS(T$3:T12,L$3:L12,"=Intermission")+SUMIFS(T$3:T12,L$3:L12,"=Timeout")+SUMIFS(T$3:T12,L$3:L12,"=Clockstop") -> 0 | AA12: =IF(D12=1,0,IF(D12=2,1080+Z12,IF(D12=3,(1080*2)+Z12,0))) -> 0 | AB12: =((1080*D12)-((E12*60)+F12)*D12)+Z12 -> 10 | AC12: =IF(L11="GameStart",0,AA12+Z12) -> 0
A13: 6 | D13: =IF(L13="Intermission",D12+1,D12) -> 1 | E13: 17 | F13: 47 | I13: Away | J13: 33 | K13: e | L13: Turnover | M13: Turnover-Giveaway | N13: Giveaway-Misplayed | Q13: 18977 | R13: Velodrome | S13: HollowBrook | T13: =IF(AND(G13="",H13=""),0,((E13*60)+F13)-((G13*60)+H13)) -> 0 | U13: =(E13*60)+F13 -> 1067 | V13: =IF(AND(G13="",H13=""),U13,((G13*60)+H13)) -> 1067 | W13: {=_xlfn._xlws.FILTER(shifts!A:A,(shifts!B:B=events!D13)*(shifts!AH:AH>=events!U13)*(shifts!AI:AI<=events!V13))} -> 1 | X13: =IF(K13="e","event_team_player_"&Y13,IF(K13="o","opp_team_player_"&Y13,"")) -> event_team_player_1 | Y13: =COUNTIFS(A$3:A13,"="&A13,K$3:K13,"="&K13) -> 1 | Z13: =SUMIFS(T$3:T13,L$3:L13,"=Intermission")+SUMIFS(T$3:T13,L$3:L13,"=Timeout")+SUMIFS(T$3:T13,L$3:L13,"=Clockstop") -> 0 | AA13: =IF(D13=1,0,IF(D13=2,1080+Z13,IF(D13=3,(1080*2)+Z13,0))) -> 0 | AB13: =((1080*D13)-((E13*60)+F13)*D13)+Z13 -> 13 | AC13: =IF(L12="GameStart",0,AA13+Z13) -> 0
A14: 6 | D14: =IF(L14="Intermission",D13+1,D13) -> 1 | E14: 17 | F14: 47 | I14: Away | J14: 70 | K14: o | L14: Turnover | M14: Turnover-Giveaway | N14: Giveaway-Misplayed | Q14: 18977 | R14: Velodrome | S14: HollowBrook | T14: =IF(AND(G14="",H14=""),0,((E14*60)+F14)-((G14*60)+H14)) -> 0 | U14: =(E14*60)+F14 -> 1067 | V14: =IF(AND(G14="",H14=""),U14,((G14*60)+H14)) -> 1067 | W14: {=_xlfn._xlws.FILTER(shifts!A:A,(shifts!B:B=events!D14)*(shifts!AH:AH>=events!U14)*(shifts!AI:AI<=events!V14))} -> 1 | X14: =IF(K14="e","event_team_player_"&Y14,IF(K14="o","opp_team_player_"&Y14,"")) -> opp_team_player_1 | Y14: =COUNTIFS(A$3:A14,"="&A14,K$3:K14,"="&K14) -> 1 | Z14: =SUMIFS(T$3:T14,L$3:L14,"=Intermission")+SUMIFS(T$3:T14,L$3:L14,"=Timeout")+SUMIFS(T$3:T14,L$3:L14,"=Clockstop") -> 0 | AA14: =IF(D14=1,0,IF(D14=2,1080+Z14,IF(D14=3,(1080*2)+Z14,0))) -> 0 | AB14: =((1080*D14)-((E14*60)+F14)*D14)+Z14 -> 13 | AC14: =IF(L13="GameStart",0,AA14+Z14) -> 0
A15: 7 | D15: =IF(L15="Intermission",D14+1,D14) -> 1 | E15: 17 | F15: 45 | I15: Home | J15: 49 | K15: e | L15: Stoppage | M15: Stoppage-Play | N15: Stoppage-Offsides | Q15: 18977 | R15: Velodrome | S15: HollowBrook | T15: =IF(AND(G15="",H15=""),0,((E15*60)+F15)-((G15*60)+H15)) -> 0 | U15: =(E15*60)+F15 -> 1065 | V15: =IF(AND(G15="",H15=""),U15,((G15*60)+H15)) -> 1065 | W15: {=_xlfn._xlws.FILTER(shifts!A:A,(shifts!B:B=events!D15)*(shifts!AH:AH>=events!U15)*(shifts!AI:AI<=events!V15))} -> 1 | X15: =IF(K15="e","event_team_player_"&Y15,IF(K15="o","opp_team_player_"&Y15,"")) -> event_team_player_1 | Y15: =COUNTIFS(A$3:A15,"="&A15,K$3:K15,"="&K15) -> 1 | Z15: =SUMIFS(T$3:T15,L$3:L15,"=Intermission")+SUMIFS(T$3:T15,L$3:L15,"=Timeout")+SUMIFS(T$3:T15,L$3:L15,"=Clockstop") -> 0 | AA15: =IF(D15=1,0,IF(D15=2,1080+Z15,IF(D15=3,(1080*2)+Z15,0))) -> 0 | AB15: =((1080*D15)-((E15*60)+F15)*D15)+Z15 -> 15 | AC15: =IF(L14="GameStart",0,AA15+Z15) -> 0
A16: 8 | D16: =IF(L16="Intermission",D15+1,D15) -> 1 | E16: 17 | F16: 45 | G16: 17 | H16: 23 | I16: Home | J16: 49 | K16: e | L16: DeadIce | Q16: 18977 | R16: Velodrome | S16: HollowBrook | T16: =IF(AND(G16="",H16=""),0,((E16*60)+F16)-((G16*60)+H16)) -> 22 | U16: =(E16*60)+F16 -> 1065 | V16: =IF(AND(G16="",H16=""),U16,((G16*60)+H16)) -> 1043 | W16: {=_xlfn._xlws.FILTER(shifts!A:A,(shifts!B:B=events!D16)*(shifts!AH:AH>=events!U16)*(shifts!AI:AI<=events!V16))} -> 1 | X16: =IF(K16="e","event_team_player_"&Y16,IF(K16="o","opp_team_player_"&Y16,"")) -> event_team_player_1 | Y16: =COUNTIFS(A$3:A16,"="&A16,K$3:K16,"="&K16) -> 1 | Z16: =SUMIFS(T$3:T16,L$3:L16,"=Intermission")+SUMIFS(T$3:T16,L$3:L16,"=Timeout")+SUMIFS(T$3:T16,L$3:L16,"=Clockstop") -> 0 | AA16: =IF(D16=1,0,IF(D16=2,1080+Z16,IF(D16=3,(1080*2)+Z16,0))) -> 0 | AB16: =((1080*D16)-((E16*60)+F16)*D16)+Z16 -> 15 | AC16: =IF(L15="GameStart",0,AA16+Z16) -> 0
A17: 9 | D17: =IF(L17="Intermission",D16+1,D16) -> 1 | E17: 17 | F17: 23 | I17: Home | J17: 70 | K17: e | L17: Faceoff | M17: Faceoff | Q17: 18977 | R17: Velodrome | S17: HollowBrook | T17: =IF(AND(G17="",H17=""),0,((E17*60)+F17)-((G17*60)+H17)) -> 0 | U17: =(E17*60)+F17 -> 1043 | V17: =IF(AND(G17="",H17=""),U17,((G17*60)+H17)) -> 1043 | W17: {=_xlfn._xlws.FILTER(shifts!A:A,(shifts!B:B=events!D17)*(shifts!AH:AH>=events!U17)*(shifts!AI:AI<=events!V17))} -> 1 | X17: =IF(K17="e","event_team_player_"&Y17,IF(K17="o","opp_team_player_"&Y17,"")) -> event_team_player_1 | Y17: =COUNTIFS(A$3:A17,"="&A17,K$3:K17,"="&K17) -> 1 | Z17: =SUMIFS(T$3:T17,L$3:L17,"=Intermission")+SUMIFS(T$3:T17,L$3:L17,"=Timeout")+SUMIFS(T$3:T17,L$3:L17,"=Clockstop") -> 0 | AA17: =IF(D17=1,0,IF(D17=2,1080+Z17,IF(D17=3,(1080*2)+Z17,0))) -> 0 | AB17: =((1080*D17)-((E17*60)+F17)*D17)+Z17 -> 37 | AC17: =IF(L16="GameStart",0,AA17+Z17) -> 0
A18: 9 | D18: =IF(L18="Intermission",D17+1,D17) -> 1 | E18: 17 | F18: 23 | I18: Home | J18: 11 | K18: o | L18: Faceoff | M18: Faceoff | Q18: 18977 | R18: Velodrome | S18: HollowBrook | T18: =IF(AND(G18="",H18=""),0,((E18*60)+F18)-((G18*60)+H18)) -> 0 | U18: =(E18*60)+F18 -> 1043 | V18: =IF(AND(G18="",H18=""),U18,((G18*60)+H18)) -> 1043 | W18: {=_xlfn._xlws.FILTER(shifts!A:A,(shifts!B:B=events!D18)*(shifts!AH:AH>=events!U18)*(shifts!AI:AI<=events!V18))} -> 1 | X18: =IF(K18="e","event_team_player_"&Y18,IF(K18="o","opp_team_player_"&Y18,"")) -> opp_team_player_1 | Y18: =COUNTIFS(A$3:A18,"="&A18,K$3:K18,"="&K18) -> 1 | Z18: =SUMIFS(T$3:T18,L$3:L18,"=Intermission")+SUMIFS(T$3:T18,L$3:L18,"=Timeout")+SUMIFS(T$3:T18,L$3:L18,"=Clockstop") -> 0 | AA18: =IF(D18=1,0,IF(D18=2,1080+Z18,IF(D18=3,(1080*2)+Z18,0))) -> 0 | AB18: =((1080*D18)-((E18*60)+F18)*D18)+Z18 -> 37 | AC18: =IF(L17="GameStart",0,AA18+Z18) -> 0
A19: 10 | D19: =IF(L19="Intermission",D18+1,D18) -> 1 | E19: 17 | F19: 22 | G19: 17 | H19: 20 | I19: Home | J19: 70 | K19: e | L19: Possession | Q19: 18977 | R19: Velodrome | S19: HollowBrook | T19: =IF(AND(G19="",H19=""),0,((E19*60)+F19)-((G19*60)+H19)) -> 2 | U19: =(E19*60)+F19 -> 1042 | V19: =IF(AND(G19="",H19=""),U19,((G19*60)+H19)) -> 1040 | W19: {=_xlfn._xlws.FILTER(shifts!A:A,(shifts!B:B=events!D19)*(shifts!AH:AH>=events!U19)*(shifts!AI:AI<=events!V19))} -> 1 | X19: =IF(K19="e","event_team_player_"&Y19,IF(K19="o","opp_team_player_"&Y19,"")) -> event_team_player_1 | Y19: =COUNTIFS(A$3:A19,"="&A19,K$3:K19,"="&K19) -> 1 | Z19: =SUMIFS(T$3:T19,L$3:L19,"=Intermission")+SUMIFS(T$3:T19,L$3:L19,"=Timeout")+SUMIFS(T$3:T19,L$3:L19,"=Clockstop") -> 0 | AA19: =IF(D19=1,0,IF(D19=2,1080+Z19,IF(D19=3,(1080*2)+Z19,0))) -> 0 | AB19: =((1080*D19)-((E19*60)+F19)*D19)+Z19 -> 38 | AC19: =IF(L18="GameStart",0,AA19+Z19) -> 0
A20: 11 | D20: =IF(L20="Intermission",D19+1,D19) -> 1 | E20: 17 | F20: 20 | I20: Home | J20: 70 | K20: e | L20: Pass | M20: Pass-Completed | N20: Pass-Backhand | Q20: 18977 | R20: Velodrome | S20: HollowBrook | T20: =IF(AND(G20="",H20=""),0,((E20*60)+F20)-((G20*60)+H20)) -> 0 | U20: =(E20*60)+F20 -> 1040 | V20: =IF(AND(G20="",H20=""),U20,((G20*60)+H20)) -> 1040 | W20: {=_xlfn._xlws.FILTER(shifts!A:A,(shifts!B:B=events!D20)*(shifts!AH:AH>=events!U20)*(shifts!AI:AI<=events!V20))} -> 1 | X20: =IF(K20="e","event_team_player_"&Y20,IF(K20="o","opp_team_player_"&Y20,"")) -> event_team_player_1 | Y20: =COUNTIFS(A$3:A20,"="&A20,K$3:K20,"="&K20) -> 1 | Z20: =SUMIFS(T$3:T20,L$3:L20,"=Intermission")+SUMIFS(T$3:T20,L$3:L20,"=Timeout")+SUMIFS(T$3:T20,L$3:L20,"=Clockstop") -> 0 | AA20: =IF(D20=1,0,IF(D20=2,1080+Z20,IF(D20=3,(1080*2)+Z20,0))) -> 0 | AB20: =((1080*D20)-((E20*60)+F20)*D20)+Z20 -> 40 | AC20: =IF(L19="GameStart",0,AA20+Z20) -> 0
A21: 11 | D21: =IF(L21="Intermission",D20+1,D20) -> 1 | E21: 17 | F21: 20 | I21: Home | J21: 87 | K21: e | L21: Pass | M21: Pass-Completed | N21: Pass-Backhand | Q21: 18977 | R21: Velodrome | S21: HollowBrook | T21: =IF(AND(G21="",H21=""),0,((E21*60)+F21)-((G21*60)+H21)) -> 0 | U21: =(E21*60)+F21 -> 1040 | V21: =IF(AND(G21="",H21=""),U21,((G21*60)+H21)) -> 1040 | W21: {=_xlfn._xlws.FILTER(shifts!A:A,(shifts!B:B=events!D21)*(shifts!AH:AH>=events!U21)*(shifts!AI:AI<=events!V21))} -> 1 | X21: =IF(K21="e","event_team_player_"&Y21,IF(K21="o","opp_team_player_"&Y21,"")) -> event_team_player_2 | Y21: =COUNTIFS(A$3:A21,"="&A21,K$3:K21,"="&K21) -> 2 | Z21: =SUMIFS(T$3:T21,L$3:L21,"=Intermission")+SUMIFS(T$3:T21,L$3:L21,"=Timeout")+SUMIFS(T$3:T21,L$3:L21,"=Clockstop") -> 0 | AA21: =IF(D21=1,0,IF(D21=2,1080+Z21,IF(D21=3,(1080*2)+Z21,0))) -> 0 | AB21: =((1080*D21)-((E21*60)+F21)*D21)+Z21 -> 40 | AC21: =IF(L20="GameStart",0,AA21+Z21) -> 0
A22: 12 | D22: =IF(L22="Intermission",D21+1,D21) -> 1 | E22: 17 | F22: 20 | G22: 17 | H22: 17 | I22: Home | J22: 87 | K22: e | L22: Possession | Q22: 18977 | R22: Velodrome | S22: HollowBrook | T22: =IF(AND(G22="",H22=""),0,((E22*60)+F22)-((G22*60)+H22)) -> 3 | U22: =(E22*60)+F22 -> 1040 | V22: =IF(AND(G22="",H22=""),U22,((G22*60)+H22)) -> 1037 | W22: {=_xlfn._xlws.FILTER(shifts!A:A,(shifts!B:B=events!D22)*(shifts!AH:AH>=events!U22)*(shifts!AI:AI<=events!V22))} -> 1 | X22: =IF(K22="e","event_team_player_"&Y22,IF(K22="o","opp_team_player_"&Y22,"")) -> event_team_player_1 | Y22: =COUNTIFS(A$3:A22,"="&A22,K$3:K22,"="&K22) -> 1 | Z22: =SUMIFS(T$3:T22,L$3:L22,"=Intermission")+SUMIFS(T$3:T22,L$3:L22,"=Timeout")+SUMIFS(T$3:T22,L$3:L22,"=Clockstop") -> 0 | AA22: =IF(D22=1,0,IF(D22=2,1080+Z22,IF(D22=3,(1080*2)+Z22,0))) -> 0 | AB22: =((1080*D22)-((E22*60)+F22)*D22)+Z22 -> 40 | AC22: =IF(L21="GameStart",0,AA22+Z22) -> 0
A23: 13 | D23: =IF(L23="Intermission",D22+1,D22) -> 1 | E23: 17 | F23: 17 | I23: Home | J23: 87 | K23: e | L23: Pass | M23: Pass-Missed | N23: Pass-Stretch | Q23: 18977 | R23: Velodrome | S23: HollowBrook | T23: =IF(AND(G23="",H23=""),0,((E23*60)+F23)-((G23*60)+H23)) -> 0 | U23: =(E23*60)+F23 -> 1037 | V23: =IF(AND(G23="",H23=""),U23,((G23*60)+H23)) -> 1037 | W23: {=_xlfn._xlws.FILTER(shifts!A:A,(shifts!B:B=events!D23)*(shifts!AH:AH>=events!U23)*(shifts!AI:AI<=events!V23))} -> 1 | X23: =IF(K23="e","event_team_player_"&Y23,IF(K23="o","opp_team_player_"&Y23,"")) -> event_team_player_1 | Y23: =COUNTIFS(A$3:A23,"="&A23,K$3:K23,"="&K23) -> 1 | Z23: =SUMIFS(T$3:T23,L$3:L23,"=Intermission")+SUMIFS(T$3:T23,L$3:L23,"=Timeout")+SUMIFS(T$3:T23,L$3:L23,"=Clockstop") -> 0 | AA23: =IF(D23=1,0,IF(D23=2,1080+Z23,IF(D23=3,(1080*2)+Z23,0))) -> 0 | AB23: =((1080*D23)-((E23*60)+F23)*D23)+Z23 -> 43 | AC23: =IF(L22="GameStart",0,AA23+Z23) -> 0
A24: 13 | D24: =IF(L24="Intermission",D23+1,D23) -> 1 | E24: 17 | F24: 17 | I24: Home | J24: 70 | K24: e | L24: Pass | M24: Pass-Missed | N24: Pass-Stretch | Q24: 18977 | R24: Velodrome | S24: HollowBrook | T24: =IF(AND(G24="",H24=""),0,((E24*60)+F24)-((G24*60)+H24)) -> 0 | U24: =(E24*60)+F24 -> 1037 | V24: =IF(AND(G24="",H24=""),U24,((G24*60)+H24)) -> 1037 | W24: {=_xlfn._xlws.FILTER(shifts!A:A,(shifts!B:B=events!D24)*(shifts!AH:AH>=events!U24)*(shifts!AI:AI<=events!V24))} -> 1 | X24: =IF(K24="e","event_team_player_"&Y24,IF(K24="o","opp_team_player_"&Y24,"")) -> event_team_player_2 | Y24: =COUNTIFS(A$3:A24,"="&A24,K$3:K24,"="&K24) -> 2 | Z24: =SUMIFS(T$3:T24,L$3:L24,"=Intermission")+SUMIFS(T$3:T24,L$3:L24,"=Timeout")+SUMIFS(T$3:T24,L$3:L24,"=Clockstop") -> 0 | AA24: =IF(D24=1,0,IF(D24=2,1080+Z24,IF(D24=3,(1080*2)+Z24,0))) -> 0 | AB24: =((1080*D24)-((E24*60)+F24)*D24)+Z24 -> 43 | AC24: =IF(L23="GameStart",0,AA24+Z24) -> 0
A25: 14 | D25: =IF(L25="Intermission",D24+1,D24) -> 1 | E25: 17 | F25: 17 | I25: Home | J25: 87 | K25: e | L25: Zone_Entry_Exit | M25: Zone-Exit | N25: ZoneEntry-Pass | Q25: 18977 | R25: Velodrome | S25: HollowBrook | T25: =IF(AND(G25="",H25=""),0,((E25*60)+F25)-((G25*60)+H25)) -> 0 | U25: =(E25*60)+F25 -> 1037 | V25: =IF(AND(G25="",H25=""),U25,((G25*60)+H25)) -> 1037 | W25: {=_xlfn._xlws.FILTER(shifts!A:A,(shifts!B:B=events!D25)*(shifts!AH:AH>=events!U25)*(shifts!AI:AI<=events!V25))} -> 1 | X25: =IF(K25="e","event_team_player_"&Y25,IF(K25="o","opp_team_player_"&Y25,"")) -> event_team_player_1 | Y25: =COUNTIFS(A$3:A25,"="&A25,K$3:K25,"="&K25) -> 1 | Z25: =SUMIFS(T$3:T25,L$3:L25,"=Intermission")+SUMIFS(T$3:T25,L$3:L25,"=Timeout")+SUMIFS(T$3:T25,L$3:L25,"=Clockstop") -> 0 | AA25: =IF(D25=1,0,IF(D25=2,1080+Z25,IF(D25=3,(1080*2)+Z25,0))) -> 0 | AB25: =((1080*D25)-((E25*60)+F25)*D25)+Z25 -> 43 | AC25: =IF(L24="GameStart",0,AA25+Z25) -> 0
A26: 14 | D26: =IF(L26="Intermission",D25+1,D25) -> 1 | E26: 17 | F26: 17 | I26: Home | J26: 70 | K26: e | L26: Zone_Entry_Exit | M26: Zone-Exit | N26: ZoneEntry-Pass | Q26: 18977 | R26: Velodrome | S26: HollowBrook | T26: =IF(AND(G26="",H26=""),0,((E26*60)+F26)-((G26*60)+H26)) -> 0 | U26: =(E26*60)+F26 -> 1037 | V26: =IF(AND(G26="",H26=""),U26,((G26*60)+H26)) -> 1037 | W26: {=_xlfn._xlws.FILTER(shifts!A:A,(shifts!B:B=events!D26)*(shifts!AH:AH>=events!U26)*(shifts!AI:AI<=events!V26))} -> 1 | X26: =IF(K26="e","event_team_player_"&Y26,IF(K26="o","opp_team_player_"&Y26,"")) -> event_team_player_2 | Y26: =COUNTIFS(A$3:A26,"="&A26,K$3:K26,"="&K26) -> 2 | Z26: =SUMIFS(T$3:T26,L$3:L26,"=Intermission")+SUMIFS(T$3:T26,L$3:L26,"=Timeout")+SUMIFS(T$3:T26,L$3:L26,"=Clockstop") -> 0 | AA26: =IF(D26=1,0,IF(D26=2,1080+Z26,IF(D26=3,(1080*2)+Z26,0))) -> 0 | AB26: =((1080*D26)-((E26*60)+F26)*D26)+Z26 -> 43 | AC26: =IF(L25="GameStart",0,AA26+Z26) -> 0
A27: 15 | B27: 1 | D27: =IF(L27="Intermission",D26+1,D26) -> 1 | E27: 17 | F27: 14 | I27: Away | J27: 11 | K27: e | L27: Turnover | M27: Turnover-Takeaway | N27: Takeaway-PokeCheck | Q27: 18977 | R27: Velodrome | S27: HollowBrook | T27: =IF(AND(G27="",H27=""),0,((E27*60)+F27)-((G27*60)+H27)) -> 0 | U27: =(E27*60)+F27 -> 1034 | V27: =IF(AND(G27="",H27=""),U27,((G27*60)+H27)) -> 1034 | W27: {=_xlfn._xlws.FILTER(shifts!A:A,(shifts!B:B=events!D27)*(shifts!AH:AH>=events!U27)*(shifts!AI:AI<=events!V27))} -> 1 | X27: =IF(K27="e","event_team_player_"&Y27,IF(K27="o","opp_team_player_"&Y27,"")) -> event_team_player_1 | Y27: =COUNTIFS(A$3:A27,"="&A27,K$3:K27,"="&K27) -> 1 | Z27: =SUMIFS(T$3:T27,L$3:L27,"=Intermission")+SUMIFS(T$3:T27,L$3:L27,"=Timeout")+SUMIFS(T$3:T27,L$3:L27,"=Clockstop") -> 0 | AA27: =IF(D27=1,0,IF(D27=2,1080+Z27,IF(D27=3,(1080*2)+Z27,0))) -> 0 | AB27: =((1080*D27)-((E27*60)+F27)*D27)+Z27 -> 46 | AC27: =IF(L26="GameStart",0,AA27+Z27) -> 0
A28: 15 | B28: 1 | D28: =IF(L28="Intermission",D27+1,D27) -> 1 | E28: 17 | F28: 14 | I28: Away | J28: 75 | K28: o | L28: Turnover | M28: Turnover-Takeaway | N28: Takeaway-PokeCheck | Q28: 18977 | R28: Velodrome | S28: HollowBrook | T28: =IF(AND(G28="",H28=""),0,((E28*60)+F28)-((G28*60)+H28)) -> 0 | U28: =(E28*60)+F28 -> 1034 | V28: =IF(AND(G28="",H28=""),U28,((G28*60)+H28)) -> 1034 | W28: {=_xlfn._xlws.FILTER(shifts!A:A,(shifts!B:B=events!D28)*(shifts!AH:AH>=events!U28)*(shifts!AI:AI<=events!V28))} -> 1 | X28: =IF(K28="e","event_team_player_"&Y28,IF(K28="o","opp_team_player_"&Y28,"")) -> opp_team_player_1 | Y28: =COUNTIFS(A$3:A28,"="&A28,K$3:K28,"="&K28) -> 1 | Z28: =SUMIFS(T$3:T28,L$3:L28,"=Intermission")+SUMIFS(T$3:T28,L$3:L28,"=Timeout")+SUMIFS(T$3:T28,L$3:L28,"=Clockstop") -> 0 | AA28: =IF(D28=1,0,IF(D28=2,1080+Z28,IF(D28=3,(1080*2)+Z28,0))) -> 0 | AB28: =((1080*D28)-((E28*60)+F28)*D28)+Z28 -> 46 | AC28: =IF(L27="GameStart",0,AA28+Z28) -> 0
A29: 16 | B29: 1 | D29: =IF(L29="Intermission",D28+1,D28) -> 1 | E29: 17 | F29: 13 | G29: 17 | H29: 12 | I29: Away | J29: 11 | K29: e | L29: Possession | Q29: 18977 | R29: Velodrome | S29: HollowBrook | T29: =IF(AND(G29="",H29=""),0,((E29*60)+F29)-((G29*60)+H29)) -> 1 | U29: =(E29*60)+F29 -> 1033 | V29: =IF(AND(G29="",H29=""),U29,((G29*60)+H29)) -> 1032 | W29: {=_xlfn._xlws.FILTER(shifts!A:A,(shifts!B:B=events!D29)*(shifts!AH:AH>=events!U29)*(shifts!AI:AI<=events!V29))} -> 1 | X29: =IF(K29="e","event_team_player_"&Y29,IF(K29="o","opp_team_player_"&Y29,"")) -> event_team_player_1 | Y29: =COUNTIFS(A$3:A29,"="&A29,K$3:K29,"="&K29) -> 1 | Z29: =SUMIFS(T$3:T29,L$3:L29,"=Intermission")+SUMIFS(T$3:T29,L$3:L29,"=Timeout")+SUMIFS(T$3:T29,L$3:L29,"=Clockstop") -> 0 | AA29: =IF(D29=1,0,IF(D29=2,1080+Z29,IF(D29=3,(1080*2)+Z29,0))) -> 0 | AB29: =((1080*D29)-((E29*60)+F29)*D29)+Z29 -> 47 | AC29: =IF(L28="GameStart",0,AA29+Z29) -> 0
A30: 17 | B30: 1 | C30: 1 | D30: =IF(L30="Intermission",D29+1,D29) -> 1 | E30: 17 | F30: 12 | G30: 17 | H30: 10 | I30: Away | J30: 11 | K30: e | L30: Zone_Entry_Exit | M30: Zone-Entry | N30: ZoneEntry-Rush | Q30: 18977 | R30: Velodrome | S30: HollowBrook | T30: =IF(AND(G30="",H30=""),0,((E30*60)+F30)-((G30*60)+H30)) -> 2 | U30: =(E30*60)+F30 -> 1032 | V30: =IF(AND(G30="",H30=""),U30,((G30*60)+H30)) -> 1030 | W30: {=_xlfn._xlws.FILTER(shifts!A:A,(shifts!B:B=events!D30)*(shifts!AH:AH>=events!U30)*(shifts!AI:AI<=events!V30))} -> 1 | X30: =IF(K30="e","event_team_player_"&Y30,IF(K30="o","opp_team_player_"&Y30,"")) -> event_team_player_1 | Y30: =COUNTIFS(A$3:A30,"="&A30,K$3:K30,"="&K30) -> 1 | Z30: =SUMIFS(T$3:T30,L$3:L30,"=Intermission")+SUMIFS(T$3:T30,L$3:L30,"=Timeout")+SUMIFS(T$3:T30,L$3:L30,"=Clockstop") -> 0 | AA30: =IF(D30=1,0,IF(D30=2,1080+Z30,IF(D30=3,(1080*2)+Z30,0))) -> 0 | AB30: =((1080*D30)-((E30*60)+F30)*D30)+Z30 -> 48 | AC30: =IF(L29="GameStart",0,AA30+Z30) -> 0
A31: 17 | B31: 1 | C31: 1 | D31: =IF(L31="Intermission",D30+1,D30) -> 1 | E31: 17 | F31: 12 | G31: 17 | H31: 10 | I31: Away | J31: 19 | K31: e | L31: Zone_Entry_Exit | M31: Zone-Entry | N31: ZoneEntry-Rush | Q31: 18977 | R31: Velodrome | S31: HollowBrook | T31: =IF(AND(G31="",H31=""),0,((E31*60)+F31)-((G31*60)+H31)) -> 2 | U31: =(E31*60)+F31 -> 1032 | V31: =IF(AND(G31="",H31=""),U31,((G31*60)+H31)) -> 1030 | W31: {=_xlfn._xlws.FILTER(shifts!A:A,(shifts!B:B=events!D31)*(shifts!AH:AH>=events!U31)*(shifts!AI:AI<=events!V31))} -> 1 | X31: =IF(K31="e","event_team_player_"&Y31,IF(K31="o","opp_team_player_"&Y31,"")) -> event_team_player_2 | Y31: =COUNTIFS(A$3:A31,"="&A31,K$3:K31,"="&K31) -> 2 | Z31: =SUMIFS(T$3:T31,L$3:L31,"=Intermission")+SUMIFS(T$3:T31,L$3:L31,"=Timeout")+SUMIFS(T$3:T31,L$3:L31,"=Clockstop") -> 0 | AA31: =IF(D31=1,0,IF(D31=2,1080+Z31,IF(D31=3,(1080*2)+Z31,0))) -> 0 | AB31: =((1080*D31)-((E31*60)+F31)*D31)+Z31 -> 48 | AC31: =IF(L30="GameStart",0,AA31+Z31) -> 0
A32: 17 | B32: 1 | C32: 1 | D32: =IF(L32="Intermission",D31+1,D31) -> 1 | E32: 17 | F32: 12 | G32: 17 | H32: 10 | I32: Away | J32: 22 | K32: e | L32: Zone_Entry_Exit | M32: Zone-Entry | N32: ZoneEntry-Rush | Q32: 18977 | R32: Velodrome | S32: HollowBrook | T32: =IF(AND(G32="",H32=""),0,((E32*60)+F32)-((G32*60)+H32)) -> 2 | U32: =(E32*60)+F32 -> 1032 | V32: =IF(AND(G32="",H32=""),U32,((G32*60)+H32)) -> 1030 | W32: {=_xlfn._xlws.FILTER(shifts!A:A,(shifts!B:B=events!D32)*(shifts!AH:AH>=events!U32)*(shifts!AI:AI<=events!V32))} -> 1 | X32: =IF(K32="e","event_team_player_"&Y32,IF(K32="o","opp_team_player_"&Y32,"")) -> event_team_player_3 | Y32: =COUNTIFS(A$3:A32,"="&A32,K$3:K32,"="&K32) -> 3 | Z32: =SUMIFS(T$3:T32,L$3:L32,"=Intermission")+SUMIFS(T$3:T32,L$3:L32,"=Timeout")+SUMIFS(T$3:T32,L$3:L32,"=Clockstop") -> 0 | AA32: =IF(D32=1,0,IF(D32=2,1080+Z32,IF(D32=3,(1080*2)+Z32,0))) -> 0 | AB32: =((1080*D32)-((E32*60)+F32)*D32)+Z32 -> 48 | AC32: =IF(L31="GameStart",0,AA32+Z32) -> 0
A33: 17 | B33: 1 | C33: 1 | D33: =IF(L33="Intermission",D32+1,D32) -> 1 | E33: 17 | F33: 12 | G33: 17 | H33: 10 | I33: Away | J33: 84 | K33: o | L33: Zone_Entry_Exit | M33: Zone-Entry | N33: ZoneEntry-Rush | Q33: 18977 | R33: Velodrome | S33: HollowBrook | T33: =IF(AND(G33="",H33=""),0,((E33*60)+F33)-((G33*60)+H33)) -> 2 | U33: =(E33*60)+F33 -> 1032 | V33: =IF(AND(G33="",H33=""),U33,((G33*60)+H33)) -> 1030 | W33: {=_xlfn._xlws.FILTER(shifts!A:A,(shifts!B:B=events!D33)*(shifts!AH:AH>=events!U33)*(shifts!AI:AI<=events!V33))} -> 1 | X33: =IF(K33="e","event_team_player_"&Y33,IF(K33="o","opp_team_player_"&Y33,"")) -> opp_team_player_1 | Y33: =COUNTIFS(A$3:A33,"="&A33,K$3:K33,"="&K33) -> 1 | Z33: =SUMIFS(T$3:T33,L$3:L33,"=Intermission")+SUMIFS(T$3:T33,L$3:L33,"=Timeout")+SUMIFS(T$3:T33,L$3:L33,"=Clockstop") -> 0 | AA33: =IF(D33=1,0,IF(D33=2,1080+Z33,IF(D33=3,(1080*2)+Z33,0))) -> 0 | AB33: =((1080*D33)-((E33*60)+F33)*D33)+Z33 -> 48 | AC33: =IF(L32="GameStart",0,AA33+Z33) -> 0
A34: 17 | B34: 1 | C34: 1 | D34: =IF(L34="Intermission",D33+1,D33) -> 1 | E34: 17 | F34: 12 | G34: 17 | H34: 10 | I34: Away | J34: 87 | K34: o | L34: Zone_Entry_Exit | M34: Zone-Entry | N34: ZoneEntry-Rush | Q34: 18977 | R34: Velodrome | S34: HollowBrook | T34: =IF(AND(G34="",H34=""),0,((E34*60)+F34)-((G34*60)+H34)) -> 2 | U34: =(E34*60)+F34 -> 1032 | V34: =IF(AND(G34="",H34=""),U34,((G34*60)+H34)) -> 1030 | W34: {=_xlfn._xlws.FILTER(shifts!A:A,(shifts!B:B=events!D34)*(shifts!AH:AH>=events!U34)*(shifts!AI:AI<=events!V34))} -> 1 | X34: =IF(K34="e","event_team_player_"&Y34,IF(K34="o","opp_team_player_"&Y34,"")) -> opp_team_player_2 | Y34: =COUNTIFS(A$3:A34,"="&A34,K$3:K34,"="&K34) -> 2 | Z34: =SUMIFS(T$3:T34,L$3:L34,"=Intermission")+SUMIFS(T$3:T34,L$3:L34,"=Timeout")+SUMIFS(T$3:T34,L$3:L34,"=Clockstop") -> 0 | AA34: =IF(D34=1,0,IF(D34=2,1080+Z34,IF(D34=3,(1080*2)+Z34,0))) -> 0 | AB34: =((1080*D34)-((E34*60)+F34)*D34)+Z34 -> 48 | AC34: =IF(L33="GameStart",0,AA34+Z34) -> 0
A35: 18 | B35: 1 | C35: 1 | D35: =IF(L35="Intermission",D34+1,D34) -> 1 | E35: 17 | F35: 10 | I35: Away | J35: 11 | K35: e | L35: Shot | M35: Shot-Blocked | N35: Shot-Wrist | Q35: 18977 | R35: Velodrome | S35: HollowBrook | T35: =IF(AND(G35="",H35=""),0,((E35*60)+F35)-((G35*60)+H35)) -> 0 | U35: =(E35*60)+F35 -> 1030 | V35: =IF(AND(G35="",H35=""),U35,((G35*60)+H35)) -> 1030 | W35: {=_xlfn._xlws.FILTER(shifts!A:A,(shifts!B:B=events!D35)*(shifts!AH:AH>=events!U35)*(shifts!AI:AI<=events!V35))} -> 1 | X35: =IF(K35="e","event_team_player_"&Y35,IF(K35="o","opp_team_player_"&Y35,"")) -> event_team_player_1 | Y35: =COUNTIFS(A$3:A35,"="&A35,K$3:K35,"="&K35) -> 1 | Z35: =SUMIFS(T$3:T35,L$3:L35,"=Intermission")+SUMIFS(T$3:T35,L$3:L35,"=Timeout")+SUMIFS(T$3:T35,L$3:L35,"=Clockstop") -> 0 | AA35: =IF(D35=1,0,IF(D35=2,1080+Z35,IF(D35=3,(1080*2)+Z35,0))) -> 0 | AB35: =((1080*D35)-((E35*60)+F35)*D35)+Z35 -> 50 | AC35: =IF(L34="GameStart",0,AA35+Z35) -> 0
A36: 18 | B36: 1 | C36: 1 | D36: =IF(L36="Intermission",D35+1,D35) -> 1 | E36: 17 | F36: 10 | I36: Away | J36: 84 | K36: o | L36: Shot | M36: Shot-Blocked | N36: Shot-Wrist | Q36: 18977 | R36: Velodrome | S36: HollowBrook | T36: =IF(AND(G36="",H36=""),0,((E36*60)+F36)-((G36*60)+H36)) -> 0 | U36: =(E36*60)+F36 -> 1030 | V36: =IF(AND(G36="",H36=""),U36,((G36*60)+H36)) -> 1030 | W36: {=_xlfn._xlws.FILTER(shifts!A:A,(shifts!B:B=events!D36)*(shifts!AH:AH>=events!U36)*(shifts!AI:AI<=events!V36))} -> 1 | X36: =IF(K36="e","event_team_player_"&Y36,IF(K36="o","opp_team_player_"&Y36,"")) -> opp_team_player_1 | Y36: =COUNTIFS(A$3:A36,"="&A36,K$3:K36,"="&K36) -> 1 | Z36: =SUMIFS(T$3:T36,L$3:L36,"=Intermission")+SUMIFS(T$3:T36,L$3:L36,"=Timeout")+SUMIFS(T$3:T36,L$3:L36,"=Clockstop") -> 0 | AA36: =IF(D36=1,0,IF(D36=2,1080+Z36,IF(D36=3,(1080*2)+Z36,0))) -> 0 | AB36: =((1080*D36)-((E36*60)+F36)*D36)+Z36 -> 50 | AC36: =IF(L35="GameStart",0,AA36+Z36) -> 0
A37: 19 | D37: =IF(L37="Intermission",D36+1,D36) -> 1 | E37: 17 | F37: 07 | G37: 17 | H37: 04 | I37: Away | J37: 19 | K37: e | L37: Possession | Q37: 18977 | R37: Velodrome | S37: HollowBrook | T37: =IF(AND(G37="",H37=""),0,((E37*60)+F37)-((G37*60)+H37)) -> 3 | U37: =(E37*60)+F37 -> 1027 | V37: =IF(AND(G37="",H37=""),U37,((G37*60)+H37)) -> 1024 | W37: {=_xlfn._xlws.FILTER(shifts!A:A,(shifts!B:B=events!D37)*(shifts!AH:AH>=events!U37)*(shifts!AI:AI<=events!V37))} -> 1 | X37: =IF(K37="e","event_team_player_"&Y37,IF(K37="o","opp_team_player_"&Y37,"")) -> event_team_player_1 | Y37: =COUNTIFS(A$3:A37,"="&A37,K$3:K37,"="&K37) -> 1 | Z37: =SUMIFS(T$3:T37,L$3:L37,"=Intermission")+SUMIFS(T$3:T37,L$3:L37,"=Timeout")+SUMIFS(T$3:T37,L$3:L37,"=Clockstop") -> 0 | AA37: =IF(D37=1,0,IF(D37=2,1080+Z37,IF(D37=3,(1080*2)+Z37,0))) -> 0 | AB37: =((1080*D37)-((E37*60)+F37)*D37)+Z37 -> 53 | AC37: =IF(L36="GameStart",0,AA37+Z37) -> 0
A38: 20 | D38: =IF(L38="Intermission",D37+1,D37) -> 1 | E38: 17 | F38: 03 | I38: Away | J38: 19 | K38: e | L38: Turnover | M38: Turnover-Giveaway | N38: Giveaway-Misplayed | Q38: 18977 | R38: Velodrome | S38: HollowBrook | T38: =IF(AND(G38="",H38=""),0,((E38*60)+F38)-((G38*60)+H38)) -> 0 | U38: =(E38*60)+F38 -> 1023 | V38: =IF(AND(G38="",H38=""),U38,((G38*60)+H38)) -> 1023 | W38: {=_xlfn._xlws.FILTER(shifts!A:A,(shifts!B:B=events!D38)*(shifts!AH:AH>=events!U38)*(shifts!AI:AI<=events!V38))} -> 1 | X38: =IF(K38="e","event_team_player_"&Y38,IF(K38="o","opp_team_player_"&Y38,"")) -> event_team_player_1 | Y38: =COUNTIFS(A$3:A38,"="&A38,K$3:K38,"="&K38) -> 1 | Z38: =SUMIFS(T$3:T38,L$3:L38,"=Intermission")+SUMIFS(T$3:T38,L$3:L38,"=Timeout")+SUMIFS(T$3:T38,L$3:L38,"=Clockstop") -> 0 | AA38: =IF(D38=1,0,IF(D38=2,1080+Z38,IF(D38=3,(1080*2)+Z38,0))) -> 0 | AB38: =((1080*D38)-((E38*60)+F38)*D38)+Z38 -> 57 | AC38: =IF(L37="GameStart",0,AA38+Z38) -> 0
A39: 20 | D39: =IF(L39="Intermission",D38+1,D38) -> 1 | E39: 17 | F39: 03 | I39: Away | J39: 49 | K39: o | L39: Turnover | M39: Turnover-Giveaway | N39: Giveaway-Misplayed | Q39: 18977 | R39: Velodrome | S39: HollowBrook | T39: =IF(AND(G39="",H39=""),0,((E39*60)+F39)-((G39*60)+H39)) -> 0 | U39: =(E39*60)+F39 -> 1023 | V39: =IF(AND(G39="",H39=""),U39,((G39*60)+H39)) -> 1023 | W39: {=_xlfn._xlws.FILTER(shifts!A:A,(shifts!B:B=events!D39)*(shifts!AH:AH>=events!U39)*(shifts!AI:AI<=events!V39))} -> 1 | X39: =IF(K39="e","event_team_player_"&Y39,IF(K39="o","opp_team_player_"&Y39,"")) -> opp_team_player_1 | Y39: =COUNTIFS(A$3:A39,"="&A39,K$3:K39,"="&K39) -> 1 | Z39: =SUMIFS(T$3:T39,L$3:L39,"=Intermission")+SUMIFS(T$3:T39,L$3:L39,"=Timeout")+SUMIFS(T$3:T39,L$3:L39,"=Clockstop") -> 0 | AA39: =IF(D39=1,0,IF(D39=2,1080+Z39,IF(D39=3,(1080*2)+Z39,0))) -> 0 | AB39: =((1080*D39)-((E39*60)+F39)*D39)+Z39 -> 57 | AC39: =IF(L38="GameStart",0,AA39+Z39) -> 0
A40: 21 | D40: =IF(L40="Intermission",D39+1,D39) -> 1 | E40: 17 | F40: 01 | I40: Home | J40: 49 | K40: e | L40: Zone_Entry_Exit | M40: Zone-Exit | N40: ZoneEntry-Pass | Q40: 18977 | R40: Velodrome | S40: HollowBrook | T40: =IF(AND(G40="",H40=""),0,((E40*60)+F40)-((G40*60)+H40)) -> 0 | U40: =(E40*60)+F40 -> 1021 | V40: =IF(AND(G40="",H40=""),U40,((G40*60)+H40)) -> 1021 | W40: {=_xlfn._xlws.FILTER(shifts!A:A,(shifts!B:B=events!D40)*(shifts!AH:AH>=events!U40)*(shifts!AI:AI<=events!V40))} -> 1 | X40: =IF(K40="e","event_team_player_"&Y40,IF(K40="o","opp_team_player_"&Y40,"")) -> event_team_player_1 | Y40: =COUNTIFS(A$3:A40,"="&A40,K$3:K40,"="&K40) -> 1 | Z40: =SUMIFS(T$3:T40,L$3:L40,"=Intermission")+SUMIFS(T$3:T40,L$3:L40,"=Timeout")+SUMIFS(T$3:T40,L$3:L40,"=Clockstop") -> 0 | AA40: =IF(D40=1,0,IF(D40=2,1080+Z40,IF(D40=3,(1080*2)+Z40,0))) -> 0 | AB40: =((1080*D40)-((E40*60)+F40)*D40)+Z40 -> 59 | AC40: =IF(L39="GameStart",0,AA40+Z40) -> 0
...

Sheet shifts
A1: shift_index | B1: Period | C1: shift_start_min | D1: shift_start_sec | E1: shift_end_min | F1: shift_end_sec | G1: shift_start_type | H1: shift_stop_type | I1: home_forward_1 | J1: home_forward_2 | K1: home_forward_3 | L1: home_defense_1 | M1: home_defense_2 | N1: home_xtra | O1: home_goalie | P1: away_forward_1 | Q1: away_forward_2 | R1: away_forward_3 | S1: away_defense_1 | T1: away_defense_2 | U1: away_xtra | V1: away_goalie | W1: stoppage_time | X1: clock_stoped | Y1: home_ozone_start | Z1: home_ozone_end | AA1: home_dzone_start | AB1: home_dzone_end | AC1: home_nzone_start | AD1: home_nzone_end | AE1: game_id | AF1: home_team | AG1: away_team | AH1: shift_start_total_seconds | AI1: shift_end_total_seconds | AJ1: shift_duration | AK1: home_team_strength | AL1: away_team_strength | AM1: home_team_en | AN1: away_team_en | AO1: home_team_pk | AP1: home_team_pp | AQ1: away_team_pp | AR1: away_team_pk | AS1: situation | AT1: strength | AU1: home_goals | AV1: away_goals
A2: 1 | B2: 1 | C2: =IF(G2<>"PeriodStart",E1,18) -> 18 | D2: 0 | E2: 16 | F2: 56 | G2: PeriodStart | I2: 70 | J2: 75 | K2: 49 | L2: 84 | M2: 87 | O2: 39 | P2: 11 | Q2: 19 | R2: 22 | S2: 33 | T2: 27 | V2: 99 | W2: =SUMIFS(events!T:T,events!L:L,"=DeadIce",events!U:U,"<="&shifts!AH2,events!V:V,">"&shifts!AI2,events!D:D,"="&shifts!B3)+SUMIFS(events!T:T,events!L:L,"=Timeout",events!U:U,"<="&shifts!AH2,events!V:V,">"&shifts!AI2,events!D:D,"="&shifts!B3) -> 0 | X2: =SUMIFS(events!U:U,events!M:M,"=DeadIce",events!V:V,"<="&shifts!AI2,events!W:W,">"&shifts!AJ2) -> 0 | Z2: 1 | AC2: 1 | AE2: 18977 | AF2: Velodrome | AG2: HollowBrook | AH2: =((C2*60)+D2) | AI2: =((E2*60)+F2) -> 1016 | AJ2: =ROUND(AH2-AI2,0) -> #VALUE! | AK2: =COUNTIF(I2:N2,">0") -> 5 | AL2: =COUNTIF(P2:U2,">0") -> 5 | AM2: =IF(O2="",1,0) -> 0 | AN2: =IF(V2="",1,0) -> 0 | AO2: =IF(AND($AM2<>1,$AK2<$AL2,AN2<>1),1,) -> 0 | AP2: =IF(AND($AM2<>1,$AK2>$AL2),1,) -> 0 | AQ2: =IF(AO2=1,1,0) -> 0 | AR2: =IF(AP2=1,1,0) -> 0 | AS2: =IF(AND(AK2=5,AL2=5,AM2=0,AN2=0),"Full Strength",IF(AQ2=1,"Away PowerPlay",IF(AP2=1,"Home PowerPlay",IF(AM2=1,"Home EmptyNet",IF(AN2=1,"Away EmptyNet",""))))) -> Full Strength | AT2: =IF(AND(AM2=0,AN2=0),AK2&"v"&AL2,IF(AM2=1,AK2&"v"&AL2&" Home EN",IF(AN2=1,AK2&"v"&AL2&" Away EN",""))) -> 5v5
A3: 2 | B3: =IF(G3="PeriodStart",B2+1,B2) -> 1 | C3: =IF(G3<>"PeriodStart",E2,18) -> 16 | D3: 56 | E3: 16 | F3: 40 | H3: Home Goalie Stopped (after Away SOG) | I3: 70 | J3: 75 | K3: 49 | L3: 84 | M3: 87 | O3: 39 | P3: 11 | Q3: 19 | R3: 22 | S3: 33 | T3: 27 | V3: 99 | W3: =SUMIFS(events!T:T,events!L:L,"=DeadIce",events!U:U,"<="&shifts!AH3,events!V:V,">"&shifts!AI3,events!D:D,"="&shifts!B4)+SUMIFS(events!T:T,events!L:L,"=Timeout",events!U:U,"<="&shifts!AH3,events!V:V,">"&shifts!AI3,events!D:D,"="&shifts!B4) -> 0 | Y3: =IF(OR($H2="Home Goal",$H2="Away Goal",$H2="Period End"),"",IF(Z2=1,1,"")) -> 1 | AA3: =IF(OR($H2="Home Goal",$H2="Away Goal",$H2="Period End"),"",IF(AB2=1,1,"")) | AB3: 1 | AC3: =IF(OR($H2="Home Goal",$H2="Away Goal",$H2="Period End"),1,IF(AD2=1,1,"")) | AE3: 18977 | AF3: Velodrome | AG3: HollowBrook | AH3: =((C3*60)+D3) -> 1016 | AI3: =((E3*60)+F3) -> 1000 | AJ3: =ROUND(AH3-AI3,0) -> 16 | AK3: =COUNTIF(I3:N3,">0") -> 5 | AL3: =COUNTIF(P3:U3,">0") -> 5 | AM3: =IF(O3="",1,0) -> 0 | AN3: =IF(V3="",1,0) -> 0 | AO3: =IF(AND($AM3<>1,$AK3<$AL3,AN3<>1),1,) -> 0 | AP3: =IF(AND($AM3<>1,$AK3>$AL3),1,) -> 0 | AQ3: =IF(AO3=1,1,0) -> 0 | AR3: =IF(AP3=1,1,0) -> 0 | AS3: =IF(AND(AK3=5,AL3=5,AM3=0,AN3=0),"Full Strength",IF(AQ3=1,"Away PowerPlay",IF(AP3=1,"Home PowerPlay",IF(AM3=1,"Home EmptyNet",IF(AN3=1,"Away EmptyNet",""))))) -> Full Strength | AT3: =IF(AND(AM3=0,AN3=0),AK3&"v"&AL3,IF(AM3=1,AK3&"v"&AL3&" Home EN",IF(AN3=1,AK3&"v"&AL3&" Away EN",""))) -> 5v5
