Workbook
Name DEfensive: Lists!$CQ:$CQ
Name EventType: Lists!$A$2:$A$16
Name Faceoff: Lists!$U$2:$U$1048576
Name Goal: Lists!$X$2:$X$1048576
Name Goal_PenaltyShot: Lists!$BO$2:$BO$1048576
Name Goal_Scored: Lists!$BM$2:$BM$1048576
Name Goal_Shootout: Lists!$BN$2:$BN$1048576
Name LoosePuck: Lists!$AD$2:$AD$1048576
Name Offensive: Lists!$CO:$CO
Name Pass: Lists!$W$2:$W$1048576
Name Pass_Completed: Lists!$AF$2:$AF$1048576
Name Pass_Deflected: Lists!$AH$2:$AH$1048576
Name Pass_Intercepted: Lists!$AI$2:$AI$1048576
Name Pass_Missed: Lists!$AG$2:$AG$1048576
Name Penalty: Lists!$AA$2:$AA$1048576
Name Penalty_Major: Lists!$AO$2:$AO$1048576
Name Penalty_Minor: Lists!$AP$2:$AP$1048576
Name Penalty_Offsetting: Lists!$AQ$2:$AQ$1048576
Name PenaltyShot_Missed: Lists!$AY$2:$AY$1048576
Name PenaltyShot_OnNet: Lists!$AX$2:$AX$1048576
Name PenaltyShot_Saved: Lists!$AZ$2:$AZ$1048576
Name PenaltyShot_Shootout: Lists!$AB$2:$AB$1048576
Name Play: Lists!$T:$T
Name Play_Defensive: Lists!$BS:$BS
Name Play_Offensive: Lists!$BR:$BR
Name Possession: Lists!$BT:$BT
Name Rebound: Lists!$BQ$2:$BQ$1048576
Name Save: Lists!$AE$2:$AE$1048576
Name Save_Freeze: Lists!$BB$2:$BB$1048576
Name Save_Played: Lists!$BP:$BP
Name Save_Rebound: Lists!$BA$2:$BA$1048576
Name Shootout_Missed: Lists!$AV$2:$AV$1048576
Name Shootout_OnNet: Lists!$AU$2:$AU$1048576
Name Shootout_Saved: Lists!$AW$2:$AW$1048576
Name Shot: Lists!$V$2:$V$1048576
Name Shot_Blocked: Lists!$BE$2:$BE$1048576
Name Shot_BlockedSameTeam: Lists!$BF$2:$BF$1048576
Name Shot_Deflected: Lists!$BG$2:$BG$1048576
Name Shot_DeflectedGoal: Lists!$BL$2:$BL$1048576
Name Shot_DeflectedOnNetSaved: Lists!$BH$2:$BH$1048576
Name Shot_Missed: Lists!$BD$2:$BD$1048576
Name Shot_MissedPost: Lists!$BW:$BW
Name Shot_OnNetGoal: Lists!$BJ$2:$BJ$1048576
Name Shot_OnNetSaved: Lists!$BC$2:$BC$1048576
Name Shot_TippedGoal: Lists!$BK$2:$BK$1048576
Name Shot_TippedOnNetSaved: Lists!$BI$2:$BI$1048576
Name Stoppage: Lists!$AC$2:$AC$1048576
Name Stoppage_Other: Lists!$AT$2:$AT$1048576
Name Stoppage_Period: Lists!$AS$2:$AS$1048576
Name Stoppage_Play: Lists!$AR$2:$AR$1048576
Name Turnover: Lists!$Y$2:$Y$1048576
Name Turnover_Giveaway: Lists!$AJ$2:$AJ$1048576
Name Turnover_Takeaway: Lists!$AK$2:$AK$1048576
Name Zone_Entry: Lists!$AL$2:$AL$1048576
Name Zone_Entry_Exit: Lists!$Z$2:$Z$1048576
Name Zone_EntryFailed: Lists!$DG:$DG
Name Zone_Exit: Lists!$AM$2:$AM$1048576
Name Zone_ExitFailed: Lists!$DH:$DH
Name Zone_Keepin: Lists!$AN$2:$AN$1048576

Sheet examples
A1: shift_index | B1: Period | C1: shift_start_min | D1: shift_start_sec | E1: shift_end_min | F1: shift_end_sec | G1: shift_start_type | H1: shift_stop_type | I1: home_forward_1 | J1: home_forward_2 | K1: home_forward_3 | L1: home_defense_1 | M1: home_defense_2 | N1: home_xtra | O1: home_goalie | P1: away_forward_1 | Q1: away_forward_2 | R1: away_forward_3 | S1: away_defense_1 | T1: away_defense_2 | U1: away_xtra | V1: away_goalie | W1: stoppage_time | X1: home_ozone_start | Y1: home_ozone_end | Z1: home_dzone_start | AA1: home_dzone_end | AB1: home_nzone_start | AC1: home_nzone_end | AD1: game_id | AE1: home_team | AF1: away_team | AG1: shift_start_total_seconds | AH1: shift_end_total_seconds | AI1: shift_duration | AJ1: home_team_strength | AK1: away_team_strength | AL1: home_team_en | AM1: away_team_en | AN1: home_team_pk | AO1: home_team_pp | AP1: away_team_pp | AQ1: away_team_pk | AR1: situation | AS1: strength | AT1: home_goals | AU1: away_goals | AV1: period_start_total_running_seconds | AW1: running_video_time | AX1: shift_start_running_time | AY1: shift_end_running_time
A2: 40 | B2: 1 | C2: 2 | D2: 07 | E2: 0 | F2: 35 | G2: OtherFaceoff | H2: Away Goalie Stopped (after Home SOG) | I2: 42 | J2: 14 | K2: 61 | L2: 22 | M2: 9 | O2: 39 | P2: 91 | Q2: 80 | R2: 89 | S2: 4 | T2: 25 | V2: 30 | Y2: 1
A3: 41 | B3: 1 | C3: 0 | D3: 35 | E3: 0 | F3: 0.01 | G3: OtherFaceoff | H3: Period End | I3: 42 | J3: 14 | K3: 61 | L3: 22 | M3: 9 | O3: 39 | P3: 77 | Q3: 13 | R3: 68 | S3: 4 | T3: 25 | V3: 30 | Y3: 1
A4: 42 | B4: 1 | G4: Intermission
A5: 43 | B5: 2 | C5: 18 | D5: 0 | E5: 17 | F5: 18 | G5: PeriodStart | H5: Away Goalie Stopped (after Home SOG) | I5: 70 | J5: 14 | K5: 55 | L5: 91 | M5: 84 | O5: 39 | P5: 77 | Q5: 13 | R5: 68 | S5: 44 | T5: 18 | V5: 30 | Y5: 1
A8: 105 | B8: 3 | C8: 1 | D8: 01 | E8: 0 | F8: 49 | I8: 42 | J8: 24 | K8: 61 | L8: 91 | M8: 84 | O8: 39 | P8: 77 | Q8: 12 | R8: 68 | S8: 44 | T8: 18 | V8: 30 | AA8: 1
A9: 106 | B9: 3 | C9: 0 | D9: 49 | E9: 0 | F9: 0.01 | H9: GameEnd | I9: 42 | J9: 24 | K9: 61 | L9: 91 | M9: 84 | O9: 39 | P9: 77 | Q9: 12 | R9: 56 | S9: 44 | T9: 18 | U9: 3 | AA9: 1
A10: 107 | B10: 3 | C10: 0 | D10: 0.01
A25: event_index | B25: linked_event_index_ | C25: linked_event_index | D25: tracking_event_index | E25: sequence_index | F25: play_index | G25: zone_change_index | H25: Period | I25: event_start_min_ | J25: event_start_sec_ | K25: event_end_min_ | L25: event_end_sec_ | M25: event_start_min | N25: event_start_sec | O25: event_end_min | P25: event_end_sec | Q25: Team_ | R25: Player | S25: role_abrev_binary | T25: role_abrev | U25: Type_ | V25: event_detail_ | W25: event_detail_2_ | X25: successful | Y25: play_detail1 | Z25: play_detail2 | AA25: play_detail_successful | AB25: context | AC25: play_tag1 | AD25: play_tag2 | AE25: high_danger | AF25: event_team_zone | AG25: home_team_zone | AH25: away_team_zone | AI25: forced_forcer | AJ25: pressured_pressurer
A27: 599 | H27: 1 | I27: 0 | J27: 01 | Q27: a | R27: 13 | S27: 1 | T27: e | U27: Shot | V27: Shot_Missed | W27: Shot-Backhand | X27: u | AF27: o | AJ27: 1 | AM27: Shot | AN27: Shot_Missed | AP27: Offensive
A28: 599 | H28: 1 | R28: 9 | T28: o | Y28: Defensive_PlayPossession-StickCheck | AA28: s | AJ28: 1 | AM28: Shot | AN28: Shot_Missed | AP28: Defensive
A29: 600 | H29: 1 | I29: 0 | J29: 00 | T29: o | U29: Stoppage | V29: Stoppage_Period | W29: Stoppage-PeriodEnd | AM29: Stoppage | AN29: Stoppage_Period
A30: 601 | H30: 2 | I30: 56 | J30: 46 | K30: 55 | L30: 39 | T30: o | U30: Intermission | AM30: Intermission
A31: 602 | H31: 2 | I31: 18 | J31: 00 | Q31: h | R31: 70 | S31: 1 | T31: e | U31: Faceoff | V31: Faceoff_PeriodStart | AF31: n | AM31: Faceoff | AN31: Faceoff_PeriodStart | AP31: Offensive
A34: 1438 | B34: 223 | H34: 3 | I34: 5 | J34: 55 | Q34: h | R34: 61 | S34: 1 | T34: e | U34: Shot | V34: Shot_Goal | AF34: o | AM34: Shot | AN34: Shot_Goal | AP34: Offensive
A35: 1438 | B35: 223 | H35: 3 | R35: 30 | T35: o | AM35: Shot | AN35: Shot_Goal | AP35: Defensive
A36: 1439 | B36: 223 | H36: 3 | I36: 5 | J36: 55 | Q36: h | R36: 61 | S36: 1 | T36: e | U36: Goal | V36: Goal_Scored | W36: Goal-Wrist | AF36: o | AM36: Goal | AN36: Goal_Scored | AP36: Offensive
A37: 1439 | B37: 223 | H37: 3 | R37: 30 | T37: o | AM37: Goal | AN37: Goal_Scored | AP37: Defensive
A38: 1440 | B38: 223 | H38: 3 | I38: 5 | J38: 55 | Q38: h | R38: 61 | S38: 1 | T38: e | U38: Stoppage | V38: Stoppage_Play | W38: Stoppage-Goal | AF38: o | AJ38: 1 | AM38: Stoppage | AN38: Stoppage_Play
A39: 1441 | B39: 223 | H39: 3 | I39: 5 | J39: 55 | K39: 5 | L39: 31 | Q39: h | R39: 61 | S39: 1 | T39: e | U39: DeadIce | AF39: o | AJ39: 1 | AM39: DeadIce
A43: 1590 | H43: 3 | I43: 0 | J43: 26 | Q43: h | R43: 84 | S43: 1 | T43: e | U43: Penalty_Delayed | AF43: d | AJ43: 1 | AM43: Penalty_Delayed | AP43: Offensive
A44: 1590 | H44: 3 | R44: 3 | T44: o | AJ44: 1 | AM44: Penalty_Delayed | AP44: Defensive
A45: 1591 | B45: 247 | H45: 3 | I45: 0 | J45: 25 | Q45: a | R45: 18 | S45: 1 | T45: e | U45: Shot | V45: Shot_OnNetSaved | W45: Shot-Wrist | X45: s | AF45: o | AM45: Shot | AN45: Shot_OnNetSaved | AP45: Offensive
A46: 1591 | B46: 247 | H46: 3 | R46: 77 | S46: 1 | T46: e | Y46: OffensivePlay_Shot-Screen | AM46: Shot | AN46: Shot_OnNetSaved | AP46: Offensive
A47: 1591 | B47: 247 | H47: 3 | R47: 39 | T47: o | AM47: Shot | AN47: Shot_OnNetSaved | AP47: Defensive
A48: 1592 | B48: 247 | H48: 3 | I48: 0 | J48: 25 | Q48: h | R48: 39 | S48: 1 | T48: e | U48: Save | V48: Save_Rebound | W48: Save-Blocker | AF48: d | AM48: Save | AN48: Save_Rebound | AP48: Defensive
A49: 1592 | B49: 247 | H49: 3 | R49: 18 | T49: o | AM49: Save | AN49: Save_Rebound | AP49: Offensive
A50: 1592 | B50: 247 | H50: 3 | R50: 77 | T50: o | Y50: OffensivePlay_Shot-Screen | AM50: Save | AN50: Save_Rebound | AP50: Offensive
A51: 1593 | B51: 247 | H51: 3 | I51: 0 | J51: 25 | Q51: h | R51: 39 | S51: 1 | T51: e | AF51: d | AP51: Offensive
A52: 1594 | H52: 3 | I52: 0 | J52: 21 | Q52: a | R52: 56 | S52: 1 | T52: e | U52: Possession | V52: PuckRecovery | X52: u | Y52: OffensivePlay_Zone-PuckRecoveryShot | AA52: u | AF52: o | AM52: Possession | AN52: PuckRecovery | AP52: Offensive
A53: 1595 | H53: 3 | I53: 0 | J53: 21 | Q53: a | R53: 56 | S53: 1 | T53: e | U53: Pass | V53: Pass_Missed | W53: Pass-Forehand | X53: u | Y53: OffensivePlay_Pass-SecondTouch | AA53: u | AF53: o | AJ53: 1 | AM53: Pass | AN53: Pass_Missed | AP53: Offensive
A54: 1595 | H54: 3 | R54: 3 | S54: 1 | T54: e | AM54: Pass | AN54: Pass_Missed | AP54: Offensive
A55: 1595 | H55: 3 | R55: 91 | T55: o | AJ55: 1 | AM55: Pass | AN55: Pass_Missed | AP55: Defensive
A56: 1596 | H56: 3 | I56: 0 | J56: 21 | Q56: h | S56: 1 | T56: e | U56: Zone_Entry_Exit | V56: Zone_Exit | W56: ZoneExit-OppTeam | AF56: d | AM56: Zone_Entry_Exit | AN56: Zone_Exit | AP56: Offensive
A57: 1597 | H57: 3 | I57: 0 | J57: 17 | K57: 0 | L57: 15 | Q57: a | R57: 44 | S57: 1 | T57: e | U57: Possession | V57: PuckRecovery | X57: s | Y57: OffensivePlay_Zone-PuckRecoveryTurnover | AA57: s | AF57: n | AM57: Possession | AN57: PuckRecovery | AP57: Offensive
A58: 1598 | H58: 3 | I58: 0 | J58: 15 | Q58: a | R58: 44 | S58: 1 | T58: e | U58: Pass | V58: Pass_Completed | W58: Pass-Forehand | X58: s | AF58: n | AM58: Pass | AN58: Pass_Completed | AP58: Offensive
A59: 1598 | H59: 3 | R59: 18 | S59: 1 | T59: e | AM59: Pass | AN59: Pass_Completed | AP59: Offensive
A60: 1599 | H60: 3 | I60: 0 | J60: 14 | Q60: a | R60: 18 | S60: 1 | T60: e | U60: Zone_Entry_Exit | V60: Zone_Entry | W60: ZoneEntry-Rush | X60: u | AF60: o | AJ60: 1 | AM60: Zone_Entry_Exit | AN60: Zone_Entry | AP60: Offensive
A61: 1599 | H61: 3 | R61: 24 | T61: o | AJ61: 1 | AM61: Zone_Entry_Exit | AN61: Zone_Entry | AP61: Defensive
A62: 1600 | H62: 3 | I62: 0 | J62: 12 | Q62: h | R62: 24 | S62: 1 | T62: e | U62: Turnover | V62: Turnover_Takeaway | W62: Takeaway-BattleWon | X62: s | Y62: Defensive_PlayPossession-SeperateFromPuck | AA62: s | AF62: d | AJ62: 1 | AM62: Turnover | AN62: Turnover_Takeaway | AP62: Defensive
...

Sheet Sheet1
A1: duration | C1: context
A2: time_start_total_seconds | C2: play_tag1
A3: time_end_total_seconds | C3: play_tag2
A4: shift_index | C4: high_danger
A5: player_role
A6: role_number
A7: running_intermission_duration
A8: period_start_total_running_seconds
A9: running_video_time
A10: event_running_start
A11: event_running_end
A12: event_id
A13: linked_event_id
A14: play_id
A15: sequence_id
A16: zone_change_id
... A72: possession_change

Sheet Rules
A1: EventType | B1: Definition | C1: Next Event | D1: Uses | E1: Linked Events | F1: Successful/Unsuccessful | G1: Successful Def | J1: EventTypeDetail | K1: Definition | L1: Next Event | M1: Uses | N1: Linked Events | O1: Successful/Unsuccessful | P1: Successful Def | S1: EventTypeDetail2 | T1: Definition | U1: Next Event | V1: Uses | W1: Linked Events | X1: Successful/Unsuccessful | Y1: Successful Def | AC1: Definition | AD1: Next Event | AE1: Uses | AF1: Linked Events | AG1: Successful/Unsuccessful | AH1: Successful Def | AL1: Definition | AM1: Next Event | AN1: Uses | AO1: Linked Events | AP1: Linked Events | AQ1: Successful/Unsuccessful | AR1: Successful Def | AT1: play_tag1 | AU1: Definition | AV1: Next Event | AW1: Uses | AX1: Linked Events | AZ1: play_tag2 | BA1: Definition | BB1: Next Event | BC1: Uses | BD1: Linked Events | BF1: Context | BG1: Definition | BH1: Next Event | BI1: Uses | BJ1: Linked Events | BM1: shift_start | BN1: Definition | BO1: Next Event | BP1: Linked Events | BR1: shift_end | BS1: Definition | BT1: Next Event | BU1: Linked Events
A2: Faceoff | J2: Faceoff | S2: PenaltyShot/Shootout | AB2: Offensive | AH2: sucessful if next play positive | AK2: Defensive | AR2: sucessful if next play positive | AT2: LowToHigh | AZ2: Rush | BF2: LeadToBreakout | BM2: PeriodStart | BR2: -
A3: Shot | E3: Save | J3: Faceoff-AfterPenalty | S3: PenaltyShot_OnNet | X3: s | AB3: OffensivePlay_Possession-DriveMiddle | AK3: Defensive_PlayPossession-PokeCheck | AT3: HighToLow | AZ3: Cycle | BF3: LeadToZoneEntry | BM3: FaceoffAfterGoal | BR3: Period Start
A4: Pass | J4: Faceoff-AfterGoal | S4: PenaltyShot_Missed | X4: u | AB4: OffensivePlay_Possession-DriveWide | AK4: Defensive_PlayPossession-SeperateFromPuck | AT4: CrossIce | AZ4: Forecheck | BF4: LeadToTurnover | BM4: GameStart | BR4: Period End
A5: Goal | E5: Shot | J5: Faceoff-PeriodStart | S5: PenaltyShot_Saved | X5: s | AB5: OffensivePlay_Possession-DriveCorner | AK5: Defensive_PlayPossession-Backcheck | AT5: Slot | AZ5: Dumpin | BF5: LeadToShot | BM5: FaceoffAfterPenalty | BR5: Puck Out of Play
A6: Turnover | E6: Pass, Shot, Play | J6: Shot-OnNet | S6: ShootoutShot_OnNet | X6: s | AB6: OffensivePlay_Possession-DriveNetMiddle | AK6: Defensive_PlayPossession-FroceWide | AZ6: Regroup | BF6: LeadToGoal | BM6: OtherFaceoff | BR6: Injury
A7: Zone_Entry_Exit | E7: Pass, Turnover, Attempted Failed, Keepins | J7: Shot-Missed | S7: ShootoutShot_Missed | X7: u | AB7: OffensivePlay_Possession-DriveNetWide | AK7: Defensive_PlayPossession-Contain | AZ7: Counter | BF7: LeadToPenalty | BM7: DeadIce/Stoppage | BR7: Home Penalty
A8: Penalty | J8: Shot-Blocked | S8: ShootoutShot_Saved | X8: s | AB8: OffensivePlay_Possession-CrashNet | AK8: Defensive_PlayPossession-BeatMiddle | AZ8: ZoneExit | BF8: LeadToFailedBreakout | BM8: Intermission | BR8: Away Penalty
A9: PenaltyShot_Shootout | J9: Shot-BlockedSameTeam | AB9: OffensivePlay_Possession-Delay | AK9: Defensive_PlayPossession-BeatWide | AZ9: ZoneEntry | BF9: LeadToFailedZoneEntry | BM9: DelayedPenalty | BR9: Home Goalie Stoppage
A10: Stoppage | E10: Save Freeze | J10: Shot-Deflected | S10: Stoppage_Period | AB10: OffensivePlay_Possession-Deke | AK10: Defensive_PlayPossession-BeatDeke | AZ10: Clear | BM10: GameStart | BR10: Away Goalie Stoppage
A11: Hit | J11: Shot-DeflectedOnNet | S11: Stoppage_Play | AB11: OffensivePlay_Possession-Chip | AK11: Defensive_PlayPossession-BeatSpeed | BR11: Home Offside
A12: Possession | J12: Shot-Tipped | S12: Stoppage_Other | AB12: OffensivePlay_Possession-Other | AK12: Defensive_PlayPossession-Pressure | BR12: Home Icing
A13: LoosePuck | J13: Pass-Completed | S13: Stoppage_GameEnd | AB13: OffensivePlay_Possession-Speed | AK13: Defensive_PlayPossession-Zone | BR13: Away Offside
A14: Save | E14: Shot, Stoppage, Deadice | J14: Pass-Missed | AB14: OffensivePlay_Possession-OpenIceDeke | AK14: Defensive_PlayPossession-ManOnMan | BR14: Away Icing
A15: TeamPossessionChange | J15: Pass-Deflected | S15: Save_Rebound | AB15: OffensivePlay_Possession-EndToEndRush | AK15: Defensive_PlayPossession-Tracker | BR15: Clock Problem
A16: Rebound | E16: Shot, Save | J16: Pass-Intercepted | S16: Save_Freeze | AB16: OffensivePlay_Possession-FrontofNet | AK16: Defensive_PlayPossession-Surf | BR16: Puck Frozen
A17: DeadIce | J17: Turnover-Giveaway | S17: Save_Played | AB17: OffensivePlay_Possession-CutBack | AK17: Defensive_PlayPossession-StickCheck | BR17: Puck in Crowd
A18: Play | J18: Turnover-Takeaway | AB18: OffensivePlay_Possession-Wheel | AK18: Defensive_PlayPass-PassIntercepted | BR18: Goalie Stopped (after SOG)
A19: Timeout | J19: Zone-Entry | S19: Pass-Stretch | X19: s/u | AB19: OffensivePlay_Possession-ForecedOutside | AK19: Defensive_PlayPass-InShotPassLane | BR19: Referee or Linesperson
A20: Intermission | J20: Zone-Exit | S20: Pass-Rim/Wrap | X20: s/u | AB20: OffensivePlay_Pass-AssistPrimary | AK20: Defensive_PlayShot-BoxOut | BR20: High Stick
A21: Clockstop | J21: Zone-Keepin | S21: Pass-Backhand | X21: s/u | AB21: OffensivePlay_Pass-AssistSecondary | AK21: Defensive_PlayShot-BlockedShot | BR21: Objects on Ice
A22: GameStart | J22: Zone_Entryfailed | S22: Pass-Forehand | X22: s/u | AB22: OffensivePlay_Pass-AssistTertiary | AK22: Defensive_PlayShot-FrontofNet | BR22: Hand Pass
A23: GameEnd | J23: Zone_ExitFailed | S23: Pass-Bank | X23: s/u | AB23: OffensivePlay_Pass-GiveAndGo | AK23: Defensive_PlayZone-ClearingAttempt | BR23: Premature Substitution
A24: Penalty_Delayed | J24: Zone_KeepinFailed | S24: Pass-Dump | X24: s/u | AB24: OffensivePlay_Pass-Reverse | AK24: Defensive_PlayZone-ZoneEntryDenial | BR24: Puck in Netting
A25: Zone_Change | J25: Penalty | S25: Pass-Tipped | X25: s/u | AB25: OffensivePlay_Pass-QuickUp | AK25: Defensive_PlayZone-ZoneExitDenial | BR25: Puck in Benches
J26: Penalty-Offsetting | S26: Pass-Lob | X26: s/u | AB26: OffensivePlay_Pass-SecondTouch | AK26: Defensive_PlayZone-PenaltyKillClear | BR26: Net Dislodged Offensive Skater
J27: Stoppage-Freeze | S27: Pass-Drop | X27: s/u | AB27: OffensivePlay_Pass-ReceiverMissed | AK27: Defensive_PlayZone-PuckRetrievalDumpIn | BR27: Puck Frzn-Goalie-Bynd Ctr
J28: Stoppage-OutfofPlay | S28: Pass-Deflected/TippedShot | X28: s/u | AB28: OffensivePlay_Shot-Screen | AK28: Defensive_PlayZone-PuckRetrievalShot | BR28: Skater Puck Frozen
J29: Stoppage-PeriodEnd | S29: Pass-ReceiverMissed | X29: s/u | AB29: OffensivePlay_Zone-Breakout | AK29: Defensive_PlayZone-PuckRetreivalTurnover | BR29: Valid stoppage type reasons (reason):
J30: Stoppage-Goal | S30: Pass-OneTouch | X30: s/u | AB30: OffensivePlay_Zone-DumpChase | AK30: Defensive_PlayZone-PuckRetreivalPass | BR30: TV timeout
J31: Stoppage-Penalty | S31: Pass-SecondTouch | X31: s/u | AB31: OffensivePlay_Zone-Forecheck | AK31: Defensive_PlayZone-PuckRetrievalRebound | BR31: Home Timeout
J32: Shootout-OnNet | S32: Pass-QuickUp | X32: s/u | AB32: OffensivePlay_Zone-Dump/RimInZone | AK32: Defensive_PlayZone-PuckRecoveryDumpIn | BR32: Visitor Timeout
J33: Shootout-Missed | S33: Pass-GiveAndGo | X33: s/u | AB33: OffensivePlay_Zone-DumpInAttempt | AK33: Defensive_PlayZone-PuckRecoveryShot | BR33: Player Injury
J34: Shootout-Saved | S34: Pass-Reverse | X34: s/u | AB34: OffensivePlay_Zone-Breakout | AK34: Defensive_PlayZone-PuckRecoveryTurnover | BR34: Official Injury
J35: PenaltyShot-OnNet | S35: Pass-Other | X35: s/u | AB35: OffensivePlay_Zone-Cycle | AK35: Defensive_PlayZone-PuckRecoveryPass | BR35: Rink Repair
J36: PenaltyShot-Missed | AB36: OffensivePlay_Zone-PuckRetrievalDumpIn | AK36: Defensive_PlayZone-PuckRecoveryRebound | BR36: Ice problem
J37: PenaltyShot-Saved | S37: Giveaway-Misplayed | AB37: OffensivePlay_Zone-PuckRetrievalShot | AK37: Defensive_PlayZone-ForcedDumpin/Clear | BR37: Player Equipment
J38: LoosePuck-Forecheck | S38: Giveaway-BattleLost | AB38: OffensivePlay_Zone-PuckRetreivalTurnover | AK38: Offensive_Zone-AttemptedKeepin | BR38: Video Review
J39: LoosePuck-Battle | S39: Giveaway-PassIntercepted | AB39: OffensivePlay_Zone-PuckRetreivalPass | AK39: Defensive_Zone-AttemptedBreakOutPass | BR39: Chlg Hm - off-side
J40: Save-Rebound | S40: Giveaway-PassMissed | AB40: OffensivePlay_Zone-PuckRetreivalRebound | AK40: Defensive_Zone-AttemptedBreakOutRush | BR40: Chlg Vis - off-side
...

Sheet Lists
A1: EventType | C1: EventTypeDetail | E1: EventTypeDetail2 | G1: OffensivePlay | I1: DefensivePlay | K1: Team | N1: NHL Net | O1: Max | P1: Min | Q1: Total Max | R1: Total Min | T1: Play | U1: Faceoff | V1: Shot | W1: Pass | X1: Goal | Y1: Turnover | Z1: Zone Entry/Exit | AA1: Penalty | AB1: PenaltyShot/Shootout | AC1: Stoppage | AD1: LoosePuck | AE1: Save | AF1: Pass-Completed | AG1: Pass-Missed | AH1: Pass-Deflected | AI1: Pass-Intercepted | AJ1: Turnover-Giveaway | AK1: Turnover-Takeaway | AL1: Zone-Entry | AM1: Zone-Exit | AN1: Zone-Keepin | AO1: Penalty-Major | AP1: Penalty-Minor | AQ1: Penalty-Offsetting | AR1: Stoppage-Play | AS1: Stoppage-Period | AT1: Stoppage-Other | AU1: Shootout-OnNet | AV1: Shootout-Missed | AW1: Shootout-Saved | AX1: PenaltyShot-OnNet | AY1: PenaltyShot-Missed | AZ1: PenaltyShot-Saved | BA1: Save-Rebound | BB1: Save-Freeze | BC1: Shot_OnNetSaved | BD1: Shot_Missed | BE1: Shot_Blocked | BF1: Shot_BlockedSameTeam | BG1: Shot_Deflected | BH1: Shot_DeflectedOnNetSaved | BI1: Shot_TippedOnNetSaved | BJ1: Shot_OnNetGoal | BK1: Shot_TippedGoal | BL1: Shot_DeflectedGoal | BM1: Goal_Scored | BN1: Goal_Shootout | BO1: Goal_PenaltyShot | BP1: Save_Played | BQ1: Rebound | BR1: Play_Offensive | BS1: Play_Defensive | BT1: Possession | BU1: Faceoff | BV1: None | BW1: Shot_MissedPost | CA1: shift_start | CC1: shift_end | CE1: label | CG1: play_detail1 | CH1: play_detail2 | CL1: Offensive | CM1: Defensive | CO1: Offensive | CQ1: Defensive | CS1: play_tag1 | CU1: play_tag2 | CW1: Context | CY1: Offensive | DD1: Defensive | DG1: Zone-EntryFailed | DH1: Zone-ExitFailed | DI1: Zone-KeepinFailed
K2: Home | L2: =K3 -> Away | N2: X | O2: 36 | P2: -36 | Q2: =O2+O4 -> 38.375 | R2: =P2-O4 -> -38.375 | T2: Play_Offensive | U2: Faceoff_AfterPenalty | V2: Shot_OnNetSaved | W2: Pass_Completed | X2: Goal_Scored | Y2: Turnover_Giveaway | Z2: Zone_Entry | AA2: Penalty_Minor | AB2: PenaltyShot_OnNet | AC2: Stoppage_Period | AD2: LoosePuck_Forecheck | AE2: Save_Rebound | AF2: Pass-Stretch | AG2: Pass-Stretch | AH2: Pass-Stretch | AI2: Pass-Stretch | AJ2: Giveaway-Misplayed | AK2: Takeaway-BattleWon | AL2: ZoneEntry-Rush | AM2: ZoneExit-Rush | AN2: Zone-KeepIn | AO2: Penalty-Bench Penalty | AP2: Penalty-Bench Penalty | AQ2: Penalty-Bench Penalty | AR2: Stoppage-Icing | AS2: Stoppage-StartofShootout | AT2: Stoppage-ObjectsonIce | AU2: Shot-Wrist | AV2: Shot-Wrist | AW2: Shot-Wrist | AX2: Shot-Wrist | AY2: Shot-Wrist | AZ2: Shot-Wrist | BA2: Save-Glove | BB2: Save-Glove | BC2: Shot-Wrist | BD2: Shot-Wrist | BE2: Shot-Wrist | BF2: Shot-Wrist | BG2: Shot-Deflection | BH2: Shot-Deflection | BI2: Shot-Tip | BJ2: Shot-Wrist | BL2: Shot-Deflection | BM2: Goal-Wrist | BN2: Goal-Wrist | BO2: Goal-Wrist | BP2: Save-Glove | BQ2: Rebound_TeamRecovered | BS2: Play-PokeCheck | BT2: Breakaway | BU2: Shot | BV2: All | BW2: Shot-Wrist | BX2: event_team_player_1 | BY2: e | CA2: PeriodStart | CC2: - | CE2: Assist-Primary | CG2: OffensivePlay-DriveMiddle | CJ2: Offensive | CL2: OffensivePlay-Drive | CO2: AssistPrimary | CQ2: AttemptedBlockedShot | CS2: LowToHigh | CU2: Rush | CW2: LeadToBreakout | CY2: OffensivePlay_ | CZ2: Possession | DA2: DriveMiddle | DD2: Defensive_Play | DE2: Possession | DF2: PokeCheck | DG2: ZoneEntry-Rush | DH2: ZoneExit-Rush | DI2: Zone-KeepIn
A3: Faceoff | B3: None | C3: Faceoff | E3: Shot-Wrist | G3: DriveMiddle | I3: PokeCheck | K3: Away | L3: =K2 -> Home | N3: Y | O3: 24 | P3: -24 | Q3: =O3+O5 -> 26.375 | R3: -24 | T3: Play_Defensive | U3: Faceoff_AfterGoal | V3: Shot_Missed | W3: Pass_Missed | X3: Goal_Shootout | Y3: Turnover_Takeaway | Z3: Zone_Exit | AA3: Penalty_Offsetting | AB3: PenaltyShot_Missed | AC3: Stoppage_Play | AD3: LoosePuck_Battle | AE3: Save_Freeze | AF3: Pass-Rim/Wrap | AG3: Pass-Rim/Wrap | AH3: Pass-Rim/Wrap | AI3: Pass-Rim/Wrap | AJ3: Giveaway-BattleLost | AK3: Takeaway-PokeCheck | AL3: ZoneEntry-Pass | AM3: ZoneExit-Pass | AN3: Zone-Pinch | AO3: Penalty-Boarding | AP3: Penalty-Boarding | AQ3: Penalty-Boarding | AR3: Stoppage-Offsides | AS3: Stoppage-PeriodStart | AT3: Stoppage-HomeTimeout | AU3: Shot-Slap | AV3: Shot-Slap | AW3: Shot-Slap | AX3: Shot-Slap | AY3: Shot-Slap | AZ3: Shot-Slap | BA3: Save-Blocker | BB3: Save-Blocker | BC3: Shot-Slap | BD3: Shot-Slap | BE3: Shot-Slap | BF3: Shot-Slap | BG3: Shot-Wrist | BH3: Shot-Wrist | BI3: Shot-Wrist | BJ3: Shot-Slap | BK3: Shot-Wrist | BL3: Shot-Wrist | BM3: Goal-Slap | BN3: Goal-Slap | BO3: Goal-Slap | BP3: Save-Blocker | BQ3: Rebound_OppTeamRecovered | BR3: Play-DriveMiddle | BS3: Play-PokeCheckFailed | BT3: PuckRetrieval | BU3: Pass | BV3: Involved | BW3: Shot-Slap | BX3: event_team_player_2 | BY3: o | CA3: FaceoffAfterGoal | CC3: Period Start | CE3: Assist-Secondary | CG3: OffensivePlay-DriveWide | CJ3: Defensive | CO3: AssistSecondary | CQ3: AttemptedBreakOutClear | CS3: HighToLow | CU3: Cycle | CW3: LeadToZoneEntry | CY3: OffensivePlay_ | CZ3: Possession | DA3: DriveWide | DD3: Defensive_Play | DE3: Possession | DF3: SeperateFromPuck | DG3: ZoneEntry-Pass | DH3: ZoneExit-Pass | DI3: Zone-Pinch
A4: Shot | C4: Faceoff-AfterPenalty | E4: Shot-Slap | G4: DriveWide | I4: PokeCheckFailed | N4: PostX | O4: 2.375 | U4: Faceoff_PeriodStart | V4: Shot_Blocked | W4: Pass_Deflected | X4: Goal_PenaltyShot | Z4: Zone_Keepin | AA4: Penalty_Major | AB4: PenaltyShot_Saved | AC4: Stoppage_Other | AE4: Save_Played | AF4: Pass-Backhand | AG4: Pass-Backhand | AH4: Pass-Backhand | AI4: Pass-Backhand | AJ4: Giveaway-PassIntercepted | AK4: Takeaway-PassIntercepted | AL4: ZoneEntry-DumpIn | AM4: ZoneExit-Clear | AN4: Zone-Other | AO4: Penalty-Charging | AP4: Penalty-Charging | AQ4: Penalty-Charging | AR4: Stoppage-ClockProblem | AS4: Stoppage-PeriodEnd | AT4: Stoppage-VisitorTimeout | AU4: Shot-Backhand | AV4: Shot-Backhand | AW4: Shot-Backhand | AX4: Shot-Backhand | AY4: Shot-Backhand | AZ4: Shot-Backhand | BA4: Save-LeftPad | BB4: Save-LeftPad | BC4: Shot-Backhand | BD4: Shot-Backhand | BE4: Shot-Backhand | BF4: Shot-Backhand | BG4: Shot-Slap | BH4: Shot-Slap | BI4: Shot-Slap | BJ4: Shot-Backhand | BK4: Shot-Slap | BL4: Shot-Slap | BM4: Goal-Backhand | BN4: Goal-Backhand | BO4: Goal-Backhand | BP4: Save-LeftPad | BQ4: Rebound_ShotGenerated | BR4: Play-DriveWide | BS4: Play-SeperateFromPuck | BT4: PuckRecovery | BU4: Goal | BV4: All | BW4: Shot-Backhand | BX4: event_team_player_3 | CA4: GameStart | CC4: Period End | CE4: Breakout | CG4: OffensivePlay-DriveCorner | CO4: AssistTertiary | CQ4: AttemptedBreakOutPass | CS4: CrossIce | CU4: Forecheck | CW4: LeadToTurnover | CY4: OffensivePlay_ | CZ4: Possession | DA4: DriveCorner | DD4: Defensive_Play | DE4: Possession | DF4: Backcheck | DG4: ZoneEntry-DumpIn | DH4: ZoneExit-Clear | DI4: Zone-Other
A5: Pass | C5: Faceoff-AfterGoal | E5: Shot-Backhand | G5: DriveCorner | I5: SeperateFromPuck | N5: PostY | O5: 2.375 | U5: Faceoff_AfterStoppage | V5: Shot_BlockedSameTeam | W5: Pass_Intercepted | Z5: Zone_Entryfailed | AB5: ShootoutShot_OnNet | AC5: Stoppage_GameEnd | AF5: Pass-Forehand | AG5: Pass-Forehand | AH5: Pass-Forehand | AI5: Pass-Forehand | AJ5: Giveaway-PassMissed | AK5: Takeaway-PassBlocked | AL5: ZoneEntry-Chip | AM5: ZoneExit-Chip | AO5: Penalty-CrossChecking | AP5: Penalty-CrossChecking | AQ5: Penalty-CrossChecking | AR5: Stoppage-HighStick | AT5: Stoppage-RinkRepair | AU5: Shot-Snap | AV5: Shot-Snap | AW5: Shot-Snap | AX5: Shot-Snap | AY5: Shot-Snap | AZ5: Shot-Snap | BA5: Save-RightPad | BB5: Save-RightPad | BC5: Shot-Snap | BD5: Shot-Snap | BE5: Shot-Snap | BF5: Shot-Snap | BG5: Shot-Backhand | BH5: Shot-Backhand | BI5: Shot-Backhand | BJ5: Shot-Snap | BK5: Shot-Backhand | BL5: Shot-Backhand | BM5: Goal-Tip | BN5: Goal-Snap | BO5: Goal-Snap | BP5: Save-RightPad | BQ5: Rebound_FlurryGenerated | BR5: Play-DriveCorner | BS5: Play-Backcheck | BT5: Regroup | BU5: Turnover | BV5: Involved | BW5: Shot-Snap | BX5: event_team_player_4 | CA5: FaceoffAfterPenalty | CC5: Puck Out of Play | CE5: End-to-End-Rush | CG5: OffensivePlay-DriveNetMiddle | CO5: AttemptedBreakOutClear | CQ5: AttemptedBreakOutRush | CS5: Slot | CU5: Dumpin | CW5: LeadToShot | CY5: OffensivePlay_ | CZ5: Possession | DA5: DriveNetMiddle | DD5: Defensive_Play | DE5: Possession | DF5: FroceWide | DG5: ZoneEntry-Chip | DH5: ZoneExit-Chip
A6: Goal | C6: Faceoff-PeriodStart | E6: Shot-Tip | G6: DriveNetMiddle | I6: Backcheck | U6: Faceoff_GameStart | V6: Shot_Deflected | Z6: Zone_ExitFailed | AB6: ShootoutShot_Missed | AF6: Pass-Bank | AG6: Pass-Bank | AH6: Pass-Bank | AI6: Pass-Bank | AJ6: Giveaway-PassBlocked | AK6: Takeaway-ShotBlocked | AL6: ZoneEntry-FromExitClear | AM6: ZoneExit-PassMiss/Misplay | AO6: Penalty-DelayofGame | AP6: Penalty-DelayofGame | AQ6: Penalty-DelayofGame | AR6: Stoppage-HandPass | AT6: Stoppage-PlayerEquipment | AU6: Shot-WrapAround | AV6: Shot-WrapAround | AW6: Shot-WrapAround | AX6: Shot-WrapAround | AY6: Shot-WrapAround | AZ6: Shot-WrapAround | BA6: Save-Stick | BB6: Save-Stick | BC6: Shot-WrapAround | BD6: Shot-WrapAround | BE6: Shot-WrapAround | BF6: Shot-WrapAround | BG6: Shot-Snap | BH6: Shot-Snap | BI6: Shot-Snap | BJ6: Shot-WrapAround | BK6: Shot-Snap | BL6: Shot-Snap | BM6: Goal-Snap | BN6: Goal-WrapAround | BO6: Goal-WrapAround | BP6: Save-Stick | BR6: Play-DriveNetMiddle | BS6: Play-FroceWide | BU6: Zone_Entry_Exit | BV6: Involved | BW6: Shot-WrapAround | BX6: event_team_player_5 | CA6: OtherFaceoff | CC6: Injury | CG6: OffensivePlay-DriveNetWide | CO6: AttemptedBreakOutPass | CQ6: AttemptedEntryDumpIn | CU6: Regroup | CW6: LeadToGoal | CY6: OffensivePlay_ | CZ6: Possession | DA6: DriveNetWide | DD6: Defensive_Play | DE6: Possession | DF6: Contain | DG6: ZoneEntry-FromExitClear | DH6: ZoneExit-PassMiss/Misplay
A7: Turnover | C7: Shot-OnNet | E7: Shot-Snap | G7: DriveNetWide | I7: FroceWide | V7: Shot_DeflectedOnNetSaved | Z7: Zone_KeepinFailed | AB7: ShootoutShot_Saved | AF7: Pass-Dump | AG7: Pass-Dump | AH7: Pass-Dump | AI7: Pass-Dump | AJ7: Giveaway-PassReceiverMissed | AK7: Takeaway-ZoneClear/Dump | AL7: ZoneEntry-PassMiss/Misplay | AM7: ZoneExit-OppTeam | AO7: Penalty-Diving | AP7: Penalty-Diving | AQ7: Penalty-Diving | AR7: Stoppage-NetDislodged | AT7: Stoppage-Challenge | AU7: Shot-Bat | AV7: Shot-Bat | AW7: Shot-Bat | AX7: Shot-Bat | AY7: Shot-Bat | AZ7: Shot-Bat | BA7: Save-Scramble | BB7: Save-Scramble | BC7: Shot-Bat | BD7: Shot-Bat | BE7: Shot-Bat | BF7: Shot-Bat | BG7: Shot-WrapAround | BH7: Shot-WrapAround | BI7: Shot-WrapAround | BJ7: Shot-Bat | BK7: Shot-WrapAround | BL7: Shot-WrapAround | BM7: Goal-WrapAround | BN7: Goal-Bat | BO7: Goal-Bat | BP7: Save-Scramble | BR7: Play-DriveNetWide | BS7: Play-Contain | BU7: Penalty | BV7: Involved | BW7: Shot-Bat | BX7: event_team_player_6 | CA7: DeadIce/Stoppage | CC7: Home Penalty | CG7: OffensivePlay-CrashNet | CO7: AttemptedBreakOutRush | CQ7: AttemptedEntryPass | CU7: Counter | CW7: LeadToPenalty | CY7: OffensivePlay_ | CZ7: Possession | DA7: CrashNet | DD7: Defensive_Play | DE7: Possession | DF7: BeatMiddle | DG7: ZoneEntry-PassMiss/Misplay | DH7: ZoneExit-OppTeam
A8: Zone_Entry_Exit | C8: Shot-Missed | E8: Shot-WrapAround | G8: CrashNet | I8: Contain | V8: Shot_Tipped | AF8: Pass-Tipped | AG8: Pass-Tipped | AH8: Pass-Tipped | AI8: Pass-Tipped | AJ8: Giveaway-ShotBlocked | AK8: Takeaway-AttemptedZoneClear/Dump | AL8: ZoneEntry-OppTeam | AM8: ZoneExit-Lob | AO8: Penalty-Elbowing | AP8: Penalty-Elbowing | AQ8: Penalty-Elbowing | AR8: Stoppage-Injury | AT8: Stoppage-Other | AU8: Shot-Cradle | AV8: Shot-Cradle | AW8: Shot-Cradle | AX8: Shot-Cradle | AY8: Shot-Cradle | AZ8: Shot-Cradle | BA8: Save-Butterfly | BB8: Save-Butterfly | BC8: Shot-Cradle | BD8: Shot-Cradle | BE8: Shot-Cradle | BF8: Shot-Cradle | BG8: Shot-Bat | BH8: Shot-Bat | BI8: Shot-Bat | BJ8: Shot-Cradle | BK8: Shot-Bat | BL8: Shot-Bat | BM8: Goal-Bat | BN8: Goal-Cradle | BO8: Goal-Cradle | BP8: Save-Butterfly | BR8: Play-CrashNet | BS8: Play-BeatMiddle | BU8: PenaltyShot_Shootout | BV8: Involved | BW8: Shot-Cradle | BX8: opp_team_player_1 | CA8: Intermission | CC8: Away Penalty | CG8: OffensivePlay-Delay | CO8: AttemptedEntryDumpIn | CQ8: AttemptedEntryRush | CU8: ZoneExit | CW8: LeadToFailedBreakout | CY8: OffensivePlay_ | CZ8: Possession | DA8: Delay | DD8: Defensive_Play | DE8: Possession | DF8: BeatWide | DG8: ZoneEntry-OppTeam | DH8: ZoneExit-Lob
A9: Penalty | C9: Shot-Blocked | E9: Shot-Bat | G9: Delay | I9: BeatMiddle | V9: Shot_TippedOnNetSaved | AF9: Pass-Lob | AG9: Pass-Lob | AH9: Pass-Lob | AI9: Pass-Lob | AJ9: Giveaway-ShotMissed | AK9: Takeaway-Other | AL9: ZoneEntry-Lob | AM9: ZoneExit-CausedTurnover | AO9: Penalty-GoalieInterference | AP9: Penalty-GoalieInterference | AQ9: Penalty-GoalieInterference | AR9: Stoppage-GoalieStoppage | AU9: Shot-Poke | AV9: Shot-Poke | AW9: Shot-Poke | AX9: Shot-Poke | AY9: Shot-Poke | AZ9: Shot-Poke | BA9: Save-Chest | BB9: Save-Chest | BC9: Shot-Poke | BD9: Shot-Poke | BE9: Shot-Poke | BF9: Shot-Poke | BG9: Shot-Cradle | BH9: Shot-Cradle | BI9: Shot-Cradle | BJ9: Shot-Poke | BK9: Shot-Cradle | BL9: Shot-Cradle | BM9: Goal-Cradle | BN9: Goal-Poke | BO9: Goal-Poke | BP9: Save-Chest | BR9: Play-Delay | BS9: Play-BeatWide | BU9: Stoppage | BV9: None | BW9: Shot-Poke | BX9: opp_team_player_2 | CA9: DelayedPenalty | CC9: Home Goalie Stoppage | CG9: OffensivePlay-Deke | CO9: AttemptedEntryPass | CQ9: AttemptedKeepin | CU9: ZoneEntry | CW9: LeadToFailedZoneEntry | CY9: OffensivePlay_ | CZ9: Possession | DA9: Deke | DD9: Defensive_Play | DE9: Possession | DF9: BeatDeke | DG9: ZoneEntry-Lob | DH9: ZoneExit-CausedTurnover
A10: PenaltyShot_Shootout | C10: Shot-BlockedSameTeam | E10: Shot-Cradle | G10: Deke | I10: BeatWide | V10: Shot_OnNetGoal | AF10: Pass-Drop | AG10: Pass-Drop | AH10: Pass-Drop | AI10: Pass-Drop | AJ10: Giveaway-ZoneClear/Dump | AL10: ZoneEntry-RushBreakaway | AM10: ZoneExit-PenaltyKillClear | AO10: Penalty-HighSticking | AP10: Penalty-HighSticking | AQ10: Penalty-HighSticking | AR10: Stoppage-PuckOutofPlay | AU10: Shot-BetweenLegs | AV10: Shot-BetweenLegs | AW10: Shot-BetweenLegs | AX10: Shot-BetweenLegs | AY10: Shot-BetweenLegs | AZ10: Shot-BetweenLegs | BA10: Save-Shoulder | BB10: Save-Shoulder | BC10: Shot-BetweenLegs | BD10: Shot-BetweenLegs | BE10: Shot-BetweenLegs | BF10: Shot-BetweenLegs | BG10: Shot-Poke | BH10: Shot-Poke | BI10: Shot-Poke | BJ10: Shot-BetweenLegs | BK10: Shot-Poke | BL10: Shot-Poke | BM10: Goal-Poke | BN10: Goal-BetweenLegs | BO10: Goal-BetweenLegs | BP10: Save-Other | BR10: Play-Deke | BS10: Play-BeatDeke | BU10: Hit | BV10: Involved | BW10: Shot-BetweenLegs | BX10: opp_team_player_3 | CA10: GameStart | CC10: Away Goalie Stoppage | CG10: OffensivePlay-Chip | CO10: AttemptedEntryRush | CQ10: Backcheck | CU10: Clear | CY10: OffensivePlay_ | CZ10: Possession | DA10: Chip | DD10: Defensive_Play | DE10: Possession | DF10: BeatSpeed | DG10: ZoneEntry-RushBreakaway | DH10: ZoneExit-PenaltyKillClear
A11: Stoppage | C11: Shot-Deflected | E11: Shot-Poke | G11: Chip | I11: BeatDeke | V11: Shot_OnNetTippedGoal | AF11: Pass-Deflected/TippedShot | AG11: Pass-Deflected/TippedShot | AH11: Pass-Deflected/TippedShot | AI11: Pass-Deflected/TippedShot | AJ11: Giveaway-AttemptedZoneClear/Dump | AL11: ZoneEntry-CausedTurnover | AM11: ZoneExit-Shot | AO11: Penalty-Holding | AP11: Penalty-Holding | AQ11: Penalty-Holding | AR11: Stoppage-Penalty | AU11: Shot-Tip | AV11: Shot-Tip | AW11: Shot-Other | AX11: Shot-Other | AY11: Shot-Other | AZ11: Shot-Other | BA11: Save-Skate | BB11: Save-Skate | BC11: Shot-Dumpin | BD11: Shot-Dumpin | BE11: Shot-Dumpin | BF11: Shot-Dumpin | BG11: Shot-BetweenLegs | BH11: Shot-BetweenLegs | BI11: Shot-BetweenLegs | BJ11: Shot-Dumpin | BK11: Shot-BetweenLegs | BL11: Shot-BetweenLegs | BM11: Goal-BetweenLegs | BN11: Goal-Other | BO11: Goal-Other | BR11: Play-Chip | BS11: Play-BeatSpeed | BU11: Possession | BV11: Involved | BW11: Shot-Dumpin | BX11: opp_team_player_4 | CC11: Home Offside | CG11: OffensivePlay-Other | CO11: AttemptedKeepin | CQ11: BeatDeke | CY11: OffensivePlay_ | CZ11: Possession | DA11: Other | DD11: Defensive_Play | DE11: Possession | DF11: Pressure | DG11: ZoneEntry-CausedTurnover | DH11: ZoneExit-Other
A12: Hit | C12: Shot-DeflectedOnNet | E12: Shot-BetweenLegs | G12: Other | I12: BeatSpeed | V12: Shot_OnNetDeflectedGoal | AF12: Pass-ReceiverMissed | AG12: Pass-ReceiverMissed | AH12: Pass-ReceiverMissed | AI12: Pass-ReceiverMissed | AJ12: Giveaway-ZoneEntry/ExitMisplay | AL12: ZoneEntry-PenaltyKillClear | AM12: ZoneExit-Other | AO12: Penalty-Interference | AP12: Penalty-Interference | AQ12: Penalty-Interference | AR12: Stoppage-Goal | AU12: Shot-Other | AV12: Shot-Other | BA12: Save-Other | BB12: Save-Other | BC12: Shot-OneTime | BD12: Shot-OneTime | BE12: Shot-OneTime | BF12: Shot-OneTime | BG12: Shot-Dumpin | BH12: Shot-Dumpin | BI12: Shot-Dumpin | BJ12: Shot-OneTime | BK12: Shot-Dumpin | BL12: Shot-Dumpin | BM12: Goal-Dumpin | BR12: Play-Other | BS12: Play-BoxOut | BU12: LoosePuck | BV12: None | BW12: Shot-OneTime | BX12: opp_team_player_5 | CC12: Home Icing | CG12: OffensivePlay-DumpChase | CO12: Breakout | CQ12: BeatFake | CY12: OffensivePlay_ | CZ12: Possession | DA12: Speed | DD12: Defensive_Play | DE12: Possession | DF12: Zone | DG12: ZoneEntry-PenaltyKillClear
A13: Possession | C13: Shot-Tipped | E13: Shot-Dumpin | G13: DumpChase | I13: BoxOut | V13: Shot_Goal | AF13: Pass-OneTouch | AG13: Pass-Other | AH13: Pass-Other | AI13: Pass-Other | AJ13: Giveaway-DumpInZone | AL13: ZoneEntry-Shot | AO13: Penalty-Hooking | AP13: Penalty-Fighting | AQ13: Penalty-Fighting | BC13: Shot-Tip | BD13: Shot_Tipped | BE13: Shot_Tipped | BF13: Shot_Tipped | BG13: Shot-OneTime | BH13: Shot-OneTime | BI13: Shot-OneTime | BJ13: Shot-Other | BK13: Shot-OneTime | BL13: Shot-OneTime | BM13: Goal-Deflection | BR13: Play-DumpChase | BS13: Play-AttemptedClear | BU13: Save | BV13: Involved | BW13: Shot_Tipped | BX13: opp_team_player_6 | CC13: Away Offside | CG13: OffensivePlay-Forecheck | CO13: Breakout | CQ13: BeatMiddle | CY13: OffensivePlay_ | CZ13: Possession | DA13: OpenIceDeke | DD13: Defensive_Play | DE13: Possession | DF13: ManOnMan | DG13: ZoneEntry-Other
A14: LoosePuck | C14: Pass-Completed | E14: Shot-Deflection | G14: Forecheck | I14: Other | V14: Shot_MissedPost | AF14: Pass-SecondTouch | AG14: Pass-SecondTouch | AH14: Pass-SecondTouch | AI14: Pass-SecondTouch | AJ14: Giveaway-Other | AL14: ZoneEntry-Other | AO14: Penalty-Roughing | AP14: Penalty-Hooking | AQ14: Penalty-Hooking | BC14: Shot-Other | BD14: Shot-Other | BE14: Shot-Other | BF14: Shot-Other | BG14: Shot-Other | BH14: Shot-Other | BI14: Shot-Other | BJ14: Shot-Deflection | BK14: Shot-Other | BL14: Shot-Other | BM14: Goal-OneTime | BR14: Play-Forecheck | BS14: Play-Other | BU14: TeamPossessionChange | BV14: None | BW14: Shot-Other | CC14: Away Icing | CG14: OffensivePlay-Speed | CO14: CededZoneEntry | CQ14: BeatSpeed | CY14: OffensivePlay_ | CZ14: Possession | DA14: EndToEndRush | DD14: Defensive_Play | DE14: Possession | DF14: Tracker
A15: Save | C15: Pass-Missed | E15: Shot-OneTime | G15: Speed | AF15: Pass-QuickUp | AG15: Pass-QuickUp | AH15: Pass-QuickUp | AI15: Pass-QuickUp | AO15: Penalty-Slashing | AP15: Penalty-Roughing | AQ15: Penalty-Roughing | BJ15: Shot-Tip | BM15: Goal-Other | BR15: Play-Speed | BU15: Rebound | BV15: Invoived | CC15: Clock Problem | CG15: OffensivePlay-Dump/RimInZone | CO15: CededZoneExit | CQ15: BeatWide | CY15: OffensivePlay_ | CZ15: Possession | DA15: FrontofNet | DD15: Defensive_Play | DE15: Possession | DF15: Surf
A16: TeamPossessionChange | C16: Pass-Deflected | E16: Shot-Other | AF16: Pass-GiveAndGo | AG16: Pass-GiveAndGo | AH16: Pass-GiveAndGo | AI16: Pass-GiveAndGo | AO16: Penalty-TooManyMenontheIce | AP16: Penalty-Slashing | AQ16: Penalty-Slashing | BR16: Play-Dump/RimInZone | CC16: Puck Frozen | CG16: DefensivePlay-PokeCheck | CO16: Chip | CQ16: BlockedShot | CY16: OffensivePlay_ | CZ16: Possession | DA16: CutBack | DD16: Defensive_Play | DE16: Possession | DF16: StickCheck
A17: Rebound | C17: Pass-Intercepted | E17: Pass-Stretch | AF17: Pass-Reverse | AG17: Pass-Reverse | AH17: Pass-Reverse | AI17: Pass-Reverse | AO17: Penalty-Tripping | AP17: Penalty-Misconduct | AQ17: Penalty-Misconduct | CC17: Puck in Crowd | CG17: DefensivePlay-PokeCheckFailed | CO17: CrashNet | CQ17: BoxOut | CY17: OffensivePlay_ | CZ17: Possession | DA17: Wheel | DD17: Defensive_Play | DE17: Pass | DF17: PassBlocked
A18: DeadIce | C18: Turnover-Giveaway | E18: Pass-Rim/Wrap | AF18: Pass-Other | AG18: Pass-Other | AH18: Pass-Other | AI18: Pass-Other | AO18: Penalty-Other | AP18: Penalty-TooManyMenontheIce | AQ18: Penalty-TooManyMenontheIce | CC18: Goalie Stopped (after SOG) | CG18: DefensivePlay-SeperateFromPuck | CO18: CutBack | CQ18: CededZoneEntry | CY18: OffensivePlay_ | CZ18: Possession | DA18: ForecedOutside | DD18: Defensive_Play | DE18: Pass | DF18: PassIntercepted
A19: Play | C19: Turnover-Takeaway | E19: Pass-Backhand | AP19: Penalty-Tripping | AQ19: Penalty-Tripping | CC19: Referee or Linesperson | CG19: DefensivePlay-Backcheck | CO19: Cycle | CQ19: CededZoneExit | CY19: OffensivePlay_ | CZ19: Pass | DA19: AssistPrimary | DD19: Defensive_Play | DE19: Pass | DF19: InShotPassLane
A20: Timeout | C20: Zone-Entry | E20: Pass-Forehand | AP20: Penalty-UnsportsmanlikeConduct | AQ20: Penalty-UnsportsmanlikeConduct | CC20: High Stick | CG20: DefensivePlay-FroceWide | CO20: Deke | CQ20: ClearingAttempt | CY20: OffensivePlay_ | CZ20: Pass | DA20: AssistSecondary | DD20: Defensive_Play | DE20: Shot | DF20: BoxOut
A21: Intermission | C21: Zone-Exit | E21: Pass-Bank | AP21: Penalty-Other | AQ21: Penalty-Other | CC21: Objects on Ice | CG21: DefensivePlay-Contain | CO21: Delay | CQ21: Contain | CY21: OffensivePlay_ | CZ21: Pass | DA21: AssistTertiary | DD21: Defensive_Play | DE21: Shot | DF21: BlockedShot
A22: Clockstop | C22: Zone-Keepin | E22: Pass-Other | CC22: Hand Pass | CG22: DefensivePlay-BeatMiddle | CO22: DriveCorner | CQ22: ForcedDumpin/Clear | CY22: OffensivePlay_ | CZ22: Pass | DA22: GiveAndGo | DD22: Defensive_Play | DE22: Shot | DF22: FrontofNet
A23: GameStart | C23: Penalty | E23: Giveaway-Misplayed | CC23: Premature Substitution | CG23: DefensivePlay-BeatWide | CO23: DriveMiddle | CQ23: ForcedLostPossession | CY23: OffensivePlay_ | CZ23: Pass | DA23: Reverse | DD23: Defensive_Play | DE23: Zone | DF23: ClearingAttempt
A24: GameEnd | C24: Penalty-Offsetting | E24: Giveaway-BattleLost | CC24: Puck in Netting | CG24: DefensivePlay-BeatDeke | CO24: DriveNetMiddle | CQ24: ForcedMissedPass | CY24: OffensivePlay_ | CZ24: Pass | DA24: QuickUp | DD24: Defensive_Play | DE24: Zone | DF24: ZoneEntryDenial
A25: Penalty_Delayed | C25: Stoppage-Freeze | E25: Giveaway-PassIntercepted | CC25: Puck in Benches | CG25: DefensivePlay-BeatSpeed | CO25: DriveNetWide | CQ25: ForcedMissedShot | CY25: OffensivePlay_ | CZ25: Pass | DA25: SecondTouch | DD25: Defensive_Play | DE25: Zone | DF25: ZoneExitDenial
A26: Zone_Change | C26: Stoppage-OutfofPlay | E26: Giveaway-PassMissed | CC26: Net Dislodged Offensive Skater | CG26: DefensivePlay-BoxOut | CO26: DriveWide | CQ26: ForcedTurnover | CY26: OffensivePlay_ | CZ26: Pass | DA26: ReceiverMissed | DD26: Defensive_Play | DE26: Zone | DF26: PenaltyKillClear
C27: Stoppage-PeriodEnd | E27: Giveaway-PassBlocked | CC27: Puck Frzn-Goalie-Bynd Ctr | CG27: DefensivePlay-AttemptedClear | CO27: Dump/RimInZone | CQ27: ForceWide | CY27: OffensivePlay_ | CZ27: Shot | DA27: Screen | DD27: Defensive_Play | DE27: Zone | DF27: PuckRetrievalDumpIn
C28: Stoppage-Goal | E28: Giveaway-ShotBlocked | CC28: Skater Puck Frozen | CG28: DefensivePlay-Other | CO28: DumpChase | CQ28: Forecheck | CY28: OffensivePlay_ | CZ28: Zone | DA28: Breakout | DD28: Defensive_Play | DE28: Zone | DF28: PuckRetrievalShot
C29: Stoppage-Penalty | E29: Giveaway-ShotMissed | CC29: Valid stoppage type reasons (reason): | CG29: OffensivePlay-Shot | CO29: DumpInAttempt | CQ29: FrontofNet | CY29: OffensivePlay_ | CZ29: Zone | DA29: DumpChase | DD29: Defensive_Play | DE29: Zone | DF29: PuckRetreivalTurnover
C30: Shootout-OnNet | E30: Giveaway-Other | CC30: TV timeout | CG30: OffensivePlay-Pass | CO30: EndToEndRush | CQ30: GapControl | CY30: OffensivePlay_ | CZ30: Zone | DA30: Forecheck | DD30: Defensive_Play | DE30: Zone | DF30: PuckRetreivalPass
C31: Shootout-Missed | E31: Takeaway-BattleWon | CC31: Home Timeout | CG31: OffensivePlay_Breakout | CO31: FakeShot | CQ31: InShotPassLane | CY31: OffensivePlay_ | CZ31: Zone | DA31: Dump/RimInZone | DD31: Defensive_Play | DE31: Zone | DF31: PuckRetrievalRebound
C32: Shootout-Saved | E32: Takeaway-PokeCheck | CC32: Visitor Timeout | CG32: OffensivePlay-AssistPrimary | CO32: ForecedOutside | CQ32: LoosePuckBattleLost | CY32: OffensivePlay_ | CZ32: Zone | DA32: DumpInAttempt | DD32: Defensive_Play | DE32: Zone | DF32: PuckRecoveryDumpIn
C33: PenaltyShot-OnNet | E33: Takeaway-PassIntercepted | CC33: Player Injury | CG33: OffensivePlay-AssistSecondary | CO33: Forecheck | CQ33: LoosePuckBattleWon | CY33: OffensivePlay_ | CZ33: Zone | DA33: Breakout | DD33: Defensive_Play | DE33: Zone | DF33: PuckRecoveryShot
C34: PenaltyShot-Missed | E34: Takeaway-PassBlocked | CC34: Official Injury | CG34: DefensivePlay-BlockedShot | CO34: FrontofNet | CQ34: ManOnMan | CY34: OffensivePlay_ | CZ34: Zone | DA34: Cycle | DD34: Defensive_Play | DE34: Zone | DF34: PuckRecoveryTurnover
C35: PenaltyShot-Saved | E35: Takeaway-ShotBlocked | CC35: Rink Repair | CG35: DefensivePlay-PassBlocked | CO35: GiveAndGo | CQ35: PassDeflected | CY35: OffensivePlay_ | CZ35: Zone | DA35: PuckRetrievalDumpIn | DD35: Defensive_Play | DE35: Zone | DF35: PuckRecoveryPass
C36: LoosePuck-Forecheck | E36: Takeaway-Other | CC36: Ice problem | CG36: DefensivePlay-PassIntercepted | CO36: LoosePuckBattleLost | CQ36: PassIntercepted | CY36: OffensivePlay_ | CZ36: Zone | DA36: PuckRetrievalShot | DD36: Defensive_Play | DE36: Zone | DF36: PuckRecoveryRebound
C37: LoosePuck-Battle | E37: ZoneEntry-Rush | CC37: Player Equipment | CG37: OffensivePlay-FrontofNet | CO37: LoosePuckBattleWon | CQ37: PenaltyKillClear | CY37: OffensivePlay_ | CZ37: Zone | DA37: PuckRetreivalTurnover | DD37: Defensive_Play | DE37: Zone | DF37: ForcedDumpin/Clear
C38: Save-Rebound | E38: ZoneEntry-Pass | CC38: Video Review | CG38: DefensivePlay-FrontofNet | CO38: LostPuck | CQ38: PokeCheck | CY38: OffensivePlay_ | CZ38: Zone | DA38: PuckRetreivalPass
C39: Save-Freeze | E39: ZoneEntry-DumpIn | CC39: Chlg Hm - off-side | CG39: OffensivePlay-DumpInAttempt | CO39: MisplayedPuck | CQ39: Pressure | CY39: OffensivePlay_ | CZ39: Zone | DA39: PuckRetreivalRebound
C40: Save | E40: ZoneExit-Rush | CC40: Chlg Vis - off-side | CG40: DefensivePlay-ClearingAttempt | CO40: OpenIceDeke | CQ40: PuckRecoveryDumpIn | CY40: OffensivePlay_ | CZ40: Zone | DA40: PuckRetreivalShot
...

Sheet events
A1: event_index_ | B1: linked_event_index_ | C1: sequence_index | D1: play_index | E1: event_start_min_ | F1: event_start_sec_ | G1: event_end_min_ | H1: event_end_sec_ | I1: team_ | J1: player_game_number | K1: role_abrev_binary_ | L1: event_team_zone_ | M1: event_type_ | N1: event_detail_ | O1: event_detail_2_ | P1: event_successful_ | Q1: play_detail1 | R1: play_detail2 | S1: play_detail_successful | T1: pressured_pressurer | U1: period | V1: home_team_zone_ | W1: away_team_zone_ | X1: team_venue_ | Y1: team_venue_abv_ | Z1: event_start_min | AA1: event_start_sec | AB1: event_end_min | AC1: event_end_sec | AD1: role_abrev | AE1: Type | AF1: event_detail | AG1: event_detail_2 | AH1: event_successful | AI1: event_team_zone | AJ1: home_team_zone | AK1: away_team_zone | AL1: team_venue | AM1: team_venue_abv | AN1: side_of_puck | AO1: event_index | AP1: linked_event_index | AQ1: tracking_event_index | AR1: zone_change_index | AS1: game_id | AT1: home_team | AU1: away_team | AV1: duration | AW1: time_start_total_seconds | AX1: time_end_total_seconds | AY1: shift_index | AZ1: player_role | BA1: role_number | BB1: running_intermission_duration | BC1: period_start_total_running_seconds | BD1: running_video_time | BE1: event_running_start | BF1: event_running_end
A2: 0 | K2: x | U2: 1 | V2: =IF(I2="","",IF(I2="Home",L2,"")) | X2: =IF(I2="H","Home",IF(I2="A","Away","")) | AB2: =IF(G2<>"",G2,IF($A2=$A1,AB1,"")) | AC2: =IF(H2<>"",H2,IF($A2=$A1,AC1,"")) | AD2: =IF(K2="x","",IF(K2=1,"e","o")) | AE2: =IF(M2<>"",M2,IF(A2=A1,M2,"")) | AO2: =A2+1000 -> 1000 | AP2: =IF(B2<>"",9000+B2,"") | AQ2: =IF(AP2<>"",AP2,A2+1000) -> 1000 | AR2: 1 | AS2: 18965 | AT2: OS Offices | AU2: Velodrome | BC2: 0 | BD2: 0 | BE2: =IF(BD2<5,0,BD2-5) -> 0 | BF2: =BE2+AV2+5 -> 5
A3: 1 | E3: 18 | F3: 00 | I3: a | J3: 70 | K3: 1 | L3: n | M3: Faceoff | N3: Faceoff_GameStart | U3: =IF(M3="Intermission",U2+1,U2) -> 1 | V3: =IF($I3="","",IF(L3="","",IF($I3="Home",$L3,IF($L3="n","n",IF($L3="d","o",IF($L3="o","d","")))))) -> n | W3: =IF($I3="","",IF(L3="","",IF($I3="Away",$L3,IF($L3="n","n",IF($L3="d","o",IF($L3="o","d","")))))) -> n | X3: =IF(Y3="H","Home",IF(Y3="A","Away","")) -> Away | Y3: =IF($I3<>"",$I3,IF($A3=$A2,Y2,"")) -> a | Z3: =IF(E3<>"",E3,IF($AQ3=$AQ2,Z2,Z3)) -> 18 | AA3: =IF($AQ3=$AQ2,AA2,F3) -> 00 | AB3: =IF(G3<>"",G3,IF($AQ3=$AQ2,AB2,"")) | AC3: =IF(H3<>"",H3,IF($AQ3=$AQ2,AC2,"")) | AD3: =IF(K3="x","",IF(K3=1,"e","o")) -> e | AE3: =IF($M3<>"",$M3,IF($A3=$A2,AE2,"")) -> Faceoff | AF3: =IF(N3<>"",N3,IF($A3=$A2,AF2,"")) -> Faceoff_GameStart | AG3: =IF(O3<>"",O3,IF($A3=$A2,AG2,"")) | AH3: =IF($P3<>"",$P3,IF($A3=$A2,AH2,"")) | AI3: =IF($L3<>"",$L3,IF($A3=$A2,AI2,"")) -> n | AJ3: =IF(V3<>"",V3,IF($A3=$A2,AJ2,"")) -> n | AK3: =IF(W3<>"",W3,IF($A3=$A2,AK2,"")) -> n | AL3: =IF(X3<>"",X3,IF($A3=$A2,AL2,"")) -> Away | AM3: =IF(Y3<>"",Y3,IF($A3=$A2,AM2,"")) -> a | AN3: =IF(AND(AD3="e",OR(AE3="Save",AF3="Turnover_Takeaway",AF3="Play_Defensive")),"Defensive",IF(AND(AD3="o",OR(AE3="Save",AF3="Turnover_Takeaway",AF3="Play_Defensive")),"Offensive",IF(OR(AE3="Deadice",AE3="Stoppage",AE3="Intermission"),"",IF(AD3="e","Offensive",IF(AD3="o","Defensive",""))))) -> Offensive | AO3: =A3+1000 -> 1001 | AP3: =IF(B3<>"",9000+B3,"") | AQ3: =IF(AP3<>"",AP3,A3+1000) -> 1001 | AR3: =IF(OR(N3="Zone_Entry",N3="Zone_Exit"),AR2+1,AR2) -> 1 | AV3: =IF(AND(AB3="",AC3=""),0,((Z3*60)+AA3)-((AB3*60)+AC3)) -> 0 | AW3: =(Z3*60)+AA3 -> 1080 | AX3: =IF(AND(AB3="",AC3=""),AW3,((AB3*60)+AC3)) -> 1080 | AY3: {=_xlfn._xlws.FILTER(shifts!A:A,(shifts!B:B=events!U3)*(shifts!AG:AG>=events!AW3)*(shifts!AH:AH<=events!AX3))} -> 1 | AZ3: =IF(AD3="e","event_team_player_"&BA3,IF(AD3="o","opp_team_player_"&BA3,"")) -> event_team_player_1 | BA3: =COUNTIFS(A$3:A3,"="&A3,AD$3:AD3,"="&AD3) -> 1 | BB3: =SUMIFS(AV3:AV3,M3:M3,"=Intermission") -> 0 | BC3: =IF(U3=1,0,IF(U3=2,1080+BB3,IF(U3=3,(1080*2)+BB3,0))) -> 0 | BD3: =IF(M3="Intermission",BD2,((1080)-((Z3*60)+AA3))+BC3) -> 0 | BE3: =IF(BD3<5,0,BD3-5) -> 0 | BF3: =BE3+AV3+5 -> 5
A4: 1 | J4: 84 | U4: =IF(M4="Intermission",U3+1,U3) -> 1 | V4: =IF($I4="","",IF(L4="","",IF($I4="Home",$L4,IF($L4="n","n",IF($L4="d","o",IF($L4="o","d","")))))) | W4: =IF($I4="","",IF(L4="","",IF($I4="Away",$L4,IF($L4="n","n",IF($L4="d","o",IF($L4="o","d","")))))) | X4: =IF(Y4="H","Home",IF(Y4="A","Away","")) -> Away | Y4: =IF($I4<>"",$I4,IF($A4=$A3,Y3,"")) -> a | Z4: =IF($AQ4=$AQ3,Z3,E4) -> 18 | AA4: =IF($AQ4=$AQ3,AA3,F4) -> 00 | AB4: =IF(G4<>"",G4,IF($AQ4=$AQ3,AB3,"")) | AC4: =IF(H4<>"",H4,IF($AQ4=$AQ3,AC3,"")) | AD4: =IF(K4="x","",IF(K4=1,"e","o")) -> o | AE4: =IF(M4<>"",M4,IF($A4=$A3,AE3,"")) -> Faceoff | AF4: =IF(N4<>"",N4,IF($A4=$A3,AF3,"")) -> Faceoff_GameStart | AG4: =IF(O4<>"",O4,IF($A4=$A3,AG3,"")) | AN4: =IF(AND(AD4="e",OR(AE4="Save",AF4="Turnover_Takeaway",AF4="Play_Defensive")),"Defensive",IF(AND(AD4="o",OR(AE4="Save",AF4="Turnover_Takeaway",AF4="Play_Defensive")),"Offensive",IF(OR(AE4="Deadice",AE4="Stoppage",AE4="Intermission"),"",IF(AD4="e","Offensive",IF(AD4="o","Defensive",""))))) -> Defensive | AP4: =IF(B4<>"",9000+B4,"") | AQ4: =IF(AP4<>"",AP4,A4+1000) -> 1001 | AR4: =IF(OR(N4="Zone_Entry",N4="Zone_Exit"),AR3+1,AR3) -> 1 | AV4: =IF(AND(AB4="",AC4=""),0,((Z4*60)+AA4)-((AB4*60)+AC4)) -> 0 | AW4: =(Z4*60)+AA4 -> 1080 | AX4: =IF(AND(AB4="",AC4=""),AW4,((AB4*60)+AC4)) -> 1080 | AY4: {=_xlfn._xlws.FILTER(shifts!A:A,(shifts!B:B=events!U4)*(shifts!AG:AG>=events!AW4)*(shifts!AH:AH<=events!AX4))} -> 1 | AZ4: =IF(AD4="e","event_team_player_"&BA4,IF(AD4="o","opp_team_player_"&BA4,"")) -> opp_team_player_1 | BA4: =COUNTIFS(A$3:A4,"="&A4,AD$3:AD4,"="&AD4) -> 1 | BB4: =SUMIFS(AV4:AV4,M4:M4,"=Intermission") -> 0 | BC4: =IF(U4=1,0,IF(U4=2,1080+BB4,IF(U4=3,(1080*2)+BB4,0))) -> 0 | BD4: =IF(M4="Intermission",BD3,((1080)-((Z4*60)+AA4))+BC4) -> 0 | BE4: =IF(BD4<5,0,BD4-5) -> 0 | BF4: =BE4+AV4+5 -> 5
A5: 1 | J5: 46 | U5: =IF(M5="Intermission",U4+1,U4) -> 1 | V5: =IF($I5="","",IF(L5="","",IF($I5="Home",$L5,IF($L5="n","n",IF($L5="d","o",IF($L5="o","d","")))))) | W5: =IF($I5="","",IF(L5="","",IF($I5="Away",$L5,IF($L5="n","n",IF($L5="d","o",IF($L5="o","d","")))))) | Z5: =IF($AQ5=$AQ4,Z4,E5) -> 18 | AA5: =IF($AQ5=$AQ4,AA4,F5) -> 00 | AB5: =IF(G5<>"",G5,IF($AQ5=$AQ4,AB4,"")) | AC5: =IF(H5<>"",H5,IF($AQ5=$AQ4,AC4,"")) | AD5: =IF(K5="x","",IF(K5=1,"e","o")) -> o | AE5: =IF(M5<>"",M5,IF($A5=$A4,AE4,"")) -> Faceoff | AF5: =IF(N5<>"",N5,IF($A5=$A4,AF4,"")) -> Faceoff_GameStart | AG5: =IF(O5<>"",O5,IF($A5=$A4,AG4,"")) | AN5: =IF(AND(AD5="e",OR(AE5="Save",AF5="Turnover_Takeaway",AF5="Play_Defensive")),"Defensive",IF(AND(AD5="o",OR(AE5="Save",AF5="Turnover_Takeaway",AF5="Play_Defensive")),"Offensive",IF(OR(AE5="Deadice",AE5="Stoppage",AE5="Intermission"),"",IF(AD5="e","Offensive",IF(AD5="o","Defensive",""))))) -> Defensive | AP5: =IF(B5<>"",9000+B5,"") | AQ5: =IF(AP5<>"",AP5,A5+1000) -> 1001 | AV5: =IF(AND(AB5="",AC5=""),0,((Z5*60)+AA5)-((AB5*60)+AC5)) -> 0 | BB5: =SUMIFS(AV5:AV5,M5:M5,"=Intermission") -> 0 | BC5: =IF(U5=1,0,IF(U5=2,1080+BB5,IF(U5=3,(1080*2)+BB5,0))) -> 0 | BD5: =IF(M5="Intermission",BD4,((1080)-((Z5*60)+AA5))+BC5) -> 0 | BE5: =IF(BD5<5,0,BD5-5) -> 0 | BF5: =BE5+AV5+5 -> 5
A6: 2 | E6: 17 | F6: 59 | G6: 17 | H6: 56 | I6: a | J6: 52 | K6: 1 | L6: n | M6: Possession | T6: 1 | U6: =IF(M6="Intermission",U5+1,U5) -> 1 | Z6: =IF($AQ6=$AQ5,Z5,E6) -> 17 | AA6: =IF($AQ6=$AQ5,AA5,F6) -> 59 | AD6: =IF(K6="x","",IF(K6=1,"e","o")) -> e | AE6: =IF(M6<>"",M6,IF($A6=$A5,AE5,"")) -> Possession | AF6: =IF(N6<>"",N6,IF($A6=$A5,AF5,"")) | AG6: =IF(O6<>"",O6,IF($A6=$A5,AG5,"")) | AN6: =IF(AND(AD6="e",OR(AE6="Save",AF6="Turnover_Takeaway",AF6="Play_Defensive")),"Defensive",IF(AND(AD6="o",OR(AE6="Save",AF6="Turnover_Takeaway",AF6="Play_Defensive")),"Offensive",IF(OR(AE6="Deadice",AE6="Stoppage",AE6="Intermission"),"",IF(AD6="e","Offensive",IF(AD6="o","Defensive",""))))) -> Offensive | AP6: =IF(B6<>"",9000+B6,"") | AQ6: =IF(AP6<>"",AP6,A6+1000) -> 1002
A7: 2 | J7: 92 | Q7: Defensive_PlayPossession-StickCheck | T7: 1 | U7: =IF(M7="Intermission",U6+1,U6) -> 1 | Z7: =IF($AQ7=$AQ6,Z6,E7) -> 17 | AA7: =IF($AQ7=$AQ6,AA6,F7) -> 59 | AD7: =IF(K7="x","",IF(K7=1,"e","o")) -> o | AE7: =IF(M7<>"",M7,IF($A7=$A6,AE6,"")) -> Possession | AF7: =IF(N7<>"",N7,IF($A7=$A6,AF6,"")) | AG7: =IF(O7<>"",O7,IF($A7=$A6,AG6,"")) | AN7: =IF(AND(AD7="e",OR(AE7="Save",AF7="Turnover_Takeaway",AF7="Play_Defensive")),"Defensive",IF(AND(AD7="o",OR(AE7="Save",AF7="Turnover_Takeaway",AF7="Play_Defensive")),"Offensive",IF(OR(AE7="Deadice",AE7="Stoppage",AE7="Intermission"),"",IF(AD7="e","Offensive",IF(AD7="o","Defensive",""))))) -> Defensive | AP7: =IF(B7<>"",9000+B7,"") | AQ7: =IF(AP7<>"",AP7,A7+1000) -> 1002
A8: 3 | E8: 17 | F8: 56 | I8: h | J8: 92 | K8: 1 | L8: n | M8: Turnover | N8: Turnover_Takeaway | O8: Takeaway-PokeCheck | P8: s | Q8: Defensive_PlayPossession-PokeCheck | S8: s | T8: 1 | U8: =IF(M8="Intermission",U7+1,U7) -> 1 | Z8: =IF($AQ8=$AQ7,Z7,E8) -> 17 | AA8: =IF($AQ8=$AQ7,AA7,F8) -> 56 | AD8: =IF(K8="x","",IF(K8=1,"e","o")) -> e | AE8: =IF(M8<>"",M8,IF($A8=$A7,AE7,"")) -> Turnover | AF8: =IF(N8<>"",N8,IF($A8=$A7,AF7,"")) -> Turnover_Takeaway | AG8: =IF(O8<>"",O8,IF($A8=$A7,AG7,"")) -> Takeaway-PokeCheck | AN8: =IF(AND(AD8="e",OR(AE8="Save",AF8="Turnover_Takeaway",AF8="Play_Defensive")),"Defensive",IF(AND(AD8="o",OR(AE8="Save",AF8="Turnover_Takeaway",AF8="Play_Defensive")),"Offensive",IF(OR(AE8="Deadice",AE8="Stoppage",AE8="Intermission"),"",IF(AD8="e","Offensive",IF(AD8="o","Defensive",""))))) -> Defensive | AP8: =IF(B8<>"",9000+B8,"") | AQ8: =IF(AP8<>"",AP8,A8+1000) -> 1003
A9: 3 | J9: 52 | T9: 1 | U9: =IF(M9="Intermission",U8+1,U8) -> 1 | Z9: =IF($AQ9=$AQ8,Z8,E9) -> 17 | AA9: =IF($AQ9=$AQ8,AA8,F9) -> 56 | AD9: =IF(K9="x","",IF(K9=1,"e","o")) -> o | AE9: =IF(M9<>"",M9,IF($A9=$A8,AE8,"")) -> Turnover | AF9: =IF(N9<>"",N9,IF($A9=$A8,AF8,"")) -> Turnover_Takeaway | AG9: =IF(O9<>"",O9,IF($A9=$A8,AG8,"")) -> Takeaway-PokeCheck | AN9: =IF(AND(AD9="e",OR(AE9="Save",AF9="Turnover_Takeaway",AF9="Play_Defensive")),"Defensive",IF(AND(AD9="o",OR(AE9="Save",AF9="Turnover_Takeaway",AF9="Play_Defensive")),"Offensive",IF(OR(AE9="Deadice",AE9="Stoppage",AE9="Intermission"),"",IF(AD9="e","Offensive",IF(AD9="o","Defensive",""))))) -> Offensive | AP9: =IF(B9<>"",9000+B9,"") | AQ9: =IF(AP9<>"",AP9,A9+1000) -> 1003
A10: 4 | E10: 17 | F10: 52 | G10: 17 | H10: 50 | I10: h | J10: 92 | K10: 1 | L10: o | M10: Zone_Entry_Exit | N10: Zone_Entry | O10: ZoneEntry-Rush | P10: s | Q10: OffensivePlay_Possession-DriveMiddle | T10: 1 | U10: =IF(M10="Intermission",U9+1,U9) -> 1 | Z10: =IF($AQ10=$AQ9,Z9,E10) -> 17 | AA10: =IF($AQ10=$AQ9,AA9,F10) -> 52 | AD10: =IF(K10="x","",IF(K10=1,"e","o")) -> e | AE10: =IF(M10<>"",M10,IF($A10=$A9,AE9,"")) -> Zone_Entry_Exit | AF10: =IF(N10<>"",N10,IF($A10=$A9,AF9,"")) -> Zone_Entry | AG10: =IF(O10<>"",O10,IF($A10=$A9,AG9,"")) -> ZoneEntry-Rush | AN10: =IF(AND(AD10="e",OR(AE10="Save",AF10="Turnover_Takeaway",AF10="Play_Defensive")),"Defensive",IF(AND(AD10="o",OR(AE10="Save",AF10="Turnover_Takeaway",AF10="Play_Defensive")),"Offensive",IF(OR(AE10="Deadice",AE10="Stoppage",AE10="Intermission"),"",IF(AD10="e","Offensive",IF(AD10="o","Defensive",""))))) -> Offensive | AP10: =IF(B10<>"",9000+B10,"") | AQ10: =IF(AP10<>"",AP10,A10+1000) -> 1004
A11: 4 | J11: 70 | Q11: Defensive_PlayPossession-StickCheck | T11: 1 | U11: =IF(M11="Intermission",U10+1,U10) -> 1 | Z11: =IF($AQ11=$AQ10,Z10,E11) -> 17 | AA11: =IF($AQ11=$AQ10,AA10,F11) -> 52 | AD11: =IF(K11="x","",IF(K11=1,"e","o")) -> o | AE11: =IF(M11<>"",M11,IF($A11=$A10,AE10,"")) -> Zone_Entry_Exit | AF11: =IF(N11<>"",N11,IF($A11=$A10,AF10,"")) -> Zone_Entry | AG11: =IF(O11<>"",O11,IF($A11=$A10,AG10,"")) -> ZoneEntry-Rush | AN11: =IF(AND(AD11="e",OR(AE11="Save",AF11="Turnover_Takeaway",AF11="Play_Defensive")),"Defensive",IF(AND(AD11="o",OR(AE11="Save",AF11="Turnover_Takeaway",AF11="Play_Defensive")),"Offensive",IF(OR(AE11="Deadice",AE11="Stoppage",AE11="Intermission"),"",IF(AD11="e","Offensive",IF(AD11="o","Defensive",""))))) -> Defensive | AP11: =IF(B11<>"",9000+B11,"") | AQ11: =IF(AP11<>"",AP11,A11+1000) -> 1004
A12: 4 | J12: 91 | T12: 1 | U12: =IF(M12="Intermission",U11+1,U11) -> 1 | Z12: =IF($AQ12=$AQ11,Z11,E12) -> 17 | AA12: =IF($AQ12=$AQ11,AA11,F12) -> 52 | AD12: =IF(K12="x","",IF(K12=1,"e","o")) -> o | AE12: =IF(M12<>"",M12,IF($A12=$A11,AE11,"")) -> Zone_Entry_Exit | AF12: =IF(N12<>"",N12,IF($A12=$A11,AF11,"")) -> Zone_Entry | AG12: =IF(O12<>"",O12,IF($A12=$A11,AG11,"")) -> ZoneEntry-Rush | AN12: =IF(AND(AD12="e",OR(AE12="Save",AF12="Turnover_Takeaway",AF12="Play_Defensive")),"Defensive",IF(AND(AD12="o",OR(AE12="Save",AF12="Turnover_Takeaway",AF12="Play_Defensive")),"Offensive",IF(OR(AE12="Deadice",AE12="Stoppage",AE12="Intermission"),"",IF(AD12="e","Offensive",IF(AD12="o","Defensive",""))))) -> Defensive | AP12: =IF(B12<>"",9000+B12,"") | AQ12: =IF(AP12<>"",AP12,A12+1000) -> 1004
A13: 5 | E13: 17 | F13: 50 | G13: 17 | H13: 48 | I13: h | J13: 92 | K13: 1 | L13: o | M13: Possession | Q13: OffensivePlay_Possession-DriveWide | T13: 1 | U13: =IF(M13="Intermission",U12+1,U12) -> 1 | Z13: =IF($AQ13=$AQ12,Z12,E13) -> 17 | AA13: =IF($AQ13=$AQ12,AA12,F13) -> 50 | AD13: =IF(K13="x","",IF(K13=1,"e","o")) -> e | AE13: =IF(M13<>"",M13,IF($A13=$A12,AE12,"")) -> Possession | AF13: =IF(N13<>"",N13,IF($A13=$A12,AF12,"")) | AG13: =IF(O13<>"",O13,IF($A13=$A12,AG12,"")) | AN13: =IF(AND(AD13="e",OR(AE13="Save",AF13="Turnover_Takeaway",AF13="Play_Defensive")),"Defensive",IF(AND(AD13="o",OR(AE13="Save",AF13="Turnover_Takeaway",AF13="Play_Defensive")),"Offensive",IF(OR(AE13="Deadice",AE13="Stoppage",AE13="Intermission"),"",IF(AD13="e","Offensive",IF(AD13="o","Defensive",""))))) -> Offensive | AP13: =IF(B13<>"",9000+B13,"") | AQ13: =IF(AP13<>"",AP13,A13+1000) -> 1005
