Workbook
Name DEfensive: Lists!$BL:$BL
Name EventType: Lists!$A$2:$A$16
Name Faceoff: Lists!$G$2:$G$1048576
Name Goal: Lists!$J$2:$J$1048576
Name Goal_PenaltyShot: Lists!$BA$2:$BA$1048576
Name Goal_Scored: Lists!$AY$2:$AY$1048576
Name Goal_Shootout: Lists!$AZ$2:$AZ$1048576
Name LoosePuck: Lists!$P$2:$P$1048576
Name Offensive: Lists!$BK:$BK
Name Pass: Lists!$I$2:$I$1048576
Name Pass_Completed: Lists!$R$2:$R$1048576
Name Pass_Deflected: Lists!$T$2:$T$1048576
Name Pass_Intercepted: Lists!$U$2:$U$1048576
Name Pass_Missed: Lists!$S$2:$S$1048576
Name Penalty: Lists!$M$2:$M$1048576
Name Penalty_Major: Lists!$AA$2:$AA$1048576
Name Penalty_Minor: Lists!$AB$2:$AB$1048576
Name Penalty_Offsetting: Lists!$AC$2:$AC$1048576
Name PenaltyShot_Missed: Lists!$AK$2:$AK$1048576
Name PenaltyShot_OnNet: Lists!$AJ$2:$AJ$1048576
Name PenaltyShot_Saved: Lists!$AL$2:$AL$1048576
Name PenaltyShot_Shootout: Lists!$N$2:$N$1048576
Name Play: Lists!$F:$F
Name Play_Defensive: Lists!$BE:$BE
Name Play_Offensive: Lists!$BD:$BD
Name Possession: Lists!$BF:$BF
Name Rebound: Lists!$BC$2:$BC$1048576
Name Save: Lists!$Q$2:$Q$1048576
Name Save_Freeze: Lists!$AN$2:$AN$1048576
Name Save_Played: Lists!$BB:$BB
Name Save_Rebound: Lists!$AM$2:$AM$1048576
Name Shootout_Missed: Lists!$AH$2:$AH$1048576
Name Shootout_OnNet: Lists!$AG$2:$AG$1048576
Name Shootout_Saved: Lists!$AI$2:$AI$1048576
Name Shot: Lists!$H$2:$H$1048576
Name Shot_Blocked: Lists!$AQ$2:$AQ$1048576
Name Shot_BlockedSameTeam: Lists!$AR$2:$AR$1048576
Name Shot_Deflected: Lists!$AS$2:$AS$1048576
Name Shot_DeflectedGoal: Lists!$AX$2:$AX$1048576
Name Shot_DeflectedOnNetSaved: Lists!$AT$2:$AT$1048576
Name Shot_Missed: Lists!$AP$2:$AP$1048576
Name Shot_MissedPost: Lists!$BH:$BH
Name Shot_OnNetGoal: Lists!$AV$2:$AV$1048576
Name Shot_OnNetSaved: Lists!$AO$2:$AO$1048576
Name Shot_TippedGoal: Lists!$AW$2:$AW$1048576
Name Shot_TippedOnNetSaved: Lists!$AU$2:$AU$1048576
Name Stoppage: Lists!$O$2:$O$1048576
Name Stoppage_Other: Lists!$AF$2:$AF$1048576
Name Stoppage_Period: Lists!$AE$2:$AE$1048576
Name Stoppage_Play: Lists!$AD$2:$AD$1048576
Name Turnover: Lists!$K$2:$K$1048576
Name Turnover_Giveaway: Lists!$V$2:$V$1048576
Name Turnover_Takeaway: Lists!$W$2:$W$1048576
Name Zone_Entry: Lists!$X$2:$X$1048576
Name Zone_Entry_Exit: Lists!$L$2:$L$1048576
Name Zone_EntryFailed: Lists!$BM:$BM
Name Zone_Exit: Lists!$Y$2:$Y$1048576
Name Zone_ExitFailed: Lists!$BN:$BN
Name Zone_Keepin: Lists!$Z$2:$Z$1048576

Sheet examples
A1: shift_index | B1: Period | C1: shift_start_min | D1: shift_start_sec | E1: shift_end_min | F1: shift_end_sec | G1: shift_start_type | H1: shift_stop_type | I1: home_forward_1 | J1: home_forward_2 | K1: home_forward_3 | L1: home_defense_1 | M1: home_defense_2 | N1: home_xtra | O1: home_goalie | P1: away_forward_1 | Q1: away_forward_2 | R1: away_forward_3 | S1: away_defense_1 | T1: away_defense_2 | U1: away_xtra | V1: away_goalie | W1: stoppage_time | X1: home_ozone_start | Y1: home_ozone_end | Z1: home_dzone_start | AA1: home_dzone_end | AB1: home_nzone_start | AC1: home_nzone_end | AD1: game_id | AE1: home_team | AF1: away_team | AG1: shift_start_total_seconds | AH1: shift_end_total_seconds | AI1: shift_duration | AJ1: home_team_strength | AK1: away_team_strength | AL1: home_team_en | AM1: away_team_en | AN1: home_team_pk | AO1: home_team_pp | AP1: away_team_pp | AQ1: away_team_pk | AR1: situation | AS1: strength | AT1: home_goals | AU1: away_goals | AV1: period_start_total_running_seconds | AW1: running_video_time | AX1: shift_start_running_time | AY1: shift_end_running_time
A2: 40 | B2: 1 | C2: 2 | D2: 07 | E2: 0 | F2: 35 | G2: OtherFaceoff | H2: Away Goalie Stopped (after Home SOG) | I2: 42 | J2: 14 | K2: 61 | L2: 22 | M2: 9 | O2: 39 | P2: 91 | Q2: 80 | R2: 89 | S2: 4 | T2: 25 | V2: 30 | Y2: 1
A3: 41 | B3: 1 | C3: 0 | D3: 35 | E3: 0 | F3: 0.01 | G3: OtherFaceoff | H3: Period End | I3: 42 | J3: 14 | K3: 61 | L3: 22 | M3: 9 | O3: 39 | P3: 77 | Q3: 13 | R3: 68 | S3: 4 | T3: 25 | V3: 30 | Y3: 1
A4: 42 | B4: 1 | G4: Intermission
A5: 43 | B5: 2 | C5: 18 | D5: 0 | E5: 17 | F5: 18 | G5: PeriodStart | H5: Away Goalie Stopped (after Home SOG) | I5: 70 | J5: 14 | K5: 55 | L5: 91 | M5: 84 | O5: 39 | P5: 77 | Q5: 13 | R5: 68 | S5: 44 | T5: 18 | V5: 30 | Y5: 1
A8: 105 | B8: 3 | C8: 1 | D8: 01 | E8: 0 | F8: 49 | I8: 42 | J8: 24 | K8: 61 | L8: 91 | M8: 84 | O8: 39 | P8: 77 | Q8: 12 | R8: 68 | S8: 44 | T8: 18 | V8: 30 | AA8: 1
A9: 106 | B9: 3 | C9: 0 | D9: 49 | E9: 0 | F9: 0.01 | H9: GameEnd | I9: 42 | J9: 24 | K9: 61 | L9: 91 | M9: 84 | O9: 39 | P9: 77 | Q9: 12 | R9: 56 | S9: 44 | T9: 18 | U9: 3 | AA9: 1
A10: 107 | B10: 3 | C10: 0 | D10: 0.01
A25: event_index | B25: linked_event_index_ | C25: linked_event_index | D25: tracking_event_index | E25: sequence_index | F25: play_index | G25: zone_change_index | H25: Period | I25: event_start_min_ | J25: event_start_sec_ | K25: event_end_min_ | L25: event_end_sec_ | M25: event_start_min | N25: event_start_sec | O25: event_end_min | P25: event_end_sec | Q25: Team_ | R25: Player | S25: role_abrev_binary | T25: role_abrev | U25: Type_ | V25: event_detail_ | W25: event_detail_2_ | X25: successful | Y25: play_detail1 | Z25: play_detail2 | AA25: play_detail_successful | AB25: context | AC25: play_tag1 | AD25: play_tag2 | AE25: high_danger | AF25: event_team_zone | AG25: home_team_zone | AH25: away_team_zone | AI25: forced_forcer | AJ25: pressured_pressurer
A27: 599 | H27: 1 | I27: 0 | J27: 01 | Q27: a | R27: 13 | S27: 1 | T27: e | U27: Shot | V27: Shot_Missed | W27: Shot-Backhand | X27: u | AF27: o | AJ27: 1 | AM27: Shot | AN27: Shot_Missed | AP27: Offensive
A28: 599 | H28: 1 | R28: 9 | T28: o | Y28: Defensive_PlayPossession-StickCheck | AA28: s | AJ28: 1 | AM28: Shot | AN28: Shot_Missed | AP28: Defensive
A29: 600 | H29: 1 | I29: 0 | J29: 00 | T29: o | U29: Stoppage | V29: Stoppage_Period | W29: Stoppage-PeriodEnd | AM29: Stoppage | AN29: Stoppage_Period
A30: 601 | H30: 2 | I30: 56 | J30: 46 | K30: 55 | L30: 39 | T30: o | U30: Intermission | AM30: Intermission
A31: 602 | H31: 2 | I31: 18 | J31: 00 | Q31: h | R31: 70 | S31: 1 | T31: e | U31: Faceoff | V31: Faceoff_PeriodStart | AF31: n | AM31: Faceoff | AN31: Faceoff_PeriodStart | AP31: Offensive
A34: 1438 | B34: 223 | H34: 3 | I34: 5 | J34: 55 | Q34: h | R34: 61 | S34: 1 | T34: e | U34: Shot | V34: Shot_Goal | AF34: o | AM34: Shot | AN34: Shot_Goal | AP34: Offensive
A35: 1438 | B35: 223 | H35: 3 | R35: 30 | T35: o | AM35: Shot | AN35: Shot_Goal | AP35: Defensive
A36: 1439 | B36: 223 | H36: 3 | I36: 5 | J36: 55 | Q36: h | R36: 61 | S36: 1 | T36: e | U36: Goal | V36: Goal_Scored | W36: Goal-Wrist | AF36: o | AM36: Goal | AN36: Goal_Scored | AP36: Offensive
A37: 1439 | B37: 223 | H37: 3 | R37: 30 | T37: o | AM37: Goal | AN37: Goal_Scored | AP37: Defensive
A38: 1440 | B38: 223 | H38: 3 | I38: 5 | J38: 55 | Q38: h | R38: 61 | S38: 1 | T38: e | U38: Stoppage | V38: Stoppage_Play | W38: Stoppage-Goal | AF38: o | AJ38: 1 | AM38: Stoppage | AN38: Stoppage_Play
A39: 1441 | B39: 223 | H39: 3 | I39: 5 | J39: 55 | K39: 5 | L39: 31 | Q39: h | R39: 61 | S39: 1 | T39: e | U39: DeadIce | AF39: o | AJ39: 1 | AM39: DeadIce
A43: 1590 | H43: 3 | I43: 0 | J43: 26 | Q43: h | R43: 84 | S43: 1 | T43: e | U43: Penalty_Delayed | AF43: d | AJ43: 1 | AM43: Penalty_Delayed | AP43: Offensive
A44: 1590 | H44: 3 | R44: 3 | T44: o | AJ44: 1 | AM44: Penalty_Delayed | AP44: Defensive
A45: 1591 | B45: 247 | H45: 3 | I45: 0 | J45: 25 | Q45: a | R45: 18 | S45: 1 | T45: e | U45: Shot | V45: Shot_OnNetSaved | W45: Shot-Wrist | X45: s | AF45: o | AM45: Shot | AN45: Shot_OnNetSaved | AP45: Offensive
A46: 1591 | B46: 247 | H46: 3 | R46: 77 | S46: 1 | T46: e | Y46: OffensivePlay_Shot-Screen | AM46: Shot | AN46: Shot_OnNetSaved | AP46: Offensive
A47: 1591 | B47: 247 | H47: 3 | R47: 39 | T47: o | AM47: Shot | AN47: Shot_OnNetSaved | AP47: Defensive
A48: 1592 | B48: 247 | H48: 3 | I48: 0 | J48: 25 | Q48: h | R48: 39 | S48: 1 | T48: e | U48: Save | V48: Save_Rebound | W48: Save-Blocker | AF48: d | AM48: Save | AN48: Save_Rebound | AP48: Defensive
A49: 1592 | B49: 247 | H49: 3 | R49: 18 | T49: o | AM49: Save | AN49: Save_Rebound | AP49: Offensive
A50: 1592 | B50: 247 | H50: 3 | R50: 77 | T50: o | Y50: OffensivePlay_Shot-Screen | AM50: Save | AN50: Save_Rebound | AP50: Offensive
A51: 1593 | B51: 247 | H51: 3 | I51: 0 | J51: 25 | Q51: h | R51: 39 | S51: 1 | T51: e | AF51: d | AP51: Offensive
A52: 1594 | H52: 3 | I52: 0 | J52: 21 | Q52: a | R52: 56 | S52: 1 | T52: e | U52: Possession | V52: PuckRecovery | X52: u | Y52: OffensivePlay_Zone-PuckRecoveryShot | AA52: u | AF52: o | AM52: Possession | AN52: PuckRecovery | AP52: Offensive
A53: 1595 | H53: 3 | I53: 0 | J53: 21 | Q53: a | R53: 56 | S53: 1 | T53: e | U53: Pass | V53: Pass_Missed | W53: Pass-Forehand | X53: u | Y53: OffensivePlay_Pass-SecondTouch | AA53: u | AF53: o | AJ53: 1 | AM53: Pass | AN53: Pass_Missed | AP53: Offensive
A54: 1595 | H54: 3 | R54: 3 | S54: 1 | T54: e | AM54: Pass | AN54: Pass_Missed | AP54: Offensive
A55: 1595 | H55: 3 | R55: 91 | T55: o | AJ55: 1 | AM55: Pass | AN55: Pass_Missed | AP55: Defensive
A56: 1596 | H56: 3 | I56: 0 | J56: 21 | Q56: h | S56: 1 | T56: e | U56: Zone_Entry_Exit | V56: Zone_Exit | W56: ZoneExit-OppTeam | AF56: d | AM56: Zone_Entry_Exit | AN56: Zone_Exit | AP56: Offensive
A57: 1597 | H57: 3 | I57: 0 | J57: 17 | K57: 0 | L57: 15 | Q57: a | R57: 44 | S57: 1 | T57: e | U57: Possession | V57: PuckRecovery | X57: s | Y57: OffensivePlay_Zone-PuckRecoveryTurnover | AA57: s | AF57: n | AM57: Possession | AN57: PuckRecovery | AP57: Offensive
A58: 1598 | H58: 3 | I58: 0 | J58: 15 | Q58: a | R58: 44 | S58: 1 | T58: e | U58: Pass | V58: Pass_Completed | W58: Pass-Forehand | X58: s | AF58: n | AM58: Pass | AN58: Pass_Completed | AP58: Offensive
A59: 1598 | H59: 3 | R59: 18 | S59: 1 | T59: e | AM59: Pass | AN59: Pass_Completed | AP59: Offensive
A60: 1599 | H60: 3 | I60: 0 | J60: 14 | Q60: a | R60: 18 | S60: 1 | T60: e | U60: Zone_Entry_Exit | V60: Zone_Entry | W60: ZoneEntry-Rush | X60: u | AF60: o | AJ60: 1 | AM60: Zone_Entry_Exit | AN60: Zone_Entry | AP60: Offensive
A61: 1599 | H61: 3 | R61: 24 | T61: o | AJ61: 1 | AM61: Zone_Entry_Exit | AN61: Zone_Entry | AP61: Defensive
A62: 1600 | H62: 3 | I62: 0 | J62: 12 | Q62: h | R62: 24 | S62: 1 | T62: e | U62: Turnover | V62: Turnover_Takeaway | W62: Takeaway-BattleWon | X62: s | Y62: Defensive_PlayPossession-SeperateFromPuck | AA62: s | AF62: d | AJ62: 1 | AM62: Turnover | AN62: Turnover_Takeaway | AP62: Defensive
...

Sheet Sheet1
A1: duration | C1: context
A2: time_start_total_seconds | C2: play_tag1
A3: time_end_total_seconds | C3: play_tag2
A4: shift_index | C4: high_danger
A5: player_role
A6: role_number
A7: running_intermission_duration
A8: period_start_total_running_seconds
A9: running_video_time
A10: event_running_start
A11: event_running_end
A12: event_id
A13: linked_event_id
A14: play_id
A15: sequence_id
A16: zone_change_id
... A72: possession_change

Sheet Rules
A1: EventType | B1: Definition | C1: Next Event | D1: Uses | E1: Linked Events | F1: Successful/Unsuccessful | G1: Successful Def | J1: EventTypeDetail | K1: Definition | L1: Next Event | M1: Uses | N1: Linked Events | O1: Successful/Unsuccessful | P1: Successful Def | S1: EventTypeDetail2 | T1: Definition | U1: Next Event | V1: Uses | W1: Linked Events | X1: Successful/Unsuccessful | Y1: Successful Def | AC1: Definition | AD1: Next Event | AE1: Uses | AF1: Linked Events | AG1: Successful/Unsuccessful | AH1: Successful Def | AL1: Definition | AM1: Next Event | AN1: Uses | AO1: Linked Events | AP1: Linked Events | AQ1: Successful/Unsuccessful | AR1: Successful Def | AT1: play_tag1 | AU1: Definition | AV1: Next Event | AW1: Uses | AX1: Linked Events | AZ1: play_tag2 | BA1: Definition | BB1: Next Event | BC1: Uses | BD1: Linked Events | BF1: Context | BG1: Definition | BH1: Next Event | BI1: Uses | BJ1: Linked Events | BM1: shift_start | BN1: Definition | BO1: Next Event | BP1: Linked Events | BR1: shift_end | BS1: Definition | BT1: Next Event | BU1: Linked Events
A2: Faceoff | J2: Faceoff | S2: PenaltyShot/Shootout | AB2: Offensive | AH2: sucessful if next play positive | AK2: Defensive | AR2: sucessful if next play positive | AT2: LowToHigh | AZ2: Rush | BF2: LeadToBreakout | BM2: PeriodStart | BR2: -
A3: Shot | E3: Save | J3: Faceoff-AfterPenalty | S3: PenaltyShot_OnNet | X3: s | AB3: OffensivePlay_Possession-DriveMiddle | AK3: Defensive_PlayPossession-PokeCheck | AT3: HighToLow | AZ3: Cycle | BF3: LeadToZoneEntry | BM3: FaceoffAfterGoal | BR3: Period Start
A4: Pass | J4: Faceoff-AfterGoal | S4: PenaltyShot_Missed | X4: u | AB4: OffensivePlay_Possession-DriveWide | AK4: Defensive_PlayPossession-SeperateFromPuck | AT4: CrossIce | AZ4: Forecheck | BF4: LeadToTurnover | BM4: GameStart | BR4: Period End
A5: Goal | E5: Shot | J5: Faceoff-PeriodStart | S5: PenaltyShot_Saved | X5: s | AB5: OffensivePlay_Possession-DriveCorner | AK5: Defensive_PlayPossession-Backcheck | AT5: Slot | AZ5: Dumpin | BF5: LeadToShot | BM5: FaceoffAfterPenalty | BR5: Puck Out of Play
A6: Turnover | E6: Pass, Shot, Play | J6: Shot-OnNet | S6: ShootoutShot_OnNet | X6: s | AB6: OffensivePlay_Possession-DriveNetMiddle | AK6: Defensive_PlayPossession-FroceWide | AZ6: Regroup | BF6: LeadToGoal | BM6: OtherFaceoff | BR6: Injury
A7: Zone_Entry_Exit | E7: Pass, Turnover, Attempted Failed, Keepins | J7: Shot-Missed | S7: ShootoutShot_Missed | X7: u | AB7: OffensivePlay_Possession-DriveNetWide | AK7: Defensive_PlayPossession-Contain | AZ7: Counter | BF7: LeadToPenalty | BM7: DeadIce/Stoppage | BR7: Home Penalty
A8: Penalty | J8: Shot-Blocked | S8: ShootoutShot_Saved | X8: s | AB8: OffensivePlay_Possession-CrashNet | AK8: Defensive_PlayPossession-BeatMiddle | AZ8: ZoneExit | BF8: LeadToFailedBreakout | BM8: Intermission | BR8: Away Penalty
A9: PenaltyShot_Shootout | J9: Shot-BlockedSameTeam | AB9: OffensivePlay_Possession-Delay | AK9: Defensive_PlayPossession-BeatWide | AZ9: ZoneEntry | BF9: LeadToFailedZoneEntry | BM9: DelayedPenalty | BR9: Home Goalie Stoppage
A10: Stoppage | E10: Save Freeze | J10: Shot-Deflected | S10: Stoppage_Period | AB10: OffensivePlay_Possession-Deke | AK10: Defensive_PlayPossession-BeatDeke | AZ10: Clear | BM10: GameStart | BR10: Away Goalie Stoppage
A11: Hit | J11: Shot-DeflectedOnNet | S11: Stoppage_Play | AB11: OffensivePlay_Possession-Chip | AK11: Defensive_PlayPossession-BeatSpeed | BR11: Home Offside
A12: Possession | J12: Shot-Tipped | S12: Stoppage_Other | AB12: OffensivePlay_Possession-Other | AK12: Defensive_PlayPossession-Pressure | BR12: Home Icing
A13: LoosePuck | J13: Pass-Completed | S13: Stoppage_GameEnd | AB13: OffensivePlay_Possession-Speed | AK13: Defensive_PlayPossession-Zone | BR13: Away Offside
A14: Save | E14: Shot, Stoppage, Deadice | J14: Pass-Missed | AB14: OffensivePlay_Possession-OpenIceDeke | AK14: Defensive_PlayPossession-ManOnMan | BR14: Away Icing
A15: TeamPossessionChange | J15: Pass-Deflected | S15: Save_Rebound | AB15: OffensivePlay_Possession-EndToEndRush | AK15: Defensive_PlayPossession-Tracker | BR15: Clock Problem
A16: Rebound | E16: Shot, Save | J16: Pass-Intercepted | S16: Save_Freeze | AB16: OffensivePlay_Possession-FrontofNet | AK16: Defensive_PlayPossession-Surf | BR16: Puck Frozen
A17: DeadIce | J17: Turnover-Giveaway | S17: Save_Played | AB17: OffensivePlay_Possession-CutBack | AK17: Defensive_PlayPossession-StickCheck | BR17: Puck in Crowd
A18: Play | J18: Turnover-Takeaway | AB18: OffensivePlay_Possession-Wheel | AK18: Defensive_PlayPass-PassIntercepted | BR18: Goalie Stopped (after SOG)
A19: Timeout | J19: Zone-Entry | S19: Pass-Stretch | X19: s/u | AB19: OffensivePlay_Possession-ForecedOutside | AK19: Defensive_PlayPass-InShotPassLane | BR19: Referee or Linesperson
A20: Intermission | J20: Zone-Exit | S20: Pass-Rim/Wrap | X20: s/u | AB20: OffensivePlay_Pass-AssistPrimary | AK20: Defensive_PlayShot-BoxOut | BR20: High Stick
A21: Clockstop | J21: Zone-Keepin | S21: Pass-Backhand | X21: s/u | AB21: OffensivePlay_Pass-AssistSecondary | AK21: Defensive_PlayShot-BlockedShot | BR21: Objects on Ice
A22: GameStart | J22: Zone_Entryfailed | S22: Pass-Forehand | X22: s/u | AB22: OffensivePlay_Pass-AssistTertiary | AK22: Defensive_PlayShot-FrontofNet | BR22: Hand Pass
A23: GameEnd | J23: Zone_ExitFailed | S23: Pass-Bank | X23: s/u | AB23: OffensivePlay_Pass-GiveAndGo | AK23: Defensive_PlayZone-ClearingAttempt | BR23: Premature Substitution
A24: Penalty_Delayed | J24: Zone_KeepinFailed | S24: Pass-Dump | X24: s/u | AB24: OffensivePlay_Pass-Reverse | AK24: Defensive_PlayZone-ZoneEntryDenial | BR24: Puck in Netting
A25: Zone_Change | J25: Penalty | S25: Pass-Tipped | X25: s/u | AB25: OffensivePlay_Pass-QuickUp | AK25: Defensive_PlayZone-ZoneExitDenial | BR25: Puck in Benches
J26: Penalty-Offsetting | S26: Pass-Lob | X26: s/u | AB26: OffensivePlay_Pass-SecondTouch | AK26: Defensive_PlayZone-PenaltyKillClear | BR26: Net Dislodged Offensive Skater
J27: Stoppage-Freeze | S27: Pass-Drop | X27: s/u | AB27: OffensivePlay_Pass-ReceiverMissed | AK27: Defensive_PlayZone-PuckRetrievalDumpIn | BR27: Puck Frzn-Goalie-Bynd Ctr
J28: Stoppage-OutfofPlay | S28: Pass-Deflected/TippedShot | X28: s/u | AB28: OffensivePlay_Shot-Screen | AK28: Defensive_PlayZone-PuckRetrievalShot | BR28: Skater Puck Frozen
J29: Stoppage-PeriodEnd | S29: Pass-ReceiverMissed | X29: s/u | AB29: OffensivePlay_Zone-Breakout | AK29: Defensive_PlayZone-PuckRetreivalTurnover | BR29: Valid stoppage type reasons (reason):
J30: Stoppage-Goal | S30: Pass-OneTouch | X30: s/u | AB30: OffensivePlay_Zone-DumpChase | AK30: Defensive_PlayZone-PuckRetreivalPass | BR30: TV timeout
J31: Stoppage-Penalty | S31: Pass-SecondTouch | X31: s/u | AB31: OffensivePlay_Zone-Forecheck | AK31: Defensive_PlayZone-PuckRetrievalRebound | BR31: Home Timeout
J32: Shootout-OnNet | S32: Pass-QuickUp | X32: s/u | AB32: OffensivePlay_Zone-Dump/RimInZone | AK32: Defensive_PlayZone-PuckRecoveryDumpIn | BR32: Visitor Timeout
J33: Shootout-Missed | S33: Pass-GiveAndGo | X33: s/u | AB33: OffensivePlay_Zone-DumpInAttempt | AK33: Defensive_PlayZone-PuckRecoveryShot | BR33: Player Injury
J34: Shootout-Saved | S34: Pass-Reverse | X34: s/u | AB34: OffensivePlay_Zone-Breakout | AK34: Defensive_PlayZone-PuckRecoveryTurnover | BR34: Official Injury
J35: PenaltyShot-OnNet | S35: Pass-Other | X35: s/u | AB35: OffensivePlay_Zone-Cycle | AK35: Defensive_PlayZone-PuckRecoveryPass | BR35: Rink Repair
J36: PenaltyShot-Missed | AB36: OffensivePlay_Zone-PuckRetrievalDumpIn | AK36: Defensive_PlayZone-PuckRecoveryRebound | BR36: Ice problem
J37: PenaltyShot-Saved | S37: Giveaway-Misplayed | AB37: OffensivePlay_Zone-PuckRetrievalShot | AK37: Defensive_PlayZone-ForcedDumpin/Clear | BR37: Player Equipment
J38: LoosePuck-Forecheck | S38: Giveaway-BattleLost | AB38: OffensivePlay_Zone-PuckRetreivalTurnover | AK38: Offensive_Zone-AttemptedKeepin | BR38: Video Review
J39: LoosePuck-Battle | S39: Giveaway-PassIntercepted | AB39: OffensivePlay_Zone-PuckRetreivalPass | AK39: Defensive_Zone-AttemptedBreakOutPass | BR39: Chlg Hm - off-side
J40: Save-Rebound | S40: Giveaway-PassMissed | AB40: OffensivePlay_Zone-PuckRetreivalRebound | AK40: Defensive_Zone-AttemptedBreakOutRush | BR40: Chlg Vis - off-side
...

Sheet Lists
A1: EventType | B1: EventTypeDetail | C1: EventTypeDetail2 | D1: OffensivePlay | E1: DefensivePlay | F1: Play | G1: Faceoff | H1: Shot | I1: Pass | J1: Goal | K1: Turnover | L1: Zone_Entry_Exit | M1: Penalty | N1: PenaltyShot/Shootout | O1: Stoppage | P1: LoosePuck | Q1: Save | R1: Pass_Completed | S1: Pass_Missed | T1: Pass_Deflected | U1: Pass_Intercepted | V1: Turnover_Giveaway | W1: Turnover_Takeaway | X1: Zone_Entry | Y1: Zone_Exit | Z1: Zone_Keepin | AA1: Penalty_Major | AB1: Penalty_Minor | AC1: Penalty_Offsetting | AD1: Stoppage_Play | AE1: Stoppage_Period | AF1: Stoppage_Other | AG1: Shootout_OnNet | AH1: Shootout_Missed | AI1: Shootout_Saved | AJ1: PenaltyShot_OnNet | AK1: PenaltyShot_Missed | AL1: PenaltyShot_Saved | AM1: Save_Rebound | AN1: Save_Freeze | AO1: Shot_OnNetSaved | AP1: Shot_Missed | AQ1: Shot_Blocked | AR1: Shot_BlockedSameTeam | AS1: Shot_Deflected | AT1: Shot_DeflectedOnNetSaved | AU1: Shot_TippedOnNetSaved | AV1: Shot_OnNetGoal | AW1: Shot_TippedGoal | AX1: Shot_DeflectedGoal | AY1: Goal_Scored | AZ1: Goal_Shootout | BA1: Goal_PenaltyShot | BB1: Save_Played | BC1: Rebound | BD1: Play_Offensive | BE1: Play_Defensive | BF1: Possession | BG1: Faceoff | BH1: Shot_MissedPost | BI1: shift_start | BJ1: shift_end | BK1: Offensive | BL1: Defensive | BM1: Zone_EntryFailed | BN1: Zone_ExitFailed | BO1: Zone_KeepinFailed | BQ1: play_details
F2: Play_Offensive | G2: Faceoff_AfterPenalty | H2: Shot_OnNetSaved | I2: Pass_Completed | J2: Goal_Scored | K2: Turnover_Giveaway | L2: Zone_Entry | M2: Penalty_Minor | N2: PenaltyShot_OnNet | O2: Stoppage_Period | P2: LoosePuck_Forecheck | Q2: Save_Rebound | R2: Pass-Stretch | S2: Pass-Stretch | T2: Pass-Stretch | U2: Pass-Stretch | V2: Giveaway-Misplayed | W2: Takeaway-BattleWon | X2: ZoneEntry-Rush | Y2: ZoneExit-Rush | Z2: Zone-KeepIn | AA2: Penalty-Bench Penalty | AB2: Penalty-Bench Penalty | AC2: Penalty-Bench Penalty | AD2: Stoppage-Icing | AE2: Stoppage-StartofShootout | AF2: Stoppage-ObjectsonIce | AG2: Shot-Wrist | AH2: Shot-Wrist | AI2: Shot-Wrist | AJ2: Shot-Wrist | AK2: Shot-Wrist | AL2: Shot-Wrist | AM2: Save-Glove | AN2: Save-Glove | AO2: Shot-Wrist | AP2: Shot-Wrist | AQ2: Shot-Wrist | AR2: Shot-Wrist | AS2: Shot-Deflection | AT2: Shot-Deflection | AU2: Shot-Tip | AV2: Shot-Wrist | AX2: Shot-Deflection | AY2: Goal-Wrist | AZ2: Goal-Wrist | BA2: Goal-Wrist | BB2: Save-Glove | BC2: Rebound_TeamRecovered | BE2: Play-PokeCheck | BF2: Breakaway | BG2: Shot | BH2: Shot-Wrist | BI2: PeriodStart | BJ2: - | BK2: AssistPrimary | BL2: AttemptedBlockedShot | BM2: ZoneEntry-Rush | BN2: ZoneExit-Rush | BO2: Zone-KeepIn | BQ2: {=_xlfn._xlws.SORT(_xlfn.UNIQUE(BK2:BK1000))} -> AssistPrimary
A3: Faceoff | B3: Faceoff | C3: Shot-Wrist | D3: DriveMiddle | E3: PokeCheck | F3: Play_Defensive | G3: Faceoff_AfterGoal | H3: Shot_Missed | I3: Pass_Missed | J3: Goal_Shootout | K3: Turnover_Takeaway | L3: Zone_Exit | M3: Penalty_Offsetting | N3: PenaltyShot_Missed | O3: Stoppage_Play | P3: LoosePuck_Battle | Q3: Save_Freeze | R3: Pass-Rim/Wrap | S3: Pass-Rim/Wrap | T3: Pass-Rim/Wrap | U3: Pass-Rim/Wrap | V3: Giveaway-BattleLost | W3: Takeaway-PokeCheck | X3: ZoneEntry-Pass | Y3: ZoneExit-Pass | Z3: Zone-Pinch | AA3: Penalty-Boarding | AB3: Penalty-Boarding | AC3: Penalty-Boarding | AD3: Stoppage-Offsides | AE3: Stoppage-PeriodStart | AF3: Stoppage-HomeTimeout | AG3: Shot-Slap | AH3: Shot-Slap | AI3: Shot-Slap | AJ3: Shot-Slap | AK3: Shot-Slap | AL3: Shot-Slap | AM3: Save-Blocker | AN3: Save-Blocker | AO3: Shot-Slap | AP3: Shot-Slap | AQ3: Shot-Slap | AR3: Shot-Slap | AS3: Shot-Wrist | AT3: Shot-Wrist | AU3: Shot-Wrist | AV3: Shot-Slap | AW3: Shot-Wrist | AX3: Shot-Wrist | AY3: Goal-Slap | AZ3: Goal-Slap | BA3: Goal-Slap | BB3: Save-Blocker | BC3: Rebound_OppTeamRecovered | BD3: Play-DriveMiddle | BE3: Play-PokeCheckFailed | BF3: PuckRetrieval | BG3: Pass | BH3: Shot-Slap | BI3: FaceoffAfterGoal | BJ3: Period Start | BK3: AssistSecondary | BL3: AttemptedBreakOutClear | BM3: ZoneEntry-Pass | BN3: ZoneExit-Pass | BO3: Zone-Pinch | BQ3: AssistSecondary
A4: Shot | B4: Faceoff-AfterPenalty | C4: Shot-Slap | D4: DriveWide | E4: PokeCheckFailed | G4: Faceoff_PeriodStart | H4: Shot_Blocked | I4: Pass_Deflected | J4: Goal_PenaltyShot | L4: Zone_Keepin | M4: Penalty_Major | N4: PenaltyShot_Saved | O4: Stoppage_Other | Q4: Save_Played | R4: Pass-Backhand | S4: Pass-Backhand | T4: Pass-Backhand | U4: Pass-Backhand | V4: Giveaway-PassIntercepted | W4: Takeaway-PassIntercepted | X4: ZoneEntry-DumpIn | Y4: ZoneExit-Clear | Z4: Zone-Other | AA4: Penalty-Charging | AB4: Penalty-Charging | AC4: Penalty-Charging | AD4: Stoppage-ClockProblem | AE4: Stoppage-PeriodEnd | AF4: Stoppage-VisitorTimeout | AG4: Shot-Backhand | AH4: Shot-Backhand | AI4: Shot-Backhand | AJ4: Shot-Backhand | AK4: Shot-Backhand | AL4: Shot-Backhand | AM4: Save-LeftPad | AN4: Save-LeftPad | AO4: Shot-Backhand | AP4: Shot-Backhand | AQ4: Shot-Backhand | AR4: Shot-Backhand | AS4: Shot-Slap | AT4: Shot-Slap | AU4: Shot-Slap | AV4: Shot-Backhand | AW4: Shot-Slap | AX4: Shot-Slap | AY4: Goal-Backhand | AZ4: Goal-Backhand | BA4: Goal-Backhand | BB4: Save-LeftPad | BC4: Rebound_ShotGenerated | BD4: Play-DriveWide | BE4: Play-SeperateFromPuck | BF4: PuckRecovery | BG4: Goal | BH4: Shot-Backhand | BI4: GameStart | BJ4: Period End | BK4: AssistTertiary | BL4: AttemptedBreakOutPass | BM4: ZoneEntry-DumpIn | BN4: ZoneExit-Clear | BO4: Zone-Other | BQ4: AssistTertiary
A5: Pass | B5: Faceoff-AfterGoal | C5: Shot-Backhand | D5: DriveCorner | E5: SeperateFromPuck | G5: Faceoff_AfterStoppage | H5: Shot_BlockedSameTeam | I5: Pass_Intercepted | L5: Zone_Entryfailed | N5: ShootoutShot_OnNet | O5: Stoppage_GameEnd | R5: Pass-Forehand | S5: Pass-Forehand | T5: Pass-Forehand | U5: Pass-Forehand | V5: Giveaway-PassMissed | W5: Takeaway-PassBlocked | X5: ZoneEntry-Chip | Y5: ZoneExit-Chip | AA5: Penalty-CrossChecking | AB5: Penalty-CrossChecking | AC5: Penalty-CrossChecking | AD5: Stoppage-HighStick | AF5: Stoppage-RinkRepair | AG5: Shot-Snap | AH5: Shot-Snap | AI5: Shot-Snap | AJ5: Shot-Snap | AK5: Shot-Snap | AL5: Shot-Snap | AM5: Save-RightPad | AN5: Save-RightPad | AO5: Shot-Snap | AP5: Shot-Snap | AQ5: Shot-Snap | AR5: Shot-Snap | AS5: Shot-Backhand | AT5: Shot-Backhand | AU5: Shot-Backhand | AV5: Shot-Snap | AW5: Shot-Backhand | AX5: Shot-Backhand | AY5: Goal-Tip | AZ5: Goal-Snap | BA5: Goal-Snap | BB5: Save-RightPad | BC5: Rebound_FlurryGenerated | BD5: Play-DriveCorner | BE5: Play-Backcheck | BF5: Regroup | BG5: Turnover | BH5: Shot-Snap | BI5: FaceoffAfterPenalty | BJ5: Puck Out of Play | BK5: AttemptedBreakOutClear | BL5: AttemptedBreakOutRush | BM5: ZoneEntry-Chip | BN5: ZoneExit-Chip | BQ5: AttemptedBlockedShot
A6: Goal | B6: Faceoff-PeriodStart | C6: Shot-Tip | D6: DriveNetMiddle | E6: Backcheck | G6: Faceoff_GameStart | H6: Shot_Deflected | L6: Zone_ExitFailed | N6: ShootoutShot_Missed | R6: Pass-Bank | S6: Pass-Bank | T6: Pass-Bank | U6: Pass-Bank | V6: Giveaway-PassBlocked | W6: Takeaway-ShotBlocked | X6: ZoneEntry-FromExitClear | Y6: ZoneExit-PassMiss/Misplay | AA6: Penalty-DelayofGame | AB6: Penalty-DelayofGame | AC6: Penalty-DelayofGame | AD6: Stoppage-HandPass | AF6: Stoppage-PlayerEquipment | AG6: Shot-WrapAround | AH6: Shot-WrapAround | AI6: Shot-WrapAround | AJ6: Shot-WrapAround | AK6: Shot-WrapAround | AL6: Shot-WrapAround | AM6: Save-Stick | AN6: Save-Stick | AO6: Shot-WrapAround | AP6: Shot-WrapAround | AQ6: Shot-WrapAround | AR6: Shot-WrapAround | AS6: Shot-Snap | AT6: Shot-Snap | AU6: Shot-Snap | AV6: Shot-WrapAround | AW6: Shot-Snap | AX6: Shot-Snap | AY6: Goal-Snap | AZ6: Goal-WrapAround | BA6: Goal-WrapAround | BB6: Save-Stick | BD6: Play-DriveNetMiddle | BE6: Play-FroceWide | BG6: Zone_Entry_Exit | BH6: Shot-WrapAround | BI6: OtherFaceoff | BJ6: Injury | BK6: AttemptedBreakOutPass | BL6: AttemptedEntryDumpIn | BM6: ZoneEntry-FromExitClear | BN6: ZoneExit-PassMiss/Misplay | BQ6: AttemptedBreakOutClear
A7: Turnover | B7: Shot-OnNet | C7: Shot-Snap | D7: DriveNetWide | E7: FroceWide | H7: Shot_DeflectedOnNetSaved | L7: Zone_KeepinFailed | N7: ShootoutShot_Saved | R7: Pass-Dump | S7: Pass-Dump | T7: Pass-Dump | U7: Pass-Dump | V7: Giveaway-PassReceiverMissed | W7: Takeaway-ZoneClear/Dump | X7: ZoneEntry-PassMiss/Misplay | Y7: ZoneExit-OppTeam | AA7: Penalty-Diving | AB7: Penalty-Diving | AC7: Penalty-Diving | AD7: Stoppage-NetDislodged | AF7: Stoppage-Challenge | AG7: Shot-Bat | AH7: Shot-Bat | AI7: Shot-Bat | AJ7: Shot-Bat | AK7: Shot-Bat | AL7: Shot-Bat | AM7: Save-Scramble | AN7: Save-Scramble | AO7: Shot-Bat | AP7: Shot-Bat | AQ7: Shot-Bat | AR7: Shot-Bat | AS7: Shot-WrapAround | AT7: Shot-WrapAround | AU7: Shot-WrapAround | AV7: Shot-Bat | AW7: Shot-WrapAround | AX7: Shot-WrapAround | AY7: Goal-WrapAround | AZ7: Goal-Bat | BA7: Goal-Bat | BB7: Save-Scramble | BD7: Play-DriveNetWide | BE7: Play-Contain | BG7: Penalty | BH7: Shot-Bat | BI7: DeadIce/Stoppage | BJ7: Home Penalty | BK7: AttemptedBreakOutRush | BL7: AttemptedEntryPass | BM7: ZoneEntry-PassMiss/Misplay | BN7: ZoneExit-OppTeam | BQ7: AttemptedBreakOutPass
A8: Zone_Entry_Exit | B8: Shot-Missed | C8: Shot-WrapAround | D8: CrashNet | E8: Contain | H8: Shot_Tipped | R8: Pass-Tipped | S8: Pass-Tipped | T8: Pass-Tipped | U8: Pass-Tipped | V8: Giveaway-ShotBlocked | W8: Takeaway-AttemptedZoneClear/Dump | X8: ZoneEntry-OppTeam | Y8: ZoneExit-Lob | AA8: Penalty-Elbowing | AB8: Penalty-Elbowing | AC8: Penalty-Elbowing | AD8: Stoppage-Injury | AF8: Stoppage-Other | AG8: Shot-Cradle | AH8: Shot-Cradle | AI8: Shot-Cradle | AJ8: Shot-Cradle | AK8: Shot-Cradle | AL8: Shot-Cradle | AM8: Save-Butterfly | AN8: Save-Butterfly | AO8: Shot-Cradle | AP8: Shot-Cradle | AQ8: Shot-Cradle | AR8: Shot-Cradle | AS8: Shot-Bat | AT8: Shot-Bat | AU8: Shot-Bat | AV8: Shot-Cradle | AW8: Shot-Bat | AX8: Shot-Bat | AY8: Goal-Bat | AZ8: Goal-Cradle | BA8: Goal-Cradle | BB8: Save-Butterfly | BD8: Play-CrashNet | BE8: Play-BeatMiddle | BG8: PenaltyShot_Shootout | BH8: Shot-Cradle | BI8: Intermission | BJ8: Away Penalty | BK8: AttemptedEntryDumpIn | BL8: AttemptedEntryRush | BM8: ZoneEntry-OppTeam | BN8: ZoneExit-Lob | BQ8: AttemptedBreakOutRush
A9: Penalty | B9: Shot-Blocked | C9: Shot-Bat | D9: Delay | E9: BeatMiddle | H9: Shot_TippedOnNetSaved | R9: Pass-Lob | S9: Pass-Lob | T9: Pass-Lob | U9: Pass-Lob | V9: Giveaway-ShotMissed | W9: Takeaway-Other | X9: ZoneEntry-Lob | Y9: ZoneExit-CausedTurnover | AA9: Penalty-GoalieInterference | AB9: Penalty-GoalieInterference | AC9: Penalty-GoalieInterference | AD9: Stoppage-GoalieStoppage | AG9: Shot-Poke | AH9: Shot-Poke | AI9: Shot-Poke | AJ9: Shot-Poke | AK9: Shot-Poke | AL9: Shot-Poke | AM9: Save-Chest | AN9: Save-Chest | AO9: Shot-Poke | AP9: Shot-Poke | AQ9: Shot-Poke | AR9: Shot-Poke | AS9: Shot-Cradle | AT9: Shot-Cradle | AU9: Shot-Cradle | AV9: Shot-Poke | AW9: Shot-Cradle | AX9: Shot-Cradle | AY9: Goal-Cradle | AZ9: Goal-Poke | BA9: Goal-Poke | BB9: Save-Chest | BD9: Play-Delay | BE9: Play-BeatWide | BG9: Stoppage | BH9: Shot-Poke | BI9: DelayedPenalty | BJ9: Home Goalie Stoppage | BK9: AttemptedEntryPass | BL9: AttemptedKeepin | BM9: ZoneEntry-Lob | BN9: ZoneExit-CausedTurnover | BQ9: AttemptedEntryDumpIn
A10: PenaltyShot_Shootout | B10: Shot-BlockedSameTeam | C10: Shot-Cradle | D10: Deke | E10: BeatWide | H10: Shot_OnNetGoal | R10: Pass-Drop | S10: Pass-Drop | T10: Pass-Drop | U10: Pass-Drop | V10: Giveaway-ZoneClear/Dump | X10: ZoneEntry-RushBreakaway | Y10: ZoneExit-PenaltyKillClear | AA10: Penalty-HighSticking | AB10: Penalty-HighSticking | AC10: Penalty-HighSticking | AD10: Stoppage-PuckOutofPlay | AG10: Shot-BetweenLegs | AH10: Shot-BetweenLegs | AI10: Shot-BetweenLegs | AJ10: Shot-BetweenLegs | AK10: Shot-BetweenLegs | AL10: Shot-BetweenLegs | AM10: Save-Shoulder | AN10: Save-Shoulder | AO10: Shot-BetweenLegs | AP10: Shot-BetweenLegs | AQ10: Shot-BetweenLegs | AR10: Shot-BetweenLegs | AS10: Shot-Poke | AT10: Shot-Poke | AU10: Shot-Poke | AV10: Shot-BetweenLegs | AW10: Shot-Poke | AX10: Shot-Poke | AY10: Goal-Poke | AZ10: Goal-BetweenLegs | BA10: Goal-BetweenLegs | BB10: Save-Other | BD10: Play-Deke | BE10: Play-BeatDeke | BG10: Hit | BH10: Shot-BetweenLegs | BI10: GameStart | BJ10: Away Goalie Stoppage | BK10: AttemptedEntryRush | BL10: Backcheck | BM10: ZoneEntry-RushBreakaway | BN10: ZoneExit-PenaltyKillClear | BQ10: AttemptedEntryPass
A11: Stoppage | B11: Shot-Deflected | C11: Shot-Poke | D11: Chip | E11: BeatDeke | H11: Shot_OnNetTippedGoal | R11: Pass-Deflected/TippedShot | S11: Pass-Deflected/TippedShot | T11: Pass-Deflected/TippedShot | U11: Pass-Deflected/TippedShot | V11: Giveaway-AttemptedZoneClear/Dump | X11: ZoneEntry-CausedTurnover | Y11: ZoneExit-Shot | AA11: Penalty-Holding | AB11: Penalty-Holding | AC11: Penalty-Holding | AD11: Stoppage-Penalty | AG11: Shot-Tip | AH11: Shot-Tip | AI11: Shot-Other | AJ11: Shot-Other | AK11: Shot-Other | AL11: Shot-Other | AM11: Save-Skate | AN11: Save-Skate | AO11: Shot-Dumpin | AP11: Shot-Dumpin | AQ11: Shot-Dumpin | AR11: Shot-Dumpin | AS11: Shot-BetweenLegs | AT11: Shot-BetweenLegs | AU11: Shot-BetweenLegs | AV11: Shot-Dumpin | AW11: Shot-BetweenLegs | AX11: Shot-BetweenLegs | AY11: Goal-BetweenLegs | AZ11: Goal-Other | BA11: Goal-Other | BD11: Play-Chip | BE11: Play-BeatSpeed | BG11: Possession | BH11: Shot-Dumpin | BJ11: Home Offside | BK11: AttemptedKeepin | BL11: BeatDeke | BM11: ZoneEntry-CausedTurnover | BN11: ZoneExit-Other | BQ11: AttemptedEntryRush
A12: Hit | B12: Shot-DeflectedOnNet | C12: Shot-BetweenLegs | D12: Other | E12: BeatSpeed | H12: Shot_OnNetDeflectedGoal | R12: Pass-ReceiverMissed | S12: Pass-ReceiverMissed | T12: Pass-ReceiverMissed | U12: Pass-ReceiverMissed | V12: Giveaway-ZoneEntry/ExitMisplay | X12: ZoneEntry-PenaltyKillClear | Y12: ZoneExit-Other | AA12: Penalty-Interference | AB12: Penalty-Interference | AC12: Penalty-Interference | AD12: Stoppage-Goal | AG12: Shot-Other | AH12: Shot-Other | AM12: Save-Other | AN12: Save-Other | AO12: Shot-OneTime | AP12: Shot-OneTime | AQ12: Shot-OneTime | AR12: Shot-OneTime | AS12: Shot-Dumpin | AT12: Shot-Dumpin | AU12: Shot-Dumpin | AV12: Shot-OneTime | AW12: Shot-Dumpin | AX12: Shot-Dumpin | AY12: Goal-Dumpin | BD12: Play-Other | BE12: Play-BoxOut | BG12: LoosePuck | BH12: Shot-OneTime | BJ12: Home Icing | BK12: Breakout | BL12: BeatFake | BM12: ZoneEntry-PenaltyKillClear | BQ12: AttemptedKeepin
A13: Possession | B13: Shot-Tipped | C13: Shot-Dumpin | D13: DumpChase | E13: BoxOut | H13: Shot_Goal | R13: Pass-OneTouch | S13: Pass-Other | T13: Pass-Other | U13: Pass-Other | V13: Giveaway-DumpInZone | X13: ZoneEntry-Shot | AA13: Penalty-Hooking | AB13: Penalty-Fighting | AC13: Penalty-Fighting | AO13: Shot-Tip | AP13: Shot_Tipped | AQ13: Shot_Tipped | AR13: Shot_Tipped | AS13: Shot-OneTime | AT13: Shot-OneTime | AU13: Shot-OneTime | AV13: Shot-Other | AW13: Shot-OneTime | AX13: Shot-OneTime | AY13: Goal-Deflection | BD13: Play-DumpChase | BE13: Play-AttemptedClear | BG13: Save | BH13: Shot_Tipped | BJ13: Away Offside | BK13: Breakout | BL13: BeatMiddle | BM13: ZoneEntry-Other | BQ13: AttemptedPass
A14: LoosePuck | B14: Pass-Completed | C14: Shot-Deflection | D14: Forecheck | E14: Other | H14: Shot_MissedPost | R14: Pass-SecondTouch | S14: Pass-SecondTouch | T14: Pass-SecondTouch | U14: Pass-SecondTouch | V14: Giveaway-Other | X14: ZoneEntry-Other | AA14: Penalty-Roughing | AB14: Penalty-Hooking | AC14: Penalty-Hooking | AO14: Shot-Other | AP14: Shot-Other | AQ14: Shot-Other | AR14: Shot-Other | AS14: Shot-Other | AT14: Shot-Other | AU14: Shot-Other | AV14: Shot-Deflection | AW14: Shot-Other | AX14: Shot-Other | AY14: Goal-OneTime | BD14: Play-Forecheck | BE14: Play-Other | BG14: TeamPossessionChange | BH14: Shot-Other | BJ14: Away Icing | BK14: CededZoneEntry | BL14: BeatSpeed | BQ14: AttemptedShot
A15: Save | B15: Pass-Missed | C15: Shot-OneTime | D15: Speed | R15: Pass-QuickUp | S15: Pass-QuickUp | T15: Pass-QuickUp | U15: Pass-QuickUp | AA15: Penalty-Slashing | AB15: Penalty-Roughing | AC15: Penalty-Roughing | AV15: Shot-Tip | AY15: Goal-Other | BD15: Play-Speed | BG15: Rebound | BJ15: Clock Problem | BK15: CededZoneExit | BL15: BeatWide | BQ15: AttemptedTip/Deflection
A16: TeamPossessionChange | B16: Pass-Deflected | C16: Shot-Other | R16: Pass-GiveAndGo | S16: Pass-GiveAndGo | T16: Pass-GiveAndGo | U16: Pass-GiveAndGo | AA16: Penalty-TooManyMenontheIce | AB16: Penalty-Slashing | AC16: Penalty-Slashing | BD16: Play-Dump/RimInZone | BJ16: Puck Frozen | BK16: Chip | BL16: BlockedShot | BQ16: Backcheck
A17: Rebound | B17: Pass-Intercepted | C17: Pass-Stretch | R17: Pass-Reverse | S17: Pass-Reverse | T17: Pass-Reverse | U17: Pass-Reverse | AA17: Penalty-Tripping | AB17: Penalty-Misconduct | AC17: Penalty-Misconduct | BJ17: Puck in Crowd | BK17: CrashNet | BL17: BoxOut | BQ17: BeatDeke
A18: DeadIce | B18: Turnover-Giveaway | C18: Pass-Rim/Wrap | R18: Pass-Other | S18: Pass-Other | T18: Pass-Other | U18: Pass-Other | AA18: Penalty-Other | AB18: Penalty-TooManyMenontheIce | AC18: Penalty-TooManyMenontheIce | BJ18: Goalie Stopped (after SOG) | BK18: CutBack | BL18: CededZoneEntry | BQ18: BeatFake
A19: Play | B19: Turnover-Takeaway | C19: Pass-Backhand | AB19: Penalty-Tripping | AC19: Penalty-Tripping | BJ19: Referee or Linesperson | BK19: Cycle | BL19: CededZoneExit | BQ19: BeatMiddle
A20: Timeout | B20: Zone-Entry | C20: Pass-Forehand | AB20: Penalty-UnsportsmanlikeConduct | AC20: Penalty-UnsportsmanlikeConduct | BJ20: High Stick | BK20: Deke | BL20: ClearingAttempt | BQ20: BeatSpeed
A21: Intermission | B21: Zone-Exit | C21: Pass-Bank | AB21: Penalty-Other | AC21: Penalty-Other | BJ21: Objects on Ice | BK21: Delay | BL21: Contain | BQ21: BeatWide
A22: Clockstop | B22: Zone-Keepin | C22: Pass-Other | BJ22: Hand Pass | BK22: DriveCorner | BL22: ForcedDumpin/Clear | BQ22: BlockedShot
A23: GameStart | B23: Penalty | C23: Giveaway-Misplayed | BJ23: Premature Substitution | BK23: DriveMiddle | BL23: ForcedLostPossession | BQ23: BoxOut
A24: GameEnd | B24: Penalty-Offsetting | C24: Giveaway-BattleLost | BJ24: Puck in Netting | BK24: DriveNetMiddle | BL24: ForcedMissedPass | BQ24: Breakout
A25: Penalty_Delayed | B25: Stoppage-Freeze | C25: Giveaway-PassIntercepted | BJ25: Puck in Benches | BK25: DriveNetWide | BL25: ForcedMissedShot | BQ25: CededZoneEntry
A26: Zone_Change | B26: Stoppage-OutfofPlay | C26: Giveaway-PassMissed | BJ26: Net Dislodged Offensive Skater | BK26: DriveWide | BL26: ForcedTurnover | BQ26: CededZoneExit
B27: Stoppage-PeriodEnd | C27: Giveaway-PassBlocked | BJ27: Puck Frzn-Goalie-Bynd Ctr | BK27: Dump/RimInZone | BL27: ForceWide | BQ27: Chip
B28: Stoppage-Goal | C28: Giveaway-ShotBlocked | BJ28: Skater Puck Frozen | BK28: DumpChase | BL28: Forecheck | BQ28: ClearingAttempt
B29: Stoppage-Penalty | C29: Giveaway-ShotMissed | BJ29: Valid stoppage type reasons (reason): | BK29: DumpInAttempt | BL29: FrontofNet | BQ29: Contain
B30: Shootout-OnNet | C30: Giveaway-Other | BJ30: TV timeout | BK30: EndToEndRush | BL30: GapControl | BQ30: CrashNet
B31: Shootout-Missed | C31: Takeaway-BattleWon | BJ31: Home Timeout | BK31: FakeShot | BL31: InShotPassLane | BQ31: CutBack
B32: Shootout-Saved | C32: Takeaway-PokeCheck | BJ32: Visitor Timeout | BK32: ForecedOutside | BL32: LoosePuckBattleLost | BQ32: Cycle
B33: PenaltyShot-OnNet | C33: Takeaway-PassIntercepted | BJ33: Player Injury | BK33: Forecheck | BL33: LoosePuckBattleWon | BQ33: DeflectedShot
B34: PenaltyShot-Missed | C34: Takeaway-PassBlocked | BJ34: Official Injury | BK34: FrontofNet | BL34: ManOnMan | BQ34: Deke
B35: PenaltyShot-Saved | C35: Takeaway-ShotBlocked | BJ35: Rink Repair | BK35: GiveAndGo | BL35: PassDeflected | BQ35: Delay
B36: LoosePuck-Forecheck | C36: Takeaway-Other | BJ36: Ice problem | BK36: LoosePuckBattleLost | BL36: PassIntercepted | BQ36: DelayedOffside
B37: LoosePuck-Battle | C37: ZoneEntry-Rush | BJ37: Player Equipment | BK37: LoosePuckBattleWon | BL37: PenaltyKillClear | BQ37: DriveCorner
B38: Save-Rebound | C38: ZoneEntry-Pass | BJ38: Video Review | BK38: LostPuck | BL38: PokeCheck | BQ38: DriveMiddle
... B43: Faceoff-GameStart | C43: Zone-KeepIn | BJ43: Chlg League - off-side | BK43: RecoveryRetreivalFaceoff | BL43: PuckRecoveryPass | BQ43: DumpChase
C44: Zone-Pinch | BJ44: Chlg League - goal interference | BK44: RecoveryRetreivalOther | BL44: PuckRecoveryRebound | BQ44: DumpInAttempt
...

Sheet shifts
A1: shift_index | B1: Period | C1: shift_start_min | D1: shift_start_sec | E1: shift_end_min | F1: shift_end_sec | G1: shift_start_type | H1: shift_stop_type | I1: home_forward_1 | J1: home_forward_2 | K1: home_forward_3 | L1: home_defense_1 | M1: home_defense_2 | N1: home_xtra | O1: home_goalie | P1: away_forward_1 | Q1: away_forward_2 | R1: away_forward_3 | S1: away_defense_1 | T1: away_defense_2 | U1: away_xtra | V1: away_goalie | W1: stoppage_time | X1: home_ozone_start | Y1: home_ozone_end | Z1: home_dzone_start | AA1: home_dzone_end | AB1: home_nzone_start | AC1: home_nzone_end | AD1: game_id | AE1: home_team | AF1: away_team | AG1: shift_start_total_seconds | AH1: shift_end_total_seconds | AI1: shift_duration | AJ1: home_team_strength | AK1: away_team_strength | AL1: home_team_en | AM1: away_team_en | AN1: home_team_pk | AO1: home_team_pp | AP1: away_team_pp | AQ1: away_team_pk | AR1: situation | AS1: strength | AT1: home_goals | AU1: away_goals | AV1: home_team_plus | AW1: home_team_minus | AX1: away_team_plus | AY1: away_team_minus | AZ1: period_start_total_running_seconds | BA1: running_video_time | BB1: shift_start_running_time | BC1: shift_end_running_time
A2: 1 | B2: 1 | C2: 18 | D2: 00 | E2: 17 | F2: 14 | G2: GameStart | I2: 10 | J2: 15 | K2: 16 | L2: 23 | M2: 37 | O2: 31 | P2: 70 | Q2: 87 | R2: 75 | S2: 22 | T2: 84 | V2: 39 | W2: =SUMIFS(events!AJ:AJ,events!Q:Q,"=DeadIce",events!AK:AK,"<="&shifts!AG2,events!AL:AL,">"&shifts!AH2,events!E:E,"="&shifts!B3)+SUMIFS(events!AJ:AJ,events!Q:Q,"=Timeout",events!AK:AK,"<="&shifts!AG2,events!AL:AL,">"&shifts!AH2,events!E:E,"="&shifts!B3) -> 0 | AB2: 1 | AD2: 18981 | AE2: Nelson | AF2: Velodrome | AG2: =((C2*60)+D2) -> 1080 | AH2: =((E2*60)+F2) -> 1034 | AI2: =ROUND(AG2-AH2,0) -> 46 | AJ2: =COUNTIF(I2:N2,">0") -> 5 | AK2: =COUNTIF(P2:U2,">0") -> 5 | AL2: =IF(O2="",1,0) -> 0 | AM2: =IF(V2="",1,0) -> 0 | AN2: =IF(AND($AL2<>1,$AJ2<$AK2,AM2<>1),1,) -> 0 | AO2: =IF(AND($AL2<>1,$AJ2>$AK2),1,) -> 0 | AP2: =IF(AN2=1,1,0) -> 0 | AQ2: =IF(AO2=1,1,0) -> 0 | AR2: =IF(AND(AJ2=5,AK2=5,AL2=0,AM2=0),"Full Strength",IF(AP2=1,"Away PowerPlay",IF(AO2=1,"Home PowerPlay",IF(AL2=1,"Home EmptyNet",IF(AM2=1,"Away EmptyNet",""))))) -> Full Strength | AS2: =IF(AND(AL2=0,AM2=0),AJ2&"v"&AK2,IF(AL2=1,AJ2&"v"&AK2&" Home EN",IF(AM2=1,AJ2&"v"&AK2&" Away EN",""))) -> 5v5 | AT2: 0 | AU2: 0 | AV2: =IF(AND($H2="Home Goal", AO2=0),1,0) -> 0 | AW2: =IF(AX2=1,-1,0) -> 0 | AX2: =IF(AND($H2="AwayGoal", AP2=0),1,0) -> 0 | AY2: =IF(AV2=1,-1,0) -> 0 | AZ2: =IFERROR(VLOOKUP(B2,events!AA:BN,40,FALSE),0) -> 0 | BA2: 0 | BB2: =IF(BA2<5,0,BA2-5) -> 0 | BC2: =BB2+AI2+3 -> 49
A3: 2 | B3: =IF(G3="PeriodStart",B2+1,B2) -> 1 | C3: =IF(G3<>"PeriodStart",E2,18) -> 17 | D3: =F2 -> 14 | E3: 17 | F3: 07 | I3: 79 | J3: 3 | K3: 44 | L3: 80 | M3: 37 | O3: =O2 -> 31 | P3: 70 | Q3: 87 | R3: 75 | S3: 22 | T3: 84 | V3: =V2 -> 39 | W3: =SUMIFS(events!AJ:AJ,events!Q:Q,"=DeadIce",events!AK:AK,"<="&shifts!AG3,events!AL:AL,">"&shifts!AH3,events!E:E,"="&shifts!B4)+SUMIFS(events!AJ:AJ,events!Q:Q,"=Timeout",events!AK:AK,"<="&shifts!AG3,events!AL:AL,">"&shifts!AH3,events!E:E,"="&shifts!B4) -> 0 | X3: =IF(OR($H2="Home Goal",$H2="Away Goal",$H2="Period End"),"",IF(Y2=1,1,"")) | Z3: =IF(OR($H2="Home Goal",$H2="Away Goal",$H2="Period End"),"",IF(AA2=1,1,"")) | AA3: 1 | AB3: =IF(OR($H2="Home Goal",$H2="Away Goal",$H2="Period End"),1,IF(AC2=1,1,"")) | AD3: 18982 | AE3: Nelson | AF3: Velodrome | AG3: =((C3*60)+D3) -> 1034 | AH3: =((E3*60)+F3) -> 1027 | AI3: =ROUND(AG3-AH3,0) -> 7 | AJ3: =COUNTIF(I3:N3,">0") -> 5 | AK3: =COUNTIF(P3:U3,">0") -> 5 | AL3: =IF(O3="",1,0) -> 0 | AM3: =IF(V3="",1,0) -> 0 | AN3: =IF(AND($AL3<>1,$AJ3<$AK3,AM3<>1),1,) -> 0 | AO3: =IF(AND($AL3<>1,$AJ3>$AK3),1,) -> 0 | AP3: =IF(AN3=1,1,0) -> 0 | AQ3: =IF(AO3=1,1,0) -> 0 | AR3: =IF(AND(AJ3=5,AK3=5,AL3=0,AM3=0),"Full Strength",IF(AP3=1,"Away PowerPlay",IF(AO3=1,"Home PowerPlay",IF(AL3=1,"Home EmptyNet",IF(AM3=1,"Away EmptyNet",""))))) -> Full Strength | AS3: =IF(AND(AL3=0,AM3=0),AJ3&"v"&AK3,IF(AL3=1,AJ3&"v"&AK3&" Home EN",IF(AM3=1,AJ3&"v"&AK3&" Away EN",""))) -> 5v5 | AT3: =IF($H2="Home Goal",AT2+1,AT2) -> 0 | AU3: =IF($H2="Away Goal",AU2+1,AU2) -> 0 | AV3: =IF(AND($H3="Home Goal", AO3=0),1,0) -> 0 | AW3: =IF(AX3=1,-1,0) -> 0 | AX3: =IF(AND($H3="Away Goal", AP3=0),1,0) -> 0 | AY3: =IF(AV3=1,-1,0) -> 0 | AZ3: =IFERROR(VLOOKUP(B3,events!AD:BR,37,FALSE),0) -> 0 | BA3: =ROUND(IF(G3="Intermission",BA2,((1080)-((C3*60)+D3))+AZ3),0) -> 46 | BB3: =IF(BA3<5,0,BA3-5) -> 41 | BC3: =BB3+AI3+3 -> 51
A4: 3 | B4: =IF(G4="PeriodStart",B3+1,B3) -> 1 | C4: =IF(G4<>"PeriodStart",E3,18) -> 17 | D4: =F3 -> 07 | E4: 17 | F4: 02 | H4: Away Icing | I4: 79 | J4: 3 | K4: 44 | L4: 80 | M4: 37 | O4: =O3 -> 31 | P4: 70 | Q4: 91 | R4: 75 | S4: 22 | T4: 52 | V4: =V3 -> 39 | W4: =SUMIFS(events!AJ:AJ,events!Q:Q,"=DeadIce",events!AK:AK,"<="&shifts!AG4,events!AL:AL,">"&shifts!AH4,events!E:E,"="&shifts!B5)+SUMIFS(events!AJ:AJ,events!Q:Q,"=Timeout",events!AK:AK,"<="&shifts!AG4,events!AL:AL,">"&shifts!AH4,events!E:E,"="&shifts!B5) -> 0 | X4: =IF(OR($H3="Home Goal",$H3="Away Goal",$H3="Period End"),"",IF(Y3=1,1,"")) | Z4: =IF(OR($H3="Home Goal",$H3="Away Goal",$H3="Period End"),"",IF(AA3=1,1,"")) -> 1 | AA4: 1 | AB4: =IF(OR($H3="Home Goal",$H3="Away Goal",$H3="Period End"),1,IF(AC3=1,1,"")) | AD4: 18983 | AE4: Nelson | AF4: Velodrome | AG4: =((C4*60)+D4) -> 1027 | AH4: =((E4*60)+F4) -> 1022 | AI4: =ROUND(AG4-AH4,0) -> 5 | AJ4: =COUNTIF(I4:N4,">0") -> 5 | AK4: =COUNTIF(P4:U4,">0") -> 5 | AL4: =IF(O4="",1,0) -> 0 | AM4: =IF(V4="",1,0) -> 0 | AN4: =IF(AND($AL4<>1,$AJ4<$AK4,AM4<>1),1,) -> 0 | AO4: =IF(AND($AL4<>1,$AJ4>$AK4),1,) -> 0 | AP4: =IF(AN4=1,1,0) -> 0 | AQ4: =IF(AO4=1,1,0) -> 0 | AR4: =IF(AND(AJ4=5,AK4=5,AL4=0,AM4=0),"Full Strength",IF(AP4=1,"Away PowerPlay",IF(AO4=1,"Home PowerPlay",IF(AL4=1,"Home EmptyNet",IF(AM4=1,"Away EmptyNet",""))))) -> Full Strength | AS4: =IF(AND(AL4=0,AM4=0),AJ4&"v"&AK4,IF(AL4=1,AJ4&"v"&AK4&" Home EN",IF(AM4=1,AJ4&"v"&AK4&" Away EN",""))) -> 5v5 | AT4: =IF($H3="Home Goal",AT3+1,AT3) -> 0 | AU4: =IF($H3="Away Goal",AU3+1,AU3) -> 0 | AV4: =IF(AND($H4="Home Goal", AO4=0),1,0) -> 0 | AW4: =IF(AX4=1,-1,0) -> 0 | AX4: =IF(AND($H4="Away Goal", AP4=0),1,0) -> 0 | AY4: =IF(AV4=1,-1,0) -> 0 | AZ4: =IFERROR(VLOOKUP(B4,events!AD:BR,37,FALSE),0) -> 0 | BA4: =ROUND(IF(G4="Intermission",BA3,((1080)-((C4*60)+D4))+AZ4),0) -> 53 | BB4: =IF(BA4<5,0,BA4-5) -> 48 | BC4: =BB4+AI4+3 -> 56
A5: =A4+1 -> 4 | B5: =IF(G5="PeriodStart",B4+1,B4) -> 1 | C5: =IF(G5<>"PeriodStart",E4,18) -> 17 | D5: =F4 -> 02 | E5: 15 | F5: 41 | G5: OtherFaceoff | I5: 79 | J5: 3 | K5: 44 | L5: 80 | M5: 8 | O5: =O4 -> 31 | P5: 42 | Q5: 91 | R5: 24 | S5: 93 | T5: 52 | V5: =V4 -> 39 | W5: =SUMIFS(events!AJ:AJ,events!Q:Q,"=DeadIce",events!AK:AK,"<="&shifts!AG5,events!AL:AL,">"&shifts!AH5,events!E:E,"="&shifts!B6)+SUMIFS(events!AJ:AJ,events!Q:Q,"=Timeout",events!AK:AK,"<="&shifts!AG5,events!AL:AL,">"&shifts!AH5,events!E:E,"="&shifts!B6) -> 0 | X5: =IF(OR($H4="Home Goal",$H4="Away Goal",$H4="Period End"),"",IF(Y4=1,1,"")) | Z5: =IF(OR($H4="Home Goal",$H4="Away Goal",$H4="Period End"),"",IF(AA4=1,1,"")) -> 1 | AA5: 1 | AB5: =IF(OR($H4="Home Goal",$H4="Away Goal",$H4="Period End"),1,IF(AC4=1,1,"")) | AD5: 18984 | AE5: Nelson | AF5: Velodrome | AG5: =((C5*60)+D5) -> 1022 | AH5: =((E5*60)+F5) -> 941 | AI5: =ROUND(AG5-AH5,0) -> 81 | AJ5: =COUNTIF(I5:N5,">0") -> 5 | AK5: =COUNTIF(P5:U5,">0") -> 5 | AL5: =IF(O5="",1,0) -> 0 | AM5: =IF(V5="",1,0) -> 0 | AN5: =IF(AND($AL5<>1,$AJ5<$AK5,AM5<>1),1,) -> 0 | AO5: =IF(AND($AL5<>1,$AJ5>$AK5),1,) -> 0 | AP5: =IF(AN5=1,1,0) -> 0 | AQ5: =IF(AO5=1,1,0) -> 0 | AR5: =IF(AND(AJ5=5,AK5=5,AL5=0,AM5=0),"Full Strength",IF(AP5=1,"Away PowerPlay",IF(AO5=1,"Home PowerPlay",IF(AL5=1,"Home EmptyNet",IF(AM5=1,"Away EmptyNet",""))))) -> Full Strength | AS5: =IF(AND(AL5=0,AM5=0),AJ5&"v"&AK5,IF(AL5=1,AJ5&"v"&AK5&" Home EN",IF(AM5=1,AJ5&"v"&AK5&" Away EN",""))) -> 5v5 | AT5: =IF($H4="Home Goal",AT4+1,AT4) -> 0 | AU5: =IF($H4="Away Goal",AU4+1,AU4) -> 0 | AV5: =IF(AND($H5="Home Goal", AO5=0),1,0) -> 0 | AW5: =IF(AX5=1,-1,0) -> 0 | AX5: =IF(AND($H5="Away Goal", AP5=0),1,0) -> 0 | AY5: =IF(AV5=1,-1,0) -> 0 | AZ5: =IFERROR(VLOOKUP(B5,events!AD:BR,37,FALSE),0) -> 0 | BA5: =ROUND(IF(G5="Intermission",BA4,((1080)-((C5*60)+D5))+AZ5),0) -> 58 | BB5: =IF(BA5<5,0,BA5-5) -> 53 | BC5: =BB5+AI5+3 -> 137
A6: =A5+1 -> 5 | B6: =IF(G6="PeriodStart",B5+1,B5) -> 1 | C6: =IF(G6<>"PeriodStart",E5,18) -> 15 | D6: =F5 -> 41 | E6: 15 | F6: 35 | H6: Away Goalie Stopped (after Home SOG) | I6: 10 | J6: 3 | K6: 44 | L6: 80 | M6: 8 | O6: =O5 -> 31 | P6: 42 | Q6: 91 | R6: 24 | S6: 93 | T6: 52 | V6: =V5 -> 39 | W6: =SUMIFS(events!AJ:AJ,events!Q:Q,"=DeadIce",events!AK:AK,"<="&shifts!AG6,events!AL:AL,">"&shifts!AH6,events!E:E,"="&shifts!B7)+SUMIFS(events!AJ:AJ,events!Q:Q,"=Timeout",events!AK:AK,"<="&shifts!AG6,events!AL:AL,">"&shifts!AH6,events!E:E,"="&shifts!B7) -> 0 | X6: =IF(OR($H5="Home Goal",$H5="Away Goal",$H5="Period End"),"",IF(Y5=1,1,"")) | Z6: =IF(OR($H5="Home Goal",$H5="Away Goal",$H5="Period End"),"",IF(AA5=1,1,"")) -> 1 | AA6: 1 | AB6: =IF(OR($H5="Home Goal",$H5="Away Goal",$H5="Period End"),1,IF(AC5=1,1,"")) | AD6: 18985 | AE6: Nelson | AF6: Velodrome | AG6: =((C6*60)+D6) -> 941 | AH6: =((E6*60)+F6) -> 935 | AI6: =ROUND(AG6-AH6,0) -> 6 | AJ6: =COUNTIF(I6:N6,">0") -> 5 | AK6: =COUNTIF(P6:U6,">0") -> 5 | AL6: =IF(O6="",1,0) -> 0 | AM6: =IF(V6="",1,0) -> 0 | AN6: =IF(AND($AL6<>1,$AJ6<$AK6,AM6<>1),1,) -> 0 | AO6: =IF(AND($AL6<>1,$AJ6>$AK6),1,) -> 0 | AP6: =IF(AN6=1,1,0) -> 0 | AQ6: =IF(AO6=1,1,0) -> 0 | AR6: =IF(AND(AJ6=5,AK6=5,AL6=0,AM6=0),"Full Strength",IF(AP6=1,"Away PowerPlay",IF(AO6=1,"Home PowerPlay",IF(AL6=1,"Home EmptyNet",IF(AM6=1,"Away EmptyNet",""))))) -> Full Strength | AS6: =IF(AND(AL6=0,AM6=0),AJ6&"v"&AK6,IF(AL6=1,AJ6&"v"&AK6&" Home EN",IF(AM6=1,AJ6&"v"&AK6&" Away EN",""))) -> 5v5 | AT6: =IF($H5="Home Goal",AT5+1,AT5) -> 0 | AU6: =IF($H5="Away Goal",AU5+1,AU5) -> 0 | AV6: =IF(AND($H6="Home Goal", AO6=0),1,0) -> 0 | AW6: =IF(AX6=1,-1,0) -> 0 | AX6: =IF(AND($H6="Away Goal", AP6=0),1,0) -> 0 | AY6: =IF(AV6=1,-1,0) -> 0 | AZ6: =IFERROR(VLOOKUP(B6,events!AD:BR,37,FALSE),0) -> 0 | BA6: =ROUND(IF(G6="Intermission",BA5,((1080)-((C6*60)+D6))+AZ6),0) -> 139 | BB6: =IF(BA6<5,0,BA6-5) -> 134 | BC6: =BB6+AI6+3 -> 143
A7: =A6+1 -> 6 | B7: =IF(G7="PeriodStart",B6+1,B6) -> 1 | C7: =IF(G7<>"PeriodStart",E6,18) -> 15 | D7: =F6 -> 35 | E7: 13 | F7: 57 | G7: OtherFaceoff | I7: 10 | J7: 7 | K7: 16 | L7: 23 | M7: 37 | O7: =O6 -> 31 | P7: 49 | Q7: 14 | R7: 61 | S7: 9 | T7: 84 | V7: =V6 -> 39 | W7: =SUMIFS(events!AJ:AJ,events!Q:Q,"=DeadIce",events!AK:AK,"<="&shifts!AG7,events!AL:AL,">"&shifts!AH7,events!E:E,"="&shifts!B8)+SUMIFS(events!AJ:AJ,events!Q:Q,"=Timeout",events!AK:AK,"<="&shifts!AG7,events!AL:AL,">"&shifts!AH7,events!E:E,"="&shifts!B8) -> 0 | X7: =IF(OR($H6="Home Goal",$H6="Away Goal",$H6="Period End"),"",IF(Y6=1,1,"")) | Z7: =IF(OR($H6="Home Goal",$H6="Away Goal",$H6="Period End"),"",IF(AA6=1,1,"")) -> 1 | AA7: 1 | AB7: =IF(OR($H6="Home Goal",$H6="Away Goal",$H6="Period End"),1,IF(AC6=1,1,"")) | AD7: 18986 | AE7: Nelson | AF7: Velodrome | AG7: =((C7*60)+D7) -> 935 | AH7: =((E7*60)+F7) -> 837 | AI7: =ROUND(AG7-AH7,0) -> 98 | AJ7: =COUNTIF(I7:N7,">0") -> 5 | AK7: =COUNTIF(P7:U7,">0") -> 5 | AL7: =IF(O7="",1,0) -> 0 | AM7: =IF(V7="",1,0) -> 0 | AN7: =IF(AND($AL7<>1,$AJ7<$AK7,AM7<>1),1,) -> 0 | AO7: =IF(AND($AL7<>1,$AJ7>$AK7),1,) -> 0 | AP7: =IF(AN7=1,1,0) -> 0 | AQ7: =IF(AO7=1,1,0) -> 0 | AR7: =IF(AND(AJ7=5,AK7=5,AL7=0,AM7=0),"Full Strength",IF(AP7=1,"Away PowerPlay",IF(AO7=1,"Home PowerPlay",IF(AL7=1,"Home EmptyNet",IF(AM7=1,"Away EmptyNet",""))))) -> Full Strength | AS7: =IF(AND(AL7=0,AM7=0),AJ7&"v"&AK7,IF(AL7=1,AJ7&"v"&AK7&" Home EN",IF(AM7=1,AJ7&"v"&AK7&" Away EN",""))) -> 5v5 | AT7: =IF($H6="Home Goal",AT6+1,AT6) -> 0 | AU7: =IF($H6="Away Goal",AU6+1,AU6) -> 0 | AV7: =IF(AND($H7="Home Goal", AO7=0),1,0) -> 0 | AW7: =IF(AX7=1,-1,0) -> 0 | AX7: =IF(AND($H7="Away Goal", AP7=0),1,0) -> 0 | AY7: =IF(AV7=1,-1,0) -> 0 | AZ7: =IFERROR(VLOOKUP(B7,events!AD:BR,37,FALSE),0) -> 0 | BA7: =ROUND(IF(G7="Intermission",BA6,((1080)-((C7*60)+D7))+AZ7),0) -> 145 | BB7: =IF(BA7<5,0,BA7-5) -> 140 | BC7: =BB7+AI7+3 -> 241
A8: =A7+1 -> 7 | B8: =IF(G8="PeriodStart",B7+1,B7) -> 1 | C8: =IF(G8<>"PeriodStart",E7,18) -> 13 | D8: =F7 -> 57 | E8: 13 | F8: 50 | I8: 10 | J8: 15 | K8: 16 | L8: 80 | M8: 37 | O8: =O7 -> 31 | P8: 49 | Q8: 14 | R8: 61 | S8: 9 | T8: 84 | V8: =V7 -> 39 | W8: =SUMIFS(events!AJ:AJ,events!Q:Q,"=DeadIce",events!AK:AK,"<="&shifts!AG8,events!AL:AL,">"&shifts!AH8,events!E:E,"="&shifts!B9)+SUMIFS(events!AJ:AJ,events!Q:Q,"=Timeout",events!AK:AK,"<="&shifts!AG8,events!AL:AL,">"&shifts!AH8,events!E:E,"="&shifts!B9) -> 0 | X8: =IF(OR($H7="Home Goal",$H7="Away Goal",$H7="Period End"),"",IF(Y7=1,1,"")) | Z8: =IF(OR($H7="Home Goal",$H7="Away Goal",$H7="Period End"),"",IF(AA7=1,1,"")) -> 1 | AA8: 1 | AB8: =IF(OR($H7="Home Goal",$H7="Away Goal",$H7="Period End"),1,IF(AC7=1,1,"")) | AD8: 18987 | AE8: Nelson | AF8: Velodrome | AG8: =((C8*60)+D8) -> 837 | AH8: =((E8*60)+F8) -> 830 | AI8: =ROUND(AG8-AH8,0) -> 7 | AJ8: =COUNTIF(I8:N8,">0") -> 5 | AK8: =COUNTIF(P8:U8,">0") -> 5 | AL8: =IF(O8="",1,0) -> 0 | AM8: =IF(V8="",1,0) -> 0 | AN8: =IF(AND($AL8<>1,$AJ8<$AK8,AM8<>1),1,) -> 0 | AO8: =IF(AND($AL8<>1,$AJ8>$AK8),1,) -> 0 | AP8: =IF(AN8=1,1,0) -> 0 | AQ8: =IF(AO8=1,1,0) -> 0 | AR8: =IF(AND(AJ8=5,AK8=5,AL8=0,AM8=0),"Full Strength",IF(AP8=1,"Away PowerPlay",IF(AO8=1,"Home PowerPlay",IF(AL8=1,"Home EmptyNet",IF(AM8=1,"Away EmptyNet",""))))) -> Full Strength | AS8: =IF(AND(AL8=0,AM8=0),AJ8&"v"&AK8,IF(AL8=1,AJ8&"v"&AK8&" Home EN",IF(AM8=1,AJ8&"v"&AK8&" Away EN",""))) -> 5v5 | AT8: =IF($H7="Home Goal",AT7+1,AT7) -> 0 | AU8: =IF($H7="Away Goal",AU7+1,AU7) -> 0 | AV8: =IF(AND($H8="Home Goal", AO8=0),1,0) -> 0 | AW8: =IF(AX8=1,-1,0) -> 0 | AX8: =IF(AND($H8="Away Goal", AP8=0),1,0) -> 0 | AY8: =IF(AV8=1,-1,0) -> 0 | AZ8: =IFERROR(VLOOKUP(B8,events!AD:BR,37,FALSE),0) -> 0 | BA8: =ROUND(IF(G8="Intermission",BA7,((1080)-((C8*60)+D8))+AZ8),0) -> 243 | BB8: =IF(BA8<5,0,BA8-5) -> 238 | BC8: =BB8+AI8+3 -> 248
A9: =A8+1 -> 8 | B9: =IF(G9="PeriodStart",B8+1,B8) -> 1 | C9: =IF(G9<>"PeriodStart",E8,18) -> 13 | D9: =F8 -> 50 | E9: 13 | F9: 45 | I9: 10 | J9: 15 | K9: 44 | L9: 80 | M9: 37 | O9: =O8 -> 31 | P9: 49 | Q9: 14 | R9: 61 | S9: 9 | T9: 84 | V9: =V8 -> 39 | W9: =SUMIFS(events!AJ:AJ,events!Q:Q,"=DeadIce",events!AK:AK,"<="&shifts!AG9,events!AL:AL,">"&shifts!AH9,events!E:E,"="&shifts!B10)+SUMIFS(events!AJ:AJ,events!Q:Q,"=Timeout",events!AK:AK,"<="&shifts!AG9,events!AL:AL,">"&shifts!AH9,events!E:E,"="&shifts!B10) -> 0 | X9: =IF(OR($H8="Home Goal",$H8="Away Goal",$H8="Period End"),"",IF(Y8=1,1,"")) | Z9: =IF(OR($H8="Home Goal",$H8="Away Goal",$H8="Period End"),"",IF(AA8=1,1,"")) -> 1 | AA9: 1 | AB9: =IF(OR($H8="Home Goal",$H8="Away Goal",$H8="Period End"),1,IF(AC8=1,1,"")) | AD9: 18988 | AE9: Nelson | AF9: Velodrome | AG9: =((C9*60)+D9) -> 830 | AH9: =((E9*60)+F9) -> 825 | AI9: =ROUND(AG9-AH9,0) -> 5 | AJ9: =COUNTIF(I9:N9,">0") -> 5 | AK9: =COUNTIF(P9:U9,">0") -> 5 | AL9: =IF(O9="",1,0) -> 0 | AM9: =IF(V9="",1,0) -> 0 | AN9: =IF(AND($AL9<>1,$AJ9<$AK9,AM9<>1),1,) -> 0 | AO9: =IF(AND($AL9<>1,$AJ9>$AK9),1,) -> 0 | AP9: =IF(AN9=1,1,0) -> 0 | AQ9: =IF(AO9=1,1,0) -> 0 | AR9: =IF(AND(AJ9=5,AK9=5,AL9=0,AM9=0),"Full Strength",IF(AP9=1,"Away PowerPlay",IF(AO9=1,"Home PowerPlay",IF(AL9=1,"Home EmptyNet",IF(AM9=1,"Away EmptyNet",""))))) -> Full Strength | AS9: =IF(AND(AL9=0,AM9=0),AJ9&"v"&AK9,IF(AL9=1,AJ9&"v"&AK9&" Home EN",IF(AM9=1,AJ9&"v"&AK9&" Away EN",""))) -> 5v5 | AT9: =IF($H8="Home Goal",AT8+1,AT8) -> 0 | AU9: =IF($H8="Away Goal",AU8+1,AU8) -> 0 | AV9: =IF(AND($H9="Home Goal", AO9=0),1,0) -> 0 | AW9: =IF(AX9=1,-1,0) -> 0 | AX9: =IF(AND($H9="Away Goal", AP9=0),1,0) -> 0 | AY9: =IF(AV9=1,-1,0) -> 0 | AZ9: =IFERROR(VLOOKUP(B9,events!AD:BR,37,FALSE),0) -> 0 | BA9: =ROUND(IF(G9="Intermission",BA8,((1080)-((C9*60)+D9))+AZ9),0) -> 250 | BB9: =IF(BA9<5,0,BA9-5) -> 245 | BC9: =BB9+AI9+3 -> 253
A10: =A9+1 -> 9 | B10: =IF(G10="PeriodStart",B9+1,B9) -> 1 | C10: =IF(G10<>"PeriodStart",E9,18) -> 13 | D10: =F9 -> 45 | E10: 13 | F10: 36 | I10: 79 | J10: 15 | K10: 44 | L10: 80 | M10: 37 | O10: =O9 -> 31 | P10: 49 | Q10: 14 | R10: 61 | S10: 9 | T10: 84 | V10: =V9 -> 39 | W10: =SUMIFS(events!AJ:AJ,events!Q:Q,"=DeadIce",events!AK:AK,"<="&shifts!AG10,events!AL:AL,">"&shifts!AH10,events!E:E,"="&shifts!B11)+SUMIFS(events!AJ:AJ,events!Q:Q,"=Timeout",events!AK:AK,"<="&shifts!AG10,events!AL:AL,">"&shifts!AH10,events!E:E,"="&shifts!B11) -> 0 | X10: =IF(OR($H9="Home Goal",$H9="Away Goal",$H9="Period End"),"",IF(Y9=1,1,"")) | Z10: =IF(OR($H9="Home Goal",$H9="Away Goal",$H9="Period End"),"",IF(AA9=1,1,"")) -> 1 | AA10: 1 | AB10: =IF(OR($H9="Home Goal",$H9="Away Goal",$H9="Period End"),1,IF(AC9=1,1,"")) | AD10: 18989 | AE10: Nelson | AF10: Velodrome | AG10: =((C10*60)+D10) -> 825 | AH10: =((E10*60)+F10) -> 816 | AI10: =ROUND(AG10-AH10,0) -> 9 | AJ10: =COUNTIF(I10:N10,">0") -> 5 | AK10: =COUNTIF(P10:U10,">0") -> 5 | AL10: =IF(O10="",1,0) -> 0 | AM10: =IF(V10="",1,0) -> 0 | AN10: =IF(AND($AL10<>1,$AJ10<$AK10,AM10<>1),1,) -> 0 | AO10: =IF(AND($AL10<>1,$AJ10>$AK10),1,) -> 0 | AP10: =IF(AN10=1,1,0) -> 0 | AQ10: =IF(AO10=1,1,0) -> 0 | AR10: =IF(AND(AJ10=5,AK10=5,AL10=0,AM10=0),"Full Strength",IF(AP10=1,"Away PowerPlay",IF(AO10=1,"Home PowerPlay",IF(AL10=1,"Home EmptyNet",IF(AM10=1,"Away EmptyNet",""))))) -> Full Strength | AS10: =IF(AND(AL10=0,AM10=0),AJ10&"v"&AK10,IF(AL10=1,AJ10&"v"&AK10&" Home EN",IF(AM10=1,AJ10&"v"&AK10&" Away EN",""))) -> 5v5 | AT10: =IF($H9="Home Goal",AT9+1,AT9) -> 0 | AU10: =IF($H9="Away Goal",AU9+1,AU9) -> 0 | AV10: =IF(AND($H10="Home Goal", AO10=0),1,0) -> 0 | AW10: =IF(AX10=1,-1,0) -> 0 | AX10: =IF(AND($H10="Away Goal", AP10=0),1,0) -> 0 | AY10: =IF(AV10=1,-1,0) -> 0 | AZ10: =IFERROR(VLOOKUP(B10,events!AD:BR,37,FALSE),0) -> 0 | BA10: =ROUND(IF(G10="Intermission",BA9,((1080)-((C10*60)+D10))+AZ10),0) -> 255 | BB10: =IF(BA10<5,0,BA10-5) -> 250 | BC10: =BB10+AI10+3 -> 262
A11: =A10+1 -> 10 | B11: =IF(G11="PeriodStart",B10+1,B10) -> 1 | C11: =IF(G11<>"PeriodStart",E10,18) -> 13 | D11: =F10 -> 36 | E11: 13 | F11: 31 | I11: 79 | J11: 15 | K11: 44 | L11: 80 | M11: 8 | O11: =O10 -> 31 | P11: 49 | Q11: 87 | R11: 61 | S11: 9 | T11: 84 | V11: =V10 -> 39 | W11: =SUMIFS(events!AJ:AJ,events!Q:Q,"=DeadIce",events!AK:AK,"<="&shifts!AG11,events!AL:AL,">"&shifts!AH11,events!E:E,"="&shifts!B12)+SUMIFS(events!AJ:AJ,events!Q:Q,"=Timeout",events!AK:AK,"<="&shifts!AG11,events!AL:AL,">"&shifts!AH11,events!E:E,"="&shifts!B12) -> 0 | X11: =IF(OR($H10="Home Goal",$H10="Away Goal",$H10="Period End"),"",IF(Y10=1,1,"")) | Z11: =IF(OR($H10="Home Goal",$H10="Away Goal",$H10="Period End"),"",IF(AA10=1,1,"")) -> 1 | AB11: =IF(OR($H10="Home Goal",$H10="Away Goal",$H10="Period End"),1,IF(AC10=1,1,"")) | AC11: 1 | AD11: 18990 | AE11: Nelson | AF11: Velodrome | AG11: =((C11*60)+D11) -> 816 | AH11: =((E11*60)+F11) -> 811 | AI11: =ROUND(AG11-AH11,0) -> 5 | AJ11: =COUNTIF(I11:N11,">0") -> 5 | AK11: =COUNTIF(P11:U11,">0") -> 5 | AL11: =IF(O11="",1,0) -> 0 | AM11: =IF(V11="",1,0) -> 0 | AN11: =IF(AND($AL11<>1,$AJ11<$AK11,AM11<>1),1,) -> 0 | AO11: =IF(AND($AL11<>1,$AJ11>$AK11),1,) -> 0 | AP11: =IF(AN11=1,1,0) -> 0 | AQ11: =IF(AO11=1,1,0) -> 0 | AR11: =IF(AND(AJ11=5,AK11=5,AL11=0,AM11=0),"Full Strength",IF(AP11=1,"Away PowerPlay",IF(AO11=1,"Home PowerPlay",IF(AL11=1,"Home EmptyNet",IF(AM11=1,"Away EmptyNet",""))))) -> Full Strength | AS11: =IF(AND(AL11=0,AM11=0),AJ11&"v"&AK11,IF(AL11=1,AJ11&"v"&AK11&" Home EN",IF(AM11=1,AJ11&"v"&AK11&" Away EN",""))) -> 5v5 | AT11: =IF($H10="Home Goal",AT10+1,AT10) -> 0 | AU11: =IF($H10="Away Goal",AU10+1,AU10) -> 0 | AV11: =IF(AND($H11="Home Goal", AO11=0),1,0) -> 0 | AW11: =IF(AX11=1,-1,0) -> 0 | AX11: =IF(AND($H11="Away Goal", AP11=0),1,0) -> 0 | AY11: =IF(AV11=1,-1,0) -> 0 | AZ11: =IFERROR(VLOOKUP(B11,events!AD:BR,37,FALSE),0) -> 0 | BA11: =ROUND(IF(G11="Intermission",BA10,((1080)-((C11*60)+D11))+AZ11),0) -> 264 | BB11: =IF(BA11<5,0,BA11-5) -> 259 | BC11: =BB11+AI11+3 -> 267
